Workbook
Name OLE_LINK1: 'Annex 3 Preserved charges'!#REF!

Sheet Overview
A2: Company and Licence name, charging year, effective from, status
B3: Company and Licence name | C3: Year | D3: Effective From | E3: Status
A4: Company and Licence name, charging year, effective from, status | B4: Eastern Power Networks | C4: 2020/21 | D4: 1 April 2020 | E4: Final
A6: List of data tables in this workbook
A7: Worksheet | B7: Information
A8: Annex 1 LV and HV charges | B8: Annex 1 contains the charges to LV and HV Designated Properties.
A9: Annex 2 EHV charges | B9: ="Annex 2 contains the charges to Designated EHV Properties and charges applied to LDNOs with Designated EHV Properties/end-users embedded in networks within the " &B4 &" Licence area." -> Annex 2 contains the charges to Designated EHV Properties and charges applied to LDNOs with Designated EHV Properties/end-users embedded in networks within the Eastern Power Networks Licence area.
A10: Annex 3 Preserved charges | B10: Annex 3 contains details of any preserved and additional charges that are valid at this time.
A11: Annex 4 LDNO charges | B11: ="Annex 4 contains charges that are levied on the owner of an embedded network within the "&B4&" Licence area. "&"Electricity suppliers and consumers who have properties connected to an embedded network should contact the embedded network owner to determine their distribution charges."&" The charges listed in this table are not payable by domestic consumers, business consumers or electricity suppliers." -> Annex 4 contains charges that are levied on the owner of an embedded network within the Eastern Power Networks Licence area. Electricity suppliers and consumers who have properties connected to an embedded network should contact the embedded network owner to determine their distribution charges. The charges listed in this table are not payable by domestic consumers, business consumers or electricity suppliers.
A12: Annex 5 LLFs | B12: Annex 5 has been intentionally left blank as this charging statement is published a complete year before the LLFs have been audited. The line loss factors that are approved by the BSC Panel for the applicable year and consequently published on the Elexon website will take precedence and be used in Settlement. This annex will be re-published with these values once they are available.
A13: Annex 6 Charges for New or Amended Designated EHV Properties | B13: ="Annex 6 contains the charges for new or amended Designated EHV Properties and charges applied to LDNOs with new or amended Designated EHV Properties/end-users embedded in networks within the " &B4 &" Licence area." -> Annex 6 contains the charges for new or amended Designated EHV Properties and charges applied to LDNOs with new or amended Designated EHV Properties/end-users embedded in networks within the Eastern Power Networks Licence area.
A14: Nodal prices | B14: Contains the underlying nodal costs used to calculate the current EDCM charges.
A15: SSC TPR to unit rate lookup table | B15: The time periods for the non half hourly metered charge rates in Annex 1 are as specified by the SSC. To determine the appropriate charge rate for each SSC/TPR a lookup table is provided.
A16: Charge calculator | B16: Charge calculator is a tool to help you estimate your distribution charges using current consumption data and forecast consumption data.
A18: Notes to users of this spreadsheet
A20: Please use this spreadsheet with reference to the LC14 use of system charging statement.
A22: Notes to DNOs populating this spreadsheet
A24: DNOs must endeavour to maintain consistency in the structure of this spreadsheet. Any changes to the structure must be noted in the 'Notes to users of this spreadsheet'
A25: The drop down list on the charge calculator can be expanded by unprotecting the charge calculator sheet and selecting 'data', 'data validation...' and then expanding the 'source' data range. The sheet can then be protected.

Sheet Annex 1 LV and HV charges
A1: Back to Overview | B1: Copy All-the-way section from CDCM Ouput 101-A in "Tariff Summary" tab into row 13 below | E1: Note: Where a tariff only has a p/kWh unit rate in Unit Charge 1 then this unit rate applies at all times.
A2: =Overview!B4& " - Effective from "&Overview!D4&" - "&Overview!E4&" LV and HV charges" -> Eastern Power Networks - Effective from 1 April 2020 - Final LV and HV charges
A4: Time Bands for Half Hourly Metered Properties | G4: Time Bands for Half Hourly Unmetered Properties
A5: Time periods | B5: Red Time Band | C5: Amber Time Band | E5: Green Time Band | I5: Black Time Band | J5: Yellow Time Band | K5: Green Time Band
A6: Monday to Friday (Including Bank Holidays) All Year | B6: 16:00 - 19:00 | C6: 07:00 - 16:00 19:00 - 23:00 | E6: 00:00 - 07:00 23:00 - 24:00 | G6: Monday to Friday (Including Bank Holidays) November to February Inclusive | I6: 16:00 - 19:00 | J6: 07:00 - 16:00 19:00 - 23:00 | K6: 00:00 - 07:00 23:00 - 24:00
A7: Saturday and Sunday All Year | E7: 00:00 - 24:00 | G7: Monday to Friday (Including Bank Holidays) March to October Inclusive | J7: 07:00 - 23:00 | K7: 00:00 - 07:00 23:00 - 24:00
A8: Notes | B8: All times are in UK Clock time | G8: Saturday and Sunday All Year | K8: 00:00 - 24:00
G9: Notes | I9: All times are in UK Clock time
A11: Tariff name | B11: Open LLFCs | C11: PCs | D11: Unit charge 1 (NHH) or red/black charge (HH) p/kWh | E11: Unit charge 2 (NHH) or amber/yellow charge (HH) p/kWh | F11: Green charge(HH) p/kWh | G11: Fixed charge p/MPAN/day | H11: Capacity charge p/kVA/day | I11: Exceeded capacity charge p/kVA/day | J11: Reactive power charge p/kVArh | K11: Closed LLFCs
A12: Domestic Unrestricted | B12: 3 | C12: 1 | D12: 2.194 | G12: 4.84 | K12: 40
A13: Domestic Two Rate | B13: 7 | C13: 2 | D13: 2.829 | E13: 0.18 | G13: 4.84 | K13: 11, 25, 43, 46, 58
A14: Domestic Off Peak (related MPAN) | B14: 22 | C14: 2 | D14: 0.242 | K14: 29, 55, 61
A15: Small Non Domestic Unrestricted | B15: 201 | C15: 3 | D15: 1.69 | G15: 4.84 | K15: 237, 238, 239
A16: Small Non Domestic Two Rate | B16: 205 | C16: 4 | D16: 2.052 | E16: 0.16 | G16: 4.84 | K16: 15, 49, 242, 247, 248
A17: Small Non Domestic Off Peak (related MPAN) | B17: 64 | C17: 4 | D17: 0.31 | K17: 33
A18: LV Medium Non-Domestic | B18: 254 | C18: 5-8 | D18: 2.222 | E18: 0.142 | G18: 51.55 | K18: 250
A19: LV Sub Medium Non-Domestic | C19: 5-8 | D19: 1.146 | E19: 0.108 | G19: 7.48
A20: HV Medium Non-Domestic | C20: 5-8 | D20: 0.747 | E20: 0.09 | G20: 102.89
A21: LV Network Domestic | B21: 1 | C21: 0 | D21: 15.283 | E21: 0.486 | F21: 0.135 | G21: 4.84
A22: LV Network Non-Domestic Non-CT | B22: 200 | C22: 0 | D22: 13.13 | E22: 0.429 | F22: 0.127 | G22: 5.42
A23: LV HH Metered | B23: 19, 86 | C23: 0 | D23: 9.8 | E23: 0.314 | F23: 0.11 | G23: 12.76 | H23: 3.64 | I23: 7.56 | J23: 0.315
A24: LV Sub HH Metered | B24: 79, 80 | C24: 0 | D24: 7.104 | E24: 0.215 | F24: 0.096 | G24: 7.48 | H24: 5.18 | I24: 6.8 | J24: 0.208
A25: HV HH Metered | B25: 84, 89 | C25: 0 | D25: 5.765 | E25: 0.174 | F25: 0.09 | G25: 102.89 | H25: 4.28 | I25: 6.02 | J25: 0.167
A26: NHH UMS category A | B26: 100, 110, 150, 160 | C26: 8 | D26: 2.119
A27: NHH UMS category B | B27: 102, 112, 152, 162 | C27: 1 | D27: 2.943
A28: NHH UMS category C | B28: 103, 113, 153, 163 | C28: 1 | D28: 4.869
A29: NHH UMS category D | B29: 101, 111, 151, 161 | C29: 1 | D29: 1.581
A30: LV UMS (Pseudo HH Metered) | B30: 350 | C30: 0 | D30: 40.982 | E30: 1.125 | F30: 0.781
A31: LV Generation NHH or Aggregate HH | B31: 912 | C31: 8 or 0 | D31: -0.983 | G31: 0 | K31: 905, 913
A32: LV Sub Generation NHH | C32: 8 | D32: -0.869 | G32: 0
A33: LV Generation Intermittent | B33: 980 | C33: 0 | D33: -0.983 | G33: 0 | J33: 0.289
A34: LV Generation Intermittent no RP charge | B34: 981 | C34: 0 | D34: -0.983 | G34: 0
A35: LV Generation Non-Intermittent | B35: 982 | C35: 0 | D35: -9.667 | E35: -0.259 | F35: -0.036 | G35: 0 | J35: 0.289
A36: LV Generation Non-Intermittent no RP charge | B36: 983 | C36: 0 | D36: -9.667 | E36: -0.259 | F36: -0.036 | G36: 0
A37: LV Sub Generation Intermittent | B37: 984 | C37: 0 | D37: -0.869 | G37: 0 | J37: 0.255
A38: LV Sub Generation Intermittent no RP charge | B38: 985 | C38: 0 | D38: -0.869 | G38: 0
A39: LV Sub Generation Non-Intermittent | B39: 986 | C39: 0 | D39: -8.618 | E39: -0.217 | F39: -0.029 | G39: 0 | J39: 0.255
A40: LV Sub Generation Non-Intermittent no RP charge | B40: 987 | C40: 0 | D40: -8.618 | E40: -0.217 | F40: -0.029 | G40: 0
A41: HV Generation Intermittent | B41: 988 | C41: 0 | D41: -0.621 | G41: 9.02 | J41: 0.207
A42: HV Generation Intermittent no RP charge | B42: 989 | C42: 0 | D42: -0.621 | G42: 9.02
...

Sheet Annex 2 EHV charges
A1: Back to Overview | C1: Copy data from EDCM Outputs 202-A in "LDNO tariffs transposed" tab into row 11 | F1: Note: The list of MPANs / MSIDs provided may be incomplete; the DNO reserves the right to apply the listed charges to any other MPANs / MSIDs associated with the site.
A2: =Overview!B4& " - Effective from "&Overview!D4&" - "&Overview!E4&" EDCM charges" -> Eastern Power Networks - Effective from 1 April 2020 - Final EDCM charges
A4: Time Periods for Designated EHV Properties
A5: Time periods | D5: Super Red Time Band
A6: Monday to Friday (Including Bank Holidays) November to February Inclusive | D6: 16:00 - 19:00
A7: Notes | D7: All times are in UK Clock time
A9: Import Unique Identifier | B9: LLFC | C9: Import MPANs/MSIDs | D9: Export Unique Identifier | E9: LLFC | F9: Export MPANs/MSIDs | G9: Name | H9: Import Super Red unit charge (p/kWh) | I9: Import fixed charge (p/day) | J9: Import capacity charge (p/kVA/day) | K9: Import exceeded capacity charge (p/kVA/day) | L9: Export Super Red unit charge (p/kWh) | M9: Export fixed charge (p/day) | N9: Export capacity charge (p/kVA/day) | O9: Export exceeded capacity charge (p/kVA/day)
A10: 3VALSW | B10: 585 | C10: 1014569699836 | G10: 3VALSW | I10: 2914.69 | J10: 5.3 | K10: 5.3
A11: ABSRSF | B11: 869 | C11: 1050000574685 | D11: ABSRSF | E11: 744 | F11: 1050000574694 | G11: ABSRSF | H11: 0.173 | I11: 18.4 | J11: 1.73 | K11: 1.73 | M11: 3679.33 | N11: 0.05 | O11: 0.05
A12: ADBRKS | B12: 586 | C12: 1023529546480 | G12: ADBRKS | H12: 0.162 | I12: 3094.55 | J12: 3.51 | K12: 3.51
A13: AIAMAN | B13: 499 | C13: 1014569292506 | D13: AIAMAN | E13: 435 | F13: 1030054607984 | G13: AIAMAN | H13: 0.652 | I13: 8.56 | J13: 8.9 | K13: 8.9 | L13: -0.626 | M13: 171.29 | N13: 0.05 | O13: 0.05
A14: ALCORG | B14: 300 | C14: 1050001015545 | D14: ALCORG | E14: 651 | F14: 1050000998050 | G14: ALCORG | I14: 5.11 | J14: 2.26 | K14: 2.26 | M14: 510.86 | N14: 0.05 | O14: 0.05
A15: ARAMAN | B15: 800 | C15: 1023483097981 | G15: ARAMAN | I15: 6701.37 | J15: 1 | K15: 1
A16: ARDLGH | B16: 564 | C16: 1050001061597 | D16: ARDLGH | E16: 666 | F16: 1050001061602 | G16: ARDLGH | H16: 0.275 | I16: 1.99 | J16: 4 | K16: 4 | M16: 795.65 | N16: 0.05 | O16: 0.05
A17: ARLAFD | B17: 587 | C17: 1030081553176 1030081553404 | D17: ARLAFD | E17: 710 | F17: 1030085114723 1030085114955 | G17: ARLAFD | I17: 3312.05 | J17: 1.7 | K17: 1.7 | M17: 1104.02 | N17: 0.05 | O17: 0.05
A18: ASTONC | B18: 503 | C18: 1050000834246 | D18: ASTONC | E18: 780 | F18: 1050000834255 | G18: ASTONC | H18: 1.797 | I18: 2.6 | J18: 3.6 | K18: 3.6 | M18: 520.15 | N18: 0.05 | O18: 0.05
A19: AVENUE | B19: 504 | C19: 1050000774970 | D19: AVENUE | E19: 781 | F19: 1050000774980 | G19: AVENUE | H19: 0.071 | I19: 17.3 | J19: 3.24 | K19: 3.24 | M19: 1124.59 | N19: 0.05 | O19: 0.05
A20: AWOUSE | B20: 589 | C20: 1023475403798 1014571965793 | G20: AWOUSE | H20: 3.024 | I20: 179.86 | J20: 2.19 | K20: 2.19
A21: BARNFM | B21: 301 | C21: 1050000774999 | D21: BARNFM | E21: 652 | F21: 1050000775005 | G21: BARNFM | H21: 0.334 | I21: 51.03 | J21: 4.18 | K21: 4.18 | M21: 2143.45 | N21: 0.05 | O21: 0.05
A22: BAYFMS | B22: 870 | C22: 1050000579318 | D22: BAYFMS | E22: 745 | F22: 1050000579327 | G22: BAYFMS | H22: 0.107 | I22: 35.35 | J22: 1.55 | K22: 1.55 | M22: 2827.82 | N22: 0.05 | O22: 0.05
A23: BDGHSE | B23: 505 | C23: 1050000669548 | D23: BDGHSE | E23: 782 | F23: 1050000669539 | G23: BDGHSE | I23: 28.47 | J23: 1.48 | K23: 1.48 | M23: 1061.26 | N23: 0.05 | O23: 0.05
A24: BDWLWF | B24: 827 | C24: 1030082700415 | D24: BDWLWF | E24: 734 | F24: 1030082700647 | G24: BDWLWF | H24: 0.013 | I24: 33.48 | J24: 1.97 | K24: 1.97 | M24: 4235.2 | N24: 0.05 | O24: 0.05
A25: BERDHF | B25: 302 | C25: 1050001382522 | D25: BERDHF | E25: 436 | F25: 1050001382531 | G25: BERDHF | I25: 1326 | J25: 1.14 | K25: 1.14 | M25: 1325.75 | N25: 0.05 | O25: 0.05
A26: BERMAT | B26: 590 | C26: 1014571751895 | G26: BERMAT | I26: 89.93 | J26: 5.38 | K26: 5.38
A27: BGWDWF | B27: 871 | C27: 1030083931374 | D27: BGWDWF | E27: 746 | F27: 1030083931142 | G27: BGWDWF | I27: 3.42 | J27: 2.33 | K27: 2.33 | M27: 280.64 | N27: 0.05 | O27: 0.05
A28: BLCAMB | B28: 539 | C28: 1050001036615 | D28: BLCAMB | E28: 653 | F28: 1050001036624 | G28: BLCAMB | I28: 5.06 | J28: 1.68 | K28: 1.68 | M28: 252.93 | N28: 0.05 | O28: 0.05
A29: BLDOCK | C29: MSID: 7308 | D29: BLDOCK | F29: MSID: 7308 | G29: BLDOCK | H29: 1.211 | I29: 37.6 | J29: 1.34 | K29: 1.34 | L29: -1.428 | M29: 752.01 | N29: 0.05 | O29: 0.05
A30: BLGTSF | B30: 534 | C30: 1050000769039 | D30: BLGTSF | E30: 466 | F30: 1050000769048 | G30: BLGTSF | I30: 11.87 | J30: 2.52 | K30: 2.52 | M30: 1127.21 | N30: 0.05 | O30: 0.05
A31: BNNSHL | B31: 540 | C31: 1050001021414 | D31: BNNSHL | E31: 654 | F31: 1050001021423 | G31: BNNSHL | H31: 9.413 | I31: 35.55 | J31: 1.74 | K31: 1.74 | M31: 1520.81 | N31: 0.05 | O31: 0.05
A32: BOCTHA | B32: 803 | C32: 1014572608412 | G32: BOCTHA | H32: 0.654 | I32: 973.99 | J32: 5.37 | K32: 5.37
A33: BOXTED | B33: 506 | C33: 1050000774270 | D33: BOXTED | E33: 783 | F33: 1050000774289 | G33: BOXTED | H33: 0.025 | I33: 1.58 | J33: 2.27 | K33: 2.27 | M33: 256.4 | N33: 0.05 | O33: 0.05
A34: BPA_CO | B34: 804 | C34: 1014572578282 | G34: BPA_CO | H34: 0.168 | I34: 515.97 | J34: 2.64 | K34: 2.64
A35: BPTLTD | B35: 591 | C35: 1023475256360 1014572502380 | G35: BPTLTD | H35: 1.03 | I35: 269.79 | J35: 1.99 | K35: 1.99
A36: BRCHGP | B36: 525 | C36: 1050000961956 | D36: BRCHGP | E36: 457 | F36: 1050000961965 | G36: BRCHGP | H36: 0.405 | I36: 35.84 | J36: 1.67 | K36: 1.67 | M36: 2204.22 | N36: 0.05 | O36: 0.05
A37: BROGB_ | B37: 821 | C37: 1030041592510 1030041592742 1030041592974 1030041593203 | G37: BROGB_ | H37: 0.002 | I37: 246.8 | J37: 1.54 | K37: 1.54
A38: BROXSF | B38: 872 | C38: 1050000521610 | D38: BROXSF | E38: 747 | F38: 1030085039971 | G38: BROXSF | H38: 1.395 | I38: 11.29 | J38: 6.4 | K38: 6.4 | M38: 2596.82 | N38: 0.05 | O38: 0.05
A39: BRTHS2 | B39: 508 | C39: 1050000782944 | D39: BRTHS2 | E39: 785 | F39: 1050000773842 | G39: BRTHS2 | H39: 0.02 | I39: 1.28 | J39: 2.73 | K39: 2.73 | M39: 256.7 | N39: 0.05 | O39: 0.05
A40: BRTHSS | B40: 873 | C40: 1030083941266 | D40: BRTHSS | E40: 735 | F40: 1030083941034 | G40: BRTHSS | H40: 0.007 | I40: 2.85 | J40: 2.09 | K40: 2.09 | M40: 255.14 | N40: 0.05 | O40: 0.05
A41: BRTHSW | B41: 874 | C41: 1030083918035 | D41: BRTHSW | E41: 748 | F41: 1030083917802 | G41: BRTHSW | H41: 0.02 | I41: 7.3 | J41: 1.5 | K41: 1.5 | M41: 250.68 | N41: 0.05 | O41: 0.05
A42: BS_BUR | B42: 805 | C42: 1023485782314 1050000914910 | D42: BS_BUR | E42: 700 | F42: 1023485782546 1050000914900 | G42: BS_BUR | H42: 1.249 | I42: 94.86 | J42: 1.41 | K42: 1.41 | L42: -1.249 | M42: 679.1 | N42: 0.05 | O42: 0.05
...

Sheet Annex 2a Import
A1: Note: The list of MPANs / MSIDs provided may be incomplete; the DNO reserves the right to apply the listed charges to any other MPANs / MSIDs associated with the site. Note: This table is automatically populated based on the content of the tab entitled 'Annex 2 EHV Charges'. The timebands are as shown in Annex 2.
A2: =Overview!B4& " - Effective from "&Overview!D4&" - "&Overview!E4&" EDCM import charges" -> Eastern Power Networks - Effective from 1 April 2020 - Final EDCM import charges
A4: Import Unique Identifier | B4: LLFC | C4: Import MPANs/MSIDs | D4: Name | E4: ='Annex 2 EHV charges'!H9 -> Import Super Red unit charge (p/kWh) | F4: ='Annex 2 EHV charges'!I9 -> Import fixed charge (p/day) | G4: ='Annex 2 EHV charges'!J9 -> Import capacity charge (p/kVA/day) | H4: ='Annex 2 EHV charges'!K9 -> Import exceeded capacity charge (p/kVA/day)
A5: {=IFERROR(INDEX('Annex 2 EHV charges'!$A$10:$A$301, MATCH(0, IF(ISBLANK('Annex 2 EHV charges'!$A$10:$A$301),1, COUNTIF(A$4:$A4, 'Annex 2 EHV charges'!$A$10:$A$301)), 0)),"")} -> 3VALSW | B5: =IF($A5="","",VLOOKUP($A5,'Annex 2 EHV charges'!$A:$O,2,0)) -> 585 | C5: =IF($A5="","",VLOOKUP($A5,'Annex 2 EHV charges'!$A:$O,3,0)) -> 1014569699836 | D5: =IF($A5="","",VLOOKUP($A5,'Annex 2 EHV charges'!$A:$O,7,0)) -> 3VALSW | E5: =IFERROR(IF(VLOOKUP($A5,'Annex 2 EHV charges'!$A:$O,8,FALSE)=0,"",VLOOKUP($A5,'Annex 2 EHV charges'!$A:$O,8,FALSE)),"") | F5: =IFERROR(IF(VLOOKUP($A5,'Annex 2 EHV charges'!$A:$O,9,FALSE)=0,"",VLOOKUP($A5,'Annex 2 EHV charges'!$A:$O,9,FALSE)),"") -> 2914.69 | G5: =IFERROR(IF(VLOOKUP($A5,'Annex 2 EHV charges'!$A:$O,10,FALSE)=0,"",VLOOKUP($A5,'Annex 2 EHV charges'!$A:$O,10,FALSE)),"") -> 5.3 | H5: =IFERROR(IF(VLOOKUP($A5,'Annex 2 EHV charges'!$A:$O,11,FALSE)=0,"",VLOOKUP($A5,'Annex 2 EHV charges'!$A:$O,11,FALSE)),"") -> 5.3
A6: {=IFERROR(INDEX('Annex 2 EHV charges'!$A$10:$A$301, MATCH(0, IF(ISBLANK('Annex 2 EHV charges'!$A$10:$A$301),1, COUNTIF(A$4:$A5, 'Annex 2 EHV charges'!$A$10:$A$301)), 0)),"")} -> ABSRSF | B6: =IF($A6="","",VLOOKUP($A6,'Annex 2 EHV charges'!$A:$O,2,0)) -> 869 | C6: =IF($A6="","",VLOOKUP($A6,'Annex 2 EHV charges'!$A:$O,3,0)) -> 1050000574685 | D6: =IF($A6="","",VLOOKUP($A6,'Annex 2 EHV charges'!$A:$O,7,0)) -> ABSRSF | E6: =IFERROR(IF(VLOOKUP($A6,'Annex 2 EHV charges'!$A:$O,8,FALSE)=0,"",VLOOKUP($A6,'Annex 2 EHV charges'!$A:$O,8,FALSE)),"") -> 0.173 | F6: =IFERROR(IF(VLOOKUP($A6,'Annex 2 EHV charges'!$A:$O,9,FALSE)=0,"",VLOOKUP($A6,'Annex 2 EHV charges'!$A:$O,9,FALSE)),"") -> 18.4 | G6: =IFERROR(IF(VLOOKUP($A6,'Annex 2 EHV charges'!$A:$O,10,FALSE)=0,"",VLOOKUP($A6,'Annex 2 EHV charges'!$A:$O,10,FALSE)),"") -> 1.73 | H6: =IFERROR(IF(VLOOKUP($A6,'Annex 2 EHV charges'!$A:$O,11,FALSE)=0,"",VLOOKUP($A6,'Annex 2 EHV charges'!$A:$O,11,FALSE)),"") -> 1.73
A7: {=IFERROR(INDEX('Annex 2 EHV charges'!$A$10:$A$301, MATCH(0, IF(ISBLANK('Annex 2 EHV charges'!$A$10:$A$301),1, COUNTIF(A$4:$A6, 'Annex 2 EHV charges'!$A$10:$A$301)), 0)),"")} -> ADBRKS | B7: =IF($A7="","",VLOOKUP($A7,'Annex 2 EHV charges'!$A:$O,2,0)) -> 586 | C7: =IF($A7="","",VLOOKUP($A7,'Annex 2 EHV charges'!$A:$O,3,0)) -> 1023529546480 | D7: =IF($A7="","",VLOOKUP($A7,'Annex 2 EHV charges'!$A:$O,7,0)) -> ADBRKS | E7: =IFERROR(IF(VLOOKUP($A7,'Annex 2 EHV charges'!$A:$O,8,FALSE)=0,"",VLOOKUP($A7,'Annex 2 EHV charges'!$A:$O,8,FALSE)),"") -> 0.162 | F7: =IFERROR(IF(VLOOKUP($A7,'Annex 2 EHV charges'!$A:$O,9,FALSE)=0,"",VLOOKUP($A7,'Annex 2 EHV charges'!$A:$O,9,FALSE)),"") -> 3094.55 | G7: =IFERROR(IF(VLOOKUP($A7,'Annex 2 EHV charges'!$A:$O,10,FALSE)=0,"",VLOOKUP($A7,'Annex 2 EHV charges'!$A:$O,10,FALSE)),"") -> 3.51 | H7: =IFERROR(IF(VLOOKUP($A7,'Annex 2 EHV charges'!$A:$O,11,FALSE)=0,"",VLOOKUP($A7,'Annex 2 EHV charges'!$A:$O,11,FALSE)),"") -> 3.51
A8: {=IFERROR(INDEX('Annex 2 EHV charges'!$A$10:$A$301, MATCH(0, IF(ISBLANK('Annex 2 EHV charges'!$A$10:$A$301),1, COUNTIF(A$4:$A7, 'Annex 2 EHV charges'!$A$10:$A$301)), 0)),"")} -> AIAMAN | B8: =IF($A8="","",VLOOKUP($A8,'Annex 2 EHV charges'!$A:$O,2,0)) -> 499 | C8: =IF($A8="","",VLOOKUP($A8,'Annex 2 EHV charges'!$A:$O,3,0)) -> 1014569292506 | D8: =IF($A8="","",VLOOKUP($A8,'Annex 2 EHV charges'!$A:$O,7,0)) -> AIAMAN | E8: =IFERROR(IF(VLOOKUP($A8,'Annex 2 EHV charges'!$A:$O,8,FALSE)=0,"",VLOOKUP($A8,'Annex 2 EHV charges'!$A:$O,8,FALSE)),"") -> 0.652 | F8: =IFERROR(IF(VLOOKUP($A8,'Annex 2 EHV charges'!$A:$O,9,FALSE)=0,"",VLOOKUP($A8,'Annex 2 EHV charges'!$A:$O,9,FALSE)),"") -> 8.56 | G8: =IFERROR(IF(VLOOKUP($A8,'Annex 2 EHV charges'!$A:$O,10,FALSE)=0,"",VLOOKUP($A8,'Annex 2 EHV charges'!$A:$O,10,FALSE)),"") -> 8.9 | H8: =IFERROR(IF(VLOOKUP($A8,'Annex 2 EHV charges'!$A:$O,11,FALSE)=0,"",VLOOKUP($A8,'Annex 2 EHV charges'!$A:$O,11,FALSE)),"") -> 8.9
A9: {=IFERROR(INDEX('Annex 2 EHV charges'!$A$10:$A$301, MATCH(0, IF(ISBLANK('Annex 2 EHV charges'!$A$10:$A$301),1, COUNTIF(A$4:$A8, 'Annex 2 EHV charges'!$A$10:$A$301)), 0)),"")} -> ALCORG | B9: =IF($A9="","",VLOOKUP($A9,'Annex 2 EHV charges'!$A:$O,2,0)) -> 300 | C9: =IF($A9="","",VLOOKUP($A9,'Annex 2 EHV charges'!$A:$O,3,0)) -> 1050001015545 | D9: =IF($A9="","",VLOOKUP($A9,'Annex 2 EHV charges'!$A:$O,7,0)) -> ALCORG | E9: =IFERROR(IF(VLOOKUP($A9,'Annex 2 EHV charges'!$A:$O,8,FALSE)=0,"",VLOOKUP($A9,'Annex 2 EHV charges'!$A:$O,8,FALSE)),"") | F9: =IFERROR(IF(VLOOKUP($A9,'Annex 2 EHV charges'!$A:$O,9,FALSE)=0,"",VLOOKUP($A9,'Annex 2 EHV charges'!$A:$O,9,FALSE)),"") -> 5.11 | G9: =IFERROR(IF(VLOOKUP($A9,'Annex 2 EHV charges'!$A:$O,10,FALSE)=0,"",VLOOKUP($A9,'Annex 2 EHV charges'!$A:$O,10,FALSE)),"") -> 2.26 | H9: =IFERROR(IF(VLOOKUP($A9,'Annex 2 EHV charges'!$A:$O,11,FALSE)=0,"",VLOOKUP($A9,'Annex 2 EHV charges'!$A:$O,11,FALSE)),"") -> 2.26
A10: {=IFERROR(INDEX('Annex 2 EHV charges'!$A$10:$A$301, MATCH(0, IF(ISBLANK('Annex 2 EHV charges'!$A$10:$A$301),1, COUNTIF(A$4:$A9, 'Annex 2 EHV charges'!$A$10:$A$301)), 0)),"")} -> ARAMAN | B10: =IF($A10="","",VLOOKUP($A10,'Annex 2 EHV charges'!$A:$O,2,0)) -> 800 | C10: =IF($A10="","",VLOOKUP($A10,'Annex 2 EHV charges'!$A:$O,3,0)) -> 1023483097981 | D10: =IF($A10="","",VLOOKUP($A10,'Annex 2 EHV charges'!$A:$O,7,0)) -> ARAMAN | E10: =IFERROR(IF(VLOOKUP($A10,'Annex 2 EHV charges'!$A:$O,8,FALSE)=0,"",VLOOKUP($A10,'Annex 2 EHV charges'!$A:$O,8,FALSE)),"") | F10: =IFERROR(IF(VLOOKUP($A10,'Annex 2 EHV charges'!$A:$O,9,FALSE)=0,"",VLOOKUP($A10,'Annex 2 EHV charges'!$A:$O,9,FALSE)),"") -> 6701.37 | G10: =IFERROR(IF(VLOOKUP($A10,'Annex 2 EHV charges'!$A:$O,10,FALSE)=0,"",VLOOKUP($A10,'Annex 2 EHV charges'!$A:$O,10,FALSE)),"") -> 1 | H10: =IFERROR(IF(VLOOKUP($A10,'Annex 2 EHV charges'!$A:$O,11,FALSE)=0,"",VLOOKUP($A10,'Annex 2 EHV charges'!$A:$O,11,FALSE)),"") -> 1
A11: {=IFERROR(INDEX('Annex 2 EHV charges'!$A$10:$A$301, MATCH(0, IF(ISBLANK('Annex 2 EHV charges'!$A$10:$A$301),1, COUNTIF(A$4:$A10, 'Annex 2 EHV charges'!$A$10:$A$301)), 0)),"")} -> ARDLGH | B11: =IF($A11="","",VLOOKUP($A11,'Annex 2 EHV charges'!$A:$O,2,0)) -> 564 | C11: =IF($A11="","",VLOOKUP($A11,'Annex 2 EHV charges'!$A:$O,3,0)) -> 1050001061597 | D11: =IF($A11="","",VLOOKUP($A11,'Annex 2 EHV charges'!$A:$O,7,0)) -> ARDLGH | E11: =IFERROR(IF(VLOOKUP($A11,'Annex 2 EHV charges'!$A:$O,8,FALSE)=0,"",VLOOKUP($A11,'Annex 2 EHV charges'!$A:$O,8,FALSE)),"") -> 0.275 | F11: =IFERROR(IF(VLOOKUP($A11,'Annex 2 EHV charges'!$A:$O,9,FALSE)=0,"",VLOOKUP($A11,'Annex 2 EHV charges'!$A:$O,9,FALSE)),"") -> 1.99 | G11: =IFERROR(IF(VLOOKUP($A11,'Annex 2 EHV charges'!$A:$O,10,FALSE)=0,"",VLOOKUP($A11,'Annex 2 EHV charges'!$A:$O,10,FALSE)),"") -> 4 | H11: =IFERROR(IF(VLOOKUP($A11,'Annex 2 EHV charges'!$A:$O,11,FALSE)=0,"",VLOOKUP($A11,'Annex 2 EHV charges'!$A:$O,11,FALSE)),"") -> 4
A12: {=IFERROR(INDEX('Annex 2 EHV charges'!$A$10:$A$301, MATCH(0, IF(ISBLANK('Annex 2 EHV charges'!$A$10:$A$301),1, COUNTIF(A$4:$A11, 'Annex 2 EHV charges'!$A$10:$A$301)), 0)),"")} -> ARLAFD | B12: =IF($A12="","",VLOOKUP($A12,'Annex 2 EHV charges'!$A:$O,2,0)) -> 587 | C12: =IF($A12="","",VLOOKUP($A12,'Annex 2 EHV charges'!$A:$O,3,0)) -> 1030081553176 1030081553404 | D12: =IF($A12="","",VLOOKUP($A12,'Annex 2 EHV charges'!$A:$O,7,0)) -> ARLAFD | E12: =IFERROR(IF(VLOOKUP($A12,'Annex 2 EHV charges'!$A:$O,8,FALSE)=0,"",VLOOKUP($A12,'Annex 2 EHV charges'!$A:$O,8,FALSE)),"") | F12: =IFERROR(IF(VLOOKUP($A12,'Annex 2 EHV charges'!$A:$O,9,FALSE)=0,"",VLOOKUP($A12,'Annex 2 EHV charges'!$A:$O,9,FALSE)),"") -> 3312.05 | G12: =IFERROR(IF(VLOOKUP($A12,'Annex 2 EHV charges'!$A:$O,10,FALSE)=0,"",VLOOKUP($A12,'Annex 2 EHV charges'!$A:$O,10,FALSE)),"") -> 1.7 | H12: =IFERROR(IF(VLOOKUP($A12,'Annex 2 EHV charges'!$A:$O,11,FALSE)=0,"",VLOOKUP($A12,'Annex 2 EHV charges'!$A:$O,11,FALSE)),"") -> 1.7
A13: {=IFERROR(INDEX('Annex 2 EHV charges'!$A$10:$A$301, MATCH(0, IF(ISBLANK('Annex 2 EHV charges'!$A$10:$A$301),1, COUNTIF(A$4:$A12, 'Annex 2 EHV charges'!$A$10:$A$301)), 0)),"")} -> ASTONC | B13: =IF($A13="","",VLOOKUP($A13,'Annex 2 EHV charges'!$A:$O,2,0)) -> 503 | C13: =IF($A13="","",VLOOKUP($A13,'Annex 2 EHV charges'!$A:$O,3,0)) -> 1050000834246 | D13: =IF($A13="","",VLOOKUP($A13,'Annex 2 EHV charges'!$A:$O,7,0)) -> ASTONC | E13: =IFERROR(IF(VLOOKUP($A13,'Annex 2 EHV charges'!$A:$O,8,FALSE)=0,"",VLOOKUP($A13,'Annex 2 EHV charges'!$A:$O,8,FALSE)),"") -> 1.797 | F13: =IFERROR(IF(VLOOKUP($A13,'Annex 2 EHV charges'!$A:$O,9,FALSE)=0,"",VLOOKUP($A13,'Annex 2 EHV charges'!$A:$O,9,FALSE)),"") -> 2.6 | G13: =IFERROR(IF(VLOOKUP($A13,'Annex 2 EHV charges'!$A:$O,10,FALSE)=0,"",VLOOKUP($A13,'Annex 2 EHV charges'!$A:$O,10,FALSE)),"") -> 3.6 | H13: =IFERROR(IF(VLOOKUP($A13,'Annex 2 EHV charges'!$A:$O,11,FALSE)=0,"",VLOOKUP($A13,'Annex 2 EHV charges'!$A:$O,11,FALSE)),"") -> 3.6
A14: {=IFERROR(INDEX('Annex 2 EHV charges'!$A$10:$A$301, MATCH(0, IF(ISBLANK('Annex 2 EHV charges'!$A$10:$A$301),1, COUNTIF(A$4:$A13, 'Annex 2 EHV charges'!$A$10:$A$301)), 0)),"")} -> AVENUE | B14: =IF($A14="","",VLOOKUP($A14,'Annex 2 EHV charges'!$A:$O,2,0)) -> 504 | C14: =IF($A14="","",VLOOKUP($A14,'Annex 2 EHV charges'!$A:$O,3,0)) -> 1050000774970 | D14: =IF($A14="","",VLOOKUP($A14,'Annex 2 EHV charges'!$A:$O,7,0)) -> AVENUE | E14: =IFERROR(IF(VLOOKUP($A14,'Annex 2 EHV charges'!$A:$O,8,FALSE)=0,"",VLOOKUP($A14,'Annex 2 EHV charges'!$A:$O,8,FALSE)),"") -> 0.071 | F14: =IFERROR(IF(VLOOKUP($A14,'Annex 2 EHV charges'!$A:$O,9,FALSE)=0,"",VLOOKUP($A14,'Annex 2 EHV charges'!$A:$O,9,FALSE)),"") -> 17.3 | G14: =IFERROR(IF(VLOOKUP($A14,'Annex 2 EHV charges'!$A:$O,10,FALSE)=0,"",VLOOKUP($A14,'Annex 2 EHV charges'!$A:$O,10,FALSE)),"") -> 3.24 | H14: =IFERROR(IF(VLOOKUP($A14,'Annex 2 EHV charges'!$A:$O,11,FALSE)=0,"",VLOOKUP($A14,'Annex 2 EHV charges'!$A:$O,11,FALSE)),"") -> 3.24
A15: {=IFERROR(INDEX('Annex 2 EHV charges'!$A$10:$A$301, MATCH(0, IF(ISBLANK('Annex 2 EHV charges'!$A$10:$A$301),1, COUNTIF(A$4:$A14, 'Annex 2 EHV charges'!$A$10:$A$301)), 0)),"")} -> AWOUSE | B15: =IF($A15="","",VLOOKUP($A15,'Annex 2 EHV charges'!$A:$O,2,0)) -> 589 | C15: =IF($A15="","",VLOOKUP($A15,'Annex 2 EHV charges'!$A:$O,3,0)) -> 1023475403798 1014571965793 | D15: =IF($A15="","",VLOOKUP($A15,'Annex 2 EHV charges'!$A:$O,7,0)) -> AWOUSE | E15: =IFERROR(IF(VLOOKUP($A15,'Annex 2 EHV charges'!$A:$O,8,FALSE)=0,"",VLOOKUP($A15,'Annex 2 EHV charges'!$A:$O,8,FALSE)),"") -> 3.024 | F15: =IFERROR(IF(VLOOKUP($A15,'Annex 2 EHV charges'!$A:$O,9,FALSE)=0,"",VLOOKUP($A15,'Annex 2 EHV charges'!$A:$O,9,FALSE)),"") -> 179.86 | G15: =IFERROR(IF(VLOOKUP($A15,'Annex 2 EHV charges'!$A:$O,10,FALSE)=0,"",VLOOKUP($A15,'Annex 2 EHV charges'!$A:$O,10,FALSE)),"") -> 2.19 | H15: =IFERROR(IF(VLOOKUP($A15,'Annex 2 EHV charges'!$A:$O,11,FALSE)=0,"",VLOOKUP($A15,'Annex 2 EHV charges'!$A:$O,11,FALSE)),"") -> 2.19
A16: {=IFERROR(INDEX('Annex 2 EHV charges'!$A$10:$A$301, MATCH(0, IF(ISBLANK('Annex 2 EHV charges'!$A$10:$A$301),1, COUNTIF(A$4:$A15, 'Annex 2 EHV charges'!$A$10:$A$301)), 0)),"")} -> BARNFM | B16: =IF($A16="","",VLOOKUP($A16,'Annex 2 EHV charges'!$A:$O,2,0)) -> 301 | C16: =IF($A16="","",VLOOKUP($A16,'Annex 2 EHV charges'!$A:$O,3,0)) -> 1050000774999 | D16: =IF($A16="","",VLOOKUP($A16,'Annex 2 EHV charges'!$A:$O,7,0)) -> BARNFM | E16: =IFERROR(IF(VLOOKUP($A16,'Annex 2 EHV charges'!$A:$O,8,FALSE)=0,"",VLOOKUP($A16,'Annex 2 EHV charges'!$A:$O,8,FALSE)),"") -> 0.334 | F16: =IFERROR(IF(VLOOKUP($A16,'Annex 2 EHV charges'!$A:$O,9,FALSE)=0,"",VLOOKUP($A16,'Annex 2 EHV charges'!$A:$O,9,FALSE)),"") -> 51.03 | G16: =IFERROR(IF(VLOOKUP($A16,'Annex 2 EHV charges'!$A:$O,10,FALSE)=0,"",VLOOKUP($A16,'Annex 2 EHV charges'!$A:$O,10,FALSE)),"") -> 4.18 | H16: =IFERROR(IF(VLOOKUP($A16,'Annex 2 EHV charges'!$A:$O,11,FALSE)=0,"",VLOOKUP($A16,'Annex 2 EHV charges'!$A:$O,11,FALSE)),"") -> 4.18
... A259: {=IFERROR(INDEX('Annex 2 EHV charges'!$A$10:$A$301, MATCH(0, IF(ISBLANK('Annex 2 EHV charges'!$A$10:$A$301),1, COUNTIF(A$4:$A258, 'Annex 2 EHV charges'!$A$10:$A$301)), 0)),"")} | B259: =IF($A259="","",VLOOKUP($A259,'Annex 2 EHV charges'!$A:$O,2,0)) | C259: =IF($A259="","",VLOOKUP($A259,'Annex 2 EHV charges'!$A:$O,3,0)) | D259: =IF($A259="","",VLOOKUP($A259,'Annex 2 EHV charges'!$A:$O,7,0)) | E259: =IFERROR(IF(VLOOKUP($A259,'Annex 2 EHV charges'!$A:$O,8,FALSE)=0,"",VLOOKUP($A259,'Annex 2 EHV charges'!$A:$O,8,FALSE)),"") | F259: =IFERROR(IF(VLOOKUP($A259,'Annex 2 EHV charges'!$A:$O,9,FALSE)=0,"",VLOOKUP($A259,'Annex 2 EHV charges'!$A:$O,9,FALSE)),"") | G259: =IFERROR(IF(VLOOKUP($A259,'Annex 2 EHV charges'!$A:$O,10,FALSE)=0,"",VLOOKUP($A259,'Annex 2 EHV charges'!$A:$O,10,FALSE)),"") | H259: =IFERROR(IF(VLOOKUP($A259,'Annex 2 EHV charges'!$A:$O,11,FALSE)=0,"",VLOOKUP($A259,'Annex 2 EHV charges'!$A:$O,11,FALSE)),"")

Sheet Annex 2b Export
A1: Note: The list of MPANs / MSIDs provided may be incomplete; the DNO reserves the right to apply the listed charges to any other MPANs / MSIDs associated with the site. Note: This table is automatically populated based on the content of the tab entitled 'Annex 2 EHV Charges'. The timebands are as shown in Annex 2.
A2: =Overview!B4& " - Effective from "&Overview!D4&" - "&Overview!E4&" EDCM export charges" -> Eastern Power Networks - Effective from 1 April 2020 - Final EDCM export charges
A4: Export Unique Identifier | B4: LLFC | C4: Export MPANs/MSIDs | D4: Name | E4: ='Annex 2 EHV charges'!L9 -> Export Super Red unit charge (p/kWh) | F4: ='Annex 2 EHV charges'!M9 -> Export fixed charge (p/day) | G4: ='Annex 2 EHV charges'!N9 -> Export capacity charge (p/kVA/day) | H4: ='Annex 2 EHV charges'!O9 -> Export exceeded capacity charge (p/kVA/day)
A5: {=IFERROR(INDEX('Annex 2 EHV charges'!$D$10:$D$301, MATCH(0, IF(ISBLANK('Annex 2 EHV charges'!$D$10:$D$301),1, COUNTIF(A$4:$A4, 'Annex 2 EHV charges'!$D$10:$D$301)), 0)),"")} -> ABSRSF | B5: =IF($A5="","",VLOOKUP($A5,'Annex 2 EHV charges'!$D:$O,2,0)) -> 744 | C5: =IF($A5="","",VLOOKUP($A5,'Annex 2 EHV charges'!$D:$O,3,0)) -> 1050000574694 | D5: =IF($A5="","",VLOOKUP($A5,'Annex 2 EHV charges'!$D:$O,4,0)) -> ABSRSF | E5: =IFERROR(IF(VLOOKUP($A5,'Annex 2 EHV charges'!$D:$O,9,FALSE)=0,"",VLOOKUP($A5,'Annex 2 EHV charges'!$D:$O,9,FALSE)),"") | F5: =IFERROR(IF(VLOOKUP($A5,'Annex 2 EHV charges'!$D:$O,10,FALSE)=0,"",VLOOKUP($A5,'Annex 2 EHV charges'!$D:$O,10,FALSE)),"") -> 3679.33 | G5: =IFERROR(IF(VLOOKUP($A5,'Annex 2 EHV charges'!$D:$O,11,FALSE)=0,"",VLOOKUP($A5,'Annex 2 EHV charges'!$D:$O,11,FALSE)),"") -> 0.05 | H5: =IFERROR(IF(VLOOKUP($A5,'Annex 2 EHV charges'!$D:$O,12,FALSE)=0,"",VLOOKUP($A5,'Annex 2 EHV charges'!$D:$O,12,FALSE)),"") -> 0.05
A6: {=IFERROR(INDEX('Annex 2 EHV charges'!$D$10:$D$301, MATCH(0, IF(ISBLANK('Annex 2 EHV charges'!$D$10:$D$301),1, COUNTIF(A$4:$A5, 'Annex 2 EHV charges'!$D$10:$D$301)), 0)),"")} -> AIAMAN | B6: =IF($A6="","",VLOOKUP($A6,'Annex 2 EHV charges'!$D:$O,2,0)) -> 435 | C6: =IF($A6="","",VLOOKUP($A6,'Annex 2 EHV charges'!$D:$O,3,0)) -> 1030054607984 | D6: =IF($A6="","",VLOOKUP($A6,'Annex 2 EHV charges'!$D:$O,4,0)) -> AIAMAN | E6: =IFERROR(IF(VLOOKUP($A6,'Annex 2 EHV charges'!$D:$O,9,FALSE)=0,"",VLOOKUP($A6,'Annex 2 EHV charges'!$D:$O,9,FALSE)),"") -> -0.626 | F6: =IFERROR(IF(VLOOKUP($A6,'Annex 2 EHV charges'!$D:$O,10,FALSE)=0,"",VLOOKUP($A6,'Annex 2 EHV charges'!$D:$O,10,FALSE)),"") -> 171.29 | G6: =IFERROR(IF(VLOOKUP($A6,'Annex 2 EHV charges'!$D:$O,11,FALSE)=0,"",VLOOKUP($A6,'Annex 2 EHV charges'!$D:$O,11,FALSE)),"") -> 0.05 | H6: =IFERROR(IF(VLOOKUP($A6,'Annex 2 EHV charges'!$D:$O,12,FALSE)=0,"",VLOOKUP($A6,'Annex 2 EHV charges'!$D:$O,12,FALSE)),"") -> 0.05
A7: {=IFERROR(INDEX('Annex 2 EHV charges'!$D$10:$D$301, MATCH(0, IF(ISBLANK('Annex 2 EHV charges'!$D$10:$D$301),1, COUNTIF(A$4:$A6, 'Annex 2 EHV charges'!$D$10:$D$301)), 0)),"")} -> ALCORG | B7: =IF($A7="","",VLOOKUP($A7,'Annex 2 EHV charges'!$D:$O,2,0)) -> 651 | C7: =IF($A7="","",VLOOKUP($A7,'Annex 2 EHV charges'!$D:$O,3,0)) -> 1050000998050 | D7: =IF($A7="","",VLOOKUP($A7,'Annex 2 EHV charges'!$D:$O,4,0)) -> ALCORG | E7: =IFERROR(IF(VLOOKUP($A7,'Annex 2 EHV charges'!$D:$O,9,FALSE)=0,"",VLOOKUP($A7,'Annex 2 EHV charges'!$D:$O,9,FALSE)),"") | F7: =IFERROR(IF(VLOOKUP($A7,'Annex 2 EHV charges'!$D:$O,10,FALSE)=0,"",VLOOKUP($A7,'Annex 2 EHV charges'!$D:$O,10,FALSE)),"") -> 510.86 | G7: =IFERROR(IF(VLOOKUP($A7,'Annex 2 EHV charges'!$D:$O,11,FALSE)=0,"",VLOOKUP($A7,'Annex 2 EHV charges'!$D:$O,11,FALSE)),"") -> 0.05 | H7: =IFERROR(IF(VLOOKUP($A7,'Annex 2 EHV charges'!$D:$O,12,FALSE)=0,"",VLOOKUP($A7,'Annex 2 EHV charges'!$D:$O,12,FALSE)),"") -> 0.05
A8: {=IFERROR(INDEX('Annex 2 EHV charges'!$D$10:$D$301, MATCH(0, IF(ISBLANK('Annex 2 EHV charges'!$D$10:$D$301),1, COUNTIF(A$4:$A7, 'Annex 2 EHV charges'!$D$10:$D$301)), 0)),"")} -> ARDLGH | B8: =IF($A8="","",VLOOKUP($A8,'Annex 2 EHV charges'!$D:$O,2,0)) -> 666 | C8: =IF($A8="","",VLOOKUP($A8,'Annex 2 EHV charges'!$D:$O,3,0)) -> 1050001061602 | D8: =IF($A8="","",VLOOKUP($A8,'Annex 2 EHV charges'!$D:$O,4,0)) -> ARDLGH | E8: =IFERROR(IF(VLOOKUP($A8,'Annex 2 EHV charges'!$D:$O,9,FALSE)=0,"",VLOOKUP($A8,'Annex 2 EHV charges'!$D:$O,9,FALSE)),"") | F8: =IFERROR(IF(VLOOKUP($A8,'Annex 2 EHV charges'!$D:$O,10,FALSE)=0,"",VLOOKUP($A8,'Annex 2 EHV charges'!$D:$O,10,FALSE)),"") -> 795.65 | G8: =IFERROR(IF(VLOOKUP($A8,'Annex 2 EHV charges'!$D:$O,11,FALSE)=0,"",VLOOKUP($A8,'Annex 2 EHV charges'!$D:$O,11,FALSE)),"") -> 0.05 | H8: =IFERROR(IF(VLOOKUP($A8,'Annex 2 EHV charges'!$D:$O,12,FALSE)=0,"",VLOOKUP($A8,'Annex 2 EHV charges'!$D:$O,12,FALSE)),"") -> 0.05
A9: {=IFERROR(INDEX('Annex 2 EHV charges'!$D$10:$D$301, MATCH(0, IF(ISBLANK('Annex 2 EHV charges'!$D$10:$D$301),1, COUNTIF(A$4:$A8, 'Annex 2 EHV charges'!$D$10:$D$301)), 0)),"")} -> ARLAFD | B9: =IF($A9="","",VLOOKUP($A9,'Annex 2 EHV charges'!$D:$O,2,0)) -> 710 | C9: =IF($A9="","",VLOOKUP($A9,'Annex 2 EHV charges'!$D:$O,3,0)) -> 1030085114723 1030085114955 | D9: =IF($A9="","",VLOOKUP($A9,'Annex 2 EHV charges'!$D:$O,4,0)) -> ARLAFD | E9: =IFERROR(IF(VLOOKUP($A9,'Annex 2 EHV charges'!$D:$O,9,FALSE)=0,"",VLOOKUP($A9,'Annex 2 EHV charges'!$D:$O,9,FALSE)),"") | F9: =IFERROR(IF(VLOOKUP($A9,'Annex 2 EHV charges'!$D:$O,10,FALSE)=0,"",VLOOKUP($A9,'Annex 2 EHV charges'!$D:$O,10,FALSE)),"") -> 1104.02 | G9: =IFERROR(IF(VLOOKUP($A9,'Annex 2 EHV charges'!$D:$O,11,FALSE)=0,"",VLOOKUP($A9,'Annex 2 EHV charges'!$D:$O,11,FALSE)),"") -> 0.05 | H9: =IFERROR(IF(VLOOKUP($A9,'Annex 2 EHV charges'!$D:$O,12,FALSE)=0,"",VLOOKUP($A9,'Annex 2 EHV charges'!$D:$O,12,FALSE)),"") -> 0.05
A10: {=IFERROR(INDEX('Annex 2 EHV charges'!$D$10:$D$301, MATCH(0, IF(ISBLANK('Annex 2 EHV charges'!$D$10:$D$301),1, COUNTIF(A$4:$A9, 'Annex 2 EHV charges'!$D$10:$D$301)), 0)),"")} -> ASTONC | B10: =IF($A10="","",VLOOKUP($A10,'Annex 2 EHV charges'!$D:$O,2,0)) -> 780 | C10: =IF($A10="","",VLOOKUP($A10,'Annex 2 EHV charges'!$D:$O,3,0)) -> 1050000834255 | D10: =IF($A10="","",VLOOKUP($A10,'Annex 2 EHV charges'!$D:$O,4,0)) -> ASTONC | E10: =IFERROR(IF(VLOOKUP($A10,'Annex 2 EHV charges'!$D:$O,9,FALSE)=0,"",VLOOKUP($A10,'Annex 2 EHV charges'!$D:$O,9,FALSE)),"") | F10: =IFERROR(IF(VLOOKUP($A10,'Annex 2 EHV charges'!$D:$O,10,FALSE)=0,"",VLOOKUP($A10,'Annex 2 EHV charges'!$D:$O,10,FALSE)),"") -> 520.15 | G10: =IFERROR(IF(VLOOKUP($A10,'Annex 2 EHV charges'!$D:$O,11,FALSE)=0,"",VLOOKUP($A10,'Annex 2 EHV charges'!$D:$O,11,FALSE)),"") -> 0.05 | H10: =IFERROR(IF(VLOOKUP($A10,'Annex 2 EHV charges'!$D:$O,12,FALSE)=0,"",VLOOKUP($A10,'Annex 2 EHV charges'!$D:$O,12,FALSE)),"") -> 0.05
A11: {=IFERROR(INDEX('Annex 2 EHV charges'!$D$10:$D$301, MATCH(0, IF(ISBLANK('Annex 2 EHV charges'!$D$10:$D$301),1, COUNTIF(A$4:$A10, 'Annex 2 EHV charges'!$D$10:$D$301)), 0)),"")} -> AVENUE | B11: =IF($A11="","",VLOOKUP($A11,'Annex 2 EHV charges'!$D:$O,2,0)) -> 781 | C11: =IF($A11="","",VLOOKUP($A11,'Annex 2 EHV charges'!$D:$O,3,0)) -> 1050000774980 | D11: =IF($A11="","",VLOOKUP($A11,'Annex 2 EHV charges'!$D:$O,4,0)) -> AVENUE | E11: =IFERROR(IF(VLOOKUP($A11,'Annex 2 EHV charges'!$D:$O,9,FALSE)=0,"",VLOOKUP($A11,'Annex 2 EHV charges'!$D:$O,9,FALSE)),"") | F11: =IFERROR(IF(VLOOKUP($A11,'Annex 2 EHV charges'!$D:$O,10,FALSE)=0,"",VLOOKUP($A11,'Annex 2 EHV charges'!$D:$O,10,FALSE)),"") -> 1124.59 | G11: =IFERROR(IF(VLOOKUP($A11,'Annex 2 EHV charges'!$D:$O,11,FALSE)=0,"",VLOOKUP($A11,'Annex 2 EHV charges'!$D:$O,11,FALSE)),"") -> 0.05 | H11: =IFERROR(IF(VLOOKUP($A11,'Annex 2 EHV charges'!$D:$O,12,FALSE)=0,"",VLOOKUP($A11,'Annex 2 EHV charges'!$D:$O,12,FALSE)),"") -> 0.05
A12: {=IFERROR(INDEX('Annex 2 EHV charges'!$D$10:$D$301, MATCH(0, IF(ISBLANK('Annex 2 EHV charges'!$D$10:$D$301),1, COUNTIF(A$4:$A11, 'Annex 2 EHV charges'!$D$10:$D$301)), 0)),"")} -> BARNFM | B12: =IF($A12="","",VLOOKUP($A12,'Annex 2 EHV charges'!$D:$O,2,0)) -> 652 | C12: =IF($A12="","",VLOOKUP($A12,'Annex 2 EHV charges'!$D:$O,3,0)) -> 1050000775005 | D12: =IF($A12="","",VLOOKUP($A12,'Annex 2 EHV charges'!$D:$O,4,0)) -> BARNFM | E12: =IFERROR(IF(VLOOKUP($A12,'Annex 2 EHV charges'!$D:$O,9,FALSE)=0,"",VLOOKUP($A12,'Annex 2 EHV charges'!$D:$O,9,FALSE)),"") | F12: =IFERROR(IF(VLOOKUP($A12,'Annex 2 EHV charges'!$D:$O,10,FALSE)=0,"",VLOOKUP($A12,'Annex 2 EHV charges'!$D:$O,10,FALSE)),"") -> 2143.45 | G12: =IFERROR(IF(VLOOKUP($A12,'Annex 2 EHV charges'!$D:$O,11,FALSE)=0,"",VLOOKUP($A12,'Annex 2 EHV charges'!$D:$O,11,FALSE)),"") -> 0.05 | H12: =IFERROR(IF(VLOOKUP($A12,'Annex 2 EHV charges'!$D:$O,12,FALSE)=0,"",VLOOKUP($A12,'Annex 2 EHV charges'!$D:$O,12,FALSE)),"") -> 0.05
A13: {=IFERROR(INDEX('Annex 2 EHV charges'!$D$10:$D$301, MATCH(0, IF(ISBLANK('Annex 2 EHV charges'!$D$10:$D$301),1, COUNTIF(A$4:$A12, 'Annex 2 EHV charges'!$D$10:$D$301)), 0)),"")} -> BAYFMS | B13: =IF($A13="","",VLOOKUP($A13,'Annex 2 EHV charges'!$D:$O,2,0)) -> 745 | C13: =IF($A13="","",VLOOKUP($A13,'Annex 2 EHV charges'!$D:$O,3,0)) -> 1050000579327 | D13: =IF($A13="","",VLOOKUP($A13,'Annex 2 EHV charges'!$D:$O,4,0)) -> BAYFMS | E13: =IFERROR(IF(VLOOKUP($A13,'Annex 2 EHV charges'!$D:$O,9,FALSE)=0,"",VLOOKUP($A13,'Annex 2 EHV charges'!$D:$O,9,FALSE)),"") | F13: =IFERROR(IF(VLOOKUP($A13,'Annex 2 EHV charges'!$D:$O,10,FALSE)=0,"",VLOOKUP($A13,'Annex 2 EHV charges'!$D:$O,10,FALSE)),"") -> 2827.82 | G13: =IFERROR(IF(VLOOKUP($A13,'Annex 2 EHV charges'!$D:$O,11,FALSE)=0,"",VLOOKUP($A13,'Annex 2 EHV charges'!$D:$O,11,FALSE)),"") -> 0.05 | H13: =IFERROR(IF(VLOOKUP($A13,'Annex 2 EHV charges'!$D:$O,12,FALSE)=0,"",VLOOKUP($A13,'Annex 2 EHV charges'!$D:$O,12,FALSE)),"") -> 0.05
A14: {=IFERROR(INDEX('Annex 2 EHV charges'!$D$10:$D$301, MATCH(0, IF(ISBLANK('Annex 2 EHV charges'!$D$10:$D$301),1, COUNTIF(A$4:$A13, 'Annex 2 EHV charges'!$D$10:$D$301)), 0)),"")} -> BDGHSE | B14: =IF($A14="","",VLOOKUP($A14,'Annex 2 EHV charges'!$D:$O,2,0)) -> 782 | C14: =IF($A14="","",VLOOKUP($A14,'Annex 2 EHV charges'!$D:$O,3,0)) -> 1050000669539 | D14: =IF($A14="","",VLOOKUP($A14,'Annex 2 EHV charges'!$D:$O,4,0)) -> BDGHSE | E14: =IFERROR(IF(VLOOKUP($A14,'Annex 2 EHV charges'!$D:$O,9,FALSE)=0,"",VLOOKUP($A14,'Annex 2 EHV charges'!$D:$O,9,FALSE)),"") | F14: =IFERROR(IF(VLOOKUP($A14,'Annex 2 EHV charges'!$D:$O,10,FALSE)=0,"",VLOOKUP($A14,'Annex 2 EHV charges'!$D:$O,10,FALSE)),"") -> 1061.26 | G14: =IFERROR(IF(VLOOKUP($A14,'Annex 2 EHV charges'!$D:$O,11,FALSE)=0,"",VLOOKUP($A14,'Annex 2 EHV charges'!$D:$O,11,FALSE)),"") -> 0.05 | H14: =IFERROR(IF(VLOOKUP($A14,'Annex 2 EHV charges'!$D:$O,12,FALSE)=0,"",VLOOKUP($A14,'Annex 2 EHV charges'!$D:$O,12,FALSE)),"") -> 0.05
A15: {=IFERROR(INDEX('Annex 2 EHV charges'!$D$10:$D$301, MATCH(0, IF(ISBLANK('Annex 2 EHV charges'!$D$10:$D$301),1, COUNTIF(A$4:$A14, 'Annex 2 EHV charges'!$D$10:$D$301)), 0)),"")} -> BDWLWF | B15: =IF($A15="","",VLOOKUP($A15,'Annex 2 EHV charges'!$D:$O,2,0)) -> 734 | C15: =IF($A15="","",VLOOKUP($A15,'Annex 2 EHV charges'!$D:$O,3,0)) -> 1030082700647 | D15: =IF($A15="","",VLOOKUP($A15,'Annex 2 EHV charges'!$D:$O,4,0)) -> BDWLWF | E15: =IFERROR(IF(VLOOKUP($A15,'Annex 2 EHV charges'!$D:$O,9,FALSE)=0,"",VLOOKUP($A15,'Annex 2 EHV charges'!$D:$O,9,FALSE)),"") | F15: =IFERROR(IF(VLOOKUP($A15,'Annex 2 EHV charges'!$D:$O,10,FALSE)=0,"",VLOOKUP($A15,'Annex 2 EHV charges'!$D:$O,10,FALSE)),"") -> 4235.2 | G15: =IFERROR(IF(VLOOKUP($A15,'Annex 2 EHV charges'!$D:$O,11,FALSE)=0,"",VLOOKUP($A15,'Annex 2 EHV charges'!$D:$O,11,FALSE)),"") -> 0.05 | H15: =IFERROR(IF(VLOOKUP($A15,'Annex 2 EHV charges'!$D:$O,12,FALSE)=0,"",VLOOKUP($A15,'Annex 2 EHV charges'!$D:$O,12,FALSE)),"") -> 0.05
A16: {=IFERROR(INDEX('Annex 2 EHV charges'!$D$10:$D$301, MATCH(0, IF(ISBLANK('Annex 2 EHV charges'!$D$10:$D$301),1, COUNTIF(A$4:$A15, 'Annex 2 EHV charges'!$D$10:$D$301)), 0)),"")} -> BERDHF | B16: =IF($A16="","",VLOOKUP($A16,'Annex 2 EHV charges'!$D:$O,2,0)) -> 436 | C16: =IF($A16="","",VLOOKUP($A16,'Annex 2 EHV charges'!$D:$O,3,0)) -> 1050001382531 | D16: =IF($A16="","",VLOOKUP($A16,'Annex 2 EHV charges'!$D:$O,4,0)) -> BERDHF | E16: =IFERROR(IF(VLOOKUP($A16,'Annex 2 EHV charges'!$D:$O,9,FALSE)=0,"",VLOOKUP($A16,'Annex 2 EHV charges'!$D:$O,9,FALSE)),"") | F16: =IFERROR(IF(VLOOKUP($A16,'Annex 2 EHV charges'!$D:$O,10,FALSE)=0,"",VLOOKUP($A16,'Annex 2 EHV charges'!$D:$O,10,FALSE)),"") -> 1325.75 | G16: =IFERROR(IF(VLOOKUP($A16,'Annex 2 EHV charges'!$D:$O,11,FALSE)=0,"",VLOOKUP($A16,'Annex 2 EHV charges'!$D:$O,11,FALSE)),"") -> 0.05 | H16: =IFERROR(IF(VLOOKUP($A16,'Annex 2 EHV charges'!$D:$O,12,FALSE)=0,"",VLOOKUP($A16,'Annex 2 EHV charges'!$D:$O,12,FALSE)),"") -> 0.05
... A161: {=IFERROR(INDEX('Annex 2 EHV charges'!$D$10:$D$301, MATCH(0, IF(ISBLANK('Annex 2 EHV charges'!$D$10:$D$301),1, COUNTIF(A$4:$A160, 'Annex 2 EHV charges'!$D$10:$D$301)), 0)),"")} | B161: =IF($A161="","",VLOOKUP($A161,'Annex 2 EHV charges'!$D:$O,2,0)) | C161: =IF($A161="","",VLOOKUP($A161,'Annex 2 EHV charges'!$D:$O,3,0)) | D161: =IF($A161="","",VLOOKUP($A161,'Annex 2 EHV charges'!$D:$O,4,0)) | E161: =IFERROR(IF(VLOOKUP($A161,'Annex 2 EHV charges'!$D:$O,9,FALSE)=0,"",VLOOKUP($A161,'Annex 2 EHV charges'!$D:$O,9,FALSE)),"") | F161: =IFERROR(IF(VLOOKUP($A161,'Annex 2 EHV charges'!$D:$O,10,FALSE)=0,"",VLOOKUP($A161,'Annex 2 EHV charges'!$D:$O,10,FALSE)),"") | G161: =IFERROR(IF(VLOOKUP($A161,'Annex 2 EHV charges'!$D:$O,11,FALSE)=0,"",VLOOKUP($A161,'Annex 2 EHV charges'!$D:$O,11,FALSE)),"") | H161: =IFERROR(IF(VLOOKUP($A161,'Annex 2 EHV charges'!$D:$O,12,FALSE)=0,"",VLOOKUP($A161,'Annex 2 EHV charges'!$D:$O,12,FALSE)),"")

Sheet Annex 3 Preserved charges
A1: Back to Overview
A2: =Overview!B4& " - Effective from "&Overview!D4&" - "&Overview!E4&" LV and HV tariffs" -> Eastern Power Networks - Effective from 1 April 2020 - Final LV and HV tariffs
A3: NHH preserved charges/additional LLFCs
B4: Closed LLFCs | C4: PCs | D4: Unit charge 1 (NHH) p/kWh | E4: Unit charge 2 (NHH) p/kWh | F4: Fixed charge p/MPAN/day
A6: Notes: | B6: Eastern Power Networks has no Preserved NHH Tariffs/Additional LLFC classes
A11: HH preserved charges/additional LLFCs
B12: Closed LLFCs | C12: PCs | D12: Red/black charge (HH) p/kWh | E12: Amber/yellow charge (HH) p/kWh | F12: Green charge (HH) p/kWh | G12: Fixed charge p/MPAN/day | H12: Capacity charge p/kVA/day | I12: Exceeded capacity charge p/kVA/day | J12: Reactive power charge p/kVArh
A14: Notes: | B14: Eastern Power Networks has no Preserved HH Tariffs/Additional LLFC classes

Sheet Annex 4 LDNO charges
A1: Back to Overview | B1: Copy LDNO sections from CDCM Ouput 101-A in "Tariff Summary" tab for rows 13 to 55 | F1: Copy data from EDCM Outputs 204-A to 204-E in "LDNO tariffs transposed" tab for rows 56 and below
A2: =Overview!B4& " - Effective from "&Overview!D4&" - "&Overview!E4&" LDNO tariffs" -> Eastern Power Networks - Effective from 1 April 2020 - Final LDNO tariffs
A4: Time Bands for Half Hourly Metered Properties | F4: Time Bands for Half Hourly Unmetered Properties
A5: Time periods | B5: Red Time Band | C5: Amber Time Band | D5: Green Time Band | H5: Black Time Band | I5: Yellow Time Band | J5: Green Time Band
A6: Monday to Friday (Including Bank Holidays) All Year | B6: 16:00 - 19:00 | C6: 07:00 - 16:00 19:00 - 23:00 | D6: 00:00 - 07:00 23:00 - 24:00 | F6: Monday to Friday (Including Bank Holidays) November to February Inclusive | H6: 16:00 - 19:00 | I6: 07:00 - 16:00 19:00 - 23:00 | J6: 00:00 - 07:00 23:00 - 24:00
A7: Saturday and Sunday All Year | D7: 00:00 - 24:00 | F7: Monday to Friday (Including Bank Holidays) March to October Inclusive | I7: 07:00 - 23:00 | J7: 00:00 - 07:00 23:00 - 24:00
A8: Notes | B8: All times are in UK Clock time | F8: Saturday and Sunday All Year | J8: 00:00 - 24:00
F9: Notes | H9: All times are in UK Clock time
A11: Tariff name | B11: Unique billing identifier | C11: PCs | D11: ='Annex 1 LV and HV charges'!D11 -> Unit charge 1 (NHH) or red/black charge (HH) p/kWh | E11: ='Annex 1 LV and HV charges'!E11 -> Unit charge 2 (NHH) or amber/yellow charge (HH) p/kWh | F11: ='Annex 1 LV and HV charges'!F11 -> Green charge(HH) p/kWh | G11: ='Annex 1 LV and HV charges'!G11 -> Fixed charge p/MPAN/day | H11: ='Annex 1 LV and HV charges'!H11 -> Capacity charge p/kVA/day | I11: ='Annex 1 LV and HV charges'!I11 -> Exceeded capacity charge p/kVA/day | J11: ='Annex 1 LV and HV charges'!J11 -> Reactive power charge p/kVArh
A12: LDNO LV: Domestic Unrestricted | B12: 101 | C12: 1 | D12: 1.51 | G12: 3.33
A13: LDNO LV: Domestic Two Rate | B13: 111 | C13: 2 | D13: 1.947 | E13: 0.124 | G13: 3.33
A14: LDNO LV: Domestic Off Peak (related MPAN) | B14: 121 | C14: 2 | D14: 0.167
A15: LDNO LV: Small Non Domestic Unrestricted | B15: 131 | C15: 3 | D15: 1.163 | G15: 3.33
A16: LDNO LV: Small Non Domestic Two Rate | B16: 141 | C16: 4 | D16: 1.412 | E16: 0.11 | G16: 3.33
A17: LDNO LV: Small Non Domestic Off Peak (related MPAN) | B17: 151 | C17: 4 | D17: 0.213
A18: LDNO LV: LV Medium Non-Domestic | B18: 161 | C18: 5-8 | D18: 1.529 | E18: 0.098 | G18: 35.47
A19: LDNO LV: LV Network Domestic | B19: 318 | C19: 0 | D19: 10.517 | E19: 0.334 | F19: 0.093 | G19: 3.33
A20: LDNO LV: LV Network Non-Domestic Non-CT | B20: 325 | C20: 0 | D20: 9.035 | E20: 0.295 | F20: 0.087 | G20: 3.73
A21: LDNO LV: LV HH Metered | B21: 181 | C21: 0 | D21: 6.744 | E21: 0.216 | F21: 0.076 | G21: 8.78 | H21: 2.5 | I21: 5.2 | J21: 0.217
A22: LDNO LV: NHH UMS category A | B22: 201 | C22: 8 | D22: 1.458
A23: LDNO LV: NHH UMS category B | B23: 201 | C23: 1 | D23: 2.025
A24: LDNO LV: NHH UMS category C | B24: 201 | C24: 1 | D24: 3.351
A25: LDNO LV: NHH UMS category D | B25: 201 | C25: 1 | D25: 1.088
A26: LDNO LV: LV UMS (Pseudo HH Metered) | B26: 211 | C26: 0 | D26: 28.202 | E26: 0.774 | F26: 0.537
A27: LDNO LV: LV Generation NHH or Aggregate HH | B27: 221 | C27: 8 or 0 | D27: -0.983 | G27: 0
A28: LDNO LV: LV Generation Intermittent | B28: 231 | C28: 0 | D28: -0.983 | G28: 0 | J28: 0.289
A29: LDNO LV: LV Generation Non-Intermittent | B29: 241 | C29: 0 | D29: -9.667 | E29: -0.259 | F29: -0.036 | G29: 0 | J29: 0.289
A30: LDNO HV: Domestic Unrestricted | B30: 102 | C30: 1 | D30: 1.15 | G30: 2.54
A31: LDNO HV: Domestic Two Rate | B31: 112 | C31: 2 | D31: 1.483 | E31: 0.094 | G31: 2.54
A32: LDNO HV: Domestic Off Peak (related MPAN) | B32: 122 | C32: 2 | D32: 0.127
A33: LDNO HV: Small Non Domestic Unrestricted | B33: 132 | C33: 3 | D33: 0.886 | G33: 2.54
A34: LDNO HV: Small Non Domestic Two Rate | B34: 142 | C34: 4 | D34: 1.076 | E34: 0.084 | G34: 2.54
A35: LDNO HV: Small Non Domestic Off Peak (related MPAN) | B35: 152 | C35: 4 | D35: 0.163
A36: LDNO HV: LV Medium Non-Domestic | B36: 162 | C36: 5-8 | D36: 1.165 | E36: 0.074 | G36: 27.03
A37: LDNO HV: LV Network Domestic | B37: 319 | C37: 0 | D37: 8.013 | E37: 0.255 | F37: 0.071 | G37: 2.54
A38: LDNO HV: LV Network Non-Domestic Non-CT | B38: 326 | C38: 0 | D38: 6.884 | E38: 0.224 | F38: 0.067 | G38: 2.84
A39: LDNO HV: LV HH Metered | B39: 182 | C39: 0 | D39: 5.138 | E39: 0.165 | F39: 0.058 | G39: 6.69 | H39: 1.91 | I39: 3.96 | J39: 0.165
A40: LDNO HV: LV Sub HH Metered | B40: 172 | C40: 0 | D40: 5.562 | E40: 0.168 | F40: 0.074 | G40: 5.86 | H40: 4.06 | I40: 5.32 | J40: 0.163
A41: LDNO HV: HV HH Metered | B41: 192 | C41: 0 | D41: 5.019 | E41: 0.152 | F41: 0.078 | G41: 89.57 | H41: 3.73 | I41: 5.24 | J41: 0.145
A42: LDNO HV: NHH UMS category A | B42: 202 | C42: 8 | D42: 1.111
...

Sheet Annex 5 LLFs
A1: Back to Overview
A2: These line loss factors are illustrative based on the latest calculated values and are published in good faith. However, the line loss factors that are approved by the BSC Panel for the applicable year and consequently published on the Elexon website will take precedence and will be used in Settlement if they differ from these values.
A3: =Overview!B4& " - Illustrative LLFs for year beginning "&Overview!D4 -> Eastern Power Networks - Illustrative LLFs for year beginning 1 April 2020
A4: Time periods | C4: Period 1 | D4: Period 2 | E4: Period 3 | F4: Period 4 | G4: Period 5
C5: Winter Peak | D5: Summer Peak | E5: Winter Shoulder | F5: Night | G5: Other
A6: Monday to Friday November to February | C6: 16:00 - 19:59 | E6: 07:00 - 15:59
A7: Monday to Friday June to August | D7: 07:00 - 19:59
A8: Monday to Friday March | E8: 07:00 - 19:59
A9: All Year | F9: 00:00 - 06:59 | G9: All Other Times
A10: Notes | C10: All times are in UK Clock time
A12: Generic demand and generation LLFs
A13: Metered voltage, respective periods and associated LLFCs
A14: Metered voltage | C14: Period 1 | D14: Period 2 | E14: Period 3 | F14: Period 4 | G14: Period 5 | H14: Associated LLFC
A15: Low Voltage Network | C15: 1.111 | D15: 1.081 | E15: 1.099 | F15: 1.075 | G15: 1.086 | H15: 1, 3, 7, 19, 22, 64, 86, 100, 101, 102, 103, 110, 111, 112, 113, 150, 151, 152, 153, 160, 161, 162, 163, 200, 201, 205, 254, 350, 901, 912, 915, 980, 981, 982, 983 | L15: `
A16: Low Voltage Substation | C16: 1.08 | D16: 1.061 | E16: 1.072 | F16: 1.057 | G16: 1.064 | H16: 79, 80, 902, 916, 984, 985, 986, 987
A17: High Voltage Network | C17: 1.052 | D17: 1.039 | E17: 1.047 | F17: 1.036 | G17: 1.041 | H17: 84, 89, 903, 918, 988, 989, 990, 991
A18: High Voltage Substation | C18: 1.051 | D18: 1.039 | E18: 1.046 | F18: 1.035 | G18: 1.04 | H18: 771, 791, 792
A19: 33kV Generic | C19: 1.016 | D19: 1.013 | E19: 1.015 | F19: 1.013 | G19: 1.013 | H19: 796, 797
A20: 132kV Generic | C20: 1.004 | D20: 1.003 | E20: 1.003 | F20: 1.002 | G20: 1.003 | H20: 798, 799
A22: EHV site specific LLFs
A23: Demand
A24: LLFC | B24: Site | D24: Period 1 | E24: Period 2 | F24: Period 3 | G24: Period 4 | H24: Period 5
A25: 300 | B25: ALCORG - Import | D25: 1.016 | E25: 1.013 | F25: 1.015 | G25: 1.013 | H25: 1.013
A26: 301 | B26: BARNFM - Import | D26: 0.992 | E26: 1 | F26: 0.995 | G26: 1.003 | H26: 0.996
A27: 302 | B27: BERDHF - Import | D27: 1 | E27: 1 | F27: 1 | G27: 1 | H27: 1
A28: 303 | B28: CLAYPV - Import | D28: 1.051 | E28: 1.051 | F28: 1.051 | G28: 1.051 | H28: 1.051
A29: 304 | B29: CLFFQY - Import | D29: 1.005 | E29: 1.004 | F29: 1.005 | G29: 1.004 | H29: 1.004
A30: 305 | B30: CLRDWN - Import | D30: 1.033 | E30: 1.005 | F30: 1.024 | G30: 1.012 | H30: 1.012
A31: 307 | B31: CRSSNG - Import | D31: 1.084 | E31: 1.083 | F31: 1.084 | G31: 1.083 | H31: 1.084
A32: 308 | B32: ERNUNN - Import | D32: 1.008 | E32: 1.007 | F32: 1.007 | G32: 1.007 | H32: 1.007
A33: 310 | B33: GREYSH - Import | D33: 1.016 | E33: 1.013 | F33: 1.015 | G33: 1.013 | H33: 1.013
A34: 311 | B34: GRNFRM - Import | D34: 1 | E34: 1.002 | F34: 1.001 | G34: 1.022 | H34: 1.002
A35: 312 | B35: HRMT_B - Import | D35: 1.024 | E35: 1.022 | F35: 1.018 | G35: 1.022 | H35: 1.022
A36: 313 | B36: HRSFEN - Import | D36: 1.023 | E36: 1.013 | F36: 1.016 | G36: 1.015 | H36: 1.015
... A265: 898 | B265: STWBRG - Import | D265: 1.014 | E265: 1.008 | F265: 1.012 | G265: 1.011 | H265: 1.013
A267: EHV site specific LLFs
A268: Generation
A269: LLFC | B269: Site | D269: Period 1 | E269: Period 2 | F269: Period 3 | G269: Period 4 | H269: Period 5
A270: 432 | B270: ESWMID - Export | D270: 1.051 | E270: 1.039 | F270: 1.046 | G270: 1.035 | H270: 1.04
A271: 434 | B271: PLMPPR - Export | D271: 0.996 | E271: 0.997 | F271: 0.997 | G271: 0.997 | H271: 0.997
...

Sheet Annex 6 new or amended EHV
A1: Back to Overview | G1: Note: The list of MPANs/MSIDs provided may be incomplete; the DNO reserves the right to apply the listed charges to any other MPANs/MSIDs associated with the site.
A2: Annex 6 - Charges for New or Amended Designated EHV Properties
A4: =Overview!B4& " - Effective from "&Overview!D4&" - "&Overview!E4&" new designated EHV charges" -> Eastern Power Networks - Effective from 1 April 2020 - Final new designated EHV charges
A5: Import Unique Identifier | B5: LLFC | C5: Import MPANs/MSIDs | D5: Export Unique Identifier | E5: LLFC | F5: Export MPANs/MSIDs | G5: Name | H5: Import Super Red unit charge (p/kWh) | I5: Import fixed charge (p/day) | J5: Import capacity charge (p/kVA/day) | K5: Import exceeded capacity charge (p/kVA/day) | L5: Export Super Red unit charge (p/kWh) | M5: Export fixed charge (p/day) | N5: Export capacity charge (p/kVA/day) | O5: Export exceeded capacity charge (p/kVA/day)
A6: ARLBES | C6: MSID: 7401 | D6: ARLBES | F6: MSID: 7402 | G6: ARLBES | H6: 0 | I6: 1700.44 | J6: 1.27 | K6: 1.27 | L6: -0.002 | M6: 1700.44 | N6: 0.05 | O6: 0.05
A7: AW_GRA | B7: 588 | C7: 1014571445536 1023477037942 | D7: AW_GRA | E7: 400 | F7: 1050001872410 1050001872400 | G7: AW_GRA | H7: 4.441 | I7: 89.93 | J7: 4.22 | K7: 4.22 | L7: 0 | M7: 0.00 | N7: 0.05 | O7: 0.05
A8: CAVDRD | B8: 429 | C8: 1050001791569 | D8: CAVDRD | E8: 773 | F8: 1050001791578 | G8: CAVDRD | H8: 0.816 | I8: 31.13 | J8: 1.46 | K8: 1.46 | L8: -1.031 | M8: 785.64 | N8: 0.05 | O8: 0.05
A9: COMBRN | B9: 306 | C9: 1050001662241 | D9: COMBRN | E9: 440 | F9: 1050001662250 | G9: COMBRN | H9: 0.473 | I9: 12.57 | J9: 4.9 | K9: 4.9 | L9: 0 | M9: 1546.27 | N9: 0.05 | O9: 0.05
A10: GOOSFM | B10: 309 | C10: 1050001727953 | D10: GOOSFM | E10: 442 | F10: 1050001727962 | G10: GOOSFM | H10: 0 | I10: 12.23 | J10: 2.13 | K10: 2.13 | L10: 0 | M10: 2139.61 | N10: 0.05 | O10: 0.05
A11: LITSTA | B11: 427 | C11: 1050001858070 | D11: LITSTA | E11: 648 | F11: 1050001858080 | G11: LITSTA | H11: 0.132 | I11: 33.85 | J11: 2.16 | K11: 2.16 | L11: 0 | M11: 6770 | N11: 0.05 | O11: 0.05
A12: MOLLAV | B12: 428 | C12: 1050001620710 | D12: MOLLAV | E12: 774 | F12: 1050001620720 | G12: MOLLAV | H12: 0 | I12: 9.12 | J12: 1.38 | K12: 1.38 | L12: -0.101 | M12: 911.78 | N12: 0.05 | O12: 0.05
A13: RAINDC | B13: 483 | C13: 1050001877738 1050001878244 | D13: RAINDC | E13: 772 | F13: 1050001877747 1050001878253 | G13: RAINDC | H13: 0 | I13: 19016.97 | J13: 2.14 | K13: 2.14 | L13: 0 | M13: 11861.83 | N13: 0.05 | O13: 0.05
A14: ICGLTD | B14: 866 | C14: 1030075706342 | D14: ICGLTD | E14: 649 | F14: 1050001431630 | G14: ICGLTD | I14: 947.65 | J14: 1.97 | K14: 1.97 | L14: 0 | M14: 0 | N14: 0.05 | O14: 0.05
A15: STA33E | B15: 802 | C15: 1050001977780 | G15: STA33E | H15: 0.018 | I15: 0.00 | J15: 0.00 | K15: 0.00
A18: =Overview!B4& " - Effective from "&Overview!D4&" - "&Overview!E4&" new designated EHV line loss factors" -> Eastern Power Networks - Effective from 1 April 2020 - Final new designated EHV line loss factors
A19: Import Unique Identifier | B19: LLFC | C19: Import MPANs/MSIDs | D19: Export Unique Identifier | E19: LLFC | F19: Export MPANs/MSIDs | G19: Name | H19: Import LLF period 1 | I19: Import LLF period 2 | J19: Import LLF period 3 | K19: Import LLF period 4 | L19: Import LLF period 5 | M19: Export LLF period 1 | N19: Export LLF period 2 | O19: Export LLF period 3 | P19: Export LLF period 4 | Q19: Export LLF period 5
A20: ARLBES | B20: 604 | C20: MSID: 7401 | D20: ARLBES | E20: 612 | F20: MSID: 7402 | G20: ARLBES | H20: 1.004 | I20: 1.003 | J20: 1.003 | K20: 1.002 | L20: 1.003 | M20: 1.004 | N20: 1.003 | O20: 1.003 | P20: 1.002 | Q20: 1.003
A21: AW_GRA | B21: 588 | C21: 1014571445536 1023477037942 | D21: AW_GRA | E21: 400 | F21: 1050001872410 1050001872400 | G21: AW_GRA | H21: 1.051 | I21: 1.039 | J21: 1.046 | K21: 1.035 | L21: 1.04 | M21: 1.051 | N21: 1.039 | O21: 1.046 | P21: 1.035 | Q21: 1.04
A22: CAVDRD | B22: 429 | C22: 1050001791569 | D22: CAVDRD | E22: 773 | F22: 1050001791578 | G22: CAVDRD | H22: 1.016 | I22: 1.013 | J22: 1.015 | K22: 1.013 | L22: 1.013 | M22: 1.016 | N22: 1.013 | O22: 1.015 | P22: 1.013 | Q22: 1.013
A23: COMBRN | B23: 306 | C23: 1050001662241 | D23: COMBRN | E23: 440 | F23: 1050001662250 | G23: COMBRN | H23: 1.016 | I23: 1.013 | J23: 1.015 | K23: 1.013 | L23: 1.013 | M23: 1.016 | N23: 1.013 | O23: 1.015 | P23: 1.013 | Q23: 1.013
A24: GOOSFM | B24: 309 | C24: 1050001727953 | D24: GOOSFM | E24: 442 | F24: 1050001727962 | G24: GOOSFM | H24: 1.016 | I24: 1.013 | J24: 1.015 | K24: 1.013 | L24: 1.013 | M24: 1.016 | N24: 1.013 | O24: 1.015 | P24: 1.013 | Q24: 1.013
A25: LITSTA | B25: 427 | C25: 1050001858070 | D25: LITSTA | E25: 648 | F25: 1050001858080 | G25: LITSTA | H25: 1.004 | I25: 1.003 | J25: 1.003 | K25: 1.002 | L25: 1.003 | M25: 1.004 | N25: 1.003 | O25: 1.003 | P25: 1.002 | Q25: 1.003
A26: MOLLAV | B26: 428 | C26: 1050001620710 | D26: MOLLAV | E26: 774 | F26: 1050001620720 | G26: MOLLAV | H26: 1.016 | I26: 1.013 | J26: 1.015 | K26: 1.013 | L26: 1.013 | M26: 1.016 | N26: 1.013 | O26: 1.015 | P26: 1.013 | Q26: 1.013
A27: RAINDC | B27: 483 | C27: 1050001877738 1050001878244 | D27: RAINDC | E27: 772 | F27: 1050001877747 1050001878253 | G27: RAINDC | H27: 1.004 | I27: 1.003 | J27: 1.003 | K27: 1.002 | L27: 1.003 | M27: 1.004 | N27: 1.003 | O27: 1.003 | P27: 1.002 | Q27: 1.003
A28: ICGLTD | B28: 866 | C28: 1030075706342 | D28: ICGLTD | E28: 649 | F28: 1050001431630 | G28: ICGLTD | H28: 1.004 | I28: 1.003 | J28: 1.004 | K28: 1.003 | L28: 1.004 | M28: 1.016 | N28: 1.013 | O28: 1.015 | P28: 1.013 | Q28: 1.013
A29: STA33E | B29: 802 | C29: 1050001977780 | G29: STA33E | H29: 1.009 | I29: 1.011 | J29: 1.014 | K29: 1.009 | L29: 1.009
A32: These line loss factors are illustrative based on the latest calculated values and are published in good faith. However, the line loss factors that are approved by the BSC Panel for the applicable year and consequently published on the Elexon website will take precedence and will be used in Settlement if they differ from these values.

Sheet Nodal prices
A1: Back to Overview
A2: =Overview!B4& " - Effective from "&Overview!D4&" - "&Overview!E4&" Nodal/Zonal charges" -> Eastern Power Networks - Effective from 1 April 2020 - Final Nodal/Zonal charges
A3: Node/Zone ID | B3: Geographical name | C3: Local charge 1 £/kVA | D3: Remote charge 1 £/kVA
A4: ABBE31 | B4: Abberton Grid | C4: 0 | D4: 0.50176557
A5: ABCS31 | B5: EPN 0005 | C5: 0.014467147 | D5: 0.0079070149
A6: ABCS32 | B6: EPN 0005 | C6: 0.70398725 | D6: 0.07700614
A7: ACRO51 | B7: Acrows Primary | C7: 0.071151757 | D7: 1.7710341
A8: ADEB51 | B8: Addenbrookes Primary | C8: 0.056383375 | D8: 0.39681067
A9: ADEL51 | B9: Adelaide St Primary | C9: 2.0265111 | D9: 5.2606403
A10: ADPT31 | B10: British Sugar | C10: -5.5541103 | D10: 3.1840921
A11: ALDA51 | B11: Arla Dairies Primary | C11: 0 | D11: 0
A12: ALDR51 | B12: Aldreth Primary | C12: 0.14686465 | D12: 2.133179
A13: ALDR52 | B13: Aldreth Primary | C13: 0.13159423 | D13: 0.18083343
A14: ALPI51 | B14: Alpington Primary | C14: 0.3146074 | D14: 1.0487375
A15: AMEP51 | B15: Amersham Primary | C15: 0.0090464312 | D15: 1.6463593
... A758: WTMI31 | B758: EPN 0119 | C758: -0.57132501 | D758: -0.00023582194

Sheet SSC TPR unit rate lookup
A1: Back to Overview
A28: Standard Settlement Configuration Id | B28: Time Pattern Regime Id | C28: Standard Settlement Configuration Desc | D28: Common Decode | G28: Change implemented | H28: Date | I28: Comments
A29: 3 | B29: 166 | C29: 10-hour OP | D29: O | H29: 40057 | I29: First published spreadsheet
A30: 4 | B30: 168 | C30: 10-hour OP | D30: O | G30: SSC 0330 charge rates corrected | H30: 40275 | I30: Previous Off-peak rate corrected to charge 2
A31: 5 | B31: 100 | C31: 10-hour OP + w/e | D31: O | G31: SSC 0250 charge rate corrected | H31: 40347 | I31: Previous rate 1 corrected to Off Peak O
