Workbook
Name OLE_LINK1: 'Annex 3 Preserved charges'!#REF!
Name YesNo: '[1]CSAD 2.1 Site Specific&EHV'!$AG$54:$AG$54

Sheet Overview
A2: Company and Licence name, charging year, effective from, status
B3: Company and Licence name | C3: Year | D3: Effective From | E3: Status
A4: Company and Licence name, charging year, effective from, status | B4: Southern Electric Power Distribution plc | C4: 2020/21 | D4: 1 April 2020 | E4: Final
A6: List of data tables in this workbook
A7: Worksheet | B7: Information
A8: Annex 1 LV and HV charges | B8: Annex 1 contains the charges to LV and HV Designated Properties.
A9: Annex 2 EHV charges | B9: ="Annex 2 contains the charges to Designated EHV Properties and charges applied to LDNOs with Designated EHV Properties/end-users embedded in networks within the " &B4 &" Licence area." -> Annex 2 contains the charges to Designated EHV Properties and charges applied to LDNOs with Designated EHV Properties/end-users embedded in networks within the Southern Electric Power Distribution plc Licence area.
A10: Annex 3 Preserved charges | B10: Annex 3 contains details of any preserved and additional charges that are valid at this time.
A11: Annex 4 LDNO charges | B11: ="Annex 4 contains charges that are levied on the owner of an embedded network within the "&B4&" Licence area. "&"Electricity suppliers and consumers who have properties connected to an embedded network should contact the embedded network owner to determine their distribution charges."&" The charges listed in this table are not payable by domestic consumers, business consumers or electricity suppliers." -> Annex 4 contains charges that are levied on the owner of an embedded network within the Southern Electric Power Distribution plc Licence area. Electricity suppliers and consumers who have properties connected to an embedded network should contact the embedded network owner to determine their distribution charges. The charges listed in this table are not payable by domestic consumers, business consumers or electricity suppliers.
A12: Annex 5 LLFs | B12: Annex 5 has been intentionally left blank as this Statement of Charges and Other Tables document is published a complete year before the LLFs have been audited. The line loss factors that are approved by the BSC Panel for the applicable year and consequently published on the Elexon website will take precedence and be used in Settlement. This annex will be re-published with these values once they are available.
A13: Annex 6 Charges for New or Amended Designated EHV Properties | B13: ="Annex 6 contains the charges for new or amended Designated EHV Properties and charges applied to LDNOs with new or amended Designated EHV Properties/end-users embedded in networks within the " &B4 &" Licence area." -> Annex 6 contains the charges for new or amended Designated EHV Properties and charges applied to LDNOs with new or amended Designated EHV Properties/end-users embedded in networks within the Southern Electric Power Distribution plc Licence area.
A14: Nodal prices | B14: Contains the underlying [nodal/network group] costs used to calculate the current EDCM charges.
A15: SSC TPR to unit rate lookup table | B15: The time periods for the non half hourly metered charge rates in Annex 1 are as specified by the SSC. To determine the appropriate charge rate for each SSC/TPR a lookup table is provided.
A16: Charge calculator | B16: Charge calculator is a tool to help you estimate your distribution charges using current consumption data and forecast consumption data.
A18: Notes to users of this spreadsheet
A20: Please use this spreadsheet with reference to the LC14 use of system charging statement.
A21: Annex 2 and Annex 6 - Import/Export unique identifier columns removed.
A23: Annex 4 -The LDNO HV Demand tariffs have been updated in compliance with Ofgem’s direction published 13-02-20. Details of the direction can be found at:
A24: https://www.ofgem.gov.uk/publications-and-updates/decision-grant-derogations-all-distribution-network-operators-distribution-use-system-charges-202021
A25: No other tariffs are affected by this change
A27: Version: 1.2 - 01/04/20
A29: Notes to DNOs populating this spreadsheet
A31: DNOs must endeavour to maintain consistency in the structure of this spreadsheet. Any changes to the structure must be noted in the 'Notes to users of this spreadsheet'
A32: The drop down list on the charge calculator can be expanded by unprotecting the charge calculator sheet and selecting 'data', 'data validation...' and then expanding the 'source' data range. The sheet can then be protected.

Sheet Annex 1 LV and HV charges
A1: Back to Overview | E1: Note: Where a tariff only has a p/kWh unit rate in Unit Charge 1 then this unit rate applies at all times.
A2: =Overview!B4& " - Effective from "&Overview!D4&" - "&Overview!E4&" LV and HV charges" -> Southern Electric Power Distribution plc - Effective from 1 April 2020 - Final LV and HV charges
A4: Time Bands for Half Hourly Metered Properties | G4: Time Bands for Half Hourly Unmetered Properties
A5: Time periods | B5: Red Time Band | C5: Amber Time Band | E5: Green Time Band | I5: Black Time Band | J5: Yellow Time Band | K5: Green Time Band
A6: Monday to Friday (Including Bank Holidays) All Year | B6: 16:30 - 19:30 | G6: Monday to Friday (Including Bank Holidays) March to October | J6: 07:00 - 22:00
A7: Monday to Friday (Including Bank Holidays) All Year | C7: 07:00 - 16:30 19:30 - 22:00 | G7: Monday to Friday (Including Bank Holidays) November to February | I7: 16:30 - 19:30 | J7: 07:00 - 16:30 19:30 - 22:00
A8: Monday to Friday (Including Bank Holidays) All Year | E8: 00:00 - 07:00 22:00 - 24:00 | G8: Monday to Friday (Including Bank Holidays) April to March | K8: 00:00 - 07:00 22:00 - 24:00
A9: Saturday and Sunday All Year | C9: 09:30 - 21:30 | E9: 00:00 - 09:30 21:30 - 24:00 | G9: Saturday and Sunday All Year | J9: 09:30 - 21:30 | K9: 00:00 - 09:30 21:30 - 24:00
A10: Notes | B10: All the above times are in UK Clock time | G10: Notes | I10: All the above times are in UK Clock time
A13: Tariff name | B13: Open LLFCs | C13: PCs | D13: Unit charge 1 (NHH) or red/black charge (HH) p/kWh | E13: Unit charge 2 (NHH) or amber/yellow charge (HH) p/kWh | F13: Green charge(HH) p/kWh | G13: Fixed charge p/MPAN/day | H13: Capacity charge p/kVA/day | I13: Exceeded capacity charge p/kVA/day | J13: Reactive power charge p/kVArh | K13: Closed LLFCs
A14: Domestic Unrestricted | B14: 100-103, 108-111, 154-155, 160 | C14: 1 | D14: 1.934 | G14: 3.51
A15: Domestic Two Rate | B15: 104-107, 156-157, 161 | C15: 2 | D15: 2.387 | E15: 0.441 | G15: 3.51 | K15: 124-125
A16: Domestic Off Peak (related MPAN) | B16: 115, 121, 150-153 | C16: 2 | D16: 0.537 | K16: 112-114, 116-120, 122-123
A17: Small Non Domestic Unrestricted | B17: 126-128, 133-134, 162, 473 | C17: 3 | D17: 1.777 | G17: 5.25
A18: Small Non Domestic Two Rate | B18: 129-131, 135-136, 163, 474 | C18: 4 | D18: 2.59 | E18: 0.591 | G18: 5.25
A19: Small Non Domestic Off Peak (related MPAN) | B19: 140, 144 | C19: 4 | D19: 0.665 | K19: 138-139, 141-143, 145
A20: LV Medium Non-Domestic | B20: 164, 400-401, 475, 479 | C20: 5-8 | D20: 1.484 | E20: 0.43 | G20: 28.97
A21: LV Sub Medium Non-Domestic | B21: 405 | C21: 5-8 | D21: 1.276 | E21: 0.409 | G21: 25.78
A22: HV Medium Non-Domestic | C22: 5-8 | D22: 0.862 | E22: 0.368 | G22: 288.71 | K22: 605-606
A23: LV Network Domestic | B23: 165, 456 | C23: 0 | D23: 8.7 | E23: 1.199 | F23: 0.386 | G23: 3.51
A24: LV Network Non-Domestic Non-CT | B24: 166, 457 | C24: 0 | D24: 9.165 | E24: 1.247 | F24: 0.389 | G24: 5.25
A25: LV HH Metered | B25: 453, 470 | C25: 0 | D25: 6.27 | E25: 0.866 | F25: 0.365 | G25: 16.49 | H25: 2.42 | I25: 4.58 | J25: 0.204
A26: LV Sub HH Metered | B26: 455, H99 | C26: 0 | D26: 4.864 | E26: 0.605 | F26: 0.347 | G26: 25.78 | H26: 4.28 | I26: 5.77 | J26: 0.129
A27: HV HH Metered | B27: 476, 658 | C27: 0 | D27: 3.544 | E27: 0.498 | F27: 0.342 | G27: 147.36 | H27: 5.28 | I27: 6.55 | J27: 0.086
A28: NHH UMS category A | B28: 500, 586 | C28: 8 | D28: 2.601
A29: NHH UMS category B | B29: 501, 587 | C29: 1 | D29: 2.657
A30: NHH UMS category C | B30: 502, 588 | C30: 1 | D30: 3.401
A31: NHH UMS category D | B31: 503, 589 | C31: 1 | D31: 2.611
A32: LV UMS (Pseudo HH Metered) | B32: 520 | C32: 0 | D32: 13.724 | E32: 2.576 | F32: 1.839
A33: LV Generation NHH or Aggregate HH | B33: 931, 993 | C33: 8&0 | D33: -0.794 | G33: 0
A34: LV Sub Generation NHH | B34: 932 | C34: 8 | D34: -0.695 | G34: 0
A35: LV Generation Intermittent | B35: 1, 477, 909 | C35: 0 | D35: -0.794 | G35: 0 | J35: 0.186
A36: LV Generation Intermittent no RP charge | B36: 7, 79 | C36: 0 | D36: -0.794 | G36: 0
A37: LV Generation Non-Intermittent | B37: 2 | C37: 0 | D37: -5.536 | E37: -0.571 | F37: -0.033 | G37: 0 | J37: 0.186
A38: LV Generation Non-Intermittent no RP charge | B38: 8, 80 | C38: 0 | D38: -5.536 | E38: -0.571 | F38: -0.033 | G38: 0
A39: LV Sub Generation Intermittent | B39: 3 | C39: 0 | D39: -0.695 | G39: 0 | J39: 0.166
A40: LV Sub Generation Intermittent no RP charge | B40: 146, 210 | C40: 0 | D40: -0.695 | G40: 0
A41: LV Sub Generation Non-Intermittent | B41: 4 | C41: 0 | D41: -4.994 | E41: -0.475 | F41: -0.026 | G41: 0 | J41: 0.166
A42: LV Sub Generation Non-Intermittent no RP charge | B42: 147, 211 | C42: 0 | D42: -4.994 | E42: -0.475 | F42: -0.026 | G42: 0
A43: HV Generation Intermittent | B43: 5, H98 | C43: 0 | D43: -0.46 | G43: 242.78 | J43: 0.147
...

Sheet Annex 2 EHV charges
A1: Back to Overview | E1: Note: The list of MPANs / MSIDs provided may be incomplete; the DNO reserves the right to apply the listed charges to any other MPANs / MSIDs associated with the site.
A2: =Overview!B4& " - Effective from "&Overview!D4&" - "&Overview!E4&" EDCM charges" -> Southern Electric Power Distribution plc - Effective from 1 April 2020 - Final EDCM charges
A4: Time Periods for Designated EHV Properties
A5: Time periods | D5: Super Red Time Band
A6: Monday to Friday (Including Bank Holidays) November to February Inclusive | D6: 16:30 - 19:30
A7: Notes | D7: All the above times are in UK Clock time
A9: Import LLFC | B9: Import MPANs/MSIDs | C9: Export LLFC | D9: Export MPANs/MSIDs | E9: Tariff | F9: Import Super Red unit charge (p/kWh) | G9: Import fixed charge (p/day) | H9: Import capacity charge (p/kVA/day) | I9: Import exceeded capacity charge (p/kVA/day) | J9: Export Super Red unit charge (p/kWh) | K9: Export fixed charge (p/day) | L9: Export capacity charge (p/kVA/day) | M9: Export exceeded capacity charge (p/kVA/day)
A10: 700 | B10: 2000027373741 | E10: Tariff 001 | F10: 0 | G10: 13766.71 | H10: 1.74 | I10: 1.74 | J10: 0 | K10: 0 | L10: 0 | M10: 0
A11: 701 | B11: 2000027366674 | E11: Tariff 002 | F11: 2.459 | G11: 8394.49 | H11: 2.24 | I11: 2.24 | J11: 0 | K11: 0 | L11: 0 | M11: 0
A12: 702 | B12: 2000027342238 | E12: Tariff 003 | F12: 0.406 | G12: 5159.36 | H12: 1.78 | I12: 1.78 | J12: 0 | K12: 0 | L12: 0 | M12: 0
A13: 704 | B13: 2000027343640 | C13: 734 | D13: 2000050928900 | E13: Tariff 004 | F13: 1.209 | G13: 1.97 | H13: 1.57 | I13: 1.57 | J13: 0 | K13: 269.86 | L13: 0.05 | M13: 0.05
A14: 706 | B14: 2000027419271 | C14: 736 | D14: 2000050932127 | E14: Tariff 005 | F14: 1.014 | G14: 9.4 | H14: 1.44 | I14: 1.44 | J14: 0 | K14: 432.39 | L14: 0.05 | M14: 0.05
A15: 707 | B15: 2000027427398 | C15: 737 | D15: 2000050935800 | E15: Tariff 006 | F15: 0.149 | G15: 52.68 | H15: 2.64 | I15: 2.64 | J15: 0 | K15: 0 | L15: 0 | M15: 0
A16: 708 | B16: 2000052675995 | E16: Tariff 007 | F16: 6.692 | G16: 6470.94 | H16: 1.72 | I16: 1.72 | J16: 0 | K16: 0 | L16: 0 | M16: 0
A17: 709 | B17: 2000054624149 | E17: Tariff 008 | F17: 1.024 | G17: 490.92 | H17: 3.18 | I17: 3.18 | J17: 0 | K17: 0 | L17: 0 | M17: 0
A18: 710 | B18: 2000027387210, 2000054817604, 2000055899218 | C18: 740 | D18: 2000055899236, 2000055899245 | E18: Tariff 009 | F18: 0 | G18: 9674.43 | H18: 2.01 | I18: 2.01 | J18: 0 | K18: 4299.75 | L18: 0.05 | M18: 0.05
A19: 711 | B19: 2000027852497 | E19: Tariff 010 | F19: 0 | G19: 7188.49 | H19: 3.06 | I19: 3.06 | J19: 0 | K19: 0 | L19: 0 | M19: 0
A20: 712 | B20: 2000055085297 | E20: Tariff 011 | F20: 1.055 | G20: 3899.52 | H20: 1.87 | I20: 1.87 | J20: 0 | K20: 0 | L20: 0 | M20: 0
A21: 713 | B21: 2000055085302 | E21: Tariff 012 | F21: 1.03 | G21: 9804.94 | H21: 1.29 | I21: 1.29 | J21: 0 | K21: 0 | L21: 0 | M21: 0
A22: 714 | B22: 2000027366665 | E22: Tariff 013 | F22: 1.285 | G22: 572.74 | H22: 2.56 | I22: 2.56 | J22: 0 | K22: 0 | L22: 0 | M22: 0
A23: 715 | B23: 2000051063430 | E23: Tariff 014 | F23: 2.437 | G23: 175.93 | H23: 2.65 | I23: 2.65 | J23: 0 | K23: 0 | L23: 0 | M23: 0
A24: 716 | B24: 2000027366762 | E24: Tariff 015 | F24: 0 | G24: 81.82 | H24: 5.03 | I24: 5.03 | J24: 0 | K24: 0 | L24: 0 | M24: 0
A25: 717 | B25: 2000027373403 | E25: Tariff 016 | F25: 1.783 | G25: 81.82 | H25: 3.73 | I25: 3.73 | J25: 0 | K25: 0 | L25: 0 | M25: 0
A26: 718 | B26: 2000050571060 | C26: 738 | D26: 2000051080338 | E26: Tariff 017 | F26: 1.067 | G26: 575.45 | H26: 1.28 | I26: 1.28 | J26: 0 | K26: 0 | L26: 0 | M26: 0
A27: 719 | B27: 2000027419449 | E27: Tariff 018 | F27: 1.038 | G27: 81.82 | H27: 2.52 | I27: 2.52 | J27: 0 | K27: 0 | L27: 0 | M27: 0
A28: 800 | B28: 2000050277851 | E28: Tariff 019 | F28: 0 | G28: 697.42 | H28: 1.44 | I28: 1.44 | J28: 0 | K28: 0 | L28: 0 | M28: 0
A29: 801 | B29: 2000050393707 | E29: Tariff 020 | F29: 0 | G29: 697.42 | H29: 1.56 | I29: 1.56 | J29: 0 | K29: 0 | L29: 0 | M29: 0
A30: 802 | B30: 2000027366841 | E30: Tariff 021 | F30: 0.788 | G30: 201.99 | H30: 3.35 | I30: 3.35 | J30: 0 | K30: 0 | L30: 0 | M30: 0
A31: 803 | B31: 2000050277513 | E31: Tariff 022 | F31: 0 | G31: 857.37 | H31: 2.43 | I31: 2.43 | J31: 0 | K31: 0 | L31: 0 | M31: 0
A32: 817 | B32: 2000050481327 | E32: Tariff 023 | F32: 0 | G32: 643.03 | H32: 2.4 | I32: 2.4 | J32: 0 | K32: 0 | L32: 0 | M32: 0
A33: 837 | B33: 2000050481309 | E33: Tariff 024 | F33: 0 | G33: 643.03 | H33: 3.94 | I33: 3.94 | J33: 0 | K33: 0 | L33: 0 | M33: 0
A34: 804 | B34: 2000050275631, 2000056717878, 2000056717887 | E34: Tariff 025 | F34: 1.195 | G34: 1046.13 | H34: 1.23 | I34: 1.23 | J34: 0 | K34: 0 | L34: 0 | M34: 0
A35: 805 | B35: 2000027474820 | E35: Tariff 026 | F35: 0 | G35: 213.67 | H35: 1.97 | I35: 1.97 | J35: 0 | K35: 0 | L35: 0 | M35: 0
A36: 806 | B36: 2000027454188 | E36: Tariff 027 | F36: 4.154 | G36: 697.42 | H36: 1.48 | I36: 1.48 | J36: 0 | K36: 0 | L36: 0 | M36: 0
A37: 807 | B37: 2000027454452 | E37: Tariff 028 | F37: 6.119 | G37: 348.71 | H37: 2.48 | I37: 2.48 | J37: 0 | K37: 0 | L37: 0 | M37: 0
A38: 808 | B38: 2000052503790 | E38: Tariff 029 | F38: 0.762 | G38: 697.42 | H38: 1.55 | I38: 1.55 | J38: 0 | K38: 0 | L38: 0 | M38: 0
A39: 809 | B39: 2000027297816 | E39: Tariff 030 | F39: 0 | G39: 398.35 | H39: 0.34 | I39: 0.34 | J39: 0 | K39: 0 | L39: 0 | M39: 0
A40: 810 | B40: 2000050467030 | C40: 918 | D40: 2000027292534 | E40: Tariff 031 | F40: 0 | G40: 810.41 | H40: 0.45 | I40: 0.45 | J40: 0 | K40: 0 | L40: 0 | M40: 0
A41: 811 | B41: 2000051063927 | E41: Tariff 032 | F41: 0 | G41: 412.74 | H41: 6 | I41: 6 | J41: 0 | K41: 0 | L41: 0 | M41: 0
A42: 812 | B42: 2000027339192 | E42: Tariff 033 | F42: 0.406 | G42: 1.82 | H42: 2.76 | I42: 2.76 | J42: 0 | K42: 0 | L42: 0 | M42: 0
...

Sheet Annex 2a Import
A1: Note: The list of MPANs / MSIDs provided may be incomplete; the DNO reserves the right to apply the listed charges to any other MPANs / MSIDs associated with the site.
A2: =Overview!B4& " - Effective from "&Overview!D4&" - "&Overview!E4&" EDCM import charges" -> Southern Electric Power Distribution plc - Effective from 1 April 2020 - Final EDCM import charges
A4: Import LLFC | B4: Import MPANs/MSIDs | C4: Tariff | D4: ='Annex 2 EHV charges'!F9 -> Import Super Red unit charge (p/kWh) | E4: ='Annex 2 EHV charges'!G9 -> Import fixed charge (p/day) | F4: ='Annex 2 EHV charges'!H9 -> Import capacity charge (p/kVA/day) | G4: ='Annex 2 EHV charges'!I9 -> Import exceeded capacity charge (p/kVA/day)
A5: 700 | B5: 2000027373741 | C5: Tariff 001 | D5: 0 | E5: 13766.71 | F5: 1.74 | G5: 1.74
A6: 701 | B6: 2000027366674 | C6: Tariff 002 | D6: 2.459 | E6: 8394.49 | F6: 2.24 | G6: 2.24
A7: 702 | B7: 2000027342238 | C7: Tariff 003 | D7: 0.406 | E7: 5159.36 | F7: 1.78 | G7: 1.78
A8: 704 | B8: 2000027343640 | C8: Tariff 004 | D8: 1.209 | E8: 1.97 | F8: 1.57 | G8: 1.57
A9: 706 | B9: 2000027419271 | C9: Tariff 005 | D9: 1.014 | E9: 9.4 | F9: 1.44 | G9: 1.44
A10: 707 | B10: 2000027427398 | C10: Tariff 006 | D10: 0.149 | E10: 52.68 | F10: 2.64 | G10: 2.64
A11: 708 | B11: 2000052675995 | C11: Tariff 007 | D11: 6.692 | E11: 6470.94 | F11: 1.72 | G11: 1.72
A12: 709 | B12: 2000054624149 | C12: Tariff 008 | D12: 1.024 | E12: 490.92 | F12: 3.18 | G12: 3.18
A13: 710 | B13: 2000027387210, 2000054817604, 2000055899218 | C13: Tariff 009 | D13: 0 | E13: 9674.43 | F13: 2.01 | G13: 2.01
A14: 711 | B14: 2000027852497 | C14: Tariff 010 | D14: 0 | E14: 7188.49 | F14: 3.06 | G14: 3.06
A15: 712 | B15: 2000055085297 | C15: Tariff 011 | D15: 1.055 | E15: 3899.52 | F15: 1.87 | G15: 1.87
A16: 713 | B16: 2000055085302 | C16: Tariff 012 | D16: 1.03 | E16: 9804.94 | F16: 1.29 | G16: 1.29
A17: 714 | B17: 2000027366665 | C17: Tariff 013 | D17: 1.285 | E17: 572.74 | F17: 2.56 | G17: 2.56
A18: 715 | B18: 2000051063430 | C18: Tariff 014 | D18: 2.437 | E18: 175.93 | F18: 2.65 | G18: 2.65
A19: 716 | B19: 2000027366762 | C19: Tariff 015 | D19: 0 | E19: 81.82 | F19: 5.03 | G19: 5.03
A20: 717 | B20: 2000027373403 | C20: Tariff 016 | D20: 1.783 | E20: 81.82 | F20: 3.73 | G20: 3.73
A21: 718 | B21: 2000050571060 | C21: Tariff 017 | D21: 1.067 | E21: 575.45 | F21: 1.28 | G21: 1.28
A22: 719 | B22: 2000027419449 | C22: Tariff 018 | D22: 1.038 | E22: 81.82 | F22: 2.52 | G22: 2.52
A23: 800 | B23: 2000050277851 | C23: Tariff 019 | D23: 0 | E23: 697.42 | F23: 1.44 | G23: 1.44
A24: 801 | B24: 2000050393707 | C24: Tariff 020 | D24: 0 | E24: 697.42 | F24: 1.56 | G24: 1.56
A25: 802 | B25: 2000027366841 | C25: Tariff 021 | D25: 0.788 | E25: 201.99 | F25: 3.35 | G25: 3.35
... A28: 837 | B28: 2000050481309 | C28: Tariff 024 | D28: 0 | E28: 643.03 | F28: 3.94 | G28: 3.94
A29: 804 | B29: 2000050275631, 2000056717878, 2000056717887 | C29: Tariff 025 | D29: 1.195 | E29: 1046.13 | F29: 1.23 | G29: 1.23
A30: 805 | B30: 2000027474820 | C30: Tariff 026 | D30: 0 | E30: 213.67 | F30: 1.97 | G30: 1.97
A31: 806 | B31: 2000027454188 | C31: Tariff 027 | D31: 4.154 | E31: 697.42 | F31: 1.48 | G31: 1.48
A32: 807 | B32: 2000027454452 | C32: Tariff 028 | D32: 6.119 | E32: 348.71 | F32: 2.48 | G32: 2.48
A33: 808 | B33: 2000052503790 | C33: Tariff 029 | D33: 0.762 | E33: 697.42 | F33: 1.55 | G33: 1.55
A34: 809 | B34: 2000027297816 | C34: Tariff 030 | D34: 0 | E34: 398.35 | F34: 0.34 | G34: 0.34
A35: 810 | B35: 2000050467030 | C35: Tariff 031 | D35: 0 | E35: 810.41 | F35: 0.45 | G35: 0.45
A36: 811 | B36: 2000051063927 | C36: Tariff 032 | D36: 0 | E36: 412.74 | F36: 6 | G36: 6
A37: 812 | B37: 2000027339192 | C37: Tariff 033 | D37: 0.406 | E37: 1.82 | F37: 2.76 | G37: 2.76
A38: 812 | B38: 2000050544330 | C38: Tariff 034 | D38: 0.399 | E38: 1.82 | F38: 2.78 | G38: 2.78
A39: 813 | B39: 2000055209191, 2000055209207, 2000055209216, 2000055209225, 2000055209234, 2000055209252, 2000055209243 | C39: Tariff 035 | D39: 0 | E39: 5026.04 | F39: 3.72 | G39: 3.72
A40: 814 | B40: 2000027340036 | C40: Tariff 036 | D40: 0.404 | E40: 267.91 | F40: 0.69 | G40: 0.69
A41: 815 | B41: 2000027454648 | C41: Tariff 037 | D41: 0 | E41: 1731.23 | F41: 1.22 | G41: 1.22
A42: 816 | B42: 2000027306995 | C42: Tariff 038 | D42: 0 | E42: 436.34 | F42: 1.94 | G42: 1.94
A43: 818 | B43: 2000050277160 | C43: Tariff 039 | D43: 0 | E43: 42902.73 | F43: 9.85 | G43: 9.85
...

Sheet Annex 2b Export
A1: Note: The list of MPANs / MSIDs provided may be incomplete; the DNO reserves the right to apply the listed charges to any other MPANs / MSIDs associated with the site.
A2: =Overview!B4& " - Effective from "&Overview!D4&" - "&Overview!E4&" EDCM export charges" -> Southern Electric Power Distribution plc - Effective from 1 April 2020 - Final EDCM export charges
A4: Export LLFC | B4: Export MPANs/MSIDs | C4: Tariff | D4: ='Annex 2 EHV charges'!J9 -> Export Super Red unit charge (p/kWh) | E4: ='Annex 2 EHV charges'!K9 -> Export fixed charge (p/day) | F4: ='Annex 2 EHV charges'!L9 -> Export capacity charge (p/kVA/day) | G4: ='Annex 2 EHV charges'!M9 -> Export exceeded capacity charge (p/kVA/day)
A5: 734 | B5: 2000050928900 | C5: Tariff 004 | D5: 0 | E5: 269.86 | F5: 0.05 | G5: 0.05
A6: 736 | B6: 2000050932127 | C6: Tariff 005 | D6: 0 | E6: 432.39 | F6: 0.05 | G6: 0.05
A7: 737 | B7: 2000050935800 | C7: Tariff 006 | D7: 0 | E7: 0 | F7: 0 | G7: 0
A8: 740 | B8: 2000055899236, 2000055899245 | C8: Tariff 009 | D8: 0 | E8: 4299.75 | F8: 0.05 | G8: 0.05
A9: 738 | B9: 2000051080338 | C9: Tariff 017 | D9: 0 | E9: 0 | F9: 0 | G9: 0
A10: 918 | B10: 2000027292534 | C10: Tariff 031 | D10: 0 | E10: 0 | F10: 0 | G10: 0
A11: 929 | B11: 2000054899591 | C11: Tariff 036 | D11: 0 | E11: 417.18 | F11: 0.05 | G11: 0.05
A12: 924 | B12: 2000054397290 | C12: Tariff 037 | D12: 0 | E12: 946.85 | F12: 0.05 | G12: 0.05
A13: 937 | B13: 2000050795630 | C13: Tariff 038 | D13: 0 | E13: 545.43 | F13: 0.05 | G13: 0.05
A14: 7174 | B14: 7174 | C14: Tariff 041 | D14: 0 | E14: 0 | F14: 0 | G14: 0
A15: 923 | B15: 2000053759174 | C15: Tariff 043 | D15: 0 | E15: 1371.61 | F15: 0.05 | G15: 0.05
A16: 4032 | B16: 4032 | C16: Tariff 055 | D16: 0 | E16: 7.16 | F16: 0.05 | G16: 0.05
A17: 4548 | B17: 4548 | C17: Tariff 056 | D17: 0 | E17: 7.27 | F17: 0.05 | G17: 0.05
A18: 925 | B18: 2000053874080 | C18: Tariff 057 | D18: 0 | E18: 262.12 | F18: 0.05 | G18: 0.05
A19: 521 | B19: 2000053874123 | C19: Tariff 058 | D19: 0 | E19: 383.75 | F19: 0.05 | G19: 0.05
A20: 930 | B20: 2000051034322 | C20: Tariff 059 | D20: 0 | E20: 0 | F20: 0 | G20: 0
... A61: 629 | B61: 2000056041565 | C61: Tariff 121 | D61: 0 | E61: 2146.98 | F61: 0.05 | G61: 0.05
A62: 914 | B62: - | C62: Tariff 122 | D62: 0 | E62: 1013.38 | F62: 0.05 | G62: 0.05
A63: 630 | B63: 2000055582819 | C63: Tariff 124 | D63: 0 | E63: 366.75 | F63: 0.05 | G63: 0.05
A64: 631 | B64: 2000056442156 | C64: Tariff 125 | D64: 0 | E64: 168.49 | F64: 0.05 | G64: 0.05
A65: 632 | B65: 2000055894948 | C65: Tariff 126 | D65: 0 | E65: 366.86 | F65: 0.05 | G65: 0.05
A66: 633 | B66: 2000055630125 | C66: Tariff 127 | D66: 0 | E66: 247.18 | F66: 0.05 | G66: 0.05
A67: 634 | B67: 2000055845782 | C67: Tariff 128 | D67: 0 | E67: 248.98 | F67: 0.05 | G67: 0.05
A68: 635 | B68: 2000055856989 | C68: Tariff 129 | D68: 0 | E68: 1691.07 | F68: 0.05 | G68: 0.05
A69: 648 | B69: 2000056875324 | C69: Tariff 131 | D69: 0 | E69: 3239.12 | F69: 0.05 | G69: 0.05
A70: 637 | B70: - | C70: Tariff 132 | D70: 0 | E70: 3481.08 | F70: 0.05 | G70: 0.05
A71: 639 | B71: 2000055875003 | C71: Tariff 134 | D71: 0 | E71: 1323.77 | F71: 0.05 | G71: 0.05
A72: 640 | B72: 2000055996668 | C72: Tariff 135 | D72: 0 | E72: 362.84 | F72: 0.05 | G72: 0.05
A73: 641 | B73: 2000055627888 | C73: Tariff 136 | D73: 0 | E73: 246.79 | F73: 0.05 | G73: 0.05
A74: 642 | B74: 2000055899797 | C74: Tariff 137 | D74: 0 | E74: 775.23 | F74: 0.05 | G74: 0.05
A75: 645 | B75: 2000055924014 | C75: Tariff 138 | D75: 0 | E75: 1678.47 | F75: 0.05 | G75: 0.05
A76: 646 | B76: 2000055878705 | C76: Tariff 139 | D76: 0 | E76: 819.41 | F76: 0.05 | G76: 0.05
A77: Z00 | B77: 2000056762142 | C77: Tariff 140 | D77: 0 | E77: 986.11 | F77: 0.05 | G77: 0.05
A78: 649 | B78: 2000055901300 | C78: Tariff 143 | D78: 0 | E78: 324.53 | F78: 0.05 | G78: 0.05
A79: 911 | B79: 2000055901355 | C79: Tariff 144 | D79: 0 | E79: 362.55 | F79: 0.05 | G79: 0.05
A80: 912 | B80: 2000055899398 | C80: Tariff 146 | D80: 0 | E80: 1086.36 | F80: 0.05 | G80: 0.05
A81: 952 | B81: 2000056479110 | C81: Tariff 147 | D81: 0 | E81: 1843.08 | F81: 0.05 | G81: 0.05
...

Sheet Annex 3 Preserved charges
A1: Back to Overview
A2: =Overview!B4& " - Effective from "&Overview!D4&" - "&Overview!E4&" LV and HV tariffs" -> Southern Electric Power Distribution plc - Effective from 1 April 2020 - Final LV and HV tariffs
A3: NHH preserved charges/additional LLFCs
B4: Closed LLFCs | C4: PCs | D4: Unit charge 1 (NHH) p/kWh | E4: Unit charge 2 (NHH) p/kWh | F4: Fixed charge p/MPAN/day
A5: Domestic Two Rate | B5: 124-125 | C5: 2 | D5: 2.387 | E5: 0.441 | F5: 3.51
A6: Domestic Off Peak (related MPAN) | B6: 112-114, 116-120, 122-123 | C6: 2 | D6: 0.537
A7: Small Non Domestic Off Peak (related MPAN) | B7: 138-139, 141-143, 145 | C7: 4 | D7: 0.665
A8: HV Medium Non-Domestic | B8: 605-606 | C8: 5-8 | D8: 0.862 | E8: 0.368 | F8: 288.71
A9: Notes: | B9: Unit time periods are as specified in the SSC.
A12: HH preserved charges/additional LLFCs
B13: Closed LLFCs | C13: PCs | D13: Red/black charge (HH) p/kWh | E13: Amber/yellow charge (HH) p/kWh | F13: Green charge (HH) p/kWh | G13: Fixed charge p/MPAN/day | H13: Capacity charge p/kVA/day | I13: Exceeded capacity charge p/kVA/day | J13: Reactive power charge p/kVArh
C14: 0
A15: Notes: | B15: Time periods
B16: Unit charges in the Red Time Band apply – between [16:30] and [19:30], Monday to Friday including bank holidays.
B17: Unit charges in the Amber Time Band apply – between [07:00] and [16:30] and [19:30] and [22:00], Monday to Friday including bank holidays, and [09:30] and [21:30] Saturday and Sunday.
B18: Unit charges in the Green Time Band apply – between [00:00] and [07:00] and [22:00] and [24:00], Monday to Friday including bank holidays, and [00:00] and [09:30] and [21:30] and [24:00], Saturday and Sunday.
B19: All times are UK clock-time.

Sheet Annex 4 LDNO charges
A1: Back to Overview
A2: =Overview!B4& " - Effective from "&Overview!D4&" - "&Overview!E4&" LDNO tariffs" -> Southern Electric Power Distribution plc - Effective from 1 April 2020 - Final LDNO tariffs
A4: Time Bands for Half Hourly Metered Properties | F4: Time Bands for Half Hourly Unmetered Properties
A5: Time periods | B5: Red Time Band | C5: Amber Time Band | D5: Green Time Band | H5: Black Time Band | I5: Yellow Time Band | J5: Green Time Band
A6: Monday to Friday (Including Bank Holidays) All Year | B6: 16:30 - 19:30 | F6: Monday to Friday (Including Bank Holidays) March to October | I6: 07:00 - 22:00
A7: Monday to Friday (Including Bank Holidays) All Year | C7: 07:00 - 16:30 19:30 - 22:00 | F7: Monday to Friday (Including Bank Holidays) November to February | H7: 16:30 - 19:30 | I7: 07:00 - 16:30 19:30 - 22:00
A8: Monday to Friday (Including Bank Holidays) All Year | D8: 00:00 - 07:00 22:00 - 24:00 | F8: Monday to Friday (Including Bank Holidays) April to March | J8: 00:00 - 07:00 22:00 - 24:00
A9: Saturday and Sunday All Year | C9: 09:30 - 21:30 | D9: 00:00 - 09:30 21:30 - 24:00 | F9: Saturday and Sunday All Year | I9: 09:30 - 21:30 | J9: 00:00 - 09:30 21:30 - 24:00
A10: Notes | B10: All the above times are in UK Clock time | F10: Notes | H10: All the above times are in UK Clock time
A13: Tariff name | B13: Unique billing identifier | C13: PCs | D13: ='Annex 1 LV and HV charges'!D13 -> Unit charge 1 (NHH) or red/black charge (HH) p/kWh | E13: ='Annex 1 LV and HV charges'!E13 -> Unit charge 2 (NHH) or amber/yellow charge (HH) p/kWh | F13: ='Annex 1 LV and HV charges'!F13 -> Green charge(HH) p/kWh | G13: ='Annex 1 LV and HV charges'!G13 -> Fixed charge p/MPAN/day | H13: ='Annex 1 LV and HV charges'!H13 -> Capacity charge p/kVA/day | I13: ='Annex 1 LV and HV charges'!I13 -> Exceeded capacity charge p/kVA/day | J13: ='Annex 1 LV and HV charges'!J13 -> Reactive power charge p/kVArh
A14: LDNO LV: Domestic Unrestricted | C14: 1 | D14: 1.262 | G14: 2.29
A15: LDNO LV: Domestic Two Rate | C15: 2 | D15: 1.557 | E15: 0.288 | G15: 2.29
A16: LDNO LV: Domestic Off Peak (related MPAN) | C16: 2 | D16: 0.35
A17: LDNO LV: Small Non Domestic Unrestricted | C17: 3 | D17: 1.159 | G17: 3.43
A18: LDNO LV: Small Non Domestic Two Rate | C18: 4 | D18: 1.69 | E18: 0.386 | G18: 3.43
A19: LDNO LV: Small Non Domestic Off Peak (related MPAN) | C19: 4 | D19: 0.434
A20: LDNO LV: LV Medium Non-Domestic | C20: 5-8 | D20: 0.968 | E20: 0.281 | G20: 18.9
A21: LDNO LV: LV Network Domestic | C21: 0 | D21: 5.676 | E21: 0.782 | F21: 0.252 | G21: 2.29
A22: LDNO LV: LV Network Non-Domestic Non-CT | C22: 0 | D22: 5.98 | E22: 0.814 | F22: 0.254 | G22: 3.43
A23: LDNO LV: LV HH Metered | C23: 0 | D23: 4.091 | E23: 0.565 | F23: 0.238 | G23: 10.76 | H23: 1.58 | I23: 2.99 | J23: 0.133
A24: LDNO LV: NHH UMS category A | C24: 8 | D24: 1.697
A25: LDNO LV: NHH UMS category B | C25: 1 | D25: 1.734
A26: LDNO LV: NHH UMS category C | C26: 1 | D26: 2.219
A27: LDNO LV: NHH UMS category D | C27: 1 | D27: 1.704
A28: LDNO LV: LV UMS (Pseudo HH Metered) | C28: 0 | D28: 8.954 | E28: 1.681 | F28: 1.2
A29: LDNO LV: LV Generation NHH or Aggregate HH | C29: 8&0 | D29: -0.794 | G29: 0
A30: LDNO LV: LV Generation Intermittent | C30: 0 | D30: -0.794 | G30: 0 | J30: 0.186
A31: LDNO LV: LV Generation Non-Intermittent | C31: 0 | D31: -5.536 | E31: -0.571 | F31: -0.033 | G31: 0 | J31: 0.186
A32: LDNO HV: Domestic Unrestricted | C32: 1 | D32: 0.87 | G32: 1.58
A33: LDNO HV: Domestic Two Rate | C33: 2 | D33: 1.073 | E33: 0.198 | G33: 1.58
A34: LDNO HV: Domestic Off Peak (related MPAN) | C34: 2 | D34: 0.241
A35: LDNO HV: Small Non Domestic Unrestricted | C35: 3 | D35: 0.799 | G35: 2.36
A36: LDNO HV: Small Non Domestic Two Rate | C36: 4 | D36: 1.165 | E36: 0.266 | G36: 2.36
A37: LDNO HV: Small Non Domestic Off Peak (related MPAN) | C37: 4 | D37: 0.299
A38: LDNO HV: LV Medium Non-Domestic | C38: 5-8 | D38: 0.668 | E38: 0.193 | G38: 13.03
A39: LDNO HV: LV Network Domestic | C39: 0 | D39: 3.913 | E39: 0.539 | F39: 0.173 | G39: 1.58
A40: LDNO HV: LV Network Non-Domestic Non-CT | C40: 0 | D40: 4.122 | E40: 0.561 | F40: 0.175 | G40: 2.36
A41: LDNO HV: LV HH Metered | C41: 0 | D41: 2.82 | E41: 0.39 | F41: 0.164 | G41: 7.41 | H41: 1.09 | I41: 2.06 | J41: 0.092
A42: LDNO HV: LV Sub HH Metered | C42: 0 | D42: 3.487 | E42: 0.434 | F42: 0.248 | G42: 18.48 | H42: 3.07 | I42: 4.14 | J42: 0.093
A43: LDNO HV: HV HH Metered | C43: 0 | D43: 2.909 | E43: 0.408 | F43: 0.28 | G43: 120.97 | H43: 4.34 | I43: 5.38 | J43: 0.071
...

Sheet Annex 5 LLFs
A1: Back to Overview
A2: This table has intentionally been left blank. The line loss factors that are approved by the BSC Panel for the applicable year and consequently published on the Elexon website will take precedence and be used in Settlement. This annex will be re-published once these values are available.
A3: =Overview!B4& " - Illustrative LLFs for year beginning "&Overview!D4 -> Southern Electric Power Distribution plc - Illustrative LLFs for year beginning 1 April 2020
A4: Time periods | B4: Period 1 | C4: Period 2 | D4: Period 3 | E4: Period 4
B5: Winter Weekday Peak | C5: Winter Weekday | D5: Other | E5: Night
A6: Monday to Friday Nov to Feb | B6: 16:00 – 19:00 | C6: 07:30 – 16:00 19:00 – 20:00 | D6: 20:00 – 00:30 | E6: 00:30 – 07:30
A7: Saturday and Sunday All Year and Monday to Friday Mar to Oct | D7: 07:30 – 00:30 | E7: 00:30 – 07:30
A8: Notes | B8: All the above times are in UK Clock time
A11: Generic demand and generation LLFs
A12: Metered voltage, respective periods and associated LLFCs
A13: Metered voltage | B13: Period 1 | C13: Period 2 | D13: Period 3 | E13: Period 4 | F13: Associated LLFC
A14: Low-voltage network | B14: 1.094 | C14: 1.085 | D14: 1.076 | E14: 1.072 | F14: 100-131, 133-136, 138-145, 150-157, 160-166, 400-401, 453, 456-457, 470,473-475, 479, 500-503, 520, 586-589 / 1, 2, 7, 8, 79, 80, 477, 909, 931, 993
A15: Low-voltage substation | B15: 1.047 | C15: 1.045 | D15: 1.044 | E15: 1.047 | F15: 405, 455, H99 / 3, 4, 146, 147, 210, 211, 932
A16: High-voltage network | B16: 1.032 | C16: 1.029 | D16: 1.024 | E16: 1.022 | F16: 476, 605, 606, 658 / 5, 6, 148, 149, 212, 213, 478, 910, H98
A17: High-voltage substation | B17: 1.022 | C17: 1.02 | D17: 1.018 | E17: 1.017 | F17: 700-719, 729-732, 735, 739, 745, 746, H96 / 734, 736, 737, 738, 740-743, 748, 749, H97
A18: 33kV generic | B18: 1.016 | C18: 1.015 | D18: 1.012 | E18: 1.011 | F18: 897 / 933
A19: 132/33kV generic | B19: 1.009 | C19: 1.008 | D19: 1.007 | E19: 1.007 | F19: 898 / 934
A20: 132kV generic | B20: 1.005 | C20: 1.004 | D20: 1.003 | E20: 1.003 | F20: 899 / 935
A22: EHV site specific LLFs
A23: Demand
A24: Tariff | B24: Period 1 | C24: Period 2 | D24: Period 3 | E24: Period 4 | F24: Associated LLFC
A25: Tariff 001 | B25: 1.022 | C25: 1.02 | D25: 1.018 | E25: 1.017 | F25: 700
A26: Tariff 002 | B26: 1.022 | C26: 1.02 | D26: 1.018 | E26: 1.017 | F26: 701
A27: Tariff 003 | B27: 1.022 | C27: 1.02 | D27: 1.018 | E27: 1.017 | F27: 702
A28: Tariff 004 | B28: 1.022 | C28: 1.02 | D28: 1.018 | E28: 1.017 | F28: 704
A29: Tariff 005 | B29: 1.022 | C29: 1.02 | D29: 1.018 | E29: 1.017 | F29: 706
A30: Tariff 006 | B30: 1.022 | C30: 1.02 | D30: 1.018 | E30: 1.017 | F30: 707
A31: Tariff 007 | B31: 1.022 | C31: 1.02 | D31: 1.018 | E31: 1.017 | F31: 708
A32: Tariff 008 | B32: 1.022 | C32: 1.02 | D32: 1.018 | E32: 1.017 | F32: 709
A33: Tariff 009 | B33: 1.022 | C33: 1.02 | D33: 1.018 | E33: 1.017 | F33: 710
A34: Tariff 010 | B34: 1.022 | C34: 1.02 | D34: 1.018 | E34: 1.017 | F34: 711
A35: Tariff 011 | B35: 1.022 | C35: 1.02 | D35: 1.018 | E35: 1.017 | F35: 712
A36: Tariff 012 | B36: 1.022 | C36: 1.02 | D36: 1.018 | E36: 1.017 | F36: 713
... A65: Tariff 041 | B65: 0.999 | C65: 0.999 | D65: 0.999 | E65: 0.999 | F65: 7174
A66: Tariff 042 | B66: N/A | C66: N/A | D66: N/A | E66: N/A | F66: N/A
A67: Tariff 043 | B67: 1 | C67: 1 | D67: 1.001 | E67: 1 | F67: 823
A68: Tariff 044 | B68: 1.04 | C68: 1.039 | D68: 1.088 | E68: 1.042 | F68: 824
A69: Tariff 045 | B69: 1.008 | C69: 1.008 | D69: 1.008 | E69: 1.007 | F69: 825
A70: Tariff 046 | B70: 1.006 | C70: 1.006 | D70: 1.006 | E70: 1.005 | F70: 826
A71: Tariff 047 | B71: 1.013 | C71: 1.013 | D71: 1.014 | E71: 1.016 | F71: 827
...

Sheet Annex 6 new or amended EHV
A1: Back to Overview | F1: Note: The list of MPANs/MSIDs provided may be incomplete; the DNO reserves the right to apply the listed charges to any other MPANs/MSIDs associated with the site. If sites appear in both Annex 2 and Annex 6, the charges in Annex 6 take precedence. Where an existing Designated EHV Property is modified and energised in the charging year, we may revise the EDCM charges for the modified Designated EHV Property.
A2: Annex 6 - Charges for New or Amended Designated EHV Properties
A4: =Overview!B4& " - Effective from "&Overview!D4&" - "&Overview!E4&" new or amended designated EHV charges" -> Southern Electric Power Distribution plc - Effective from 1 April 2020 - Final new or amended designated EHV charges
A5: Effective from date | B5: Import LLFC | C5: Import MPANs/MSIDs | D5: Export LLFC | E5: Export MPANs/MSIDs | F5: Tariff | G5: ='Annex 2 EHV charges'!F9 -> Import Super Red unit charge (p/kWh) | H5: ='Annex 2 EHV charges'!G9 -> Import fixed charge (p/day) | I5: ='Annex 2 EHV charges'!H9 -> Import capacity charge (p/kVA/day) | J5: ='Annex 2 EHV charges'!I9 -> Import exceeded capacity charge (p/kVA/day) | K5: ='Annex 2 EHV charges'!J9 -> Export Super Red unit charge (p/kWh) | L5: ='Annex 2 EHV charges'!K9 -> Export fixed charge (p/day) | M5: ='Annex 2 EHV charges'!L9 -> Export capacity charge (p/kVA/day) | N5: ='Annex 2 EHV charges'!M9 -> Export exceeded capacity charge (p/kVA/day)
A17: =Overview!B4& " - Effective from "&Overview!D4&" - "&Overview!E4&" new or amended designated EHV line loss factors" -> Southern Electric Power Distribution plc - Effective from 1 April 2020 - Final new or amended designated EHV line loss factors
A18: Effective from date | B18: Import LLFC | C18: Import MPANs/MSIDs | D18: Export LLFC | E18: Export MPANs/MSIDs | F18: Tariff | G18: Import LLF period 1 | H18: Import LLF period 2 | I18: Import LLF period 3 | J18: Import LLF period 4 | K18: Export LLF period 1 | L18: Export LLF period 2 | M18: Export LLF period 3 | N18: Export LLF period 4

Sheet Nodal prices
A1: Back to Overview
A2: =Overview!B4& " - Effective from "&Overview!D4&" - "&Overview!E4&" Nodal/Zonal charges" -> Southern Electric Power Distribution plc - Effective from 1 April 2020 - Final Nodal/Zonal charges
A3: Node/Zone ID | B3: Geographical name | C3: Local charge 1 £/kVA | D3: Remote charge 1 £/kVA
A4: 1 | B4: Mannington | C4: 16.339175 | D4: 0
A5: 2 | B5: Melksham | C5: 1.0642836 | D5: 0
A6: 3 | B6: Fleet & Bramley | C6: 2.6414871 | D6: 0
A7: 4 | B7: Amersham | C7: 0 | D7: 0
A8: 5 | B8: Bramley (ANDO & THAT) | C8: 0 | D8: 0
A9: 6 | B9: Axminster | C9: 1.5710959 | D9: 0
A10: 7 | B10: Bramley (BASI) | C10: 0 | D10: 0
A11: 8 | B11: Minety | C11: 0 | D11: 0
A12: 9 | B12: Fawley & Nursling | C12: 0 | D12: 0
A13: 10 | B13: Botley Wood | C13: 0 | D13: 0
A14: 11 | B14: Iver 132 | C14: 0 | D14: 0
A15: 12 | B15: Lovedean A2 | C15: 0 | D15: 0
... A784: 851 | B784: DELT-E 11.000 | C784: 0 | D784: 0

Sheet SSC TPR unit rate lookup
A1: Back to Overview
A28: Standard Settlement Configuration Id | B28: Time Pattern Regime Id | C28: Standard Settlement Configuration Desc | D28: Common Decode | G28: Change implemented | H28: Date | I28: Comments
A29: 3 | B29: 166 | C29: 10-hour OP | D29: O | H29: 40057 | I29: First published spreadsheet
A30: 4 | B30: 168 | C30: 10-hour OP | D30: O | G30: SSC 0330 charge rates corrected | H30: 40275 | I30: Previous Off-peak rate corrected to charge 2
A31: 5 | B31: 100 | C31: 10-hour OP + w/e | D31: O | G31: SSC 0250 charge rate corrected | H31: 40347 | I31: Previous rate 1 corrected to Off Peak O
A32: 6 | B32: 257 | C32: 10.5-hour OP | D32: O | G32: SSC 0134 charge rate corrected | H32: 41166 | I32: TPR 00101 corrected from Off Peak O to Rate 1
A33: 7 | B33: 158 | C33: 10.5-hour OP | D33: O | G33: New SSCs added | H33: 41178 | I33: New SSCs from 0953 added.
A34: 8 | B34: 159 | C34: 10.5-hour OP | D34: O | G34: SSC 0394 charge rate corrected | H34: 41758 | I34: TPR 01177 corrected to rate 2
A35: 9 | B35: 1111 | C35: 10.5-hour OP | D35: O | G35: Table reviewed and updated | H35: 41758 | I35: New SSCs from 0949 to 0952, 0975 & 0976 and 0982 & 0983 added.
A36: 10 | B36: 1104 | C36: 10.5-hour OP | D36: O | G36: Table reviewed and updated | H36: 41944 | I36: New SSCs from 0984 and 0985 added.
A37: 11 | B37: 1112 | C37: 10.5-hour OP | D37: O | G37: SSC 0313 charge code corrected | H37: 42081 | I37: TPR 01006 corrected to code O
A38: 12 | B38: 1116 | C38: 10.5-hour OP | D38: O | G38: SSC 0320 charge code corrected | H38: 42081 | I38: TPR 00072 corrected to code 2
A39: 13 | B39: 139 | C39: 11 Hour OP | D39: EMEB or MIDE only | G39: SSC 0781 charge code corrected | H39: 42081 | I39: TPR 00327 corrected to code O
A40: 15 | B40: 152 | C40: 11 Hour OP | D40: EMEB or MIDE only | G40: SSC 0935 charge code corrected | H40: 42081 | I40: TPR 00375 corrected to code 1 or Unsupported (SWAE and SWEB)
A41: 16 | B41: 113 | C41: 11.5-hour OP | D41: Unsupported (SWEB) | G41: SSC 0953 charge code corrected | H41: 42081 | I41: TPR 00424 corrected to code 1 or Unsupported (SWAE and SWEB)
... A74: 50 | B74: 14 | C74: 12-hour OP + w/e & Summer | D74: O | G74: SSC 0942 charge code corrected | H74: 42166 | I74: TPR 00400 corrected to code 1
A75: 51 | B75: 112 | C75: 12-hour night | D75: 1 | G75: SSC 0943 charge code corrected | H75: 42166 | I75: TPR 00404 corrected to code 1
A76: 51 | B76: 120 | C76: 12-hour night | D76: 2 | G76: SSC 0944 charge code corrected | H76: 42166 | I76: TPR 00406 corrected to code 1
A77: 52 | B77: 114 | C77: 12-hour OP | D77: EMEB or MIDE only | G77: SSC 0945 charge code corrected | H77: 42166 | I77: TPR 00408 corrected to code 1
A78: 53 | B78: 115 | C78: 12-hour OP | D78: EMEB or MIDE only | G78: SSC 0946 charge code corrected | H78: 42166 | I78: TPR 00410 corrected to code 1
A79: 55 | B79: 117 | C79: 12-hour OP | D79: EMEB or MIDE only | G79: SSC 0954 charge code corrected | H79: 42166 | I79: TPR 00426 corrected to code 1
A80: 56 | B80: 118 | C80: 12-hour OP | D80: EMEB or MIDE only | G80: SSC 0967 charge code corrected | H80: 42166 | I80: TPR 00442 corrected to code 1
A81: 57 | B81: 119 | C81: 12-hour OP | D81: O | G81: SSC 0970 charge code corrected | H81: 42166 | I81: TPR 00447 corrected to code 2
A82: 58 | B82: 21 | C82: Key Meter pseudo 2-rate | D82: 1 | G82: SSC 0970 charge code corrected | H82: 42166 | I82: TPR 00448 corrected to code 1
A83: 58 | B83: 175 | C83: Key Meter pseudo 2-rate | D83: 1 | G83: SSC 0971 charge code corrected | H83: 42166 | I83: TPR 00493 corrected to code 1
A84: 59 | B84: 121 | C84: 12-hour OP | D84: EMEB or MIDE only
A85: 60 | B85: 122 | C85: 12-hour OP | D85: O
A86: 62 | B86: 1119 | C86: 8-hour OP (see also SSC 427) | D86: 2 or Unsupported (SWEB)
A87: 63 | B87: 172 | C87: 9-hour OP | D87: EMEB or MIDE only
A88: 64 | B88: 1105 | C88: 12-hour OP | D88: O
A89: 65 | B89: 10 | C89: 12-hour OP + Summer | D89: O
A90: 66 | B90: 1106 | C90: 12-hour OP + Summer | D90: O
A91: 67 | B91: 102 | C91: 12.5-hour OP | D91: Unsupported (SWEB)
A92: 71 | B92: 109 | C92: 12.5-hour OP | D92: O
A93: 72 | B93: 111 | C93: 12.5-hour OP | D93: O
A94: 73 | B94: 156 | C94: 12.5-hour OP | D94: Unsupported (SWEB)
A95: 74 | B95: 17 | C95: 12.5-hour OP + Summer | D95: O
... A99: 78 | B99: 13 | C99: 12.5-hour OP + w/e & Summer | D99: O
A100: 79 | B100: 97 | C100: 14-hour E7 | D100: 2
A101: 79 | B101: 164 | C101: 14-hour E7 | D101: 1
...

Sheet Charge Calculator
B1: Back to Overview
B2: =Overview!B4& " - Effective from "&Overview!D4&" - "&Overview!E4 -> Southern Electric Power Distribution plc - Effective from 1 April 2020 - Final
B4: LV and HV tariff calculator | L4: EHV site calculator
B5: Step 1, Choose your tariff using the drop down list in cell B10 | L5: Step 1, Choose your tariff using the drop down list in cell L10
B6: Step 2, After selecting a tariff in step 1, Cells C12-I12 will generate headings, please enter your consumption in cells C13:I13 underneath each heading generated (if no heading leave cell blank) | L6: Step 2, After selecting a tariff in step 1, Cells M12-T12 will generate headings, please enter your consumption in cells M13:T13 underneath each heading generated (if no heading leave cell blank)
B7: Step 3, Enter a forecast of consumption if required in cells C14:I14 | L7: Step 3, Enter a forecast of consumption if required in cells M14:T14
B9: Tariff details Choose tariff name from drop down box below | C9: ='Annex 1 LV and HV charges'!D13 -> Unit charge 1 (NHH) or red/black charge (HH) p/kWh | D9: ='Annex 1 LV and HV charges'!E13 -> Unit charge 2 (NHH) or amber/yellow charge (HH) p/kWh | E9: ='Annex 1 LV and HV charges'!F13 -> Green charge(HH) p/kWh | F9: ='Annex 1 LV and HV charges'!G13 -> Fixed charge p/MPAN/day | G9: ='Annex 1 LV and HV charges'!H13 -> Capacity charge p/kVA/day | H9: ='Annex 1 LV and HV charges'!I13 -> Exceeded capacity charge p/kVA/day | I9: ='Annex 1 LV and HV charges'!J13 -> Reactive power charge p/kVArh | L9: Site details Choose the site name from the drop down box below | M9: ='Annex 2 EHV charges'!F9 -> Import Super Red unit charge (p/kWh) | N9: ='Annex 2 EHV charges'!G9 -> Import fixed charge (p/day) | O9: ='Annex 2 EHV charges'!H9 -> Import capacity charge (p/kVA/day) | P9: ='Annex 2 EHV charges'!I9 -> Import exceeded capacity charge (p/kVA/day) | Q9: ='Annex 2 EHV charges'!J9 -> Export Super Red unit charge (p/kWh) | R9: ='Annex 2 EHV charges'!K9 -> Export fixed charge (p/day) | S9: ='Annex 2 EHV charges'!L9 -> Export capacity charge (p/kVA/day) | T9: ='Annex 2 EHV charges'!M9 -> Export exceeded capacity charge (p/kVA/day)
C10: =IFERROR(VLOOKUP($B$10,'Annex 1 LV and HV charges'!$A:$K,4,FALSE),"") | D10: =IFERROR(VLOOKUP($B$10,'Annex 1 LV and HV charges'!$A:$K,5,FALSE),"") | E10: =IFERROR(VLOOKUP($B$10,'Annex 1 LV and HV charges'!$A:$K,6,FALSE),"") | F10: =IFERROR(VLOOKUP($B$10,'Annex 1 LV and HV charges'!$A:$K,7,FALSE),"") | G10: =IFERROR(VLOOKUP($B$10,'Annex 1 LV and HV charges'!$A:$K,8,FALSE),"") | H10: =IFERROR(VLOOKUP($B$10,'Annex 1 LV and HV charges'!$A:$K,9,FALSE),"") | I10: =IFERROR(VLOOKUP($B$10,'Annex 1 LV and HV charges'!$A:$K,10,FALSE),"") | M10: =IFERROR(VLOOKUP($L$10,'Annex 2 EHV charges'!$G:$M,2,FALSE),"") -> 6.04 | N10: =IFERROR(VLOOKUP($L$10,'Annex 2 EHV charges'!$G:$M,3,FALSE),"") -> 6.04 | O10: =IFERROR(VLOOKUP($L$10,'Annex 2 EHV charges'!$G:$M,4,FALSE),"") -> 0 | P10: =IFERROR(VLOOKUP($L$10,'Annex 2 EHV charges'!$G:$M,5,FALSE),"") -> 0 | Q10: =IFERROR(VLOOKUP($L$10,'Annex 2 EHV charges'!$G:$M,6,FALSE),"") -> 0 | R10: =IFERROR(VLOOKUP($L$10,'Annex 2 EHV charges'!$G:$M,7,FALSE),"") -> 0 | S10: =IFERROR(VLOOKUP($L$10,'Annex 2 EHV charges'!$G:$M,8,FALSE),"") | T10: =IFERROR(VLOOKUP($L$10,'Annex 2 EHV charges'!$G:$M,9,FALSE),"")
B12: Tariff components | C12: Unit 1 kWh (red/black/day) | D12: Unit 2 kWh (amber/yellow /night) | E12: Unit 3 kWh (green) | F12: Number of days in consumption period i.e. 365 if one year | G12: Maximum import or export capacity kVA | H12: Average daily exceeded capacity kVA | I12: Excess reactive units kVArh | L12: Tariff components | M12: Import super red kWh | N12: Number of days in consumption period i.e. 365 if one year | O12: Maximum import capacity kVA | P12: Average daily exceeded capacity kVA | Q12: Export Super Red kWh | R12: Number of days in consumption period i.e. 365 if one year | S12: Maximum export capacity kVA | T12: Average daily exceeded capacity kVA
B13: Enter current consumption details | L13: Enter current consumption details | R13: =N13 -> 0
B14: Enter forecast consumption details (if different) | C14: =C13 -> 0 | D14: =D13 -> 0 | E14: =E13 -> 0 | F14: =F13 -> 0 | G14: =G13 -> 0 | H14: =H13 -> 0 | I14: =I13 -> 0 | L14: Enter forecast consumption details (if different) | M14: =M13 -> 0 | N14: =N13 -> 0 | O14: =O13 -> 0 | P14: =P13 -> 0 | Q14: =Q13 -> 0 | R14: =R13 -> 0 | S14: =S13 -> 0 | T14: =T13 -> 0
B16: Charge components | C16: Unit 1 £ | D16: Unit 2 £ | E16: Unit 3 £ | F16: Fixed charge £ | G16: Capacity charge £ | H16: Exceeded capacity charge £ | I16: Reactive power charge £ | L16: Charge components | M16: Import super red charge £ | N16: Import fixed charge £ | O16: Import capacity charge £ | P16: Import exceeded capacity charge £ | Q16: Export super red charge £ | R16: Export fixed charge £ | S16: Export capacity charge £ | T16: Export exceeded capacity charge £
B17: Current consumption period charges | C17: =IFERROR(C10*C13/100,"") | D17: =IFERROR(D10*D13/100,"") | E17: =IFERROR(E10*E13/100,"") | F17: =IFERROR(F10*F13/100,"") | G17: =IFERROR(G10*G13*F13/100,"") | H17: =IFERROR(H10*H13*F13/100,"") | I17: =IFERROR(I10*I13/100,"") | L17: Current consumption period charges | M17: =IFERROR(M10*M13/100,"") -> 0 | N17: =IFERROR(N10*N13/100,"") -> 0 | O17: =IFERROR(O10*O13*N13/100,"") -> 0 | P17: =IFERROR(P10*P13*N13/100,"") -> 0 | Q17: =IFERROR(Q10*Q13/100,"") -> 0 | R17: =IFERROR(R10*R13/100,"") -> 0 | S17: =IFERROR(S10*S13*R13/100,"") | T17: =IFERROR(T10*T13*R13/100,"")
B18: Forecast consumption period charges | C18: =IFERROR(C10*C14/100,"") | D18: =IFERROR(D10*D14/100,"") | E18: =IFERROR(E10*E14/100,"") | F18: =IFERROR(F10*F14/100,"") | G18: =IFERROR(G10*G14*F14/100,"") | H18: =IFERROR(H10*H14*F14/100,"") | I18: =IFERROR(I10*I14/100,"") | L18: Forecast consumption period charges | M18: =IFERROR(M10*M14/100,"") -> 0 | N18: =IFERROR(N10*N14/100,"") -> 0 | O18: =IFERROR(O10*O14*N14/100,"") -> 0 | P18: =IFERROR(P10*P14*N14/100,"") -> 0 | Q18: =IFERROR(Q10*Q14/100,"") -> 0 | R18: =IFERROR(R10*R14/100,"") -> 0 | S18: =IFERROR(S10*S14*R14/100,"") | T18: =IFERROR(T10*T14*R14/100,"")
C20: Total charge £ | M20: Import total charge £ | N20: Export total charge £
B21: Current consumption period charges | C21: =SUM(C17:I17) -> 0 | L21: Current consumption period charges | M21: =SUM(M17:P17) -> 0 | N21: =SUM(Q17:T17) -> 0
B22: Forecast consumption period charges | C22: =SUM(C18:I18) -> 0 | L22: Forecast consumption period charges | M22: =SUM(M18:P18) -> 0 | N22: =SUM(Q18:T18) -> 0
B24: These charges are estimates based on tariff selected and consumption values entered. | L24: These charges are estimates based on site selected and consumption values entered.
