Workbook

Sheet Overview
A2: Company and Licence name, charging year, effective from, status
B3: Company and Licence name | C3: Year | D3: Effective From | E3: Status
A4: Company and Licence name, charging year, effective from, status | B4: Northern Powergrid (Yorkshire) Plc | C4: 2026/27 | D4: 1 April 2026 | E4: Final
A6: List of data tables in this workbook
A7: Worksheet | B7: Information
A8: Annex 1 LV, HV and Unmetered Supplies charges | B8: Annex 1 contains the charges to LV and HV Designated Properties and Unmetered Supplies.
A9: Annex 2 Designated EHV charges | B9: ="Annex 2 contains the charges to Designated EHV Properties and charges applied to LDNOs with Designated EHV Properties/end-users embedded in networks within the " &B4 &" Licence area." -> Annex 2 contains the charges to Designated EHV Properties and charges applied to LDNOs with Designated EHV Properties/end-users embedded in networks within the Northern Powergrid (Yorkshire) Plc Licence area.
A10: Annex 3 Preserved charges | B10: Annex 3 contains details of any preserved and additional charges that are valid at this time.
A11: Annex 4 LDNO charges | B11: ="Annex 4 contains charges that are levied on the owner of an embedded network within the "&B4&" Licence area. "&"Electricity suppliers and consumers who have properties connected to an embedded network should contact the embedded network owner to determine their distribution charges."&" The charges listed in this table are not payable by domestic consumers, business consumers or electricity suppliers." -> Annex 4 contains charges that are levied on the owner of an embedded network within the Northern Powergrid (Yorkshire) Plc Licence area. Electricity suppliers and consumers who have properties connected to an embedded network should contact the embedded network owner to determine their distribution charges. The charges listed in this table are not payable by domestic consumers, business consumers or electricity suppliers.
A12: Annex 5 LLFs | B12: Annex 5 has been intentionally left blank as this charging statement is published a complete year before the LLFs have been audited. The line loss factors that are approved by the BSC Panel for the applicable year and consequently published on the Elexon website will take precedence and be used in Settlement. This annex will be re-published with these values once they are available.
A13: Annex 6 Charges for New or Amended Designated EHV Properties | B13: ="Annex 6 contains the charges for new or amended Designated EHV Properties and charges applied to LDNOs with new or amended Designated EHV Properties/end-users embedded in networks within the " &B4 &" Licence area." -> Annex 6 contains the charges for new or amended Designated EHV Properties and charges applied to LDNOs with new or amended Designated EHV Properties/end-users embedded in networks within the Northern Powergrid (Yorkshire) Plc Licence area.
A14: Annex 7 Fixed adders for Supplier of Last Resort and Eligible Bad Debt pass-through costs | B14: Annex 7 contains the fixed adders to recover Supplier of Last Resort and Eligible Bad Debt pass-through costs.
A15: Nodal prices | B15: Contains the underlying [nodal/network group] costs used to calculate the current Designated EHV Properties charges.
A16: Residual Charging Bandings | B16: Contains the four Residual charging band allocation for Customers
A17: TNUoS Mapping | B17: Contains the mapping between DUoS tariff names and expected TNUoS charging bands
A18: Charge calculator | B18: Charge calculator is a tool to help you estimate your distribution charges using current consumption data and forecast consumption data.
A20: Notes to users of this spreadsheet
A22: Please use this spreadsheet with reference to the LC14 use of system charging statement.
A24: Notes to DNOs populating this spreadsheet
A26: DNOs must endeavour to maintain consistency in the structure of this spreadsheet. Any changes to the structure must be noted in the 'Notes to users of this spreadsheet'
A27: The drop down list on the charge calculator can be expanded by unprotecting the charge calculator sheet and selecting 'data', 'data validation...' and then expanding the 'source' data range. The sheet can then be protected.

Sheet Annex 1 LV, HV and UMS charges
A1: Back to Overview
A2: =Overview!B4& " - Effective from "&Overview!D4&" - "&Overview!E4&" LV and HV charges" -> Northern Powergrid (Yorkshire) Plc - Effective from 1 April 2026 - Final LV and HV charges
A4: Time Bands for LV and HV Designated Properties | G4: Time Bands for Unmetered Properties
A5: Time periods | B5: Red Time Band | C5: Amber Time Band | E5: Green Time Band | I5: Black Time Band | J5: Yellow Time Band | K5: Green Time Band
A6: Monday to Friday (Including Bank Holidays) All Year | B6: 16:00 to 19:30 | C6: 08:00 to 16:00 19:30 to 22:00 | E6: 00:00 to 08:00 22:00 to 24:00 | G6: Monday to Friday (Including Bank Holidays) November to February Inclusive | I6: 16:00 to 19:30 | J6: 08:00 to 16:00 19:30 to 22:00 | K6: 00:00 to 08:00 22:00 to 24:00
A7: Saturday and Sunday All Year | B7: 0 | C7: 0 | E7: 00:00 to 24:00 | G7: Monday to Friday (Including Bank Holidays) April to October Inclusive and March | I7: 0 | J7: 08:00 to 22:00 | K7: 00:00 to 08:00 22:00 to 24:00
A8: Notes | B8: All the above times are in UK Clock time | G8: Saturday and Sunday All year | I8: 0 | J8: 0 | K8: 00:00 to 24:00
G9: Notes | I9: All the above times are in UK Clock time
A11: Tariff name | B11: Open LLFCs | C11: PCs | D11: Red/black unit charge p/kWh | E11: Amber/yellow unit charge p/kWh | F11: Green unit charge p/kWh | G11: Fixed charge p/MPAN/day | H11: Capacity charge p/kVA/day | I11: Exceeded capacity charge p/kVA/day | J11: Reactive power charge p/kVArh | K11: Closed LLFCs
A12: Domestic Aggregated or CT with Residual | B12: 1A, 1AH, 100, 120, 279 | C12: 0, 1, 2 | D12: 6.786 | E12: 1.819 | F12: 0.212 | G12: 18.03 | H12: 0 | I12: 0 | J12: 0 | K12: 999
A13: Domestic Aggregated (Related MPAN) | B13: 3A, 111 | C13: 2 | D13: 6.786 | E13: 1.819 | F13: 0.212 | G13: 0 | H13: 0 | I13: 0 | J13: 0
A14: Non-Domestic Aggregated or CT No Residual | B14: 2Z, 2ZH | C14: 0, 3, 4, 5-8 | D14: 8.165 | E14: 2.188 | F14: 0.255 | G14: 12.11 | H14: 0 | I14: 0 | J14: 0
A15: Non-Domestic Aggregated or CT Band 1 | B15: 2A, 2AH | C15: 0, 3, 4, 5-8 | D15: 8.165 | E15: 2.188 | F15: 0.255 | G15: 17.83 | H15: 0 | I15: 0 | J15: 0
A16: Non-Domestic Aggregated or CT Band 2 | B16: 2B, 2BH | C16: 0, 3, 4, 5-8 | D16: 8.165 | E16: 2.188 | F16: 0.255 | G16: 26.38 | H16: 0 | I16: 0 | J16: 0
A17: Non-Domestic Aggregated or CT Band 3 | B17: 2C, 2CH | C17: 0, 3, 4, 5-8 | D17: 8.165 | E17: 2.188 | F17: 0.255 | G17: 41.96 | H17: 0 | I17: 0 | J17: 0
A18: Non-Domestic Aggregated or CT Band 4 | B18: 2D, 2DH | C18: 0, 3, 4, 5-8 | D18: 8.165 | E18: 2.188 | F18: 0.255 | G18: 95.09 | H18: 0 | I18: 0 | J18: 0
A19: Non-Domestic Aggregated (related MPAN) | B19: 4A | C19: 4 | D19: 8.165 | E19: 2.188 | F19: 0.255 | G19: 0 | H19: 0 | I19: 0 | J19: 0
A20: LV Site Specific No Residual | B20: 5Z | C20: 0 | D20: 5.829 | E20: 1.528 | F20: 0.172 | G20: 16.1 | H20: 3.82 | I20: 3.82 | J20: 0.118
A21: LV Site Specific Band 1 | B21: 5A | C21: 0 | D21: 5.829 | E21: 1.528 | F21: 0.172 | G21: 154.8 | H21: 3.82 | I21: 3.82 | J21: 0.118
A22: LV Site Specific Band 2 | B22: 5B | C22: 0 | D22: 5.829 | E22: 1.528 | F22: 0.172 | G22: 293.65 | H22: 3.82 | I22: 3.82 | J22: 0.118
A23: LV Site Specific Band 3 | B23: 5C | C23: 0 | D23: 5.829 | E23: 1.528 | F23: 0.172 | G23: 433.95 | H23: 3.82 | I23: 3.82 | J23: 0.118
A24: LV Site Specific Band 4 | B24: 5D | C24: 0 | D24: 5.829 | E24: 1.528 | F24: 0.172 | G24: 886.25 | H24: 3.82 | I24: 3.82 | J24: 0.118
A25: LV Sub Site Specific No Residual | B25: 6Z | C25: 0 | D25: 3.714 | E25: 0.923 | F25: 0.094 | G25: 16.1 | H25: 3.07 | I25: 3.07 | J25: 0.068
A26: LV Sub Site Specific Band 1 | B26: 6A | C26: 0 | D26: 3.714 | E26: 0.923 | F26: 0.094 | G26: 154.8 | H26: 3.07 | I26: 3.07 | J26: 0.068
A27: LV Sub Site Specific Band 2 | B27: 6B | C27: 0 | D27: 3.714 | E27: 0.923 | F27: 0.094 | G27: 293.65 | H27: 3.07 | I27: 3.07 | J27: 0.068
A28: LV Sub Site Specific Band 3 | B28: 6C | C28: 0 | D28: 3.714 | E28: 0.923 | F28: 0.094 | G28: 433.95 | H28: 3.07 | I28: 3.07 | J28: 0.068
A29: LV Sub Site Specific Band 4 | B29: 6D | C29: 0 | D29: 3.714 | E29: 0.923 | F29: 0.094 | G29: 886.25 | H29: 3.07 | I29: 3.07 | J29: 0.068
A30: HV Site Specific No Residual | B30: 7Z | C30: 0 | D30: 2.514 | E30: 0.588 | F30: 0.052 | G30: 421.64 | H30: 3.78 | I30: 3.78 | J30: 0.041
... A34: HV Site Specific Band 4 | B34: 7D | C34: 0 | D34: 2.514 | E34: 0.588 | F34: 0.052 | G34: 12820.57 | H34: 3.78 | I34: 3.78 | J34: 0.041
A35: Unmetered Supplies | B35: 8A | C35: 0, 1, 8 | D35: 20.504 | E35: 2.393 | F35: 0.89 | G35: 0 | H35: 0 | I35: 0 | J35: 0
A36: LV Generation Aggregated | B36: 20 | C36: 0 | D36: -4.895 | E36: -1.312 | F36: -0.153 | G36: 0 | H36: 0 | I36: 0 | J36: 0
A37: LV Sub Generation Aggregated | B37: 30 | C37: 0 | D37: -4.046 | E37: -1.07 | F37: -0.122 | G37: 0 | H37: 0 | I37: 0 | J37: 0
A38: LV Generation Site Specific | B38: 24, 22 | C38: 0 | D38: -4.895 | E38: -1.312 | F38: -0.153 | G38: 0 | H38: 0 | I38: 0 | J38: 0.091
A39: LV Generation Site Specific no RP charge | B39: 222, 224 | C39: 0 | D39: -4.895 | E39: -1.312 | F39: -0.153 | G39: 0 | H39: 0 | I39: 0 | J39: 0
A40: LV Sub Generation Site Specific | B40: 23, 25 | C40: 0 | D40: -4.046 | E40: -1.07 | F40: -0.122 | G40: 0 | H40: 0 | I40: 0 | J40: 0.083
A41: LV Sub Generation Site Specific no RP charge | B41: 223, 225 | C41: 0 | D41: -4.046 | E41: -1.07 | F41: -0.122 | G41: 0 | H41: 0 | I41: 0 | J41: 0
A42: HV Generation Site Specific | B42: 26, 28 | C42: 0 | D42: -2.826 | E42: -0.702 | F42: -0.071 | G42: 93.7 | H42: 0 | I42: 0 | J42: 0.073
A43: HV Generation Site Specific no RP charge | B43: 226, 228 | C43: 0 | D43: -2.826 | E43: -0.702 | F43: -0.071 | G43: 93.7 | H43: 0 | I43: 0 | J43: 0

Sheet Annex 2 Designated EHV charges
A1: Back to Overview | F1: Note: The list of MPANs / MSIDs provided may be incomplete; the DNO reserves the right to apply the listed charges to any other MPANs / MSIDs associated with the site.
A2: =Overview!B4& " - Effective from "&Overview!D4&" - "&Overview!E4&" Designated EHV charges" -> Northern Powergrid (Yorkshire) Plc - Effective from 1 April 2026 - Final Designated EHV charges
A4: Time Periods for Designated EHV Properties
A5: Time periods | D5: Super Red Time Band
A6: Monday to Friday (Including Bank Holidays) November to February Inclusive | D6: 1600 - 1930
A7: Notes | D7: All the above times are in UK Clock time
A9: Import Unique Identifier | B9: LLFC | C9: Import MPANs/MSIDs | D9: Export Unique Identifier | E9: LLFC | F9: Export MPANs/MSIDs | G9: Name | H9: Residual Charging Band | I9: Import Super Red unit charge (p/kWh) | J9: Import fixed charge (p/day) | K9: Import capacity charge (p/kVA/day) | L9: Import exceeded capacity charge (p/kVA/day) | M9: Export Super Red unit charge (p/kWh) | N9: Export fixed charge (p/day) | O9: Export capacity charge (p/kVA/day) | P9: Export exceeded capacity charge (p/kVA/day)
A10: 750 | B10: 750 | C10: 2300000599657 2336541294017 | E10: 0 | G10: EHV Site Specific (LLFC 750) | H10: 4 | I10: 0.045 | J10: 103218.15 | K10: 2.85 | L10: 2.85 | M10: 0 | N10: 0 | O10: 0 | P10: 0
A11: 751 | B11: 751 | C11: 2300000702517 2300000702526 2300000702535 2376555002010 2376555002029 2376555002038 | E11: 0 | G11: EHV Site Specific (LLFC 751) | H11: 4 | I11: 0.001 | J11: 108020.24 | K11: 0.92 | L11: 0.92 | M11: 0 | N11: 0 | O11: 0 | P11: 0
A12: 753 | B12: 753 | C12: 2356555555010 | D12: 90 | E12: 90 | F12: 2394000039650 | G12: EHV Site Specific (LLFC 753 & 90) | H12: 3 | I12: 0.042 | J12: 47306.88 | K12: 0.75 | L12: 0.75 | M12: 0 | N12: 183.27 | O12: 0.05 | P12: 0.05
A13: 754 | B13: 754 | C13: 2356555554017 2380002015807 | D13: 82 | E13: 82 | F13: 2394000039660 2394000110620 | G13: EHV Site Specific (LLFC 754 & 82) | H13: 2 | I13: 0.161 | J13: 25592.75 | K13: 0.68 | L13: 0.68 | M13: 0 | N13: 621.12 | O13: 0.05 | P13: 0.05
A14: 755 | B14: 755 | C14: 2316521850010 | D14: 76 | E14: 76 | F14: 2394000039641 | G14: EHV Site Specific (LLFC 755 & 76) | H14: 2 | I14: 0.027 | J14: 18816.11 | K14: 0.95 | L14: 0.95 | M14: 0 | N14: 564.58 | O14: 0.05 | P14: 0.05
A15: 756 | B15: 756 | C15: 2346540436013 | D15: 75 | E15: 75 | F15: 2394000039679 | G15: EHV Site Specific (LLFC 756 & 75) | H15: 2 | I15: 0.014 | J15: 23569.63 | K15: 1.1 | L15: 1.1 | M15: 0 | N15: 779.95 | O15: 0.05 | P15: 0.05
A16: 757 | B16: 757 | C16: 2336566756217 | D16: 95 | E16: 95 | F16: 2394000060226 | G16: EHV Site Specific (LLFC 757 & 95) | H16: 1 | I16: 0 | J16: 2293.86 | K16: 0.35 | L16: 0.35 | M16: -0.001 | N16: 1100.61 | O16: 0.05 | P16: 0.05
A17: 804 | B17: 804 | C17: MSID_0645 | D17: 800 | E17: 800 | F17: MSID_0645 | G17: EHV Site Specific (LLFC 804 & 800) | H17: 4 | I17: 0.01 | J17: 119342.94 | K17: 1.14 | L17: 1.14 | M17: -0.008 | N17: 2782.58 | O17: 0.05 | P17: 0.05
A18: 760 | B18: 760 | C18: 2300000880966 2376509001013 | D18: 60 | E18: 60 | F18: 2300000233736 2300000880975 | G18: EHV Site Specific (LLFC 760 & 60) | H18: 4 | I18: 0 | J18: 105037.14 | K18: 0.87 | L18: 0.87 | M18: 0 | N18: 1212.66 | O18: 0.05 | P18: 0.05
A19: 761 | B19: 761 | C19: 2300000526686 2336518071011 | E19: 0 | G19: EHV Site Specific (LLFC 761) | H19: 3 | I19: 0 | J19: 36679.86 | K19: 0.67 | L19: 0.67 | M19: 0 | N19: 0 | O19: 0 | P19: 0
A20: 762 | B20: 762 | C20: 2300000457400 | D20: 62 | E20: 62 | F20: 2300000457410 | G20: EHV Site Specific (LLFC 762 & 62) | H20: 0 | I20: 0 | J20: 40.02 | K20: 0.42 | L20: 0.42 | M20: -0.032 | N20: 453.52 | O20: 0.05 | P20: 0.05
A21: 763 | B21: 763 | C21: MSID_7376 MSID_7542 | D21: 80 | E21: 80 | F21: MSID_7377 MSID_7543 | G21: EHV Site Specific (LLFC 763 & 80) | H21: 0 | I21: 0.003 | J21: 101.82 | K21: 0.5 | L21: 0.5 | M21: -0.002 | N21: 1694.65 | O21: 0.05 | P21: 0.05
A22: 764 | B22: 764 | C22: 2300000233959 2300000233968 2300000233977 | E22: 0 | G22: EHV Site Specific (LLFC 764) | H22: 4 | I22: 0 | J22: 107168.57 | K22: 0.44 | L22: 0.44 | M22: 0 | N22: 0 | O22: 0 | P22: 0
A23: 765 | B23: 765 | C23: 2300000457084 2390000010840 2390000010859 | E23: 0 | G23: EHV Site Specific (LLFC 765) | H23: 4 | I23: 0.042 | J23: 105486.6 | K23: 0.86 | L23: 0.86 | M23: 0 | N23: 0 | O23: 0 | P23: 0
A24: 766 | B24: 766 | C24: 2376508030013 2376508030022 | D24: 66 | E24: 66 | F24: 2300000233912 2300000996990 | G24: EHV Site Specific (LLFC 766 & 66) | H24: 4 | I24: 0 | J24: 103377.23 | K24: 1.59 | L24: 1.59 | M24: 0 | N24: 209.85 | O24: 0.05 | P24: 0.05
A25: 769 | B25: 769 | C25: 2346526241119 2390000139108 | D25: 128 | E25: 128 | F25: 2394000133317 2394000139114 | G25: EHV Site Specific (LLFC 769 & 128) | H25: 1 | I25: 0 | J25: 2194.53 | K25: 0.53 | L25: 0.53 | M25: 0 | N25: 0 | O25: 0.05 | P25: 0.05
A26: 771 | B26: 771 | C26: 2366591376117 | D26: 92 | E26: 92 | F26: 2394000019176 | G26: EHV Site Specific (LLFC 771 & 92) | H26: 0 | I26: 0 | J26: 0 | K26: 0.35 | L26: 0.35 | M26: 0 | N26: 0 | O26: 0.05 | P26: 0.05
A27: 772 | B27: 772 | C27: 2366591373116 | E27: 0 | G27: EHV Site Specific (LLFC 772) | H27: 1 | I27: 0 | J27: 2194.53 | K27: 1.04 | L27: 1.04 | M27: 0 | N27: 0 | O27: 0 | P27: 0
A28: 773 | B28: 773 | C28: 2366591486111 2380002104680 | D28: 65 | E28: 65 | F28: 2394000117991 | G28: EHV Site Specific (LLFC 773 & 65) | H28: 1 | I28: 0 | J28: 2194.53 | K28: 0.91 | L28: 0.91 | M28: 0 | N28: 0 | O28: 0.05 | P28: 0.05
A29: 774 | B29: 774 | C29: 2326522910011 2326522910020 | D29: 74 | E29: 74 | F29: 2394000002925 2394100008408 | G29: EHV Site Specific (LLFC 774 & 74) | H29: 3 | I29: 0.322 | J29: 36408.15 | K29: 0.37 | L29: 0.37 | M29: 0 | N29: 0 | O29: 0 | P29: 0
A30: 775 | B30: 775 | C30: 2380000531989 | D30: 87 | E30: 87 | F30: 2394000024440 | G30: EHV Site Specific (LLFC 775 & 87) | H30: 0 | I30: 0.052 | J30: 281.82 | K30: 0.49 | L30: 0.49 | M30: -0.222 | N30: 1078.61 | O30: 0.05 | P30: 0.05
A31: 777 | B31: 777 | C31: MSID_7430 | D31: 77 | E31: 77 | F31: MSID_7431 | G31: EHV Site Specific (LLFC 777 & 77) | H31: 0 | I31: 0.067 | J31: 6.15 | K31: 0.55 | L31: 0.55 | M31: -0.101 | N31: 178.32 | O31: 0.05 | P31: 0.05
A32: 778 | B32: 778 | C32: 2300000443816 | D32: 78 | E32: 78 | F32: 2300000443825 | G32: EHV Site Specific (LLFC 778 & 78) | H32: 0 | I32: 0 | J32: 12.87 | K32: 1.55 | L32: 1.55 | M32: 0 | N32: 1354.6 | O32: 0.05 | P32: 0.05
A33: 780 | B33: 780 | C33: 2380000825051 | E33: 0 | G33: EHV Site Specific (LLFC 780) | H33: 4 | I33: 0 | J33: 104316.26 | K33: 0.43 | L33: 0.43 | M33: 0 | N33: 0 | O33: 0 | P33: 0
A34: 782 | B34: 782 | C34: 2300001016288 2300001016297 | E34: 0 | G34: EHV Site Specific (LLFC 782) | H34: 2 | I34: 0.777 | J34: 13539.29 | K34: 0.53 | L34: 0.53 | M34: 0 | N34: 0 | O34: 0 | P34: 0
A35: 783 | B35: 783 | C35: 2300000974268 | D35: 83 | E35: 83 | F35: 2300000974408 2394000113560 2394000135253 | G35: EHV Site Specific (LLFC 783 & 83) | H35: 0 | I35: 0.011 | J35: 4.92 | K35: 0.6 | L35: 0.6 | M35: 0 | N35: 0 | O35: 0 | P35: 0
A36: 784 | B36: 784 | C36: 2300001007247 | D36: 84 | E36: 84 | F36: 2300001007256 | G36: EHV Site Specific (LLFC 784 & 84) | H36: 0 | I36: 0.012 | J36: 0.61 | K36: 0.69 | L36: 0.69 | M36: 0 | N36: 0 | O36: 0 | P36: 0
A37: 785 | B37: 785 | C37: 2380000151720 | D37: 85 | E37: 85 | F37: 2394000011646 | G37: EHV Site Specific (LLFC 785 & 85) | H37: 0 | I37: 0.046 | J37: 1.72 | K37: 0.45 | L37: 0.45 | M37: 0 | N37: 0 | O37: 0 | P37: 0
A38: 786 | B38: 786 | C38: 2380000148115 | D38: 86 | E38: 86 | F38: 2391100013704 2394000011502 | G38: EHV Site Specific (LLFC 786 & 86) | H38: 0 | I38: 0 | J38: 1.16 | K38: 0.37 | L38: 0.37 | M38: 0 | N38: 0 | O38: 0 | P38: 0
A39: 787 | B39: 787 | C39: 2380000123421 2380000123430 | D39: 129 | E39: 129 | F39: 2394000134454 2394000134463 | G39: EHV Site Specific (LLFC 787 & 129) | H39: 3 | I39: 0 | J39: 37260.87 | K39: 1.18 | L39: 1.18 | M39: 0 | N39: 249.99 | O39: 0.05 | P39: 0.05
A40: 788 | B40: 788 | C40: 2380000654644 | D40: 88 | E40: 88 | F40: 2394000027673 | G40: EHV Site Specific (LLFC 788 & 88) | H40: 0 | I40: 0.002 | J40: 32.05 | K40: 0.76 | L40: 0.76 | M40: -0.332 | N40: 854.62 | O40: 0.05 | P40: 0.05
A41: 789 | B41: 789 | C41: 2380001118812 | D41: 89 | E41: 89 | F41: 2394000043364 2394000138110 | G41: EHV Site Specific (LLFC 789 & 89) | H41: 0 | I41: 0.001 | J41: 20.57 | K41: 0.94 | L41: 0.94 | M41: -0.175 | N41: 866.11 | O41: 0.05 | P41: 0.05
A42: 790 | B42: 790 | C42: 2380001476585 | D42: 94 | E42: 94 | F42: 2394000056790 | G42: EHV Site Specific (LLFC 790 & 94) | H42: 0 | I42: 0.001 | J42: 23.77 | K42: 0.4 | L42: 0.4 | M42: 0 | N42: 1601.1 | O42: 0.05 | P42: 0.05
...

Sheet Annex 2a Import
A1: Note: The list of MPANs / MSIDs provided may be incomplete; the DNO reserves the right to apply the listed charges to any other MPANs / MSIDs associated with the site. Note: This table is automatically populated based on the content of the tab entitled 'Annex 2 Designated EHV Charges'. The timebands are as shown in Annex 2.
A2: =Overview!B4& " - Effective from "&Overview!D4&" - "&Overview!E4&" Designated EHV import charges" -> Northern Powergrid (Yorkshire) Plc - Effective from 1 April 2026 - Final Designated EHV import charges
A4: Import Unique Identifier | B4: LLFC | C4: Import MPANs/MSIDs | D4: Name | E4: ='Annex 2 Designated EHV charges'!I9 -> Import Super Red unit charge (p/kWh) | F4: ='Annex 2 Designated EHV charges'!J9 -> Import fixed charge (p/day) | G4: ='Annex 2 Designated EHV charges'!K9 -> Import capacity charge (p/kVA/day) | H4: ='Annex 2 Designated EHV charges'!L9 -> Import exceeded capacity charge (p/kVA/day)
A5: 750 | B5: =IF($A5="","",VLOOKUP($A5,'Annex 2 Designated EHV charges'!$A:$P,2,0)) -> 750 | C5: =IF($A5="","",VLOOKUP($A5,'Annex 2 Designated EHV charges'!$A:$P,3,0)) -> 2300000599657 2336541294017 | D5: =IF($A5="","",VLOOKUP($A5,'Annex 2 Designated EHV charges'!$A:$P,7,0)) -> EHV Site Specific (LLFC 750) | E5: =IFERROR(IF(VLOOKUP($A5,'Annex 2 Designated EHV charges'!$A:$P,9,FALSE)=0,"",VLOOKUP($A5,'Annex 2 Designated EHV charges'!$A:$P,9,FALSE)),"") -> 0.045 | F5: =IFERROR(IF(VLOOKUP($A5,'Annex 2 Designated EHV charges'!$A:$P,10,FALSE)=0,"",VLOOKUP($A5,'Annex 2 Designated EHV charges'!$A:$P,10,FALSE)),"") -> 103218.15 | G5: =IFERROR(IF(VLOOKUP($A5,'Annex 2 Designated EHV charges'!$A:$P,11,FALSE)=0,"",VLOOKUP($A5,'Annex 2 Designated EHV charges'!$A:$P,11,FALSE)),"") -> 2.85 | H5: =IFERROR(IF(VLOOKUP($A5,'Annex 2 Designated EHV charges'!$A:$P,12,FALSE)=0,"",VLOOKUP($A5,'Annex 2 Designated EHV charges'!$A:$P,12,FALSE)),"") -> 2.85
A6: 751 | B6: =IF($A6="","",VLOOKUP($A6,'Annex 2 Designated EHV charges'!$A:$P,2,0)) -> 751 | C6: =IF($A6="","",VLOOKUP($A6,'Annex 2 Designated EHV charges'!$A:$P,3,0)) -> 2300000702517 2300000702526 2300000702535 2376555002010 2376555002029 2376555002038 | D6: =IF($A6="","",VLOOKUP($A6,'Annex 2 Designated EHV charges'!$A:$P,7,0)) -> EHV Site Specific (LLFC 751) | E6: =IFERROR(IF(VLOOKUP($A6,'Annex 2 Designated EHV charges'!$A:$P,9,FALSE)=0,"",VLOOKUP($A6,'Annex 2 Designated EHV charges'!$A:$P,9,FALSE)),"") -> 0.001 | F6: =IFERROR(IF(VLOOKUP($A6,'Annex 2 Designated EHV charges'!$A:$P,10,FALSE)=0,"",VLOOKUP($A6,'Annex 2 Designated EHV charges'!$A:$P,10,FALSE)),"") -> 108020.24 | G6: =IFERROR(IF(VLOOKUP($A6,'Annex 2 Designated EHV charges'!$A:$P,11,FALSE)=0,"",VLOOKUP($A6,'Annex 2 Designated EHV charges'!$A:$P,11,FALSE)),"") -> 0.92 | H6: =IFERROR(IF(VLOOKUP($A6,'Annex 2 Designated EHV charges'!$A:$P,12,FALSE)=0,"",VLOOKUP($A6,'Annex 2 Designated EHV charges'!$A:$P,12,FALSE)),"") -> 0.92
A7: 753 | B7: =IF($A7="","",VLOOKUP($A7,'Annex 2 Designated EHV charges'!$A:$P,2,0)) -> 753 | C7: =IF($A7="","",VLOOKUP($A7,'Annex 2 Designated EHV charges'!$A:$P,3,0)) -> 2356555555010 | D7: =IF($A7="","",VLOOKUP($A7,'Annex 2 Designated EHV charges'!$A:$P,7,0)) -> EHV Site Specific (LLFC 753 & 90) | E7: =IFERROR(IF(VLOOKUP($A7,'Annex 2 Designated EHV charges'!$A:$P,9,FALSE)=0,"",VLOOKUP($A7,'Annex 2 Designated EHV charges'!$A:$P,9,FALSE)),"") -> 0.042 | F7: =IFERROR(IF(VLOOKUP($A7,'Annex 2 Designated EHV charges'!$A:$P,10,FALSE)=0,"",VLOOKUP($A7,'Annex 2 Designated EHV charges'!$A:$P,10,FALSE)),"") -> 47306.88 | G7: =IFERROR(IF(VLOOKUP($A7,'Annex 2 Designated EHV charges'!$A:$P,11,FALSE)=0,"",VLOOKUP($A7,'Annex 2 Designated EHV charges'!$A:$P,11,FALSE)),"") -> 0.75 | H7: =IFERROR(IF(VLOOKUP($A7,'Annex 2 Designated EHV charges'!$A:$P,12,FALSE)=0,"",VLOOKUP($A7,'Annex 2 Designated EHV charges'!$A:$P,12,FALSE)),"") -> 0.75
A8: 754 | B8: =IF($A8="","",VLOOKUP($A8,'Annex 2 Designated EHV charges'!$A:$P,2,0)) -> 754 | C8: =IF($A8="","",VLOOKUP($A8,'Annex 2 Designated EHV charges'!$A:$P,3,0)) -> 2356555554017 2380002015807 | D8: =IF($A8="","",VLOOKUP($A8,'Annex 2 Designated EHV charges'!$A:$P,7,0)) -> EHV Site Specific (LLFC 754 & 82) | E8: =IFERROR(IF(VLOOKUP($A8,'Annex 2 Designated EHV charges'!$A:$P,9,FALSE)=0,"",VLOOKUP($A8,'Annex 2 Designated EHV charges'!$A:$P,9,FALSE)),"") -> 0.161 | F8: =IFERROR(IF(VLOOKUP($A8,'Annex 2 Designated EHV charges'!$A:$P,10,FALSE)=0,"",VLOOKUP($A8,'Annex 2 Designated EHV charges'!$A:$P,10,FALSE)),"") -> 25592.75 | G8: =IFERROR(IF(VLOOKUP($A8,'Annex 2 Designated EHV charges'!$A:$P,11,FALSE)=0,"",VLOOKUP($A8,'Annex 2 Designated EHV charges'!$A:$P,11,FALSE)),"") -> 0.68 | H8: =IFERROR(IF(VLOOKUP($A8,'Annex 2 Designated EHV charges'!$A:$P,12,FALSE)=0,"",VLOOKUP($A8,'Annex 2 Designated EHV charges'!$A:$P,12,FALSE)),"") -> 0.68
A9: 755 | B9: =IF($A9="","",VLOOKUP($A9,'Annex 2 Designated EHV charges'!$A:$P,2,0)) -> 755 | C9: =IF($A9="","",VLOOKUP($A9,'Annex 2 Designated EHV charges'!$A:$P,3,0)) -> 2316521850010 | D9: =IF($A9="","",VLOOKUP($A9,'Annex 2 Designated EHV charges'!$A:$P,7,0)) -> EHV Site Specific (LLFC 755 & 76) | E9: =IFERROR(IF(VLOOKUP($A9,'Annex 2 Designated EHV charges'!$A:$P,9,FALSE)=0,"",VLOOKUP($A9,'Annex 2 Designated EHV charges'!$A:$P,9,FALSE)),"") -> 0.027 | F9: =IFERROR(IF(VLOOKUP($A9,'Annex 2 Designated EHV charges'!$A:$P,10,FALSE)=0,"",VLOOKUP($A9,'Annex 2 Designated EHV charges'!$A:$P,10,FALSE)),"") -> 18816.11 | G9: =IFERROR(IF(VLOOKUP($A9,'Annex 2 Designated EHV charges'!$A:$P,11,FALSE)=0,"",VLOOKUP($A9,'Annex 2 Designated EHV charges'!$A:$P,11,FALSE)),"") -> 0.95 | H9: =IFERROR(IF(VLOOKUP($A9,'Annex 2 Designated EHV charges'!$A:$P,12,FALSE)=0,"",VLOOKUP($A9,'Annex 2 Designated EHV charges'!$A:$P,12,FALSE)),"") -> 0.95
A10: 756 | B10: =IF($A10="","",VLOOKUP($A10,'Annex 2 Designated EHV charges'!$A:$P,2,0)) -> 756 | C10: =IF($A10="","",VLOOKUP($A10,'Annex 2 Designated EHV charges'!$A:$P,3,0)) -> 2346540436013 | D10: =IF($A10="","",VLOOKUP($A10,'Annex 2 Designated EHV charges'!$A:$P,7,0)) -> EHV Site Specific (LLFC 756 & 75) | E10: =IFERROR(IF(VLOOKUP($A10,'Annex 2 Designated EHV charges'!$A:$P,9,FALSE)=0,"",VLOOKUP($A10,'Annex 2 Designated EHV charges'!$A:$P,9,FALSE)),"") -> 0.014 | F10: =IFERROR(IF(VLOOKUP($A10,'Annex 2 Designated EHV charges'!$A:$P,10,FALSE)=0,"",VLOOKUP($A10,'Annex 2 Designated EHV charges'!$A:$P,10,FALSE)),"") -> 23569.63 | G10: =IFERROR(IF(VLOOKUP($A10,'Annex 2 Designated EHV charges'!$A:$P,11,FALSE)=0,"",VLOOKUP($A10,'Annex 2 Designated EHV charges'!$A:$P,11,FALSE)),"") -> 1.1 | H10: =IFERROR(IF(VLOOKUP($A10,'Annex 2 Designated EHV charges'!$A:$P,12,FALSE)=0,"",VLOOKUP($A10,'Annex 2 Designated EHV charges'!$A:$P,12,FALSE)),"") -> 1.1
A11: 757 | B11: =IF($A11="","",VLOOKUP($A11,'Annex 2 Designated EHV charges'!$A:$P,2,0)) -> 757 | C11: =IF($A11="","",VLOOKUP($A11,'Annex 2 Designated EHV charges'!$A:$P,3,0)) -> 2336566756217 | D11: =IF($A11="","",VLOOKUP($A11,'Annex 2 Designated EHV charges'!$A:$P,7,0)) -> EHV Site Specific (LLFC 757 & 95) | E11: =IFERROR(IF(VLOOKUP($A11,'Annex 2 Designated EHV charges'!$A:$P,9,FALSE)=0,"",VLOOKUP($A11,'Annex 2 Designated EHV charges'!$A:$P,9,FALSE)),"") | F11: =IFERROR(IF(VLOOKUP($A11,'Annex 2 Designated EHV charges'!$A:$P,10,FALSE)=0,"",VLOOKUP($A11,'Annex 2 Designated EHV charges'!$A:$P,10,FALSE)),"") -> 2293.86 | G11: =IFERROR(IF(VLOOKUP($A11,'Annex 2 Designated EHV charges'!$A:$P,11,FALSE)=0,"",VLOOKUP($A11,'Annex 2 Designated EHV charges'!$A:$P,11,FALSE)),"") -> 0.35 | H11: =IFERROR(IF(VLOOKUP($A11,'Annex 2 Designated EHV charges'!$A:$P,12,FALSE)=0,"",VLOOKUP($A11,'Annex 2 Designated EHV charges'!$A:$P,12,FALSE)),"") -> 0.35
A12: 804 | B12: =IF($A12="","",VLOOKUP($A12,'Annex 2 Designated EHV charges'!$A:$P,2,0)) -> 804 | C12: =IF($A12="","",VLOOKUP($A12,'Annex 2 Designated EHV charges'!$A:$P,3,0)) -> MSID_0645 | D12: =IF($A12="","",VLOOKUP($A12,'Annex 2 Designated EHV charges'!$A:$P,7,0)) -> EHV Site Specific (LLFC 804 & 800) | E12: =IFERROR(IF(VLOOKUP($A12,'Annex 2 Designated EHV charges'!$A:$P,9,FALSE)=0,"",VLOOKUP($A12,'Annex 2 Designated EHV charges'!$A:$P,9,FALSE)),"") -> 0.01 | F12: =IFERROR(IF(VLOOKUP($A12,'Annex 2 Designated EHV charges'!$A:$P,10,FALSE)=0,"",VLOOKUP($A12,'Annex 2 Designated EHV charges'!$A:$P,10,FALSE)),"") -> 119342.94 | G12: =IFERROR(IF(VLOOKUP($A12,'Annex 2 Designated EHV charges'!$A:$P,11,FALSE)=0,"",VLOOKUP($A12,'Annex 2 Designated EHV charges'!$A:$P,11,FALSE)),"") -> 1.14 | H12: =IFERROR(IF(VLOOKUP($A12,'Annex 2 Designated EHV charges'!$A:$P,12,FALSE)=0,"",VLOOKUP($A12,'Annex 2 Designated EHV charges'!$A:$P,12,FALSE)),"") -> 1.14
A13: 760 | B13: =IF($A13="","",VLOOKUP($A13,'Annex 2 Designated EHV charges'!$A:$P,2,0)) -> 760 | C13: =IF($A13="","",VLOOKUP($A13,'Annex 2 Designated EHV charges'!$A:$P,3,0)) -> 2300000880966 2376509001013 | D13: =IF($A13="","",VLOOKUP($A13,'Annex 2 Designated EHV charges'!$A:$P,7,0)) -> EHV Site Specific (LLFC 760 & 60) | E13: =IFERROR(IF(VLOOKUP($A13,'Annex 2 Designated EHV charges'!$A:$P,9,FALSE)=0,"",VLOOKUP($A13,'Annex 2 Designated EHV charges'!$A:$P,9,FALSE)),"") | F13: =IFERROR(IF(VLOOKUP($A13,'Annex 2 Designated EHV charges'!$A:$P,10,FALSE)=0,"",VLOOKUP($A13,'Annex 2 Designated EHV charges'!$A:$P,10,FALSE)),"") -> 105037.14 | G13: =IFERROR(IF(VLOOKUP($A13,'Annex 2 Designated EHV charges'!$A:$P,11,FALSE)=0,"",VLOOKUP($A13,'Annex 2 Designated EHV charges'!$A:$P,11,FALSE)),"") -> 0.87 | H13: =IFERROR(IF(VLOOKUP($A13,'Annex 2 Designated EHV charges'!$A:$P,12,FALSE)=0,"",VLOOKUP($A13,'Annex 2 Designated EHV charges'!$A:$P,12,FALSE)),"") -> 0.87
A14: 761 | B14: =IF($A14="","",VLOOKUP($A14,'Annex 2 Designated EHV charges'!$A:$P,2,0)) -> 761 | C14: =IF($A14="","",VLOOKUP($A14,'Annex 2 Designated EHV charges'!$A:$P,3,0)) -> 2300000526686 2336518071011 | D14: =IF($A14="","",VLOOKUP($A14,'Annex 2 Designated EHV charges'!$A:$P,7,0)) -> EHV Site Specific (LLFC 761) | E14: =IFERROR(IF(VLOOKUP($A14,'Annex 2 Designated EHV charges'!$A:$P,9,FALSE)=0,"",VLOOKUP($A14,'Annex 2 Designated EHV charges'!$A:$P,9,FALSE)),"") | F14: =IFERROR(IF(VLOOKUP($A14,'Annex 2 Designated EHV charges'!$A:$P,10,FALSE)=0,"",VLOOKUP($A14,'Annex 2 Designated EHV charges'!$A:$P,10,FALSE)),"") -> 36679.86 | G14: =IFERROR(IF(VLOOKUP($A14,'Annex 2 Designated EHV charges'!$A:$P,11,FALSE)=0,"",VLOOKUP($A14,'Annex 2 Designated EHV charges'!$A:$P,11,FALSE)),"") -> 0.67 | H14: =IFERROR(IF(VLOOKUP($A14,'Annex 2 Designated EHV charges'!$A:$P,12,FALSE)=0,"",VLOOKUP($A14,'Annex 2 Designated EHV charges'!$A:$P,12,FALSE)),"") -> 0.67
A15: 762 | B15: =IF($A15="","",VLOOKUP($A15,'Annex 2 Designated EHV charges'!$A:$P,2,0)) -> 762 | C15: =IF($A15="","",VLOOKUP($A15,'Annex 2 Designated EHV charges'!$A:$P,3,0)) -> 2300000457400 | D15: =IF($A15="","",VLOOKUP($A15,'Annex 2 Designated EHV charges'!$A:$P,7,0)) -> EHV Site Specific (LLFC 762 & 62) | E15: =IFERROR(IF(VLOOKUP($A15,'Annex 2 Designated EHV charges'!$A:$P,9,FALSE)=0,"",VLOOKUP($A15,'Annex 2 Designated EHV charges'!$A:$P,9,FALSE)),"") | F15: =IFERROR(IF(VLOOKUP($A15,'Annex 2 Designated EHV charges'!$A:$P,10,FALSE)=0,"",VLOOKUP($A15,'Annex 2 Designated EHV charges'!$A:$P,10,FALSE)),"") -> 40.02 | G15: =IFERROR(IF(VLOOKUP($A15,'Annex 2 Designated EHV charges'!$A:$P,11,FALSE)=0,"",VLOOKUP($A15,'Annex 2 Designated EHV charges'!$A:$P,11,FALSE)),"") -> 0.42 | H15: =IFERROR(IF(VLOOKUP($A15,'Annex 2 Designated EHV charges'!$A:$P,12,FALSE)=0,"",VLOOKUP($A15,'Annex 2 Designated EHV charges'!$A:$P,12,FALSE)),"") -> 0.42
A16: 763 | B16: =IF($A16="","",VLOOKUP($A16,'Annex 2 Designated EHV charges'!$A:$P,2,0)) -> 763 | C16: =IF($A16="","",VLOOKUP($A16,'Annex 2 Designated EHV charges'!$A:$P,3,0)) -> MSID_7376 MSID_7542 | D16: =IF($A16="","",VLOOKUP($A16,'Annex 2 Designated EHV charges'!$A:$P,7,0)) -> EHV Site Specific (LLFC 763 & 80) | E16: =IFERROR(IF(VLOOKUP($A16,'Annex 2 Designated EHV charges'!$A:$P,9,FALSE)=0,"",VLOOKUP($A16,'Annex 2 Designated EHV charges'!$A:$P,9,FALSE)),"") -> 0.003 | F16: =IFERROR(IF(VLOOKUP($A16,'Annex 2 Designated EHV charges'!$A:$P,10,FALSE)=0,"",VLOOKUP($A16,'Annex 2 Designated EHV charges'!$A:$P,10,FALSE)),"") -> 101.82 | G16: =IFERROR(IF(VLOOKUP($A16,'Annex 2 Designated EHV charges'!$A:$P,11,FALSE)=0,"",VLOOKUP($A16,'Annex 2 Designated EHV charges'!$A:$P,11,FALSE)),"") -> 0.5 | H16: =IFERROR(IF(VLOOKUP($A16,'Annex 2 Designated EHV charges'!$A:$P,12,FALSE)=0,"",VLOOKUP($A16,'Annex 2 Designated EHV charges'!$A:$P,12,FALSE)),"") -> 0.5
... A172: 725 | B172: =IF($A172="","",VLOOKUP($A172,'Annex 2 Designated EHV charges'!$A:$P,2,0)) -> 725 | C172: =IF($A172="","",VLOOKUP($A172,'Annex 2 Designated EHV charges'!$A:$P,3,0)) -> MSID_7588 | D172: =IF($A172="","",VLOOKUP($A172,'Annex 2 Designated EHV charges'!$A:$P,7,0)) -> EHV Site Specific (LLFC 725 & 510) | E172: =IFERROR(IF(VLOOKUP($A172,'Annex 2 Designated EHV charges'!$A:$P,9,FALSE)=0,"",VLOOKUP($A172,'Annex 2 Designated EHV charges'!$A:$P,9,FALSE)),"") | F172: =IFERROR(IF(VLOOKUP($A172,'Annex 2 Designated EHV charges'!$A:$P,10,FALSE)=0,"",VLOOKUP($A172,'Annex 2 Designated EHV charges'!$A:$P,10,FALSE)),"") -> 3009.74 | G172: =IFERROR(IF(VLOOKUP($A172,'Annex 2 Designated EHV charges'!$A:$P,11,FALSE)=0,"",VLOOKUP($A172,'Annex 2 Designated EHV charges'!$A:$P,11,FALSE)),"") -> 1.33 | H172: =IFERROR(IF(VLOOKUP($A172,'Annex 2 Designated EHV charges'!$A:$P,12,FALSE)=0,"",VLOOKUP($A172,'Annex 2 Designated EHV charges'!$A:$P,12,FALSE)),"") -> 1.33

Sheet Annex 2b Export
A1: Note: The list of MPANs / MSIDs provided may be incomplete; the DNO reserves the right to apply the listed charges to any other MPANs / MSIDs associated with the site. Note: This table is automatically populated based on the content of the tab entitled 'Annex 2 Designated EHV Charges'. The timebands are as shown in Annex 2.
A2: =Overview!B4& " - Effective from "&Overview!D4&" - "&Overview!E4&" Designated EHV export charges" -> Northern Powergrid (Yorkshire) Plc - Effective from 1 April 2026 - Final Designated EHV export charges
A4: Export Unique Identifier | B4: LLFC | C4: Export MPANs/MSIDs | D4: Name | E4: ='Annex 2 Designated EHV charges'!M9 -> Export Super Red unit charge (p/kWh) | F4: ='Annex 2 Designated EHV charges'!N9 -> Export fixed charge (p/day) | G4: ='Annex 2 Designated EHV charges'!O9 -> Export capacity charge (p/kVA/day) | H4: ='Annex 2 Designated EHV charges'!P9 -> Export exceeded capacity charge (p/kVA/day)
A5: 90 | B5: =IF($A5="","",VLOOKUP($A5,'Annex 2 Designated EHV charges'!$D:$P,2,0)) -> 90 | C5: =IF($A5="","",VLOOKUP($A5,'Annex 2 Designated EHV charges'!$D:$P,3,0)) -> 2394000039650 | D5: =IF($A5="","",VLOOKUP($A5,'Annex 2 Designated EHV charges'!$D:$P,4,0)) -> EHV Site Specific (LLFC 753 & 90) | E5: =IFERROR(IF(VLOOKUP($A5,'Annex 2 Designated EHV charges'!$D:$P,10,FALSE)=0,0,VLOOKUP($A5,'Annex 2 Designated EHV charges'!$D:$P,10,FALSE)),"") -> 0 | F5: =IFERROR(IF(VLOOKUP($A5,'Annex 2 Designated EHV charges'!$D:$P,11,FALSE)=0,0,VLOOKUP($A5,'Annex 2 Designated EHV charges'!$D:$P,11,FALSE)),"") -> 183.27 | G5: =IFERROR(IF(VLOOKUP($A5,'Annex 2 Designated EHV charges'!$D:$P,12,FALSE)=0,0,VLOOKUP($A5,'Annex 2 Designated EHV charges'!$D:$P,12,FALSE)),"") -> 0.05 | H5: =IFERROR(IF(VLOOKUP($A5,'Annex 2 Designated EHV charges'!$D:$P,13,FALSE)=0,0,VLOOKUP($A5,'Annex 2 Designated EHV charges'!$D:$P,13,FALSE)),"") -> 0.05
A6: 82 | B6: =IF($A6="","",VLOOKUP($A6,'Annex 2 Designated EHV charges'!$D:$P,2,0)) -> 82 | C6: =IF($A6="","",VLOOKUP($A6,'Annex 2 Designated EHV charges'!$D:$P,3,0)) -> 2394000039660 2394000110620 | D6: =IF($A6="","",VLOOKUP($A6,'Annex 2 Designated EHV charges'!$D:$P,4,0)) -> EHV Site Specific (LLFC 754 & 82) | E6: =IFERROR(IF(VLOOKUP($A6,'Annex 2 Designated EHV charges'!$D:$P,10,FALSE)=0,0,VLOOKUP($A6,'Annex 2 Designated EHV charges'!$D:$P,10,FALSE)),"") -> 0 | F6: =IFERROR(IF(VLOOKUP($A6,'Annex 2 Designated EHV charges'!$D:$P,11,FALSE)=0,0,VLOOKUP($A6,'Annex 2 Designated EHV charges'!$D:$P,11,FALSE)),"") -> 621.12 | G6: =IFERROR(IF(VLOOKUP($A6,'Annex 2 Designated EHV charges'!$D:$P,12,FALSE)=0,0,VLOOKUP($A6,'Annex 2 Designated EHV charges'!$D:$P,12,FALSE)),"") -> 0.05 | H6: =IFERROR(IF(VLOOKUP($A6,'Annex 2 Designated EHV charges'!$D:$P,13,FALSE)=0,0,VLOOKUP($A6,'Annex 2 Designated EHV charges'!$D:$P,13,FALSE)),"") -> 0.05
A7: 76 | B7: =IF($A7="","",VLOOKUP($A7,'Annex 2 Designated EHV charges'!$D:$P,2,0)) -> 76 | C7: =IF($A7="","",VLOOKUP($A7,'Annex 2 Designated EHV charges'!$D:$P,3,0)) -> 2394000039641 | D7: =IF($A7="","",VLOOKUP($A7,'Annex 2 Designated EHV charges'!$D:$P,4,0)) -> EHV Site Specific (LLFC 755 & 76) | E7: =IFERROR(IF(VLOOKUP($A7,'Annex 2 Designated EHV charges'!$D:$P,10,FALSE)=0,0,VLOOKUP($A7,'Annex 2 Designated EHV charges'!$D:$P,10,FALSE)),"") -> 0 | F7: =IFERROR(IF(VLOOKUP($A7,'Annex 2 Designated EHV charges'!$D:$P,11,FALSE)=0,0,VLOOKUP($A7,'Annex 2 Designated EHV charges'!$D:$P,11,FALSE)),"") -> 564.58 | G7: =IFERROR(IF(VLOOKUP($A7,'Annex 2 Designated EHV charges'!$D:$P,12,FALSE)=0,0,VLOOKUP($A7,'Annex 2 Designated EHV charges'!$D:$P,12,FALSE)),"") -> 0.05 | H7: =IFERROR(IF(VLOOKUP($A7,'Annex 2 Designated EHV charges'!$D:$P,13,FALSE)=0,0,VLOOKUP($A7,'Annex 2 Designated EHV charges'!$D:$P,13,FALSE)),"") -> 0.05
A8: 75 | B8: =IF($A8="","",VLOOKUP($A8,'Annex 2 Designated EHV charges'!$D:$P,2,0)) -> 75 | C8: =IF($A8="","",VLOOKUP($A8,'Annex 2 Designated EHV charges'!$D:$P,3,0)) -> 2394000039679 | D8: =IF($A8="","",VLOOKUP($A8,'Annex 2 Designated EHV charges'!$D:$P,4,0)) -> EHV Site Specific (LLFC 756 & 75) | E8: =IFERROR(IF(VLOOKUP($A8,'Annex 2 Designated EHV charges'!$D:$P,10,FALSE)=0,0,VLOOKUP($A8,'Annex 2 Designated EHV charges'!$D:$P,10,FALSE)),"") -> 0 | F8: =IFERROR(IF(VLOOKUP($A8,'Annex 2 Designated EHV charges'!$D:$P,11,FALSE)=0,0,VLOOKUP($A8,'Annex 2 Designated EHV charges'!$D:$P,11,FALSE)),"") -> 779.95 | G8: =IFERROR(IF(VLOOKUP($A8,'Annex 2 Designated EHV charges'!$D:$P,12,FALSE)=0,0,VLOOKUP($A8,'Annex 2 Designated EHV charges'!$D:$P,12,FALSE)),"") -> 0.05 | H8: =IFERROR(IF(VLOOKUP($A8,'Annex 2 Designated EHV charges'!$D:$P,13,FALSE)=0,0,VLOOKUP($A8,'Annex 2 Designated EHV charges'!$D:$P,13,FALSE)),"") -> 0.05
A9: 95 | B9: =IF($A9="","",VLOOKUP($A9,'Annex 2 Designated EHV charges'!$D:$P,2,0)) -> 95 | C9: =IF($A9="","",VLOOKUP($A9,'Annex 2 Designated EHV charges'!$D:$P,3,0)) -> 2394000060226 | D9: =IF($A9="","",VLOOKUP($A9,'Annex 2 Designated EHV charges'!$D:$P,4,0)) -> EHV Site Specific (LLFC 757 & 95) | E9: =IFERROR(IF(VLOOKUP($A9,'Annex 2 Designated EHV charges'!$D:$P,10,FALSE)=0,0,VLOOKUP($A9,'Annex 2 Designated EHV charges'!$D:$P,10,FALSE)),"") -> -0.001 | F9: =IFERROR(IF(VLOOKUP($A9,'Annex 2 Designated EHV charges'!$D:$P,11,FALSE)=0,0,VLOOKUP($A9,'Annex 2 Designated EHV charges'!$D:$P,11,FALSE)),"") -> 1100.61 | G9: =IFERROR(IF(VLOOKUP($A9,'Annex 2 Designated EHV charges'!$D:$P,12,FALSE)=0,0,VLOOKUP($A9,'Annex 2 Designated EHV charges'!$D:$P,12,FALSE)),"") -> 0.05 | H9: =IFERROR(IF(VLOOKUP($A9,'Annex 2 Designated EHV charges'!$D:$P,13,FALSE)=0,0,VLOOKUP($A9,'Annex 2 Designated EHV charges'!$D:$P,13,FALSE)),"") -> 0.05
A10: 800 | B10: =IF($A10="","",VLOOKUP($A10,'Annex 2 Designated EHV charges'!$D:$P,2,0)) -> 800 | C10: =IF($A10="","",VLOOKUP($A10,'Annex 2 Designated EHV charges'!$D:$P,3,0)) -> MSID_0645 | D10: =IF($A10="","",VLOOKUP($A10,'Annex 2 Designated EHV charges'!$D:$P,4,0)) -> EHV Site Specific (LLFC 804 & 800) | E10: =IFERROR(IF(VLOOKUP($A10,'Annex 2 Designated EHV charges'!$D:$P,10,FALSE)=0,0,VLOOKUP($A10,'Annex 2 Designated EHV charges'!$D:$P,10,FALSE)),"") -> -0.008 | F10: =IFERROR(IF(VLOOKUP($A10,'Annex 2 Designated EHV charges'!$D:$P,11,FALSE)=0,0,VLOOKUP($A10,'Annex 2 Designated EHV charges'!$D:$P,11,FALSE)),"") -> 2782.58 | G10: =IFERROR(IF(VLOOKUP($A10,'Annex 2 Designated EHV charges'!$D:$P,12,FALSE)=0,0,VLOOKUP($A10,'Annex 2 Designated EHV charges'!$D:$P,12,FALSE)),"") -> 0.05 | H10: =IFERROR(IF(VLOOKUP($A10,'Annex 2 Designated EHV charges'!$D:$P,13,FALSE)=0,0,VLOOKUP($A10,'Annex 2 Designated EHV charges'!$D:$P,13,FALSE)),"") -> 0.05
A11: 60 | B11: =IF($A11="","",VLOOKUP($A11,'Annex 2 Designated EHV charges'!$D:$P,2,0)) -> 60 | C11: =IF($A11="","",VLOOKUP($A11,'Annex 2 Designated EHV charges'!$D:$P,3,0)) -> 2300000233736 2300000880975 | D11: =IF($A11="","",VLOOKUP($A11,'Annex 2 Designated EHV charges'!$D:$P,4,0)) -> EHV Site Specific (LLFC 760 & 60) | E11: =IFERROR(IF(VLOOKUP($A11,'Annex 2 Designated EHV charges'!$D:$P,10,FALSE)=0,0,VLOOKUP($A11,'Annex 2 Designated EHV charges'!$D:$P,10,FALSE)),"") -> 0 | F11: =IFERROR(IF(VLOOKUP($A11,'Annex 2 Designated EHV charges'!$D:$P,11,FALSE)=0,0,VLOOKUP($A11,'Annex 2 Designated EHV charges'!$D:$P,11,FALSE)),"") -> 1212.66 | G11: =IFERROR(IF(VLOOKUP($A11,'Annex 2 Designated EHV charges'!$D:$P,12,FALSE)=0,0,VLOOKUP($A11,'Annex 2 Designated EHV charges'!$D:$P,12,FALSE)),"") -> 0.05 | H11: =IFERROR(IF(VLOOKUP($A11,'Annex 2 Designated EHV charges'!$D:$P,13,FALSE)=0,0,VLOOKUP($A11,'Annex 2 Designated EHV charges'!$D:$P,13,FALSE)),"") -> 0.05
A12: 62 | B12: =IF($A12="","",VLOOKUP($A12,'Annex 2 Designated EHV charges'!$D:$P,2,0)) -> 62 | C12: =IF($A12="","",VLOOKUP($A12,'Annex 2 Designated EHV charges'!$D:$P,3,0)) -> 2300000457410 | D12: =IF($A12="","",VLOOKUP($A12,'Annex 2 Designated EHV charges'!$D:$P,4,0)) -> EHV Site Specific (LLFC 762 & 62) | E12: =IFERROR(IF(VLOOKUP($A12,'Annex 2 Designated EHV charges'!$D:$P,10,FALSE)=0,0,VLOOKUP($A12,'Annex 2 Designated EHV charges'!$D:$P,10,FALSE)),"") -> -0.032 | F12: =IFERROR(IF(VLOOKUP($A12,'Annex 2 Designated EHV charges'!$D:$P,11,FALSE)=0,0,VLOOKUP($A12,'Annex 2 Designated EHV charges'!$D:$P,11,FALSE)),"") -> 453.52 | G12: =IFERROR(IF(VLOOKUP($A12,'Annex 2 Designated EHV charges'!$D:$P,12,FALSE)=0,0,VLOOKUP($A12,'Annex 2 Designated EHV charges'!$D:$P,12,FALSE)),"") -> 0.05 | H12: =IFERROR(IF(VLOOKUP($A12,'Annex 2 Designated EHV charges'!$D:$P,13,FALSE)=0,0,VLOOKUP($A12,'Annex 2 Designated EHV charges'!$D:$P,13,FALSE)),"") -> 0.05
A13: 80 | B13: =IF($A13="","",VLOOKUP($A13,'Annex 2 Designated EHV charges'!$D:$P,2,0)) -> 80 | C13: =IF($A13="","",VLOOKUP($A13,'Annex 2 Designated EHV charges'!$D:$P,3,0)) -> MSID_7377 MSID_7543 | D13: =IF($A13="","",VLOOKUP($A13,'Annex 2 Designated EHV charges'!$D:$P,4,0)) -> EHV Site Specific (LLFC 763 & 80) | E13: =IFERROR(IF(VLOOKUP($A13,'Annex 2 Designated EHV charges'!$D:$P,10,FALSE)=0,0,VLOOKUP($A13,'Annex 2 Designated EHV charges'!$D:$P,10,FALSE)),"") -> -0.002 | F13: =IFERROR(IF(VLOOKUP($A13,'Annex 2 Designated EHV charges'!$D:$P,11,FALSE)=0,0,VLOOKUP($A13,'Annex 2 Designated EHV charges'!$D:$P,11,FALSE)),"") -> 1694.65 | G13: =IFERROR(IF(VLOOKUP($A13,'Annex 2 Designated EHV charges'!$D:$P,12,FALSE)=0,0,VLOOKUP($A13,'Annex 2 Designated EHV charges'!$D:$P,12,FALSE)),"") -> 0.05 | H13: =IFERROR(IF(VLOOKUP($A13,'Annex 2 Designated EHV charges'!$D:$P,13,FALSE)=0,0,VLOOKUP($A13,'Annex 2 Designated EHV charges'!$D:$P,13,FALSE)),"") -> 0.05
A14: 66 | B14: =IF($A14="","",VLOOKUP($A14,'Annex 2 Designated EHV charges'!$D:$P,2,0)) -> 66 | C14: =IF($A14="","",VLOOKUP($A14,'Annex 2 Designated EHV charges'!$D:$P,3,0)) -> 2300000233912 2300000996990 | D14: =IF($A14="","",VLOOKUP($A14,'Annex 2 Designated EHV charges'!$D:$P,4,0)) -> EHV Site Specific (LLFC 766 & 66) | E14: =IFERROR(IF(VLOOKUP($A14,'Annex 2 Designated EHV charges'!$D:$P,10,FALSE)=0,0,VLOOKUP($A14,'Annex 2 Designated EHV charges'!$D:$P,10,FALSE)),"") -> 0 | F14: =IFERROR(IF(VLOOKUP($A14,'Annex 2 Designated EHV charges'!$D:$P,11,FALSE)=0,0,VLOOKUP($A14,'Annex 2 Designated EHV charges'!$D:$P,11,FALSE)),"") -> 209.85 | G14: =IFERROR(IF(VLOOKUP($A14,'Annex 2 Designated EHV charges'!$D:$P,12,FALSE)=0,0,VLOOKUP($A14,'Annex 2 Designated EHV charges'!$D:$P,12,FALSE)),"") -> 0.05 | H14: =IFERROR(IF(VLOOKUP($A14,'Annex 2 Designated EHV charges'!$D:$P,13,FALSE)=0,0,VLOOKUP($A14,'Annex 2 Designated EHV charges'!$D:$P,13,FALSE)),"") -> 0.05
A15: 128 | B15: =IF($A15="","",VLOOKUP($A15,'Annex 2 Designated EHV charges'!$D:$P,2,0)) -> 128 | C15: =IF($A15="","",VLOOKUP($A15,'Annex 2 Designated EHV charges'!$D:$P,3,0)) -> 2394000133317 2394000139114 | D15: =IF($A15="","",VLOOKUP($A15,'Annex 2 Designated EHV charges'!$D:$P,4,0)) -> EHV Site Specific (LLFC 769 & 128) | E15: =IFERROR(IF(VLOOKUP($A15,'Annex 2 Designated EHV charges'!$D:$P,10,FALSE)=0,0,VLOOKUP($A15,'Annex 2 Designated EHV charges'!$D:$P,10,FALSE)),"") -> 0 | F15: =IFERROR(IF(VLOOKUP($A15,'Annex 2 Designated EHV charges'!$D:$P,11,FALSE)=0,0,VLOOKUP($A15,'Annex 2 Designated EHV charges'!$D:$P,11,FALSE)),"") -> 0 | G15: =IFERROR(IF(VLOOKUP($A15,'Annex 2 Designated EHV charges'!$D:$P,12,FALSE)=0,0,VLOOKUP($A15,'Annex 2 Designated EHV charges'!$D:$P,12,FALSE)),"") -> 0.05 | H15: =IFERROR(IF(VLOOKUP($A15,'Annex 2 Designated EHV charges'!$D:$P,13,FALSE)=0,0,VLOOKUP($A15,'Annex 2 Designated EHV charges'!$D:$P,13,FALSE)),"") -> 0.05
A16: 92 | B16: =IF($A16="","",VLOOKUP($A16,'Annex 2 Designated EHV charges'!$D:$P,2,0)) -> 92 | C16: =IF($A16="","",VLOOKUP($A16,'Annex 2 Designated EHV charges'!$D:$P,3,0)) -> 2394000019176 | D16: =IF($A16="","",VLOOKUP($A16,'Annex 2 Designated EHV charges'!$D:$P,4,0)) -> EHV Site Specific (LLFC 771 & 92) | E16: =IFERROR(IF(VLOOKUP($A16,'Annex 2 Designated EHV charges'!$D:$P,10,FALSE)=0,0,VLOOKUP($A16,'Annex 2 Designated EHV charges'!$D:$P,10,FALSE)),"") -> 0 | F16: =IFERROR(IF(VLOOKUP($A16,'Annex 2 Designated EHV charges'!$D:$P,11,FALSE)=0,0,VLOOKUP($A16,'Annex 2 Designated EHV charges'!$D:$P,11,FALSE)),"") -> 0 | G16: =IFERROR(IF(VLOOKUP($A16,'Annex 2 Designated EHV charges'!$D:$P,12,FALSE)=0,0,VLOOKUP($A16,'Annex 2 Designated EHV charges'!$D:$P,12,FALSE)),"") -> 0.05 | H16: =IFERROR(IF(VLOOKUP($A16,'Annex 2 Designated EHV charges'!$D:$P,13,FALSE)=0,0,VLOOKUP($A16,'Annex 2 Designated EHV charges'!$D:$P,13,FALSE)),"") -> 0.05
... A111: 510 | B111: =IF($A111="","",VLOOKUP($A111,'Annex 2 Designated EHV charges'!$D:$P,2,0)) -> 510 | C111: =IF($A111="","",VLOOKUP($A111,'Annex 2 Designated EHV charges'!$D:$P,3,0)) -> MSID_7589 | D111: =IF($A111="","",VLOOKUP($A111,'Annex 2 Designated EHV charges'!$D:$P,4,0)) -> EHV Site Specific (LLFC 725 & 510) | E111: =IFERROR(IF(VLOOKUP($A111,'Annex 2 Designated EHV charges'!$D:$P,10,FALSE)=0,0,VLOOKUP($A111,'Annex 2 Designated EHV charges'!$D:$P,10,FALSE)),"") -> 0 | F111: =IFERROR(IF(VLOOKUP($A111,'Annex 2 Designated EHV charges'!$D:$P,11,FALSE)=0,0,VLOOKUP($A111,'Annex 2 Designated EHV charges'!$D:$P,11,FALSE)),"") -> 3009.74 | G111: =IFERROR(IF(VLOOKUP($A111,'Annex 2 Designated EHV charges'!$D:$P,12,FALSE)=0,0,VLOOKUP($A111,'Annex 2 Designated EHV charges'!$D:$P,12,FALSE)),"") -> 0.05 | H111: =IFERROR(IF(VLOOKUP($A111,'Annex 2 Designated EHV charges'!$D:$P,13,FALSE)=0,0,VLOOKUP($A111,'Annex 2 Designated EHV charges'!$D:$P,13,FALSE)),"") -> 0.05

Sheet Annex 3 Preserved charges
A1: Back to Overview
A2: =Overview!B4& " - Effective from "&Overview!D4&" - "&Overview!E4&" LV and HV tariffs" -> Northern Powergrid (Yorkshire) Plc - Effective from 1 April 2026 - Final LV and HV tariffs
A3: NHH preserved charges/additional LLFCs
B4: Closed LLFCs | C4: PCs | D4: Unit charge 1 (NHH) p/kWh | E4: Unit charge 2 (NHH) p/kWh | F4: Fixed charge p/MPAN/day
A6: Notes:
A11: HH preserved charges/additional LLFCs
B12: Closed LLFCs | C12: PCs | D12: Red/black charge (HH) p/kWh | E12: Amber/yellow charge (HH) p/kWh | F12: Green charge (HH) p/kWh | G12: Fixed charge p/MPAN/day | H12: Capacity charge p/kVA/day | I12: Exceeded capacity charge p/kVA/day | J12: Reactive power charge p/kVArh
A14: Notes: | B14: Time periods
A24: =Overview!B4&" has no preserved charges/additional LLFCs" -> Northern Powergrid (Yorkshire) Plc has no preserved charges/additional LLFCs

Sheet Annex 4 LDNO charges
A1: Back to Overview
A2: =Overview!B4& " - Effective from "&Overview!D4&" - "&Overview!E4&" LDNO tariffs" -> Northern Powergrid (Yorkshire) Plc - Effective from 1 April 2026 - Final LDNO tariffs
A4: Time Bands for LV and HV Designated Properties | F4: Time Bands for Unmetered Properties
A5: Time periods | B5: Red Time Band | C5: Amber Time Band | D5: Green Time Band | H5: Black Time Band | I5: Yellow Time Band | J5: Green Time Band
A6: Monday to Friday (Including Bank Holidays) All Year | B6: 16:00 to 19:30 | C6: 08:00 to 16:00 19:30 to 22:00 | D6: 00:00 to 08:00 22:00 to 24:00 | F6: Monday to Friday (Including Bank Holidays) November to February Inclusive | H6: 16:00 to 19:30 | I6: 08:00 to 16:00 19:30 to 22:00 | J6: 00:00 to 08:00 22:00 to 24:00
A7: Saturday and Sunday All Year | B7: 0 | C7: 0 | D7: 00:00 to 24:00 | F7: Monday to Friday (Including Bank Holidays) April to October Inclusive and March | H7: 0 | I7: 08:00 to 22:00 | J7: 00:00 to 08:00 22:00 to 24:00
A8: Notes | B8: All the above times are in UK Clock time | F8: Saturday and Sunday All year | H8: 0 | I8: 0 | J8: 00:00 to 24:00
F9: Notes | H9: All the above times are in UK Clock time
A11: Tariff name | B11: Unique billing identifier | C11: PCs | D11: ='Annex 1 LV, HV and UMS charges'!D11 -> Red/black unit charge p/kWh | E11: ='Annex 1 LV, HV and UMS charges'!E11 -> Amber/yellow unit charge p/kWh | F11: ='Annex 1 LV, HV and UMS charges'!F11 -> Green unit charge p/kWh | G11: ='Annex 1 LV, HV and UMS charges'!G11 -> Fixed charge p/MPAN/day | H11: ='Annex 1 LV, HV and UMS charges'!H11 -> Capacity charge p/kVA/day | I11: ='Annex 1 LV, HV and UMS charges'!I11 -> Exceeded capacity charge p/kVA/day | J11: ='Annex 1 LV, HV and UMS charges'!J11 -> Reactive power charge p/kVArh
A12: LDNO LV: Domestic Aggregated or CT with Residual | B12: 150, 151, 148 | C12: 0, 1, 2 | D12: 4.034 | E12: 1.081 | F12: 0.126 | G12: 10.72 | H12: 0 | I12: 0 | J12: 0
A13: LDNO LV: Domestic Aggregated (related MPAN) | B13: 152 | C13: 2 | D13: 4.034 | E13: 1.081 | F13: 0.126 | G13: 0 | H13: 0 | I13: 0 | J13: 0
A14: LDNO LV: Non-Domestic Aggregated or CT No Residual | B14: 201 | C14: 0, 3, 4, 5-8 | D14: 4.854 | E14: 1.301 | F14: 0.152 | G14: 7.2 | H14: 0 | I14: 0 | J14: 0
A15: LDNO LV: Non-Domestic Aggregated or CT Band 1 | B15: 153, 154, 156, 149 | C15: 0, 3, 4, 5-8 | D15: 4.854 | E15: 1.301 | F15: 0.152 | G15: 10.6 | H15: 0 | I15: 0 | J15: 0
A16: LDNO LV: Non-Domestic Aggregated or CT Band 2 | B16: 202 | C16: 0, 3, 4, 5-8 | D16: 4.854 | E16: 1.301 | F16: 0.152 | G16: 15.68 | H16: 0 | I16: 0 | J16: 0
A17: LDNO LV: Non-Domestic Aggregated or CT Band 3 | B17: 203 | C17: 0, 3, 4, 5-8 | D17: 4.854 | E17: 1.301 | F17: 0.152 | G17: 24.94 | H17: 0 | I17: 0 | J17: 0
A18: LDNO LV: Non-Domestic Aggregated or CT Band 4 | B18: 204 | C18: 0, 3, 4, 5-8 | D18: 4.854 | E18: 1.301 | F18: 0.152 | G18: 56.53 | H18: 0 | I18: 0 | J18: 0
A19: LDNO LV: Non-Domestic Aggregated (related MPAN) | B19: 155 | C19: 4 | D19: 4.854 | E19: 1.301 | F19: 0.152 | G19: 0 | H19: 0 | I19: 0 | J19: 0
A20: LDNO LV: LV Site Specific No Residual | B20: 205 | C20: 0 | D20: 3.465 | E20: 0.908 | F20: 0.102 | G20: 9.57 | H20: 2.27 | I20: 2.27 | J20: 0.07
A21: LDNO LV: LV Site Specific Band 1 | B21: 157 | C21: 0 | D21: 3.465 | E21: 0.908 | F21: 0.102 | G21: 92.03 | H21: 2.27 | I21: 2.27 | J21: 0.07
A22: LDNO LV: LV Site Specific Band 2 | B22: 206 | C22: 0 | D22: 3.465 | E22: 0.908 | F22: 0.102 | G22: 174.57 | H22: 2.27 | I22: 2.27 | J22: 0.07
A23: LDNO LV: LV Site Specific Band 3 | B23: 207 | C23: 0 | D23: 3.465 | E23: 0.908 | F23: 0.102 | G23: 257.98 | H23: 2.27 | I23: 2.27 | J23: 0.07
A24: LDNO LV: LV Site Specific Band 4 | B24: 208 | C24: 0 | D24: 3.465 | E24: 0.908 | F24: 0.102 | G24: 526.87 | H24: 2.27 | I24: 2.27 | J24: 0.07
A25: LDNO LV: Unmetered Supplies | B25: 132, 133, 134, 135, 170 | C25: 0, 1, 8 | D25: 12.19 | E25: 1.423 | F25: 0.529 | G25: 0 | H25: 0 | I25: 0 | J25: 0
A26: LDNO LV: LV Generation Aggregated | B26: 172 | C26: 0, 8 | D26: -4.895 | E26: -1.312 | F26: -0.153 | G26: 0 | H26: 0 | I26: 0 | J26: 0
A27: LDNO LV: LV Generation Site Specific | B27: 173, 174 | C27: 0 | D27: -4.895 | E27: -1.312 | F27: -0.153 | G27: 0 | H27: 0 | I27: 0 | J27: 0.091
A28: LDNO HV: Domestic Aggregated or CT with Residual | B28: 158, 159, 398 | C28: 0, 1, 2 | D28: 2.787 | E28: 0.747 | F28: 0.087 | G28: 7.41 | H28: 0 | I28: 0 | J28: 0
A29: LDNO HV: Domestic Aggregated (Related MPAN) | B29: 160 | C29: 2 | D29: 2.787 | E29: 0.747 | F29: 0.087 | G29: 0 | H29: 0 | I29: 0 | J29: 0
A30: LDNO HV: Non-Domestic Aggregated or CT No Residual | B30: 209 | C30: 0, 3, 4, 5-8 | D30: 3.353 | E30: 0.899 | F30: 0.105 | G30: 4.98 | H30: 0 | I30: 0 | J30: 0
A31: LDNO HV: Non-Domestic Aggregated or CT Band 1 | B31: 161, 162, 164, 399 | C31: 0, 3, 4, 5-8 | D31: 3.353 | E31: 0.899 | F31: 0.105 | G31: 7.32 | H31: 0 | I31: 0 | J31: 0
A32: LDNO HV: Non-Domestic Aggregated or CT Band 2 | B32: 210 | C32: 0, 3, 4, 5-8 | D32: 3.353 | E32: 0.899 | F32: 0.105 | G32: 10.83 | H32: 0 | I32: 0 | J32: 0
A33: LDNO HV: Non-Domestic Aggregated or CT Band 3 | B33: 211 | C33: 0, 3, 4, 5-8 | D33: 3.353 | E33: 0.899 | F33: 0.105 | G33: 17.23 | H33: 0 | I33: 0 | J33: 0
A34: LDNO HV: Non-Domestic Aggregated or CT Band 4 | B34: 212 | C34: 0, 3, 4, 5-8 | D34: 3.353 | E34: 0.899 | F34: 0.105 | G34: 39.05 | H34: 0 | I34: 0 | J34: 0
A35: LDNO HV: Non-Domestic Aggregated (related MPAN) | B35: 163 | C35: 4 | D35: 3.353 | E35: 0.899 | F35: 0.105 | G35: 0 | H35: 0 | I35: 0 | J35: 0
A36: LDNO HV: LV Site Specific No Residual | B36: 213 | C36: 0 | D36: 2.394 | E36: 0.627 | F36: 0.07 | G36: 6.61 | H36: 1.57 | I36: 1.57 | J36: 0.049
A37: LDNO HV: LV Site Specific Band 1 | B37: 165 | C37: 0 | D37: 2.394 | E37: 0.627 | F37: 0.07 | G37: 63.58 | H37: 1.57 | I37: 1.57 | J37: 0.049
A38: LDNO HV: LV Site Specific Band 2 | B38: 215 | C38: 0 | D38: 2.394 | E38: 0.627 | F38: 0.07 | G38: 120.6 | H38: 1.57 | I38: 1.57 | J38: 0.049
A39: LDNO HV: LV Site Specific Band 3 | B39: 216 | C39: 0 | D39: 2.394 | E39: 0.627 | F39: 0.07 | G39: 178.22 | H39: 1.57 | I39: 1.57 | J39: 0.049
A40: LDNO HV: LV Site Specific Band 4 | B40: 217 | C40: 0 | D40: 2.394 | E40: 0.627 | F40: 0.07 | G40: 363.97 | H40: 1.57 | I40: 1.57 | J40: 0.049
A41: LDNO HV: LV Sub Site Specific No Residual | B41: 218 | C41: 0 | D41: 2.578 | E41: 0.64 | F41: 0.065 | G41: 11.18 | H41: 2.13 | I41: 2.13 | J41: 0.047
A42: LDNO HV: LV Sub Site Specific Band 1 | B42: 166 | C42: 0 | D42: 2.578 | E42: 0.64 | F42: 0.065 | G42: 107.44 | H42: 2.13 | I42: 2.13 | J42: 0.047
...

Sheet Annex 5 LLFs
A1: Back to Overview
A2: This table has intentionally been left blank. The line loss factors that are approved by the BSC Panel for the applicable year and consequently published on the Elexon website will take precedence and be used in Settlement. This annex will be re-published once these values are available.
A3: =Overview!B4& " - Illustrative LLFs for year beginning "&Overview!D4 -> Northern Powergrid (Yorkshire) Plc - Illustrative LLFs for year beginning 1 April 2026
A4: Time periods | B4: Period 1 | C4: Period 2 | D4: Period 3 | E4: Period 4
A5: Monday – Friday (Apr – Oct) | B5: 0 | C5: 0 | D5: 00:00 – 07:00 | E5: 07:00 – 24:00
A6: Monday – Friday (Nov – Feb) | B6: 16:00 – 19:00 | C6: 07:00 – 16:00 19:00 – 20:00 | D6: 00:00 – 07:00 | E6: 20:00 – 24:00
A7: Monday – Friday (Mar) | B7: 0 | C7: 0 | D7: 00:00 – 07:00 | E7: 07:00 – 24:00
A8: Saturday and Sunday (All Year) | B8: 0 | C8: 0 | D8: 00:00 – 07:00 | E8: 07:00 – 24:00
A9: Notes | B9: All the above times are in UK Clock time
A12: Generic demand and generation LLFs
A13: Metered voltage, respective periods and associated LLFCs
A14: Metered voltage | B14: Period 1 | C14: Period 2 | D14: Period 3 | E14: Period 4 | F14: Associated LLFC
A15: Low Voltage Network | B15: 1.172 | C15: 1.153 | D15: 1.107 | E15: 1.128 | F15: 100, 111, 120, 1A, 1AH, 20, 22, 222, 224, 24, 279, 2A, 2AH, 2B, 2BH, 2C, 2CH, 2D, 2DH, 2Z, 2ZH, 3A, 4A, 5A, 5B, 5C, 5D, 5Z, 8A, 995, 999
A16: Low Voltage Substation | B16: 1.045 | C16: 1.045 | D16: 1.047 | E16: 1.044 | F16: 223, 225, 23, 25, 30, 6A, 6B, 6C, 6D, 6Z
A17: High Voltage Network | B17: 1.029 | C17: 1.028 | D17: 1.022 | E17: 1.024 | F17: 226, 228, 26, 28, 7A, 7B, 7C, 7D, 7Z
A18: High Voltage Substation | B18: 1.019 | C18: 1.019 | D18: 1.016 | E18: 1.017 | F18: 31, 32, 34, 36, 37, 38, 39, 68, 69, 71, 72, 831, 832, 833, 834, 835, 836, 837, 838, 839, 840, 841, 842, 844, 845, 846, 847, 848, 849, 850, 851, 852, 853, 854, 855, 856, 858, 859, 861, 862, 863, 865, 866, 867, 868, 869, 870, 871, 872, 873, 874, 875, 876, 877, 880, 881, 882, 883, 884, 885, 886, 888, 892, 893, 894, 895, 896, 897, 898, 899, 900
A19: Greater than 22kV connected - generation | B19: 1.013 | C19: 1.012 | D19: 1.009 | E19: 1.01 | F19: 699, 700, 701, 702, 703, 704, 705, 706, 707, 708, 709, 710, 711, 712, 713, 714, 715, 716, 717, 718, 719, 720, 721, 722, 723, 724, 818, 819, 820, 911, 914, 915, 934, 935, 936, 937, 938, 939, 940, 941, 942, 943, 944, 945, 949, 950, 951, 952, 953, 954, 955, 956, 957, 958, 959, 960, 961, 962, 963, 964, 965, 966, 967, 968, 969, 970, 971, 972, 973, 974, 975, 976, 977, 978, 979, 980, 981, 982, 983, 984, 985, 986, 987, 988, 989, 990, 994, ME1, MX1
A20: Greater than 22kV connected - demand | B20: 1.013 | C20: 1.012 | D20: 1.009 | E20: 1.01 | F20: 129, 455, 456, 457, 458, 459, 460, 461, 462, 463, 464, 465, 466, 467, 468, 469, 470, 473, 474, 475, 476, 477, 478, 479, 482, 483, 484, 485, 486, 487, 488, 489, 490, 491, 492, 493, 494, 495, 496, 497, 498, 499, 503, 504, 505, 506, 507, 508, 509, 540, 541, 542, 543, 544, 545, 546, 547, 548, 549, 550, 554, 555, 556, 557, 558, 559, 560, 561, 562, 563, 564, 565, 566, 567, 568, 569, 570, 571, 572, 573, 574, 575, 576, 577, 578, 579, 582, ME2, MX2
A22: Designated EHV site specific LLFs
A23: Demand
A24: Site | B24: Period 1 | C24: Period 2 | D24: Period 3 | E24: Period 4 | F24: Associated LLFC
A25: Site 1 | B25: 1.026 | C25: 1.026 | D25: 1.025 | E25: 1.026 | F25: 750
A26: Site 2 | B26: 1.004 | C26: 1.004 | D26: 1.004 | E26: 1.004 | F26: 751
A27: Site 3 | B27: 1.033 | C27: 1.031 | D27: 1.032 | E27: 1.025 | F27: 753
A28: Site 4 | B28: 1.009 | C28: 1.009 | D28: 1.016 | E28: 1.009 | F28: 754
A29: Site 5 | B29: 1.01 | C29: 1.01 | D29: 1.019 | E29: 1.01 | F29: 755
A30: Site 6 | B30: 1.005 | C30: 1.005 | D30: 1.01 | E30: 1.007 | F30: 756
A31: Site 7 | B31: 1 | C31: 1.004 | D31: 1.002 | E31: 1.002 | F31: 757
A32: Site 8 | B32: 1.007 | C32: 1.007 | D32: 1.007 | E32: 1.007 | F32: 804
A33: Site 9 | B33: 1.004 | C33: 1.004 | D33: 1.005 | E33: 1.005 | F33: 760
A34: Site 10 | B34: 1 | C34: 1 | D34: 1 | E34: 1 | F34: 761
A35: Site 11 | B35: 1.008 | C35: 1.008 | D35: 1.006 | E35: 1.007 | F35: 762
A36: Site 12 | B36: 1.01 | C36: 1.005 | D36: 1.004 | E36: 1.006 | F36: 763
... A136: Site 112 | B136: 1.013 | C136: 1.012 | D136: 1.009 | E136: 1.01 | F136: 725
A139: EHV site specific LLFs
A140: Generation
A141: Site | B141: Period 1 | C141: Period 2 | D141: Period 3 | E141: Period 4 | F141: Associated LLFC
A142: Site 1 | B142: 1.052 | C142: 1.046 | D142: 1.014 | E142: 1.026 | F142: 90
A143: Site 2 | B143: 1.004 | C143: 1.004 | D143: 0.993 | E143: 1.001 | F143: 82
A144: Site 3 | B144: 0.993 | C144: 0.993 | D144: 0.981 | E144: 0.992 | F144: 76
...

Sheet Annex 6 New or Amended EHV
A1: Back to Overview | C1: Note: The list of MPANs/MSIDs provided may be incomplete; the DNO reserves the right to apply the listed charges to any other MPANs/MSIDs associated with the site. If sites appear in both Annex 2 and Annex 6, the charges in Annex 6 take precedence. Where an existing Designated EHV Property is modified and energised in the charging year, we may revise the EDCM charges for the modified Designated EHV Property.
A2: Annex 6 - Charges for New or Amended Designated EHV Properties
A4: =Overview!B4& " - Effective from "&Overview!D4&" - "&Overview!E4&" new Designated EHV charges" -> Northern Powergrid (Yorkshire) Plc - Effective from 1 April 2026 - Final new Designated EHV charges
A5: Effective from date | B5: Import Unique Identifier | C5: LLFC | D5: Import MPANs/MSIDs | E5: Export Unique Identifier | F5: LLFC | G5: Export MPANs/MSIDs | H5: Name | I5: ='Annex 2 Designated EHV charges'!I9 -> Import Super Red unit charge (p/kWh) | J5: ='Annex 2 Designated EHV charges'!J9 -> Import fixed charge (p/day) | K5: ='Annex 2 Designated EHV charges'!K9 -> Import capacity charge (p/kVA/day) | L5: ='Annex 2 Designated EHV charges'!L9 -> Import exceeded capacity charge (p/kVA/day) | M5: ='Annex 2 Designated EHV charges'!M9 -> Export Super Red unit charge (p/kWh) | N5: ='Annex 2 Designated EHV charges'!N9 -> Export fixed charge (p/day) | O5: ='Annex 2 Designated EHV charges'!O9 -> Export capacity charge (p/kVA/day) | P5: ='Annex 2 Designated EHV charges'!P9 -> Export exceeded capacity charge (p/kVA/day)
A17: =Overview!B4& " - Effective from "&Overview!D4&" - "&Overview!E4&" new Designated EHV line loss factors" -> Northern Powergrid (Yorkshire) Plc - Effective from 1 April 2026 - Final new Designated EHV line loss factors
A18: Effective from date | B18: Import Unique Identifier | C18: LLFC | D18: Import MPANs/MSIDs | E18: Export Unique Identifier | F18: LLFC | G18: Export MPANs/MSIDs | H18: Name | I18: Import LLF period 1 | J18: Import LLF period 2 | K18: Import LLF period 3 | L18: Import LLF period 4 | M18: Import LLF period 5 | N18: Export LLF period 1 | O18: Export LLF period 2 | P18: Export LLF period 3 | Q18: Export LLF period 4 | R18: Export LLF period 5
A32: New or Amended Charges for Designated EHV Properties can be found in the relevant 'Addendum' spreadsheet published on our website, as updated from time to time.

Sheet Annex 7 Pass-Through Costs
