Workbook
Name OLE_LINK1: 'Annex 3 Preserved charges'!#REF!

Sheet Overview
A2: Company and Licence name, charging year, effective from, status
B3: Company and Licence name | C3: Year | D3: Effective From | E3: Status
A4: Company and Licence name, charging year, effective from, status | B4: Eastern Power Networks | C4: 2017/2018 | D4: 01/04/2017 | E4: Final
A6: List of data tables in this workbook
A7: Worksheet | B7: Information
A8: Annex 1 LV and HV charges | B8: Annex 1 contains charges to LV and HV Designated Properties.
A9: Annex 2 EHV charges | B9: ="Annex 2 contains the charges to Designated EHV Properties and charges applied to LDNOs with Designated EHV Properties/end-users embedded in networks within the " &B4 &" Licence area." -> Annex 2 contains the charges to Designated EHV Properties and charges applied to LDNOs with Designated EHV Properties/end-users embedded in networks within the Eastern Power Networks Licence area.
A10: Annex 3 Preserved charges | B10: Annex 3 contains details of any preserved and additional charges that are valid at this time.
A11: Annex 4 LDNO charges | B11: ="Annex 4 contains charges that are levied on the owner of an embedded network within the "&B4&" Licence area. "&"Electricity suppliers and consumers who have properties connected to an embedded network should contact the embedded network owner to determine their distribution charges."&" The charges listed in this table are not payable by domestic consumers, business consumers or electricity suppliers." -> Annex 4 contains charges that are levied on the owner of an embedded network within the Eastern Power Networks Licence area. Electricity suppliers and consumers who have properties connected to an embedded network should contact the embedded network owner to determine their distribution charges. The charges listed in this table are not payable by domestic consumers, business consumers or electricity suppliers.
A12: Annex 5 LLFs | B12: Annex 5 contains illustrative LLFs. LLFs are used in Settlement to adjust the metering system volumes to take account of losses on the distribution network. Illustrative LLFs are provided with reference to the metered voltage or associated LLFC for generic LLFs and by reference to the LLFCs for site specific LLFs. Each LLF is applicable to a defined time period. The LLFs used in Settlement are published on the Elexon portal website, www.elexonportal.co.uk. The website contains the LLFs in standard industry data formats and in a summary form. A user guide with details on registering and using the portal is also available.
A13: Annex 6 new Designated EHV Properties | B13: ="Annex 6 contains the charges to new Designated EHV Properties and charges applied to LDNOs with new Designated EHV Properties/end-users embedded in networks within the " &B4 &" Licence area." -> Annex 6 contains the charges to new Designated EHV Properties and charges applied to LDNOs with new Designated EHV Properties/end-users embedded in networks within the Eastern Power Networks Licence area.
A14: Nodal prices | B14: Contains the underlying [nodal/network group] costs used to calculate the current EDCM charges.
A15: SSC TPR to unit rate lookup table | B15: The time periods for the non half hourly metered charge rates in Annex 1 are as specified by the SSC. To determine the appropriate charge rate for each SSC/TPR a lookup table is provided.
A16: Charge calculator | B16: Charge calculator is a tool to help you estimate your distribution charges using current consumption data and forecast consumption data.
A18: Notes to users of this spreadsheet
A20: Please use this spreadsheet with reference to the LC14 use of system charging statement.
A22: Notes to DNOs populating this spreadsheet
A24: DNOs must endeavour to maintain consistency in the structure of this spreadsheet. Any changes to the structure must be noted in the 'Notes to users of this spreadsheet'
A25: The drop down list on the charge calculator can be expanded by unprotecting the charge calculator sheet and selecting 'data', 'data validation...' and then expanding the 'source' data range. The sheet can then be protected.

Sheet Annex 1 LV and HV charges
A1: Back to Overview | B1: 'DNOs paste value cells A15:I41 from CDCM 3701 into cells A14:I40
A2: =Overview!B4& " - Effective from "&Overview!D4&" - "&Overview!E4&" LV and HV charges" -> Eastern Power Networks - Effective from 01/04/2017 - Final LV and HV charges
A4: Time Bands for Half Hourly Metered Properties | G4: Time Bands for Half Hourly Unmetered Properties
A5: Time periods | B5: Red Time Band | C5: Amber Time Band | E5: Green Time Band | I5: Black Time Band | J5: Yellow Time Band | K5: Green Time Band
A6: Monday to Friday (Including Bank Holidays) All Year | B6: 16:00 - 19:00 | C6: 07:00 - 16:00 19.00 - 23.00 | E6: 00:00 - 07:00 23:00 - 24:00 | G6: Monday to Friday (Including Bank Holidays) November to February Inclusive | I6: 16:00 - 19:00 | J6: 07:00 - 16:00 19:00 - 23:00 | K6: 00:00 - 07:00 23:00 - 24:00
A7: Saturday and Sunday All Year | E7: 00:00 - 24:00 | G7: Monday to Friday (Including Bank Holidays) March to October Inclusive | J7: 07:00 - 23:00 | K7: 00:00 - 07:00 23:00 - 24:00
A8: Notes | B8: All times are in UK Clock time | G8: Saturday and Sunday All Year | K8: 00:00 - 24:00
G9: Notes | I9: All times are in UK Clock time
A13: Tariff name | B13: Open LLFCs | C13: PCs | D13: Unit charge 1 (NHH) or red/black charge (HH) p/kWh | E13: Unit charge 2 (NHH) or amber/yellow charge (HH) p/kWh | F13: Green charge(HH) p/kWh | G13: Fixed charge p/MPAN/day | H13: Capacity charge p/kVA/day | I13: Reactive power charge p/kVArh | J13: Exceeded capacity charge p/kVA/day | K13: Closed LLFCs
A14: Domestic Unrestricted | B14: 3, 40 | C14: 1 | D14: 1.998 | E14: 0 | F14: 0 | G14: 4.69 | H14: 0 | I14: 0
A15: Domestic Two Rate | B15: 7, 11, 25, 43, 46, 58 | C15: 2 | D15: 2.396 | E15: 0.03 | F15: 0 | G15: 4.69 | H15: 0 | I15: 0
A16: Domestic Off Peak (related MPAN) | B16: 22, 29, 55, 61 | C16: 2 | D16: 0.092 | E16: 0 | F16: 0 | G16: 0 | H16: 0 | I16: 0
A17: Small Non Domestic Unrestricted | B17: 201, 237, 238, 239 | C17: 3 | D17: 1.535 | E17: 0 | F17: 0 | G17: 5.05 | H17: 0 | I17: 0
A18: Small Non Domestic Two Rate | B18: 15, 49, 205, 242, 247, 248 | C18: 4 | D18: 1.838 | E18: 0.03 | F18: 0 | G18: 5.05 | H18: 0 | I18: 0
A19: Small Non Domestic Off Peak (related MPAN) | B19: 33, 64 | C19: 4 | D19: 0.18 | E19: 0 | F19: 0 | G19: 0 | H19: 0 | I19: 0
A20: LV Medium Non-Domestic | B20: 250, 254 | C20: 5-8 | D20: 1.733 | E20: 0.023 | F20: 0 | G20: 32.92 | H20: 0 | I20: 0
A21: LV Sub Medium Non-Domestic | D21: 1.044 | E21: 0.013 | F21: 0 | G21: 10.19 | H21: 0 | I21: 0
A22: HV Medium Non-Domestic | D22: 0.685 | E22: 0.004 | F22: 0 | G22: 102.52 | H22: 0 | I22: 0
A23: LV Network Domestic | B23: 1 | C23: 0 | D23: 15.253 | E23: 0.131 | F23: 0.023 | G23: 4.69 | H23: 0 | I23: 0
A24: LV Network Non-Domestic Non-CT | B24: 200 | C24: 0 | D24: 13.855 | E24: 0.119 | F24: 0.021 | G24: 5.37 | H24: 0 | I24: 0
A25: LV HH Metered | B25: 86 | C25: 0 | D25: 10.911 | E25: 0.078 | F25: 0.014 | G25: 14.87 | H25: 3.15 | I25: 0.332 | J25: =H25 -> 3.15
A26: LV Sub HH Metered | B26: 80 | C26: 0 | D26: 7.717 | E26: 0.035 | F26: 0.007 | G26: 10.19 | H26: 4.67 | I26: 0.215 | J26: =H26 -> 4.67
A27: HV HH Metered | B27: 84 | C27: 0 | D27: 6.384 | E27: 0.02 | F27: 0.004 | G27: 102.52 | H27: 3.87 | I27: 0.179 | J27: =H27 -> 3.87
A28: NHH UMS category A | B28: 100, 110, 150, 160 | C28: 8 | D28: 1.749 | E28: 0 | F28: 0 | G28: 0 | H28: 0 | I28: 0
A29: NHH UMS category B | B29: 102, 112, 152, 162 | C29: 1 | D29: 2.604 | E29: 0 | F29: 0 | G29: 0 | H29: 0 | I29: 0
A30: NHH UMS category C | B30: 103, 113, 153, 163 | C30: 1 | D30: 4.43 | E30: 0 | F30: 0 | G30: 0 | H30: 0 | I30: 0
A31: NHH UMS category D | B31: 101, 111, 151, 161 | C31: 1 | D31: 1.181 | E31: 0 | F31: 0 | G31: 0 | H31: 0 | I31: 0
A32: LV UMS (Pseudo HH Metered) | B32: 350 | C32: 0 | D32: 39.655 | E32: 0.653 | F32: 0.552 | G32: 0 | H32: 0 | I32: 0
A33: LV Generation NHH or Aggregate HH | B33: 905, 912, 913 | C33: 8 or 0 | D33: -0.905 | E33: 0 | F33: 0 | G33: 0 | H33: 0 | I33: 0
A34: LV Sub Generation NHH | D34: -0.802 | E34: 0 | F34: 0 | G34: 0 | H34: 0 | I34: 0
A35: LV Generation Intermittent | B35: 901 | C35: 0 | D35: -0.905 | E35: 0 | F35: 0 | G35: 0 | H35: 0 | I35: 0.289
A36: LV Generation Non-Intermittent | B36: 915 | C36: 0 | D36: -9.684 | E36: -0.09 | F36: -0.016 | G36: 0 | H36: 0 | I36: 0.289
A37: LV Sub Generation Intermittent | B37: 902 | C37: 0 | D37: -0.802 | E37: 0 | F37: 0 | G37: 0 | H37: 0 | I37: 0.259
A38: LV Sub Generation Non-Intermittent | B38: 916 | C38: 0 | D38: -8.626 | E38: -0.072 | F38: -0.013 | G38: 0 | H38: 0 | I38: 0.259
A39: HV Generation Intermittent | B39: 903 | C39: 0 | D39: -0.577 | E39: 0 | F39: 0 | G39: 48.95 | H39: 0 | I39: 0.211
A40: HV Generation Non-Intermittent | B40: 918 | C40: 0 | D40: -6.312 | E40: -0.03 | F40: -0.006 | G40: 48.95 | H40: 0 | I40: 0.211

Sheet Annex 2 EHV charges
A1: Back to Overview | C1: Copy EDCM table 5001 range starting B101 and paste into G11. Extend or reduce print area as required. | F1: Note: The list of MPANs / MSIDs provided may be incomplete; the DNO reserves the right to apply the listed charges to any other MPANs / MSIDs associated with the site.
A2: =Overview!B4& " - Effective from "&Overview!D4&" - "&Overview!E4&" EDCM charges" -> Eastern Power Networks - Effective from 01/04/2017 - Final EDCM charges
A4: Time Periods for Designated EHV Properties
A5: Time periods | D5: Super Red Time Band
A6: Monday to Friday (Including Bank Holidays) November to February Inclusive | D6: 16:00 - 19:00
A7: Notes | D7: All times are in UK Clock time
A10: Import Unique Identifier | B10: LLFC | C10: Import MPANs/MSIDs | D10: Export Unique Identifier | E10: LLFC | F10: Export MPANs/MSIDs | G10: Name | H10: Import Super Red unit charge (p/kWh) | I10: Import fixed charge (p/day) | J10: Import capacity charge (p/kVA/day) | K10: Import exceeded capacity charge (p/kVA/day) | L10: Export Super Red unit charge (p/kWh) | M10: Export fixed charge (p/day) | N10: Export capacity charge (p/kVA/day) | O10: Export exceeded capacity charge (p/kVA/day)
A11: 3VALSW | B11: 771 | C11: 1014569699836 | G11: AFFINITY WATER LIMITED | H11: 0.717 | I11: 178.32 | J11: 5.56 | K11: 5.56 | L11: 0 | M11: 0 | N11: 0 | O11: 0
A12: ABSRSF | B12: 869 | C12: 1050000574685 | D12: ABSRSF | E12: 744 | F12: 1050000574694 | G12: ABBOTS RIPTON SOLAR ENERGY LIMITED | H12: 1.908 | I12: 18.24 | J12: 3 | K12: 3 | L12: 0 | M12: 3647.93 | N12: 0.05 | O12: 0.05
A13: ADBRKS | B13: 771 | C13: 1023529546480 | G13: ADDENBROOKES NHS TRUST | H13: 1.414 | I13: 3068.14 | J13: 3.93 | K13: 3.93 | L13: 0 | M13: 0 | N13: 0 | O13: 0
A14: AIAMAN | B14: 771 | C14: 1014569292506 | D14: AIAMAN | E14: 792 | F14: 1030054607984 | G14: A I A MANAGEMENT LTD | H14: 2.944 | I14: 8.49 | J14: 19.01 | K14: 19.01 | L14: -2.844 | M14: 169.83 | N14: 0.05 | O14: 0.05
A15: ARAMAN | B15: 800 | C15: 1023483097981 | G15: AIRCRAFT RESEARCH ASSOCIATION LIMITED | H15: 0.111 | I15: 6644.17 | J15: 0.95 | K15: 0.95 | L15: 0 | M15: 0 | N15: 0 | O15: 0
A16: ARLAFD | B16: 771 | C16: 1030081553176 1030081553404 | D16: ARLAFD | E16: 792 | F16: 1030085114723 1030085114955 | G16: ARLA FOODS LIMITED | H16: 4.172 | I16: 3283.78 | J16: 1.78 | K16: 1.78 | L16: 0 | M16: 1094.59 | N16: 0.05 | O16: 0.05
A17: ASTONC | B17: 503 | C17: 1050000834246 | D17: ASTONC | E17: 780 | F17: 1050000834255 | G17: ASTON CLINTON | H17: 5.981 | I17: 2.58 | J17: 3.14 | K17: 3.14 | L17: 0 | M17: 515.71 | N17: 0.05 | O17: 0.05
A18: AVENUE | B18: 504 | C18: 1050000774970 | D18: AVENUE | E18: 781 | F18: 1050000774980 | G18: LIGHTSOURCE SPV 15 LIMITED | H18: 0.064 | I18: 17.15 | J18: 4.11 | K18: 4.11 | L18: 0 | M18: 1114.99 | N18: 0.05 | O18: 0.05
A19: AW_GRA | B19: 771 | C19: 1023477037942 1014571445536 | G19: ANGLIAN WATER SERVICES | H19: 2.419 | I19: 178.32 | J19: 6.81 | K19: 6.81 | L19: 0 | M19: 0 | N19: 0 | O19: 0
A20: AWOUSE | B20: 771 | C20: 1023475403798 1014571965793 | G20: ANGLIAN WATER SERVICES | H20: 2.605 | I20: 178.32 | J20: 4.15 | K20: 4.15 | L20: 0 | M20: 0 | N20: 0 | O20: 0
A21: BARNFM | B21: 796 | C21: 1050000774999 | D21: BARNFM | E21: 797 | F21: 1050000775005 | G21: BARN FARM SOLAR | H21: 4.001 | I21: 44.65 | J21: 6.69 | K21: 6.69 | L21: 0 | M21: 1875.31 | N21: 0.05 | O21: 0.05
A22: BAYFMS | B22: 870 | C22: 1050000579318 | D22: BAYFMS | E22: 745 | F22: 1050000579327 | G22: BAY FARM IMPORT | H22: 2.292 | I22: 31.89 | J22: 4.26 | K22: 4.26 | L22: 0 | M22: 2551.06 | N22: 0.05 | O22: 0.05
A23: BDGHSE | B23: 505 | C23: 1050000669548 | D23: BDGHSE | E23: 782 | F23: 1050000669539 | G23: BOARDINGHOUSE WINDFARM LIMITED | H23: 0.926 | I23: 28.23 | J23: 1.66 | K23: 1.66 | L23: 0 | M23: 1052.2 | N23: 0.05 | O23: 0.05
A24: BDWLWF | B24: 827 | C24: 1030082700415 | D24: BDWLWF | E24: 734 | F24: 1030082700647 | G24: RWE INNOGY UK LIMITED | H24: 2.857 | I24: 38.42 | J24: 2.59 | K24: 2.59 | L24: 0 | M24: 3938.04 | N24: 0.05 | O24: 0.05
A25: BERMAT | B25: 771 | C25: 1014571751895 | G25: BERNARD MATTHEWS LIMITED | H25: 0.474 | I25: 89.16 | J25: 6.61 | K25: 6.61 | L25: 0 | M25: 0 | N25: 0 | O25: 0
A26: BGWDWF | B26: 871 | C26: 1030083931374 | D26: BGWDWF | E26: 746 | F26: 1030083931142 | G26: BIGGLESWADE WIND FARM LIMITED | H26: 1.302 | I26: 3.39 | J26: 4.27 | K26: 4.27 | L26: 0 | M26: 278.25 | N26: 0.05 | O26: 0.05
A27: BLGTSF | B27: 534 | C27: 1050000769039 | D27: BLGTSF | E27: 466 | F27: 1050000769048 | G27: SOLAR CENTURY | H27: 4.192 | I27: 11.76 | J27: 2.87 | K27: 2.87 | L27: 0 | M27: 1117.59 | N27: 0.05 | O27: 0.05
A28: BOCTHA | B28: 803 | C28: 1014572608412 | G28: BOC LTD | H28: 2.91 | I28: 965.67 | J28: 5.03 | K28: 5.03 | L28: 0 | M28: 0 | N28: 0 | O28: 0
A29: BOXTED | B29: 506 | C29: 1050000774270 | D29: BOXTED | E29: 783 | F29: 1050000774289 | G29: PUSH ENERGY (BOXTED AIRFIELD) LIMITED | H29: 4.797 | I29: 5.88 | J29: 3.23 | K29: 3.23 | L29: 0 | M29: 952.82 | N29: 0.05 | O29: 0.05
A30: BPA_CO | B30: 804 | C30: 1014572578282 | G30: BRITISH PIPELINE AGENCY LTD | H30: 0.626 | I30: 511.57 | J30: 1.64 | K30: 1.64 | L30: 0 | M30: 0 | N30: 0 | O30: 0
A31: BPTLTD | B31: 771 | C31: 1023475256360 1014572502380 | G31: ZURICH ASSURANCE LTD | H31: 2.09 | I31: 178.32 | J31: 1.93 | K31: 1.93 | L31: 0 | M31: 0 | N31: 0 | O31: 0
A32: BRCHGP | B32: 525 | C32: 1050000961956 | D32: BRCHGP | E32: 457 | F32: 1050000961965 | G32: BIRCH GRAVEL PIT SOLAR | H32: 3.597 | I32: 43.72 | J32: 2.82 | K32: 2.82 | L32: 0 | M32: 2688.79 | N32: 0.05 | O32: 0.05
A33: BROGB_ | B33: 821 | C33: 1030041592510 1030041592742 1030041592974 1030041593203 | G33: INFINIS ENERGY SERVICES LIMITED | H33: 0.03 | I33: 228.45 | J33: 1.58 | K33: 1.58 | L33: 0 | M33: 0 | N33: 0 | O33: 0
A34: BROXSF | B34: 872 | C34: 1050000521610 | D34: BROXSF | E34: 747 | F34: 1030085039971 | G34: BROXTED SOLAR CO LTD | H34: 5.277 | I34: 11.19 | J34: 6.12 | K34: 6.12 | L34: 0 | M34: 2574.65 | N34: 0.05 | O34: 0.05
A35: BRTHS2 | B35: 508 | C35: 1050000782944 | D35: BRTHS2 | E35: 785 | F35: 1050000773842 | G35: BURNTHOUSE SOLAR LIMITED | H35: 0.521 | I35: 1.27 | J35: 3.12 | K35: 3.12 | L35: 0 | M35: 254.51 | N35: 0.05 | O35: 0.05
A36: BRTHSS | B36: 873 | C36: 1030083941266 | D36: BRTHSS | E36: 735 | F36: 1030083941034 | G36: TURVES SOLAR LTD | H36: 0.521 | I36: 2.82 | J36: 2.84 | K36: 2.84 | L36: 0 | M36: 252.96 | N36: 0.05 | O36: 0.05
A37: BRTHSW | B37: 874 | C37: 1030083918035 | D37: BRTHSW | E37: 748 | F37: 1030083917802 | G37: REG BURNHOUSE FARM LTD | H37: 0.521 | I37: 7.24 | J37: 2.13 | K37: 2.13 | L37: 0 | M37: 248.54 | N37: 0.05 | O37: 0.05
A38: BS_BUR | B38: 805 | C38: 1023485782314 | D38: BS_BUR | E38: 700 | F38: 1023485782546 | G38: ASSOCIATED BRITISH FOODS PLC | H38: 1.932 | I38: 62.7 | J38: 1.52 | K38: 1.52 | L38: -2.113 | M38: 448.87 | N38: 0.05 | O38: 0.05
A39: BS_WIS | B39: 806 | C39: 1014568635628 | D39: BS_WIS | E39: 719 | F39: 1023470427970 | G39: ASSOCIATED BRITISH FOODS PLC | H39: 0.997 | I39: 25.58 | J39: 1.39 | K39: 1.39 | L39: -0.997 | M39: 230.21 | N39: 0.05 | O39: 0.05
A40: BSBURY | B40: 796 | C40: 1050000914910 | D40: BSBURY | E40: 797 | F40: 1050000914900 | G40: ASSOCIATED BRITISH FOODS PLC | H40: 1.932 | I40: 23.25 | J40: 2.63 | K40: 2.63 | L40: -2.113 | M40: 232.53 | N40: 0.05 | O40: 0.05
A41: BSGBRN | B41: 507 | C41: 1050000773851 | D41: BSGBRN | E41: 784 | F41: 1050000773860 | G41: PUSH ENERGY (BASSINGBOURN) | H41: 0.932 | I41: 12.78 | J41: 2.16 | K41: 2.16 | L41: 0 | M41: 1533.09 | N41: 0.05 | O41: 0.05
A42: BTLCOM | B42: 771 | C42: 1050000169030 1014572546086 | G42: BRITISH TELECOMMUNICATIONS PLC | H42: 4.824 | I42: 178.32 | J42: 9.13 | K42: 9.13 | L42: 0 | M42: 0 | N42: 0 | O42: 0
A43: BURYLN | B43: 796 | C43: 1050000729676 | D43: BURYLN | E43: 786 | F43: 1050000729667 | G43: SE BURY LANE SOLAR LTD | H43: 0.862 | I43: 2.08 | J43: 2.37 | K43: 2.37 | L43: 0 | M43: 519.83 | N43: 0.05 | O43: 0.05
...

Sheet Annex 2a Import
A1: Note: The list of MPANs / MSIDs provided may be incomplete; the DNO reserves the right to apply the listed charges to any other MPANs / MSIDs associated with the site. Note: This table is automatically populated based on the content of the tab entitled 'Annex 2 EHV Charges'. The timebands are as shown in Annex 2.
A2: =Overview!B4& " - Effective from "&Overview!D4&" - "&Overview!E4&" EDCM import charges" -> Eastern Power Networks - Effective from 01/04/2017 - Final EDCM import charges
A4: Import Unique Identifier | B4: LLFC | C4: Import MPANs/MSIDs | D4: Name | E4: ='Annex 2 EHV charges'!H10 -> Import Super Red unit charge (p/kWh) | F4: ='Annex 2 EHV charges'!I10 -> Import fixed charge (p/day) | G4: ='Annex 2 EHV charges'!J10 -> Import capacity charge (p/kVA/day) | H4: ='Annex 2 EHV charges'!K10 -> Import exceeded capacity charge (p/kVA/day)
A5: {=IFERROR(INDEX('Annex 2 EHV charges'!$A$11:$A$218, MATCH(0, IF(ISBLANK('Annex 2 EHV charges'!$A$11:$A$218),1, COUNTIF(A$4:$A4, 'Annex 2 EHV charges'!$A$11:$A$218)), 0)),"")} -> 3VALSW | B5: =IF($A5="","",VLOOKUP($A5,'Annex 2 EHV charges'!$A:$O,2,0)) -> 771 | C5: =IF($A5="","",VLOOKUP($A5,'Annex 2 EHV charges'!$A:$O,3,0)) -> 1014569699836 | D5: =IF($A5="","",VLOOKUP($A5,'Annex 2 EHV charges'!$A:$O,7,0)) -> AFFINITY WATER LIMITED | E5: =IFERROR(IF(VLOOKUP($A5,'Annex 2 EHV charges'!$A:$O,8,FALSE)=0,"",VLOOKUP($A5,'Annex 2 EHV charges'!$A:$O,8,FALSE)),"") -> 0.717 | F5: =IFERROR(IF(VLOOKUP($A5,'Annex 2 EHV charges'!$A:$O,9,FALSE)=0,"",VLOOKUP($A5,'Annex 2 EHV charges'!$A:$O,9,FALSE)),"") -> 178.32 | G5: =IFERROR(IF(VLOOKUP($A5,'Annex 2 EHV charges'!$A:$O,10,FALSE)=0,"",VLOOKUP($A5,'Annex 2 EHV charges'!$A:$O,10,FALSE)),"") -> 5.56 | H5: =IFERROR(IF(VLOOKUP($A5,'Annex 2 EHV charges'!$A:$O,11,FALSE)=0,"",VLOOKUP($A5,'Annex 2 EHV charges'!$A:$O,11,FALSE)),"") -> 5.56
A6: {=IFERROR(INDEX('Annex 2 EHV charges'!$A$11:$A$218, MATCH(0, IF(ISBLANK('Annex 2 EHV charges'!$A$11:$A$218),1, COUNTIF(A$4:$A5, 'Annex 2 EHV charges'!$A$11:$A$218)), 0)),"")} -> ABSRSF | B6: =IF($A6="","",VLOOKUP($A6,'Annex 2 EHV charges'!$A:$O,2,0)) -> 869 | C6: =IF($A6="","",VLOOKUP($A6,'Annex 2 EHV charges'!$A:$O,3,0)) -> 1050000574685 | D6: =IF($A6="","",VLOOKUP($A6,'Annex 2 EHV charges'!$A:$O,7,0)) -> ABBOTS RIPTON SOLAR ENERGY LIMITED | E6: =IFERROR(IF(VLOOKUP($A6,'Annex 2 EHV charges'!$A:$O,8,FALSE)=0,"",VLOOKUP($A6,'Annex 2 EHV charges'!$A:$O,8,FALSE)),"") -> 1.908 | F6: =IFERROR(IF(VLOOKUP($A6,'Annex 2 EHV charges'!$A:$O,9,FALSE)=0,"",VLOOKUP($A6,'Annex 2 EHV charges'!$A:$O,9,FALSE)),"") -> 18.24 | G6: =IFERROR(IF(VLOOKUP($A6,'Annex 2 EHV charges'!$A:$O,10,FALSE)=0,"",VLOOKUP($A6,'Annex 2 EHV charges'!$A:$O,10,FALSE)),"") -> 3 | H6: =IFERROR(IF(VLOOKUP($A6,'Annex 2 EHV charges'!$A:$O,11,FALSE)=0,"",VLOOKUP($A6,'Annex 2 EHV charges'!$A:$O,11,FALSE)),"") -> 3
A7: {=IFERROR(INDEX('Annex 2 EHV charges'!$A$11:$A$218, MATCH(0, IF(ISBLANK('Annex 2 EHV charges'!$A$11:$A$218),1, COUNTIF(A$4:$A6, 'Annex 2 EHV charges'!$A$11:$A$218)), 0)),"")} -> ADBRKS | B7: =IF($A7="","",VLOOKUP($A7,'Annex 2 EHV charges'!$A:$O,2,0)) -> 771 | C7: =IF($A7="","",VLOOKUP($A7,'Annex 2 EHV charges'!$A:$O,3,0)) -> 1023529546480 | D7: =IF($A7="","",VLOOKUP($A7,'Annex 2 EHV charges'!$A:$O,7,0)) -> ADDENBROOKES NHS TRUST | E7: =IFERROR(IF(VLOOKUP($A7,'Annex 2 EHV charges'!$A:$O,8,FALSE)=0,"",VLOOKUP($A7,'Annex 2 EHV charges'!$A:$O,8,FALSE)),"") -> 1.414 | F7: =IFERROR(IF(VLOOKUP($A7,'Annex 2 EHV charges'!$A:$O,9,FALSE)=0,"",VLOOKUP($A7,'Annex 2 EHV charges'!$A:$O,9,FALSE)),"") -> 3068.14 | G7: =IFERROR(IF(VLOOKUP($A7,'Annex 2 EHV charges'!$A:$O,10,FALSE)=0,"",VLOOKUP($A7,'Annex 2 EHV charges'!$A:$O,10,FALSE)),"") -> 3.93 | H7: =IFERROR(IF(VLOOKUP($A7,'Annex 2 EHV charges'!$A:$O,11,FALSE)=0,"",VLOOKUP($A7,'Annex 2 EHV charges'!$A:$O,11,FALSE)),"") -> 3.93
A8: {=IFERROR(INDEX('Annex 2 EHV charges'!$A$11:$A$218, MATCH(0, IF(ISBLANK('Annex 2 EHV charges'!$A$11:$A$218),1, COUNTIF(A$4:$A7, 'Annex 2 EHV charges'!$A$11:$A$218)), 0)),"")} -> AIAMAN | B8: =IF($A8="","",VLOOKUP($A8,'Annex 2 EHV charges'!$A:$O,2,0)) -> 771 | C8: =IF($A8="","",VLOOKUP($A8,'Annex 2 EHV charges'!$A:$O,3,0)) -> 1014569292506 | D8: =IF($A8="","",VLOOKUP($A8,'Annex 2 EHV charges'!$A:$O,7,0)) -> A I A MANAGEMENT LTD | E8: =IFERROR(IF(VLOOKUP($A8,'Annex 2 EHV charges'!$A:$O,8,FALSE)=0,"",VLOOKUP($A8,'Annex 2 EHV charges'!$A:$O,8,FALSE)),"") -> 2.944 | F8: =IFERROR(IF(VLOOKUP($A8,'Annex 2 EHV charges'!$A:$O,9,FALSE)=0,"",VLOOKUP($A8,'Annex 2 EHV charges'!$A:$O,9,FALSE)),"") -> 8.49 | G8: =IFERROR(IF(VLOOKUP($A8,'Annex 2 EHV charges'!$A:$O,10,FALSE)=0,"",VLOOKUP($A8,'Annex 2 EHV charges'!$A:$O,10,FALSE)),"") -> 19.01 | H8: =IFERROR(IF(VLOOKUP($A8,'Annex 2 EHV charges'!$A:$O,11,FALSE)=0,"",VLOOKUP($A8,'Annex 2 EHV charges'!$A:$O,11,FALSE)),"") -> 19.01
A9: {=IFERROR(INDEX('Annex 2 EHV charges'!$A$11:$A$218, MATCH(0, IF(ISBLANK('Annex 2 EHV charges'!$A$11:$A$218),1, COUNTIF(A$4:$A8, 'Annex 2 EHV charges'!$A$11:$A$218)), 0)),"")} -> ARAMAN | B9: =IF($A9="","",VLOOKUP($A9,'Annex 2 EHV charges'!$A:$O,2,0)) -> 800 | C9: =IF($A9="","",VLOOKUP($A9,'Annex 2 EHV charges'!$A:$O,3,0)) -> 1023483097981 | D9: =IF($A9="","",VLOOKUP($A9,'Annex 2 EHV charges'!$A:$O,7,0)) -> AIRCRAFT RESEARCH ASSOCIATION LIMITED | E9: =IFERROR(IF(VLOOKUP($A9,'Annex 2 EHV charges'!$A:$O,8,FALSE)=0,"",VLOOKUP($A9,'Annex 2 EHV charges'!$A:$O,8,FALSE)),"") -> 0.111 | F9: =IFERROR(IF(VLOOKUP($A9,'Annex 2 EHV charges'!$A:$O,9,FALSE)=0,"",VLOOKUP($A9,'Annex 2 EHV charges'!$A:$O,9,FALSE)),"") -> 6644.17 | G9: =IFERROR(IF(VLOOKUP($A9,'Annex 2 EHV charges'!$A:$O,10,FALSE)=0,"",VLOOKUP($A9,'Annex 2 EHV charges'!$A:$O,10,FALSE)),"") -> 0.95 | H9: =IFERROR(IF(VLOOKUP($A9,'Annex 2 EHV charges'!$A:$O,11,FALSE)=0,"",VLOOKUP($A9,'Annex 2 EHV charges'!$A:$O,11,FALSE)),"") -> 0.95
A10: {=IFERROR(INDEX('Annex 2 EHV charges'!$A$11:$A$218, MATCH(0, IF(ISBLANK('Annex 2 EHV charges'!$A$11:$A$218),1, COUNTIF(A$4:$A9, 'Annex 2 EHV charges'!$A$11:$A$218)), 0)),"")} -> ARLAFD | B10: =IF($A10="","",VLOOKUP($A10,'Annex 2 EHV charges'!$A:$O,2,0)) -> 771 | C10: =IF($A10="","",VLOOKUP($A10,'Annex 2 EHV charges'!$A:$O,3,0)) -> 1030081553176 1030081553404 | D10: =IF($A10="","",VLOOKUP($A10,'Annex 2 EHV charges'!$A:$O,7,0)) -> ARLA FOODS LIMITED | E10: =IFERROR(IF(VLOOKUP($A10,'Annex 2 EHV charges'!$A:$O,8,FALSE)=0,"",VLOOKUP($A10,'Annex 2 EHV charges'!$A:$O,8,FALSE)),"") -> 4.172 | F10: =IFERROR(IF(VLOOKUP($A10,'Annex 2 EHV charges'!$A:$O,9,FALSE)=0,"",VLOOKUP($A10,'Annex 2 EHV charges'!$A:$O,9,FALSE)),"") -> 3283.78 | G10: =IFERROR(IF(VLOOKUP($A10,'Annex 2 EHV charges'!$A:$O,10,FALSE)=0,"",VLOOKUP($A10,'Annex 2 EHV charges'!$A:$O,10,FALSE)),"") -> 1.78 | H10: =IFERROR(IF(VLOOKUP($A10,'Annex 2 EHV charges'!$A:$O,11,FALSE)=0,"",VLOOKUP($A10,'Annex 2 EHV charges'!$A:$O,11,FALSE)),"") -> 1.78
A11: {=IFERROR(INDEX('Annex 2 EHV charges'!$A$11:$A$218, MATCH(0, IF(ISBLANK('Annex 2 EHV charges'!$A$11:$A$218),1, COUNTIF(A$4:$A10, 'Annex 2 EHV charges'!$A$11:$A$218)), 0)),"")} -> ASTONC | B11: =IF($A11="","",VLOOKUP($A11,'Annex 2 EHV charges'!$A:$O,2,0)) -> 503 | C11: =IF($A11="","",VLOOKUP($A11,'Annex 2 EHV charges'!$A:$O,3,0)) -> 1050000834246 | D11: =IF($A11="","",VLOOKUP($A11,'Annex 2 EHV charges'!$A:$O,7,0)) -> ASTON CLINTON | E11: =IFERROR(IF(VLOOKUP($A11,'Annex 2 EHV charges'!$A:$O,8,FALSE)=0,"",VLOOKUP($A11,'Annex 2 EHV charges'!$A:$O,8,FALSE)),"") -> 5.981 | F11: =IFERROR(IF(VLOOKUP($A11,'Annex 2 EHV charges'!$A:$O,9,FALSE)=0,"",VLOOKUP($A11,'Annex 2 EHV charges'!$A:$O,9,FALSE)),"") -> 2.58 | G11: =IFERROR(IF(VLOOKUP($A11,'Annex 2 EHV charges'!$A:$O,10,FALSE)=0,"",VLOOKUP($A11,'Annex 2 EHV charges'!$A:$O,10,FALSE)),"") -> 3.14 | H11: =IFERROR(IF(VLOOKUP($A11,'Annex 2 EHV charges'!$A:$O,11,FALSE)=0,"",VLOOKUP($A11,'Annex 2 EHV charges'!$A:$O,11,FALSE)),"") -> 3.14
A12: {=IFERROR(INDEX('Annex 2 EHV charges'!$A$11:$A$218, MATCH(0, IF(ISBLANK('Annex 2 EHV charges'!$A$11:$A$218),1, COUNTIF(A$4:$A11, 'Annex 2 EHV charges'!$A$11:$A$218)), 0)),"")} -> AVENUE | B12: =IF($A12="","",VLOOKUP($A12,'Annex 2 EHV charges'!$A:$O,2,0)) -> 504 | C12: =IF($A12="","",VLOOKUP($A12,'Annex 2 EHV charges'!$A:$O,3,0)) -> 1050000774970 | D12: =IF($A12="","",VLOOKUP($A12,'Annex 2 EHV charges'!$A:$O,7,0)) -> LIGHTSOURCE SPV 15 LIMITED | E12: =IFERROR(IF(VLOOKUP($A12,'Annex 2 EHV charges'!$A:$O,8,FALSE)=0,"",VLOOKUP($A12,'Annex 2 EHV charges'!$A:$O,8,FALSE)),"") -> 0.064 | F12: =IFERROR(IF(VLOOKUP($A12,'Annex 2 EHV charges'!$A:$O,9,FALSE)=0,"",VLOOKUP($A12,'Annex 2 EHV charges'!$A:$O,9,FALSE)),"") -> 17.15 | G12: =IFERROR(IF(VLOOKUP($A12,'Annex 2 EHV charges'!$A:$O,10,FALSE)=0,"",VLOOKUP($A12,'Annex 2 EHV charges'!$A:$O,10,FALSE)),"") -> 4.11 | H12: =IFERROR(IF(VLOOKUP($A12,'Annex 2 EHV charges'!$A:$O,11,FALSE)=0,"",VLOOKUP($A12,'Annex 2 EHV charges'!$A:$O,11,FALSE)),"") -> 4.11
A13: {=IFERROR(INDEX('Annex 2 EHV charges'!$A$11:$A$218, MATCH(0, IF(ISBLANK('Annex 2 EHV charges'!$A$11:$A$218),1, COUNTIF(A$4:$A12, 'Annex 2 EHV charges'!$A$11:$A$218)), 0)),"")} -> AW_GRA | B13: =IF($A13="","",VLOOKUP($A13,'Annex 2 EHV charges'!$A:$O,2,0)) -> 771 | C13: =IF($A13="","",VLOOKUP($A13,'Annex 2 EHV charges'!$A:$O,3,0)) -> 1023477037942 1014571445536 | D13: =IF($A13="","",VLOOKUP($A13,'Annex 2 EHV charges'!$A:$O,7,0)) -> ANGLIAN WATER SERVICES | E13: =IFERROR(IF(VLOOKUP($A13,'Annex 2 EHV charges'!$A:$O,8,FALSE)=0,"",VLOOKUP($A13,'Annex 2 EHV charges'!$A:$O,8,FALSE)),"") -> 2.419 | F13: =IFERROR(IF(VLOOKUP($A13,'Annex 2 EHV charges'!$A:$O,9,FALSE)=0,"",VLOOKUP($A13,'Annex 2 EHV charges'!$A:$O,9,FALSE)),"") -> 178.32 | G13: =IFERROR(IF(VLOOKUP($A13,'Annex 2 EHV charges'!$A:$O,10,FALSE)=0,"",VLOOKUP($A13,'Annex 2 EHV charges'!$A:$O,10,FALSE)),"") -> 6.81 | H13: =IFERROR(IF(VLOOKUP($A13,'Annex 2 EHV charges'!$A:$O,11,FALSE)=0,"",VLOOKUP($A13,'Annex 2 EHV charges'!$A:$O,11,FALSE)),"") -> 6.81
A14: {=IFERROR(INDEX('Annex 2 EHV charges'!$A$11:$A$218, MATCH(0, IF(ISBLANK('Annex 2 EHV charges'!$A$11:$A$218),1, COUNTIF(A$4:$A13, 'Annex 2 EHV charges'!$A$11:$A$218)), 0)),"")} -> AWOUSE | B14: =IF($A14="","",VLOOKUP($A14,'Annex 2 EHV charges'!$A:$O,2,0)) -> 771 | C14: =IF($A14="","",VLOOKUP($A14,'Annex 2 EHV charges'!$A:$O,3,0)) -> 1023475403798 1014571965793 | D14: =IF($A14="","",VLOOKUP($A14,'Annex 2 EHV charges'!$A:$O,7,0)) -> ANGLIAN WATER SERVICES | E14: =IFERROR(IF(VLOOKUP($A14,'Annex 2 EHV charges'!$A:$O,8,FALSE)=0,"",VLOOKUP($A14,'Annex 2 EHV charges'!$A:$O,8,FALSE)),"") -> 2.605 | F14: =IFERROR(IF(VLOOKUP($A14,'Annex 2 EHV charges'!$A:$O,9,FALSE)=0,"",VLOOKUP($A14,'Annex 2 EHV charges'!$A:$O,9,FALSE)),"") -> 178.32 | G14: =IFERROR(IF(VLOOKUP($A14,'Annex 2 EHV charges'!$A:$O,10,FALSE)=0,"",VLOOKUP($A14,'Annex 2 EHV charges'!$A:$O,10,FALSE)),"") -> 4.15 | H14: =IFERROR(IF(VLOOKUP($A14,'Annex 2 EHV charges'!$A:$O,11,FALSE)=0,"",VLOOKUP($A14,'Annex 2 EHV charges'!$A:$O,11,FALSE)),"") -> 4.15
A15: {=IFERROR(INDEX('Annex 2 EHV charges'!$A$11:$A$218, MATCH(0, IF(ISBLANK('Annex 2 EHV charges'!$A$11:$A$218),1, COUNTIF(A$4:$A14, 'Annex 2 EHV charges'!$A$11:$A$218)), 0)),"")} -> BARNFM | B15: =IF($A15="","",VLOOKUP($A15,'Annex 2 EHV charges'!$A:$O,2,0)) -> 796 | C15: =IF($A15="","",VLOOKUP($A15,'Annex 2 EHV charges'!$A:$O,3,0)) -> 1050000774999 | D15: =IF($A15="","",VLOOKUP($A15,'Annex 2 EHV charges'!$A:$O,7,0)) -> BARN FARM SOLAR | E15: =IFERROR(IF(VLOOKUP($A15,'Annex 2 EHV charges'!$A:$O,8,FALSE)=0,"",VLOOKUP($A15,'Annex 2 EHV charges'!$A:$O,8,FALSE)),"") -> 4.001 | F15: =IFERROR(IF(VLOOKUP($A15,'Annex 2 EHV charges'!$A:$O,9,FALSE)=0,"",VLOOKUP($A15,'Annex 2 EHV charges'!$A:$O,9,FALSE)),"") -> 44.65 | G15: =IFERROR(IF(VLOOKUP($A15,'Annex 2 EHV charges'!$A:$O,10,FALSE)=0,"",VLOOKUP($A15,'Annex 2 EHV charges'!$A:$O,10,FALSE)),"") -> 6.69 | H15: =IFERROR(IF(VLOOKUP($A15,'Annex 2 EHV charges'!$A:$O,11,FALSE)=0,"",VLOOKUP($A15,'Annex 2 EHV charges'!$A:$O,11,FALSE)),"") -> 6.69
A16: {=IFERROR(INDEX('Annex 2 EHV charges'!$A$11:$A$218, MATCH(0, IF(ISBLANK('Annex 2 EHV charges'!$A$11:$A$218),1, COUNTIF(A$4:$A15, 'Annex 2 EHV charges'!$A$11:$A$218)), 0)),"")} -> BAYFMS | B16: =IF($A16="","",VLOOKUP($A16,'Annex 2 EHV charges'!$A:$O,2,0)) -> 870 | C16: =IF($A16="","",VLOOKUP($A16,'Annex 2 EHV charges'!$A:$O,3,0)) -> 1050000579318 | D16: =IF($A16="","",VLOOKUP($A16,'Annex 2 EHV charges'!$A:$O,7,0)) -> BAY FARM IMPORT | E16: =IFERROR(IF(VLOOKUP($A16,'Annex 2 EHV charges'!$A:$O,8,FALSE)=0,"",VLOOKUP($A16,'Annex 2 EHV charges'!$A:$O,8,FALSE)),"") -> 2.292 | F16: =IFERROR(IF(VLOOKUP($A16,'Annex 2 EHV charges'!$A:$O,9,FALSE)=0,"",VLOOKUP($A16,'Annex 2 EHV charges'!$A:$O,9,FALSE)),"") -> 31.89 | G16: =IFERROR(IF(VLOOKUP($A16,'Annex 2 EHV charges'!$A:$O,10,FALSE)=0,"",VLOOKUP($A16,'Annex 2 EHV charges'!$A:$O,10,FALSE)),"") -> 4.26 | H16: =IFERROR(IF(VLOOKUP($A16,'Annex 2 EHV charges'!$A:$O,11,FALSE)=0,"",VLOOKUP($A16,'Annex 2 EHV charges'!$A:$O,11,FALSE)),"") -> 4.26
... A212: {=IFERROR(INDEX('Annex 2 EHV charges'!$A$11:$A$218, MATCH(0, IF(ISBLANK('Annex 2 EHV charges'!$A$11:$A$218),1, COUNTIF(A$4:$A211, 'Annex 2 EHV charges'!$A$11:$A$218)), 0)),"")} -> WWYNDC | B212: =IF($A212="","",VLOOKUP($A212,'Annex 2 EHV charges'!$A:$O,2,0)) -> 771 | C212: =IF($A212="","",VLOOKUP($A212,'Annex 2 EHV charges'!$A:$O,3,0)) -> 1030059750786 1030059751015 | D212: =IF($A212="","",VLOOKUP($A212,'Annex 2 EHV charges'!$A:$O,7,0)) -> COLT TECHNOLOGY SERVICES | E212: =IFERROR(IF(VLOOKUP($A212,'Annex 2 EHV charges'!$A:$O,8,FALSE)=0,"",VLOOKUP($A212,'Annex 2 EHV charges'!$A:$O,8,FALSE)),"") -> 0.04 | F212: =IFERROR(IF(VLOOKUP($A212,'Annex 2 EHV charges'!$A:$O,9,FALSE)=0,"",VLOOKUP($A212,'Annex 2 EHV charges'!$A:$O,9,FALSE)),"") -> 19880.33 | G212: =IFERROR(IF(VLOOKUP($A212,'Annex 2 EHV charges'!$A:$O,10,FALSE)=0,"",VLOOKUP($A212,'Annex 2 EHV charges'!$A:$O,10,FALSE)),"") -> 3.97 | H212: =IFERROR(IF(VLOOKUP($A212,'Annex 2 EHV charges'!$A:$O,11,FALSE)=0,"",VLOOKUP($A212,'Annex 2 EHV charges'!$A:$O,11,FALSE)),"") -> 3.97

Sheet Annex 2b Export
A1: Note: The list of MPANs / MSIDs provided may be incomplete; the DNO reserves the right to apply the listed charges to any other MPANs / MSIDs associated with the site. Note: This table is automatically populated based on the content of the tab entitled 'Annex 2 EHV Charges'. The timebands are as shown in Annex 2.
A2: =Overview!B4& " - Effective from "&Overview!D4&" - "&Overview!E4&" EDCM export charges" -> Eastern Power Networks - Effective from 01/04/2017 - Final EDCM export charges
A4: Export Unique Identifier | B4: LLFC | C4: Export MPANs/MSIDs | D4: Name | E4: ='Annex 2 EHV charges'!L10 -> Export Super Red unit charge (p/kWh) | F4: ='Annex 2 EHV charges'!M10 -> Export fixed charge (p/day) | G4: ='Annex 2 EHV charges'!N10 -> Export capacity charge (p/kVA/day) | H4: ='Annex 2 EHV charges'!O10 -> Export exceeded capacity charge (p/kVA/day)
A5: {=IFERROR(INDEX('Annex 2 EHV charges'!$D$11:$D$218, MATCH(0, IF(ISBLANK('Annex 2 EHV charges'!$D$11:$D$218),1, COUNTIF(A$4:$A4, 'Annex 2 EHV charges'!$D$11:$D$218)), 0)),"")} -> ABSRSF | B5: =IF($A5="","",VLOOKUP($A5,'Annex 2 EHV charges'!$D:$O,2,0)) -> 744 | C5: =IF($A5="","",VLOOKUP($A5,'Annex 2 EHV charges'!$D:$O,3,0)) -> 1050000574694 | D5: =IF($A5="","",VLOOKUP($A5,'Annex 2 EHV charges'!$D:$O,4,0)) -> ABBOTS RIPTON SOLAR ENERGY LIMITED | E5: =IFERROR(IF(VLOOKUP($A5,'Annex 2 EHV charges'!$D:$O,9,FALSE)=0,"",VLOOKUP($A5,'Annex 2 EHV charges'!$D:$O,9,FALSE)),"") | F5: =IFERROR(IF(VLOOKUP($A5,'Annex 2 EHV charges'!$D:$O,10,FALSE)=0,"",VLOOKUP($A5,'Annex 2 EHV charges'!$D:$O,10,FALSE)),"") -> 3647.93 | G5: =IFERROR(IF(VLOOKUP($A5,'Annex 2 EHV charges'!$D:$O,11,FALSE)=0,"",VLOOKUP($A5,'Annex 2 EHV charges'!$D:$O,11,FALSE)),"") -> 0.05 | H5: =IFERROR(IF(VLOOKUP($A5,'Annex 2 EHV charges'!$D:$O,12,FALSE)=0,"",VLOOKUP($A5,'Annex 2 EHV charges'!$D:$O,12,FALSE)),"") -> 0.05
A6: {=IFERROR(INDEX('Annex 2 EHV charges'!$D$11:$D$218, MATCH(0, IF(ISBLANK('Annex 2 EHV charges'!$D$11:$D$218),1, COUNTIF(A$4:$A5, 'Annex 2 EHV charges'!$D$11:$D$218)), 0)),"")} -> AIAMAN | B6: =IF($A6="","",VLOOKUP($A6,'Annex 2 EHV charges'!$D:$O,2,0)) -> 792 | C6: =IF($A6="","",VLOOKUP($A6,'Annex 2 EHV charges'!$D:$O,3,0)) -> 1030054607984 | D6: =IF($A6="","",VLOOKUP($A6,'Annex 2 EHV charges'!$D:$O,4,0)) -> A I A MANAGEMENT LTD | E6: =IFERROR(IF(VLOOKUP($A6,'Annex 2 EHV charges'!$D:$O,9,FALSE)=0,"",VLOOKUP($A6,'Annex 2 EHV charges'!$D:$O,9,FALSE)),"") -> -2.844 | F6: =IFERROR(IF(VLOOKUP($A6,'Annex 2 EHV charges'!$D:$O,10,FALSE)=0,"",VLOOKUP($A6,'Annex 2 EHV charges'!$D:$O,10,FALSE)),"") -> 169.83 | G6: =IFERROR(IF(VLOOKUP($A6,'Annex 2 EHV charges'!$D:$O,11,FALSE)=0,"",VLOOKUP($A6,'Annex 2 EHV charges'!$D:$O,11,FALSE)),"") -> 0.05 | H6: =IFERROR(IF(VLOOKUP($A6,'Annex 2 EHV charges'!$D:$O,12,FALSE)=0,"",VLOOKUP($A6,'Annex 2 EHV charges'!$D:$O,12,FALSE)),"") -> 0.05
A7: {=IFERROR(INDEX('Annex 2 EHV charges'!$D$11:$D$218, MATCH(0, IF(ISBLANK('Annex 2 EHV charges'!$D$11:$D$218),1, COUNTIF(A$4:$A6, 'Annex 2 EHV charges'!$D$11:$D$218)), 0)),"")} -> ARLAFD | B7: =IF($A7="","",VLOOKUP($A7,'Annex 2 EHV charges'!$D:$O,2,0)) -> 792 | C7: =IF($A7="","",VLOOKUP($A7,'Annex 2 EHV charges'!$D:$O,3,0)) -> 1030085114723 1030085114955 | D7: =IF($A7="","",VLOOKUP($A7,'Annex 2 EHV charges'!$D:$O,4,0)) -> ARLA FOODS LIMITED | E7: =IFERROR(IF(VLOOKUP($A7,'Annex 2 EHV charges'!$D:$O,9,FALSE)=0,"",VLOOKUP($A7,'Annex 2 EHV charges'!$D:$O,9,FALSE)),"") | F7: =IFERROR(IF(VLOOKUP($A7,'Annex 2 EHV charges'!$D:$O,10,FALSE)=0,"",VLOOKUP($A7,'Annex 2 EHV charges'!$D:$O,10,FALSE)),"") -> 1094.59 | G7: =IFERROR(IF(VLOOKUP($A7,'Annex 2 EHV charges'!$D:$O,11,FALSE)=0,"",VLOOKUP($A7,'Annex 2 EHV charges'!$D:$O,11,FALSE)),"") -> 0.05 | H7: =IFERROR(IF(VLOOKUP($A7,'Annex 2 EHV charges'!$D:$O,12,FALSE)=0,"",VLOOKUP($A7,'Annex 2 EHV charges'!$D:$O,12,FALSE)),"") -> 0.05
A8: {=IFERROR(INDEX('Annex 2 EHV charges'!$D$11:$D$218, MATCH(0, IF(ISBLANK('Annex 2 EHV charges'!$D$11:$D$218),1, COUNTIF(A$4:$A7, 'Annex 2 EHV charges'!$D$11:$D$218)), 0)),"")} -> ASTONC | B8: =IF($A8="","",VLOOKUP($A8,'Annex 2 EHV charges'!$D:$O,2,0)) -> 780 | C8: =IF($A8="","",VLOOKUP($A8,'Annex 2 EHV charges'!$D:$O,3,0)) -> 1050000834255 | D8: =IF($A8="","",VLOOKUP($A8,'Annex 2 EHV charges'!$D:$O,4,0)) -> ASTON CLINTON | E8: =IFERROR(IF(VLOOKUP($A8,'Annex 2 EHV charges'!$D:$O,9,FALSE)=0,"",VLOOKUP($A8,'Annex 2 EHV charges'!$D:$O,9,FALSE)),"") | F8: =IFERROR(IF(VLOOKUP($A8,'Annex 2 EHV charges'!$D:$O,10,FALSE)=0,"",VLOOKUP($A8,'Annex 2 EHV charges'!$D:$O,10,FALSE)),"") -> 515.71 | G8: =IFERROR(IF(VLOOKUP($A8,'Annex 2 EHV charges'!$D:$O,11,FALSE)=0,"",VLOOKUP($A8,'Annex 2 EHV charges'!$D:$O,11,FALSE)),"") -> 0.05 | H8: =IFERROR(IF(VLOOKUP($A8,'Annex 2 EHV charges'!$D:$O,12,FALSE)=0,"",VLOOKUP($A8,'Annex 2 EHV charges'!$D:$O,12,FALSE)),"") -> 0.05
A9: {=IFERROR(INDEX('Annex 2 EHV charges'!$D$11:$D$218, MATCH(0, IF(ISBLANK('Annex 2 EHV charges'!$D$11:$D$218),1, COUNTIF(A$4:$A8, 'Annex 2 EHV charges'!$D$11:$D$218)), 0)),"")} -> AVENUE | B9: =IF($A9="","",VLOOKUP($A9,'Annex 2 EHV charges'!$D:$O,2,0)) -> 781 | C9: =IF($A9="","",VLOOKUP($A9,'Annex 2 EHV charges'!$D:$O,3,0)) -> 1050000774980 | D9: =IF($A9="","",VLOOKUP($A9,'Annex 2 EHV charges'!$D:$O,4,0)) -> LIGHTSOURCE SPV 15 LIMITED | E9: =IFERROR(IF(VLOOKUP($A9,'Annex 2 EHV charges'!$D:$O,9,FALSE)=0,"",VLOOKUP($A9,'Annex 2 EHV charges'!$D:$O,9,FALSE)),"") | F9: =IFERROR(IF(VLOOKUP($A9,'Annex 2 EHV charges'!$D:$O,10,FALSE)=0,"",VLOOKUP($A9,'Annex 2 EHV charges'!$D:$O,10,FALSE)),"") -> 1114.99 | G9: =IFERROR(IF(VLOOKUP($A9,'Annex 2 EHV charges'!$D:$O,11,FALSE)=0,"",VLOOKUP($A9,'Annex 2 EHV charges'!$D:$O,11,FALSE)),"") -> 0.05 | H9: =IFERROR(IF(VLOOKUP($A9,'Annex 2 EHV charges'!$D:$O,12,FALSE)=0,"",VLOOKUP($A9,'Annex 2 EHV charges'!$D:$O,12,FALSE)),"") -> 0.05
A10: {=IFERROR(INDEX('Annex 2 EHV charges'!$D$11:$D$218, MATCH(0, IF(ISBLANK('Annex 2 EHV charges'!$D$11:$D$218),1, COUNTIF(A$4:$A9, 'Annex 2 EHV charges'!$D$11:$D$218)), 0)),"")} -> BARNFM | B10: =IF($A10="","",VLOOKUP($A10,'Annex 2 EHV charges'!$D:$O,2,0)) -> 797 | C10: =IF($A10="","",VLOOKUP($A10,'Annex 2 EHV charges'!$D:$O,3,0)) -> 1050000775005 | D10: =IF($A10="","",VLOOKUP($A10,'Annex 2 EHV charges'!$D:$O,4,0)) -> BARN FARM SOLAR | E10: =IFERROR(IF(VLOOKUP($A10,'Annex 2 EHV charges'!$D:$O,9,FALSE)=0,"",VLOOKUP($A10,'Annex 2 EHV charges'!$D:$O,9,FALSE)),"") | F10: =IFERROR(IF(VLOOKUP($A10,'Annex 2 EHV charges'!$D:$O,10,FALSE)=0,"",VLOOKUP($A10,'Annex 2 EHV charges'!$D:$O,10,FALSE)),"") -> 1875.31 | G10: =IFERROR(IF(VLOOKUP($A10,'Annex 2 EHV charges'!$D:$O,11,FALSE)=0,"",VLOOKUP($A10,'Annex 2 EHV charges'!$D:$O,11,FALSE)),"") -> 0.05 | H10: =IFERROR(IF(VLOOKUP($A10,'Annex 2 EHV charges'!$D:$O,12,FALSE)=0,"",VLOOKUP($A10,'Annex 2 EHV charges'!$D:$O,12,FALSE)),"") -> 0.05
A11: {=IFERROR(INDEX('Annex 2 EHV charges'!$D$11:$D$218, MATCH(0, IF(ISBLANK('Annex 2 EHV charges'!$D$11:$D$218),1, COUNTIF(A$4:$A10, 'Annex 2 EHV charges'!$D$11:$D$218)), 0)),"")} -> BAYFMS | B11: =IF($A11="","",VLOOKUP($A11,'Annex 2 EHV charges'!$D:$O,2,0)) -> 745 | C11: =IF($A11="","",VLOOKUP($A11,'Annex 2 EHV charges'!$D:$O,3,0)) -> 1050000579327 | D11: =IF($A11="","",VLOOKUP($A11,'Annex 2 EHV charges'!$D:$O,4,0)) -> BAY FARM IMPORT | E11: =IFERROR(IF(VLOOKUP($A11,'Annex 2 EHV charges'!$D:$O,9,FALSE)=0,"",VLOOKUP($A11,'Annex 2 EHV charges'!$D:$O,9,FALSE)),"") | F11: =IFERROR(IF(VLOOKUP($A11,'Annex 2 EHV charges'!$D:$O,10,FALSE)=0,"",VLOOKUP($A11,'Annex 2 EHV charges'!$D:$O,10,FALSE)),"") -> 2551.06 | G11: =IFERROR(IF(VLOOKUP($A11,'Annex 2 EHV charges'!$D:$O,11,FALSE)=0,"",VLOOKUP($A11,'Annex 2 EHV charges'!$D:$O,11,FALSE)),"") -> 0.05 | H11: =IFERROR(IF(VLOOKUP($A11,'Annex 2 EHV charges'!$D:$O,12,FALSE)=0,"",VLOOKUP($A11,'Annex 2 EHV charges'!$D:$O,12,FALSE)),"") -> 0.05
A12: {=IFERROR(INDEX('Annex 2 EHV charges'!$D$11:$D$218, MATCH(0, IF(ISBLANK('Annex 2 EHV charges'!$D$11:$D$218),1, COUNTIF(A$4:$A11, 'Annex 2 EHV charges'!$D$11:$D$218)), 0)),"")} -> BDGHSE | B12: =IF($A12="","",VLOOKUP($A12,'Annex 2 EHV charges'!$D:$O,2,0)) -> 782 | C12: =IF($A12="","",VLOOKUP($A12,'Annex 2 EHV charges'!$D:$O,3,0)) -> 1050000669539 | D12: =IF($A12="","",VLOOKUP($A12,'Annex 2 EHV charges'!$D:$O,4,0)) -> BOARDINGHOUSE WINDFARM LIMITED | E12: =IFERROR(IF(VLOOKUP($A12,'Annex 2 EHV charges'!$D:$O,9,FALSE)=0,"",VLOOKUP($A12,'Annex 2 EHV charges'!$D:$O,9,FALSE)),"") | F12: =IFERROR(IF(VLOOKUP($A12,'Annex 2 EHV charges'!$D:$O,10,FALSE)=0,"",VLOOKUP($A12,'Annex 2 EHV charges'!$D:$O,10,FALSE)),"") -> 1052.2 | G12: =IFERROR(IF(VLOOKUP($A12,'Annex 2 EHV charges'!$D:$O,11,FALSE)=0,"",VLOOKUP($A12,'Annex 2 EHV charges'!$D:$O,11,FALSE)),"") -> 0.05 | H12: =IFERROR(IF(VLOOKUP($A12,'Annex 2 EHV charges'!$D:$O,12,FALSE)=0,"",VLOOKUP($A12,'Annex 2 EHV charges'!$D:$O,12,FALSE)),"") -> 0.05
A13: {=IFERROR(INDEX('Annex 2 EHV charges'!$D$11:$D$218, MATCH(0, IF(ISBLANK('Annex 2 EHV charges'!$D$11:$D$218),1, COUNTIF(A$4:$A12, 'Annex 2 EHV charges'!$D$11:$D$218)), 0)),"")} -> BDWLWF | B13: =IF($A13="","",VLOOKUP($A13,'Annex 2 EHV charges'!$D:$O,2,0)) -> 734 | C13: =IF($A13="","",VLOOKUP($A13,'Annex 2 EHV charges'!$D:$O,3,0)) -> 1030082700647 | D13: =IF($A13="","",VLOOKUP($A13,'Annex 2 EHV charges'!$D:$O,4,0)) -> RWE INNOGY UK LIMITED | E13: =IFERROR(IF(VLOOKUP($A13,'Annex 2 EHV charges'!$D:$O,9,FALSE)=0,"",VLOOKUP($A13,'Annex 2 EHV charges'!$D:$O,9,FALSE)),"") | F13: =IFERROR(IF(VLOOKUP($A13,'Annex 2 EHV charges'!$D:$O,10,FALSE)=0,"",VLOOKUP($A13,'Annex 2 EHV charges'!$D:$O,10,FALSE)),"") -> 3938.04 | G13: =IFERROR(IF(VLOOKUP($A13,'Annex 2 EHV charges'!$D:$O,11,FALSE)=0,"",VLOOKUP($A13,'Annex 2 EHV charges'!$D:$O,11,FALSE)),"") -> 0.05 | H13: =IFERROR(IF(VLOOKUP($A13,'Annex 2 EHV charges'!$D:$O,12,FALSE)=0,"",VLOOKUP($A13,'Annex 2 EHV charges'!$D:$O,12,FALSE)),"") -> 0.05
A14: {=IFERROR(INDEX('Annex 2 EHV charges'!$D$11:$D$218, MATCH(0, IF(ISBLANK('Annex 2 EHV charges'!$D$11:$D$218),1, COUNTIF(A$4:$A13, 'Annex 2 EHV charges'!$D$11:$D$218)), 0)),"")} -> BGWDWF | B14: =IF($A14="","",VLOOKUP($A14,'Annex 2 EHV charges'!$D:$O,2,0)) -> 746 | C14: =IF($A14="","",VLOOKUP($A14,'Annex 2 EHV charges'!$D:$O,3,0)) -> 1030083931142 | D14: =IF($A14="","",VLOOKUP($A14,'Annex 2 EHV charges'!$D:$O,4,0)) -> BIGGLESWADE WIND FARM LIMITED | E14: =IFERROR(IF(VLOOKUP($A14,'Annex 2 EHV charges'!$D:$O,9,FALSE)=0,"",VLOOKUP($A14,'Annex 2 EHV charges'!$D:$O,9,FALSE)),"") | F14: =IFERROR(IF(VLOOKUP($A14,'Annex 2 EHV charges'!$D:$O,10,FALSE)=0,"",VLOOKUP($A14,'Annex 2 EHV charges'!$D:$O,10,FALSE)),"") -> 278.25 | G14: =IFERROR(IF(VLOOKUP($A14,'Annex 2 EHV charges'!$D:$O,11,FALSE)=0,"",VLOOKUP($A14,'Annex 2 EHV charges'!$D:$O,11,FALSE)),"") -> 0.05 | H14: =IFERROR(IF(VLOOKUP($A14,'Annex 2 EHV charges'!$D:$O,12,FALSE)=0,"",VLOOKUP($A14,'Annex 2 EHV charges'!$D:$O,12,FALSE)),"") -> 0.05
A15: {=IFERROR(INDEX('Annex 2 EHV charges'!$D$11:$D$218, MATCH(0, IF(ISBLANK('Annex 2 EHV charges'!$D$11:$D$218),1, COUNTIF(A$4:$A14, 'Annex 2 EHV charges'!$D$11:$D$218)), 0)),"")} -> BLGTSF | B15: =IF($A15="","",VLOOKUP($A15,'Annex 2 EHV charges'!$D:$O,2,0)) -> 466 | C15: =IF($A15="","",VLOOKUP($A15,'Annex 2 EHV charges'!$D:$O,3,0)) -> 1050000769048 | D15: =IF($A15="","",VLOOKUP($A15,'Annex 2 EHV charges'!$D:$O,4,0)) -> SOLAR CENTURY | E15: =IFERROR(IF(VLOOKUP($A15,'Annex 2 EHV charges'!$D:$O,9,FALSE)=0,"",VLOOKUP($A15,'Annex 2 EHV charges'!$D:$O,9,FALSE)),"") | F15: =IFERROR(IF(VLOOKUP($A15,'Annex 2 EHV charges'!$D:$O,10,FALSE)=0,"",VLOOKUP($A15,'Annex 2 EHV charges'!$D:$O,10,FALSE)),"") -> 1117.59 | G15: =IFERROR(IF(VLOOKUP($A15,'Annex 2 EHV charges'!$D:$O,11,FALSE)=0,"",VLOOKUP($A15,'Annex 2 EHV charges'!$D:$O,11,FALSE)),"") -> 0.05 | H15: =IFERROR(IF(VLOOKUP($A15,'Annex 2 EHV charges'!$D:$O,12,FALSE)=0,"",VLOOKUP($A15,'Annex 2 EHV charges'!$D:$O,12,FALSE)),"") -> 0.05
A16: {=IFERROR(INDEX('Annex 2 EHV charges'!$D$11:$D$218, MATCH(0, IF(ISBLANK('Annex 2 EHV charges'!$D$11:$D$218),1, COUNTIF(A$4:$A15, 'Annex 2 EHV charges'!$D$11:$D$218)), 0)),"")} -> BOXTED | B16: =IF($A16="","",VLOOKUP($A16,'Annex 2 EHV charges'!$D:$O,2,0)) -> 783 | C16: =IF($A16="","",VLOOKUP($A16,'Annex 2 EHV charges'!$D:$O,3,0)) -> 1050000774289 | D16: =IF($A16="","",VLOOKUP($A16,'Annex 2 EHV charges'!$D:$O,4,0)) -> PUSH ENERGY (BOXTED AIRFIELD) LIMITED | E16: =IFERROR(IF(VLOOKUP($A16,'Annex 2 EHV charges'!$D:$O,9,FALSE)=0,"",VLOOKUP($A16,'Annex 2 EHV charges'!$D:$O,9,FALSE)),"") | F16: =IFERROR(IF(VLOOKUP($A16,'Annex 2 EHV charges'!$D:$O,10,FALSE)=0,"",VLOOKUP($A16,'Annex 2 EHV charges'!$D:$O,10,FALSE)),"") -> 952.82 | G16: =IFERROR(IF(VLOOKUP($A16,'Annex 2 EHV charges'!$D:$O,11,FALSE)=0,"",VLOOKUP($A16,'Annex 2 EHV charges'!$D:$O,11,FALSE)),"") -> 0.05 | H16: =IFERROR(IF(VLOOKUP($A16,'Annex 2 EHV charges'!$D:$O,12,FALSE)=0,"",VLOOKUP($A16,'Annex 2 EHV charges'!$D:$O,12,FALSE)),"") -> 0.05
... A123: {=IFERROR(INDEX('Annex 2 EHV charges'!$D$11:$D$218, MATCH(0, IF(ISBLANK('Annex 2 EHV charges'!$D$11:$D$218),1, COUNTIF(A$4:$A122, 'Annex 2 EHV charges'!$D$11:$D$218)), 0)),"")} -> WSTNLV | B123: =IF($A123="","",VLOOKUP($A123,'Annex 2 EHV charges'!$D:$O,2,0)) -> 471 | C123: =IF($A123="","",VLOOKUP($A123,'Annex 2 EHV charges'!$D:$O,3,0)) -> 1050000811601 | D123: =IF($A123="","",VLOOKUP($A123,'Annex 2 EHV charges'!$D:$O,4,0)) -> WESTON LONGVILLE G1 SOLAR FARM LIMITED | E123: =IFERROR(IF(VLOOKUP($A123,'Annex 2 EHV charges'!$D:$O,9,FALSE)=0,"",VLOOKUP($A123,'Annex 2 EHV charges'!$D:$O,9,FALSE)),"") | F123: =IFERROR(IF(VLOOKUP($A123,'Annex 2 EHV charges'!$D:$O,10,FALSE)=0,"",VLOOKUP($A123,'Annex 2 EHV charges'!$D:$O,10,FALSE)),"") -> 708.76 | G123: =IFERROR(IF(VLOOKUP($A123,'Annex 2 EHV charges'!$D:$O,11,FALSE)=0,"",VLOOKUP($A123,'Annex 2 EHV charges'!$D:$O,11,FALSE)),"") -> 0.05 | H123: =IFERROR(IF(VLOOKUP($A123,'Annex 2 EHV charges'!$D:$O,12,FALSE)=0,"",VLOOKUP($A123,'Annex 2 EHV charges'!$D:$O,12,FALSE)),"") -> 0.05

Sheet Annex 3 Preserved charges
A1: Back to Overview
A2: =Overview!B4& " - Effective from "&Overview!D4&" - "&Overview!E4&" LV and HV tariffs" -> Eastern Power Networks - Effective from 01/04/2017 - Final LV and HV tariffs
A3: NHH preserved charges/additional LLFCs
B4: Closed LLFCs | C4: PCs | D4: Unit charge 1 (NHH) p/kWh | E4: Unit charge 2 (NHH) p/kWh | F4: Fixed charge p/MPAN/day
A6: Notes: | B6: =Overview!B4& " has no Preserved NHH Tariffs/Additional LLFC classes" -> Eastern Power Networks has no Preserved NHH Tariffs/Additional LLFC classes
A11: HH preserved charges/additional LLFCs
B12: Closed LLFCs | C12: PCs | D12: Red/black charge (HH) p/kWh | E12: Amber/yellow charge (HH) p/kWh | F12: Green charge (HH) p/kWh | G12: Fixed charge p/MPAN/day | H12: Capacity charge p/kVA/day | I12: Reactive power charge p/kVArh | J12: Exceeded capacity charge p/kVA/day
C13: 0
A14: Notes: | B14: =Overview!B4& " has no Preserved HH Tariffs/Additional LLFC classes" -> Eastern Power Networks has no Preserved HH Tariffs/Additional LLFC classes

Sheet Annex 4 LDNO charges
A1: Back to Overview | B1: Copy from CDCM table 3701 "Tariffs!A42:I84" and paste values into A14 | F1: Copy from EDCM table 6005 "LDNORev!B549:G683" and paste values into D57
A2: =Overview!B4& " - Effective from "&Overview!D4&" - "&Overview!E4&" LDNO tariffs" -> Eastern Power Networks - Effective from 01/04/2017 - Final LDNO tariffs
A4: Time Bands for Half Hourly Metered Properties | F4: Time Bands for Half Hourly Unmetered Properties
A5: Time periods | B5: Red Time Band | C5: Amber Time Band | D5: Green Time Band | H5: Black Time Band | I5: Yellow Time Band | J5: Green Time Band
A6: Monday to Friday (Including Bank Holidays) All Year | B6: 16:00 - 19:00 | C6: 07:00 - 16:00 19:00 - 23:00 | D6: 00:00 - 07:00 23:00 - 24:00 | F6: Monday to Friday (Including Bank Holidays) November to February Inclusive | H6: 16:00 - 19:00 | I6: 07:00 - 16:00 19:00 - 23:00 | J6: 00:00 - 07:00 23:00 - 24:00
A7: Saturday and Sunday All Year | D7: 00:00 - 24:00 | F7: Monday to Friday (Including Bank Holidays) March to October Inclusive | I7: 07:00 - 23:00 | J7: 00:00 - 07:00 23:00 - 24:00
A8: Notes | B8: All times are in UK Clock time | F8: Saturday and Sunday All Year | J8: 00:00 - 24:00
F9: Notes | H9: All times are in UK Clock time
A13: Tariff name | B13: Unique billing identifier | C13: PCs | D13: ='Annex 1 LV and HV charges'!D13 -> Unit charge 1 (NHH) or red/black charge (HH) p/kWh | E13: ='Annex 1 LV and HV charges'!E13 -> Unit charge 2 (NHH) or amber/yellow charge (HH) p/kWh | F13: ='Annex 1 LV and HV charges'!F13 -> Green charge(HH) p/kWh | G13: ='Annex 1 LV and HV charges'!G13 -> Fixed charge p/MPAN/day | H13: ='Annex 1 LV and HV charges'!H13 -> Capacity charge p/kVA/day | I13: ='Annex 1 LV and HV charges'!I13 -> Reactive power charge p/kVArh | J13: ='Annex 1 LV and HV charges'!J13 -> Exceeded capacity charge p/kVA/day
A14: LDNO LV: Domestic Unrestricted | C14: 1 | D14: 1.352 | E14: 0 | F14: 0 | G14: 3.17 | H14: 0 | I14: 0
A15: LDNO LV: Domestic Two Rate | C15: 2 | D15: 1.622 | E15: 0.02 | F15: 0 | G15: 3.17 | H15: 0 | I15: 0
A16: LDNO LV: Domestic Off Peak (related MPAN) | C16: 2 | D16: 0.062 | E16: 0 | F16: 0 | G16: 0 | H16: 0 | I16: 0
A17: LDNO LV: Small Non Domestic Unrestricted | C17: 3 | D17: 1.039 | E17: 0 | F17: 0 | G17: 3.42 | H17: 0 | I17: 0
A18: LDNO LV: Small Non Domestic Two Rate | C18: 4 | D18: 1.244 | E18: 0.02 | F18: 0 | G18: 3.42 | H18: 0 | I18: 0
A19: LDNO LV: Small Non Domestic Off Peak (related MPAN) | C19: 4 | D19: 0.122 | E19: 0 | F19: 0 | G19: 0 | H19: 0 | I19: 0
A20: LDNO LV: LV Medium Non-Domestic | C20: 5-8 | D20: 1.173 | E20: 0.016 | F20: 0 | G20: 22.28 | H20: 0 | I20: 0
A21: LDNO LV: LV Network Domestic | C21: 0 | D21: 10.324 | E21: 0.089 | F21: 0.016 | G21: 3.17 | H21: 0 | I21: 0
A22: LDNO LV: LV Network Non-Domestic Non-CT | C22: 0 | D22: 9.377 | E22: 0.081 | F22: 0.014 | G22: 3.63 | H22: 0 | I22: 0
A23: LDNO LV: LV HH Metered | C23: 0 | D23: 7.385 | E23: 0.053 | F23: 0.009 | G23: 10.06 | H23: 2.13 | I23: 0.225 | J23: =H23 -> 2.13
A24: LDNO LV: NHH UMS category A | C24: 8 | D24: 1.184 | E24: 0 | F24: 0 | G24: 0 | H24: 0 | I24: 0
A25: LDNO LV: NHH UMS category B | C25: 1 | D25: 1.762 | E25: 0 | F25: 0 | G25: 0 | H25: 0 | I25: 0
A26: LDNO LV: NHH UMS category C | C26: 1 | D26: 2.998 | E26: 0 | F26: 0 | G26: 0 | H26: 0 | I26: 0
A27: LDNO LV: NHH UMS category D | C27: 1 | D27: 0.799 | E27: 0 | F27: 0 | G27: 0 | H27: 0 | I27: 0
A28: LDNO LV: LV UMS (Pseudo HH Metered) | C28: 0 | D28: 26.839 | E28: 0.442 | F28: 0.374 | G28: 0 | H28: 0 | I28: 0
A29: LDNO LV: LV Generation NHH or Aggregate HH | C29: 8 or 0 | D29: -0.905 | E29: 0 | F29: 0 | G29: 0 | H29: 0 | I29: 0
A30: LDNO LV: LV Generation Intermittent | C30: 0 | D30: -0.905 | E30: 0 | F30: 0 | G30: 0 | H30: 0 | I30: 0.289
A31: LDNO LV: LV Generation Non-Intermittent | C31: 0 | D31: -9.684 | E31: -0.09 | F31: -0.016 | G31: 0 | H31: 0 | I31: 0.289
A32: LDNO HV: Domestic Unrestricted | C32: 1 | D32: 0.947 | E32: 0 | F32: 0 | G32: 2.22 | H32: 0 | I32: 0
A33: LDNO HV: Domestic Two Rate | C33: 2 | D33: 1.136 | E33: 0.014 | F33: 0 | G33: 2.22 | H33: 0 | I33: 0
A34: LDNO HV: Domestic Off Peak (related MPAN) | C34: 2 | D34: 0.044 | E34: 0 | F34: 0 | G34: 0 | H34: 0 | I34: 0
A35: LDNO HV: Small Non Domestic Unrestricted | C35: 3 | D35: 0.728 | E35: 0 | F35: 0 | G35: 2.39 | H35: 0 | I35: 0
A36: LDNO HV: Small Non Domestic Two Rate | C36: 4 | D36: 0.871 | E36: 0.014 | F36: 0 | G36: 2.39 | H36: 0 | I36: 0
A37: LDNO HV: Small Non Domestic Off Peak (related MPAN) | C37: 4 | D37: 0.085 | E37: 0 | F37: 0 | G37: 0 | H37: 0 | I37: 0
A38: LDNO HV: LV Medium Non-Domestic | C38: 5-8 | D38: 0.822 | E38: 0.011 | F38: 0 | G38: 15.61 | H38: 0 | I38: 0
A39: LDNO HV: LV Network Domestic | C39: 0 | D39: 7.232 | E39: 0.062 | F39: 0.011 | G39: 2.22 | H39: 0 | I39: 0
A40: LDNO HV: LV Network Non-Domestic Non-CT | C40: 0 | D40: 6.569 | E40: 0.056 | F40: 0.01 | G40: 2.55 | H40: 0 | I40: 0
A41: LDNO HV: LV HH Metered | C41: 0 | D41: 5.173 | E41: 0.037 | F41: 0.007 | G41: 7.05 | H41: 1.49 | I41: 0.157 | J41: =H41 -> 1.49
A42: LDNO HV: LV Sub HH Metered | C42: 0 | D42: 5.603 | E42: 0.025 | F42: 0.005 | G42: 7.4 | H42: 3.39 | I42: 0.156 | J42: =H42 -> 3.39
A43: LDNO HV: HV HH Metered | C43: 0 | D43: 5.225 | E43: 0.016 | F43: 0.003 | G43: 83.91 | H43: 3.17 | I43: 0.147 | J43: =H43 -> 3.17
A44: LDNO HV: NHH UMS category A | C44: 8 | D44: 0.829 | E44: 0 | F44: 0 | G44: 0 | H44: 0 | I44: 0
...

Sheet Annex 5 LLFs
A1: Back to Overview
A2: These line loss factors are illustrative based on the latest calculated values and are published in good faith. However, the line loss factors that are approved by the BSC Panel for the applicable year and consequently published on the Elexon website will take precedence and be used in Settlement if they differ from these values.
A3: =Overview!B4& " - Illustrative LLFs for year beginning "&Overview!D4 -> Eastern Power Networks - Illustrative LLFs for year beginning 01/04/2017
A4: Time periods | C4: Period 1 | D4: Period 2 | E4: Period 3 | F4: Period 4 | G4: Period 5
C5: Winter Peak | D5: Summer Peak | E5: Winter Shoulder | F5: Night | G5: Other
A6: Monday to Friday November to February | C6: 16:00 - 19:59 | E6: 07:00 - 15:59
A7: Monday to Friday June to August | D7: 07:00 - 19:59
A8: Monday to Friday March | E8: 07:00 - 19:59
A9: All Year | F9: 00:00 - 06:59 | G9: All Other Times
A10: Notes | C10: All times are in UK Clock time
A12: Generic demand and generation LLFs
A13: Metered voltage, respective periods and associated LLFCs
A14: Metered voltage | C14: Period 1 | D14: Period 2 | E14: Period 3 | F14: Period 4 | G14: Period 5 | H14: Associated LLFC
A15: Low-voltage network | C15: 1.117 | D15: 1.08 | E15: 1.087 | F15: 1.079 | G15: 1.1 | H15: 1, 3, 7, 11, 15, 22, 25, 29, 33, 40, 43, 46, 49, 55, 58, 61, 64, 86, 100, 101, 102, 103, 110, 111, 112, 113, 150, 151, 152, 153, 160, 161, 162, 163, 200, 201, 205, 237, 238, 239, 242, 247, 248, 250, 254, 350, 901, 905, 912, 913, 915
A16: Low-voltage substation | C16: 1.085 | D16: 1.063 | E16: 1.074 | F16: 1.058 | G16: 1.066 | H16: 80, 902, 916
A17: High-voltage network | C17: 1.053 | D17: 1.04 | E17: 1.046 | F17: 1.035 | G17: 1.041 | H17: 84, 903, 918
A18: High-voltage substation | C18: 1.052 | D18: 1.039 | E18: 1.046 | F18: 1.035 | G18: 1.04 | H18: 771, 791, 792
A19: 33kV generic | C19: 1.017 | D19: 1.014 | E19: 1.016 | F19: 1.013 | G19: 1.014 | H19: 796, 797
A20: 132kV generic | C20: 1.004 | D20: 1.003 | E20: 1.003 | F20: 1.002 | G20: 1.003 | H20: 798, 799
A22: EHV site specific LLFs
A23: Demand
A24: LLFC | B24: Site | D24: Period 1 | E24: Period 2 | F24: Period 3 | G24: Period 4 | H24: Period 5
A25: 500 | B25: Stratton Hall Solar - IMPORT | D25: 1.06 | E25: 1.024 | F25: 1.039 | G25: 1.042 | H25: 1.055
A26: 501 | B26: Weston Airfield - IMPORT | D26: 1.064 | E26: 1.045 | F26: 1.042 | G26: 1.038 | H26: 1.046
A27: 502 | B27: Suffolk EFW - IMPORT | D27: 1.056 | E27: 1.05 | F27: 1.015 | G27: 1.072 | H27: 1.036
A28: 503 | B28: Aston Clinton SF - IMPORT | D28: 1.032 | E28: 1.031 | F28: 1.03 | G28: 1.023 | H28: 1.026
A29: 504 | B29: Avenue Farm - IMPORT | D29: 1.021 | E29: 1.022 | F29: 1.023 | G29: 1.02 | H29: 1.02
A30: 505 | B30: Boardinghouse Wind - IMPORT | D30: 1.144 | E30: 1.133 | F30: 1.137 | G30: 1.132 | H30: 1.134
A31: 506 | B31: Boxted Airfield SF - IMPORT | D31: 1.051 | E31: 1.028 | F31: 1.043 | G31: 1.036 | H31: 1.044
A32: 507 | B32: Bassingbourn Solar - IMPORT | D32: 1.012 | E32: 1.012 | F32: 1.013 | G32: 1.012 | H32: 1.012
A33: 508 | B33: Burnthouse Solar II - IMPORT | D33: 1.029 | E33: 1.02 | F33: 1.027 | G33: 1.023 | H33: 1.027
A34: 509 | B34: Croydon Solar Farm - IMPORT | D34: 0.999 | E34: 1 | F34: 1 | G34: 0.999 | H34: 1.004
A35: 510 | B35: Exning Solar Farm - IMPORT | D35: 1.006 | E35: 1.006 | F35: 1.006 | G35: 1.006 | H35: 1.006
A36: 511 | B36: Fenland Solar Farm - IMPORT | D36: 1.037 | E36: 1.023 | F36: 1.033 | G36: 1.028 | H36: 1.032
... A162: 898 | B162: Stowbridge Solar Farm - IMPORT | D162: 1.021 | E162: 1.016 | F162: 1.019 | G162: 1.02 | H162: 1.02
A164: EHV site specific LLFs
A165: Generation
A166: LLFC | B166: Site | D166: Period 1 | E166: Period 2 | F166: Period 3 | G166: Period 4 | H166: Period 5
A167: 450 | B167: Hydes Farm - EXPORT | D167: 1.008 | E167: 0.996 | F167: 1.003 | G167: 1.004 | H167: 1
A168: 451 | B168: Jacks Lane Wind Farm - EXPORT | D168: 1.004 | E168: 0.994 | F168: 1.007 | G168: 0.994 | H168: 1.003
...

Sheet Annex 6 New Designated EHV Prop
A1: Back to Overview | G1: Note: The list of MPANs/MSIDs provided may be incomplete; the DNO reserves the right to apply the listed charges to any other MPANs/MSIDs associated with the site.
A2: Annex 6 - Addendum to Annex 2 EHV charges
A4: =Overview!B4& " - Effective from "&Overview!D4&" - "&Overview!E4&" new designated EHV charges" -> Eastern Power Networks - Effective from 01/04/2017 - Final new designated EHV charges
A5: Import Unique Identifier | B5: LLFC | C5: Import MPANs/MSIDs | D5: Export Unique Identifier | E5: LLFC | F5: Export MPANs/MSIDs | G5: Name | H5: ='Annex 2 EHV charges'!H10 -> Import Super Red unit charge (p/kWh) | I5: ='Annex 2 EHV charges'!I10 -> Import fixed charge (p/day) | J5: ='Annex 2 EHV charges'!J10 -> Import capacity charge (p/kVA/day) | K5: ='Annex 2 EHV charges'!K10 -> Import exceeded capacity charge (p/kVA/day) | L5: ='Annex 2 EHV charges'!L10 -> Export Super Red unit charge (p/kWh) | M5: ='Annex 2 EHV charges'!M10 -> Export fixed charge (p/day) | N5: ='Annex 2 EHV charges'!N10 -> Export capacity charge (p/kVA/day) | O5: ='Annex 2 EHV charges'!O10 -> Export exceeded capacity charge (p/kVA/day)
A6: ALCORG | B6: 796 | C6: 1050001015545 | D6: =A6 -> ALCORG | E6: 797 | F6: 1050000998050 | G6: ALCOR LSPV LTD | H6: 4.113 | I6: 5.06 | J6: 3.81 | K6: =J6 -> 3.81 | L6: 0 | M6: 506.26 | N6: 0.05 | O6: 0.05
A7: ARDLGH | B7: 796 | C7: 1050001061597 | D7: =A7 -> ARDLGH | E7: 797 | F7: 1050001061602 | G7: SUNSAVE 28 (ARDLEIGH) LIMITED | H7: 3.983 | I7: 1.33 | J7: 4.98 | K7: =J7 -> 4.98 | L7: 0 | M7: 533.31 | N7: 0.05 | O7: 0.05
A8: BERDHF | B8: 798 | C8: 1050001382522 | D8: BERDHF | E8: 799 | F8: 1050001382531 | G8: STATERA ENERGY LIMITED | H8: 0 | I8: 1308.59 | J8: 1.15 | K8: 1.15 | L8: 0 | M8: 1308.59 | N8: 0.05 | O8: 0.05
A9: BLCAMB | B9: 796 | C9: 1050001036615 | D9: =A9 -> BLCAMB | E9: 797 | F9: 1050001036624 | G9: BURY GREEN FARM SOLAR LIMITED | H9: 0.463 | I9: 5.01 | J9: 1.9 | K9: =J9 -> 1.9 | M9: 250.7 | N9: 0.05 | O9: 0.05
A10: BLDOCK | B10: MSID 7308 | C10: 1097000000183 | D10: =A10 -> BLDOCK | E10: MSID 7309 | F10: 1097000000192 | G10: GREEN FROG POWER LTD | H10: 1.095 | I10: 5.22 | J10: 1.42 | K10: =J10 -> 1.42 | L10: -1.553 | M10: 521.85 | N10: 0.05 | O10: 0.05
A11: BNNSHL | B11: 796 | C11: 1050001021414 | D11: =A11 -> BNNSHL | E11: 797 | F11: 1050001021423 | G11: BUNNS HILL SOLAR LIMITED | H11: 0.311 | I11: 35.24 | J11: 5.59 | K11: =J11 -> 5.59 | L11: 0 | M11: 1507.7 | N11: 0.05 | O11: 0.05
A12: CLAYBT | B12: 796 | C12: 1050001382364 | D12: CLAYBT | E12: 797 | F12: 1050001382373 | G12: ANESCO LIMITED | H12: 0.244 | I12: 0 | J12: 1.49 | K12: 1.49 | L12: -0.288 | M12: 0 | N12: 0.05 | O12: 0.05
A13: CLAYPV | B13: 796 | C13: 1050001382337 | D13: CLAYPV | E13: 797 | F13: 1050001382355 | G13: ANESCO LIMITED | H13: 0.244 | I13: 0 | J13: 1.49 | K13: 1.49 | L13: 0 | M13: 0 | N13: 0.05 | O13: 0.05
A14: CLDECT | B14: 796 | C14: 1050000714173 | D14: =A14 -> CLDECT | E14: 797 | F14: 1050000714182 | G14: AMP GM005 | H14: 0.21 | I14: 11.66 | J14: 1.42 | K14: =J14 -> 1.42 | L14: 0 | M14: 2565.22 | N14: 0.05 | O14: 0.05
A15: CLRDWN | B15: 796 | C15: 1050001495174 | D15: CLRDWN | E15: 797 | F15: 1050001495183 | G15: BESS CLAREDWON LTD | H15: 5.386 | I15: 484.99 | J15: 1 | K15: 1 | L15: -5.386 | M15: 484.99 | N15: 0.05 | O15: 0.05
A16: CRANHM | B16: 796 | C16: 1050001191792 | D16: =A16 -> CRANHM | E16: 797 | F16: 1050001191808 | G16: WEL SOLAR PARK 12 LTD | H16: 0.619 | I16: 10.06 | J16: 1.98 | K16: 1.98 | M16: 551.09 | N16: 0.05 | O16: 0.05
A17: CRSSNG | B17: 796 | C17: 1050001047087 | D17: =A17 -> CRSSNG | E17: 797 | F17: 1050001047078 | G17: CRESSING SOLAR FARM LIMITED | I17: 0.97 | J17: 1.98 | K17: 1.98 | M17: 486.04 | N17: 0.05 | O17: 0.05
A18: DRAYTN | B18: 796 | C18: 1050001047272 | D18: =A18 -> DRAYTN | E18: 797 | F18: 1050001047263 | G18: HAYMAKER (SIXTEEN) LTD | H18: 5.981 | I18: 11.68 | J18: 2.11 | K18: =J18 -> 2.11 | L18: 0 | M18: 525.43 | N18: 0.05 | O18: 0.05
A19: ERNUNN | B19: 798 | C19: 1050001440510 | D19: ERNUNN | E19: 799 | F19: 1050001440529 | G19: PLUTUS POWERGEN | H19: 0 | I19: 18.73 | J19: 2.22 | K19: 2.22 | L19: -0.615 | M19: 1440.53 | N19: 0.05 | O19: 0.05
A20: GREYSH | B20: 796 | C20: 1050001391466 | D20: GREYSH | E20: 797 | F20: 1050001391475 | G20: PUSH ENERGY LTD | H20: 11.997 | I20: 100.18 | J20: 2.17 | K20: 2.17 | L20: -11.532 | M20: 1953.53 | N20: 0.05 | O20: 0.05
A21: HDATTP | B21: 796 | C21: 1050001197873 | D21: =A21 -> HDATTP | E21: 797 | F21: 1050001197864 | G21: HODDESDON ADVANCED THERMAL TREATMENT WKS | H21: 0.002 | I21: 110.21 | J21: 1.74 | K21: 1.74 | L21: -0.721 | M21: 734.74 | N21: 0.05 | O21: 0.05
A22: HHFARM | B22: 796 | C22: 1050001231451 | D22: =A22 -> HHFARM | E22: 797 | F22: 1050001231460 | G22: LIGHTSOURCE SPV 9 LIMITED | H22: 1.527 | I22: 18.43 | J22: 1.51 | K22: 1.51 | L22: 0 | M22: 552.98 | N22: 0.05 | O22: 0.05
