Workbook
Name days_in_year: '[1]General inputs'!$H$25
Name OLE_LINK1: 'Annex 3 Preserved charges'!#REF!

Sheet Overview
A2: Company and Licence name, charging year, effective from, status
B3: Company and Licence name | C3: Year | D3: Effective From | E3: Status
A4: Company and Licence name, charging year, effective from, status | B4: SP Distribution | C4: 2022/23 | D4: 1 April 2022 | E4: Final
A6: List of data tables in this workbook
A7: Worksheet | B7: Information
A8: Annex 1 LV, HV and Unmetered Supplies charges | B8: Annex 1 contains the charges to LV and HV Designated Properties and Unmetered Supplies.
A9: Annex 2 EHV charges | B9: ="Annex 2 contains the charges to Designated EHV Properties and charges applied to LDNOs with Designated EHV Properties/end-users embedded in networks within the " &B4 &" Licence area." -> Annex 2 contains the charges to Designated EHV Properties and charges applied to LDNOs with Designated EHV Properties/end-users embedded in networks within the SP Distribution Licence area.
A10: Annex 3 Preserved charges | B10: Annex 3 contains details of any preserved and additional charges that are valid at this time.
A11: Annex 4 LDNO charges | B11: ="Annex 4 contains charges that are levied on the owner of an embedded network within the "&B4&" Licence area. "&"Electricity suppliers and consumers who have properties connected to an embedded network should contact the embedded network owner to determine their distribution charges."&" The charges listed in this table are not payable by domestic consumers, business consumers or electricity suppliers." -> Annex 4 contains charges that are levied on the owner of an embedded network within the SP Distribution Licence area. Electricity suppliers and consumers who have properties connected to an embedded network should contact the embedded network owner to determine their distribution charges. The charges listed in this table are not payable by domestic consumers, business consumers or electricity suppliers.
A12: Annex 5 LLFs | B12: Annex 5 has been intentionally left blank as this charging statement is published a complete year before the LLFs have been audited. The line loss factors that are approved by the BSC Panel for the applicable year and consequently published on the Elexon website will take precedence and be used in Settlement. This annex will be re-published with these values once they are available.
A13: Annex 6 Charges for New or Amended Designated EHV Properties | B13: ="Annex 6 contains the charges for new or amended Designated EHV Properties and charges applied to LDNOs with new or amended Designated EHV Properties/end-users embedded in networks within the " &B4 &" Licence area." -> Annex 6 contains the charges for new or amended Designated EHV Properties and charges applied to LDNOs with new or amended Designated EHV Properties/end-users embedded in networks within the SP Distribution Licence area.
A14: Annex 7 Fixed adders for Supplier of Last Resort and Eligible Bad Debt pass-through costs | B14: Annex 7 contains the fixed adders to recover Supplier of Last Resort and Eligible Bad Debt pass-through costs. The Excess Supplier of Last Resort fixed adder relates to an increase to previously published charges only.
A15: Nodal prices | B15: Contains the underlying [nodal/network group] costs used to calculate the current EDCM charges.
A16: Residual Charging Bandings | B16: Contains the four Residual charging band allocation for Customers
A17: Charge calculator | B17: Charge calculator is a tool to help you estimate your distribution charges using current consumption data and forecast consumption data.
A19: Notes to users of this spreadsheet
A21: Please use this spreadsheet with reference to the LC14 use of system charging statement.
A23: Notes to DNOs populating this spreadsheet
A25: DNOs must endeavour to maintain consistency in the structure of this spreadsheet. Any changes to the structure must be noted in the 'Notes to users of this spreadsheet'
A26: The drop down list on the charge calculator can be expanded by unprotecting the charge calculator sheet and selecting 'data', 'data validation...' and then expanding the 'source' data range. The sheet can then be protected.

Sheet Annex 1 LV, HV and UMS charges
A1: Back to Overview | B1: 'DNOs paste value cells A15:J47 from CDCM 3701 into cells A14:J46
A2: =Overview!B4& " - Effective from "&Overview!D4&" - "&Overview!E4&" LV and HV charges" -> SP Distribution - Effective from 1 April 2022 - Final LV and HV charges
A4: Time Bands for LV and HV Designated Properties | G4: Time Bands for Unmetered Properties
A5: Time periods | B5: Red Time Band | C5: Amber Time Band | E5: Green Time Band | I5: Black Time Band | J5: Yellow Time Band | K5: Green Time Band
A6: Monday to Friday (Including Bank Holidays) All Year | B6: 16.30 - 19.30 | C6: 08.00 - 16.30 19.30 - 22.30 | E6: 00.00 - 08.00 22.30 - 00.00 | G6: Monday to Friday (Including Bank Holidays) June to August Inclusive | J6: 08.00 - 22.30 | K6: 00.00 - 08.00 22.30 - 00.00
A7: Saturday and Sunday All Year | C7: 16.00 - 20.00 | E7: 00.00 - 16.00 20.00 - 00.00 | G7: Monday to Friday (Including Bank Holidays) November to February Inclusive | I7: 16.30 - 19.30 | J7: 08.00 - 16.30 19.30 - 22.30 | K7: 00.00 - 08.00 22.30 - 00.00
A8: Notes | B8: All the above times are in UK Clock time | G8: Monday to Friday (Including Bank Holidays) March, April, May and September, October | J8: 08.00 - 22.30 | K8: 00.00 - 08.00 22.30 - 00.00
G9: Saturday and Sunday All year | J9: 16.00 - 20.00 | K9: 00:00-16:00 20:00-00:00
G10: Notes | I10: All the above times are in UK Clock time
A13: Tariff name | B13: Open LLFCs | C13: PCs | D13: Red/black unit charge p/kWh | E13: Amber/yellow unit charge p/kWh | F13: Green unit charge p/kWh | G13: Fixed charge p/MPAN/day | H13: Capacity charge p/kVA/day | I13: Exceeded capacity charge p/kVA/day | J13: Reactive power charge p/kVArh | K13: Closed LLFCs
A14: Domestic Aggregated with Residual | B14: 100, 101, 110, 111, 114, 115, 118, 119, 120, 121, 160, 161, 162, 163, 180 | C14: 0, 1, 2 | D14: 8.501 | E14: 0.962 | F14: 0.019 | G14: 27.13
A15: Domestic Aggregated (Related MPAN) | B15: 112, 113, 116, 117, 132, 133, 136, 137, 164, 165, 166 | C15: 2 | D15: 8.501 | E15: 0.962 | F15: 0.019 | K15: 130, 134, 135
A16: Non-Domestic Aggregated No Residual | B16: D00,F00 | C16: 0, 3, 4, 5-8 | D16: 10.706 | E16: 1.212 | F16: 0.024 | G16: 6.37 | K16: 201, 204, 221, 260, 280, 200, 202, 203, 220, 222, 400, 401, 402
A17: Non-Domestic Aggregated Band 1 | B17: D01,F01 | C17: 0, 3, 4, 5-8 | D17: 10.706 | E17: 1.212 | F17: 0.024 | G17: 11.11 | K17: 201, 204, 221, 260, 280, 200, 202, 203, 220, 222, 400, 401, 402
A18: Non-Domestic Aggregated Band 2 | B18: D02,F02 | C18: 0, 3, 4, 5-8 | D18: 10.706 | E18: 1.212 | F18: 0.024 | G18: 32.32 | K18: 201, 204, 221, 260, 280, 200, 202, 203, 220, 222, 400, 401, 402
A19: Non-Domestic Aggregated Band 3 | B19: D03,F03 | C19: 0, 3, 4, 5-8 | D19: 10.706 | E19: 1.212 | F19: 0.024 | G19: 71.14 | K19: 201, 204, 221, 260, 280, 200, 202, 203, 220, 222, 400, 401, 402
A20: Non-Domestic Aggregated Band 4 | B20: D04,F04 | C20: 0, 3, 4, 5-8 | D20: 10.706 | E20: 1.212 | F20: 0.024 | G20: 209.3 | K20: 201, 204, 221, 260, 280, 200, 202, 203, 220, 222, 400, 401, 402
A21: Non-Domestic Aggregated (related MPAN) | B21: 225, 240, 241, 301 | C21: 4 | D21: 10.706 | E21: 1.212 | F21: 0.024 | K21: 223, 242, 243, 245, 246
A22: LV Site Specific No Residual | B22: G00, H00 | C22: 0 | D22: 6.926 | E22: 0.75 | F22: 0.014 | G22: 25.01 | H22: 2.65 | I22: 3.84 | J22: 0.213 | K22: 500, 502, 504
A23: LV Site Specific Band 1 | B23: G01, H01 | C23: 0 | D23: 6.926 | E23: 0.75 | F23: 0.014 | G23: 343.29 | H23: 2.65 | I23: 3.84 | J23: 0.213 | K23: 500, 502, 504
A24: LV Site Specific Band 2 | B24: G02, H02 | C24: 0 | D24: 6.926 | E24: 0.75 | F24: 0.014 | G24: 684.83 | H24: 2.65 | I24: 3.84 | J24: 0.213 | K24: 500, 502, 504
A25: LV Site Specific Band 3 | B25: G03, H03 | C25: 0 | D25: 6.926 | E25: 0.75 | F25: 0.014 | G25: 1126.71 | H25: 2.65 | I25: 3.84 | J25: 0.213 | K25: 500, 502, 504
A26: LV Site Specific Band 4 | B26: G04, H04 | C26: 0 | D26: 6.926 | E26: 0.75 | F26: 0.014 | G26: 2465.99 | H26: 2.65 | I26: 3.84 | J26: 0.213 | K26: 500, 502, 504
A27: LV Sub Site Specific No Residual | B27: K00, L00 | C27: 0 | D27: 4.073 | E27: 0.383 | F27: 0.005 | G27: 8.85 | H27: 4.8 | I27: 5.45 | J27: 0.112 | K27: 506, 507, 508
A28: LV Sub Site Specific Band 1 | B28: K01, L01 | C28: 0 | D28: 4.073 | E28: 0.383 | F28: 0.005 | G28: 327.13 | H28: 4.8 | I28: 5.45 | J28: 0.112 | K28: 506, 507, 508
A29: LV Sub Site Specific Band 2 | B29: K02, L02 | C29: 0 | D29: 4.073 | E29: 0.383 | F29: 0.005 | G29: 668.67 | H29: 4.8 | I29: 5.45 | J29: 0.112 | K29: 506, 507, 508
A30: LV Sub Site Specific Band 3 | B30: K03, L03 | C30: 0 | D30: 4.073 | E30: 0.383 | F30: 0.005 | G30: 1110.54 | H30: 4.8 | I30: 5.45 | J30: 0.112 | K30: 506, 507, 508
A31: LV Sub Site Specific Band 4 | B31: K04, L04 | C31: 0 | D31: 4.073 | E31: 0.383 | F31: 0.005 | G31: 2449.83 | H31: 4.8 | I31: 5.45 | J31: 0.112 | K31: 506, 507, 508
A32: HV Site Specific No Residual | B32: M00, N00 | C32: 0 | D32: 3.029 | E32: 0.262 | F32: 0.003 | G32: 133.52 | H32: 5.3 | I32: 6.49 | J32: 0.077 | K32: 501, 505, 503
A33: HV Site Specific Band 1 | B33: M01, N01 | C33: 0 | D33: 3.029 | E33: 0.262 | F33: 0.003 | G33: 1603.45 | H33: 5.3 | I33: 6.49 | J33: 0.077 | K33: 501, 505, 503
... A36: HV Site Specific Band 4 | B36: M04, N04 | C36: 0 | D36: 3.029 | E36: 0.262 | F36: 0.003 | G36: 31562.57 | H36: 5.3 | I36: 6.49 | J36: 0.077 | K36: 501, 505, 503
A37: Unmetered Supplies | B37: 900, 901, 902, 903, 910 | C37: 0, 1 or 8 | D37: 21.869 | E37: 2.649 | F37: 1.788 | K37: 904, 905, 906, 907, 908, 909
A38: LV Generation Aggregated | B38: 781, 782, 783, 784, 785 | C38: 0 | D38: -6.3 | E38: -0.713 | F38: -0.014
A39: LV Sub Generation Aggregated | B39: 602 | C39: 0 | D39: -5.55 | E39: -0.614 | F39: -0.012
A40: LV Generation Site Specific | B40: 603, 604, 607, 608 | C40: 0 | D40: -6.3 | E40: -0.713 | F40: -0.014 | J40: 0.191
A41: LV Generation Site Specific no RP charge | B41: 794, 795 | C41: 0 | D41: -6.3 | E41: -0.713 | F41: -0.014
A42: LV Sub Generation Site Specific | B42: 609, 610 | C42: 0 | D42: -5.55 | E42: -0.614 | F42: -0.012 | J42: 0.168
A43: LV Sub Generation Site Specific no RP charge | B43: 796, 797 | C43: 0 | D43: -5.55 | E43: -0.614 | F43: -0.012
A44: HV Generation Site Specific | B44: 605, 606, 611, 612 | C44: 0 | D44: -3.601 | E44: -0.337 | F44: -0.004 | G44: 97.47 | J44: 0.14
A45: HV Generation Site Specific no RP charge | B45: 798, 799 | C45: 0 | D45: -3.601 | E45: -0.337 | F45: -0.004 | G45: 97.47

Sheet Annex 2 EHV charges
A1: Back to Overview | C1: Copy EDCM table 5001 range starting B101 and paste into G11. Extend or reduce print area as required. | F1: Note: The list of MPANs / MSIDs provided may be incomplete; the DNO reserves the right to apply the listed charges to any other MPANs / MSIDs associated with the site.
A2: =Overview!B4& " - Effective from "&Overview!D4&" - "&Overview!E4&" EDCM charges" -> SP Distribution - Effective from 1 April 2022 - Final EDCM charges | P2: 1
P3: 1
A4: Time Periods for Designated EHV Properties | P4: 1
A5: Time periods | D5: Super Red Time Band | P5: 1
A6: Monday to Friday (Including Bank Holidays) June to August Inclusive | P6: 1
A7: Monday to Friday (Including Bank Holidays) November to February Inclusive | D7: 16:30 - 19:30 | P7: 1
A8: Notes | D8: All the above times are in UK Clock time | P8: 1
P9: 1
A10: Import Unique Identifier | B10: LLFC | C10: Import MPANs/MSIDs | D10: Export Unique Identifier | E10: LLFC | F10: Export MPANs/MSIDs | G10: Name | H10: Import Super Red unit charge (p/kWh) | I10: Import fixed charge (p/day) | J10: Import capacity charge (p/kVA/day) | K10: Import exceeded capacity charge (p/kVA/day) | L10: Export Super Red unit charge (p/kWh) | M10: Export fixed charge (p/day) | N10: Export capacity charge (p/kVA/day) | O10: Export exceeded capacity charge (p/kVA/day) | P10: x
A11: 800 | B11: 800 | C11: 1800060775972 | D11: 644 | E11: 644 | F11: 1800060775990 | G11: Rhodders | H11: - | I11: 253.25 | J11: 0.66 | K11: 0.66 | L11: - | M11: 5687.62 | N11: 0.05 | O11: 0.05 | P11: 1
A12: 801 | B12: 801 | C12: 1800060004220 | D12: MSID 8182 | E12: MSID 8182 | F12: MSID 8182 | G12: Minsca | H12: - | I12: 419.5 | J12: - | K12: - | L12: - | M12: - | N12: - | O12: - | P12: 1
A13: 802 | B13: 802 | C13: 1800060539962 | D13: 683 | E13: 683 | F13: 1800060539971 | G13: Bankend Rig | H13: - | I13: 131.36 | J13: 2.69 | K13: 2.69 | L13: - | M13: 4944.09 | N13: 0.05 | O13: 0.05 | P13: 1
A14: 803 | B14: 803 | C14: 1800060532708 | D14: 684 | E14: 684 | F14: 1800060532717 | G14: Barlockhart Moor | H14: - | I14: 160.43 | J14: 0.84 | K14: 0.84 | L14: - | M14: 8983 | N14: 0.05 | O14: 0.05 | P14: 1
A15: 804 | B15: 804 | C15: 1800060532726 | D15: 685 | E15: 685 | F15: 1800060532735 | G15: Blantyre Muir | H15: - | I15: 370.62 | J15: 0.66 | K15: 0.66 | L15: - | M15: 5840.28 | N15: 0.05 | O15: 0.05 | P15: 1
A16: 805 | B16: 805 | C16: 1800060587850 | D16: 693 | E16: 693 | F16: 1800060587869 | G16: Hunterston WF | H16: - | I16: 10916.73 | J16: 0.63 | K16: 0.63 | L16: - | M16: - | N16: - | O16: - | P16: 1
A17: 806 | B17: 806 | C17: 1800060532647 | D17: 688 | E17: 688 | F17: 1800060532656 | G17: Middleton Farm | H17: - | I17: 229.85 | J17: 0.85 | K17: 0.85 | L17: - | M17: 5222.16 | N17: 0.05 | O17: 0.05 | P17: 1
A18: 807 | B18: 807 | C18: 1800060532665 | D18: 689 | E18: 689 | F18: 1800060532674 | G18: Neilston Community | H18: - | I18: 135.72 | J18: 0.94 | K18: 0.94 | L18: - | M18: 6406.7 | N18: 0.05 | O18: 0.05 | P18: 1
A19: 808 | B19: 808 | C19: 1800053653870 | D19: 681 | E19: 681 | F19: 1800053653880 | G19: Garlaff Landfill | H19: - | I19: 104.76 | J19: 0.63 | K19: 0.63 | L19: - | M19: - | N19: - | O19: - | P19: 1
A20: 809 | B20: 809 | C20: 1800054992968 | D20: 629 | E20: 629 | F20: 1800054992977 | G20: Hagshaw Hill Extension | H20: - | I20: 718.91 | J20: 0.66 | K20: 0.66 | L20: - | M20: 18154.96 | N20: 0.05 | O20: 0.05 | P20: 1
A21: 811 | B21: 811 | C21: 1800060328035 | D21: 671 | E21: 671 | F21: 1800060328044 | G21: Muirhall | H21: - | I21: 341.85 | J21: 0.83 | K21: 0.83 | L21: - | M21: 8204.45 | N21: 0.05 | O21: 0.05 | P21: 1
A22: 812 | B22: 812 | C22: 1800060372113 | D22: 672 | E22: 672 | F22: 1800060372122 | G22: Burnfoot | H22: - | I22: 114.9 | J22: 0.7 | K22: 0.7 | L22: - | M22: 8017.86 | N22: 0.05 | O22: 0.05 | P22: 1
A23: 813 | B23: 813 | C23: 1800060532498 | D23: 690 | E23: 690 | F23: 1800060532503 | G23: Westfield WF | H23: - | I23: 60.76 | J23: 0.94 | K23: 0.94 | L23: - | M23: 7138.36 | N23: 0.05 | O23: 0.05 | P23: 1
A24: 814 | B24: 814 | C24: 1800060532683 | D24: 691 | E24: 691 | F24: 1800060532692 | G24: Barmoor WF | H24: - | I24: 201.67 | J24: 0.9 | K24: 0.9 | L24: - | M24: 19067.14 | N24: 0.05 | O24: 0.05 | P24: 1
A25: 815 | B25: 815 | C25: 1800060566984 | D25: 692 | E25: 692 | F25: 1800060566993 | G25: Nutberry WF | H25: - | I25: 811.8 | J25: 0.83 | K25: 0.83 | L25: - | M25: 15368.76 | N25: 0.05 | O25: 0.05 | P25: 1
A26: 816 | B26: 816 | C26: 1800060652454 | D26: 695 | E26: 695 | F26: 1800060652463 | G26: Carcreugh WF | H26: - | I26: 314.69 | J26: 0.65 | K26: 0.65 | L26: - | M26: 6423.35 | N26: 0.05 | O26: 0.05 | P26: 1
A27: 817 | B27: 817 | C27: 1800060567668 | G27: Magnox | H27: - | I27: 3246.12 | J27: 1.74 | K27: 1.74 | P27: 1
A28: 818 | B28: 818 | C28: 1800060642767 | D28: 700 | E28: 700 | F28: 1800060642776 | G28: West Browncastle WF | H28: - | I28: 507.77 | J28: 0.69 | K28: 0.69 | L28: - | M28: 28744.73 | N28: 0.05 | O28: 0.05 | P28: 1
A29: 819 | B29: 819 | C29: 1800060632661 | D29: 699 | E29: 699 | F29: 1800060632670 | G29: Viridor (Waste energy) | H29: - | I29: 1485.96 | J29: 1.01 | K29: 1.01 | L29: - | M29: 8903.35 | N29: 0.05 | O29: 0.05 | P29: 1
A30: 820 | B30: 820 | C30: 1800060289486 | D30: 620 | E30: 620 | F30: 1800060289510 | G30: Craigengelt | H30: - | I30: 151.25 | J30: 0.75 | K30: 0.75 | L30: - | M30: 20660.37 | N30: 0.05 | O30: 0.05 | P30: 1
A31: 821 | B31: 821 | C31: 1800054865132 | D31: 621 | E31: 621 | F31: 1800054865141 | G31: Greenknowes | H31: - | I31: 621.98 | J31: 0.71 | K31: 0.71 | L31: - | M31: 37319.01 | N31: 0.05 | O31: 0.05 | P31: 1
A32: 822 | B32: 822 | C32: 1800060683754 | D32: 703 | E32: 703 | F32: 1800060683763 | G32: Ewe Hill Dumfries WF | H32: - | I32: 474.4 | J32: 0.91 | K32: 0.91 | L32: - | M32: 21402.14 | N32: 0.05 | O32: 0.05 | P32: 1
A33: 823 | B33: 823 | C33: 1800060697223 | D33: 704 | E33: 704 | F33: 1800060697232 | G33: Langhope Rig (D) WF | H33: - | I33: 42.69 | J33: 1.37 | K33: 1.37 | L33: - | M33: 1400.11 | N33: 0.05 | O33: 0.05 | P33: See Annex 6
A34: 824 | B34: 824 | C34: 1800060674253 | D34: 705 | E34: 705 | F34: 1800060674262 | G34: Muirhall Extention WF | H34: - | I34: 54.73 | J34: 0.9 | K34: 0.9 | L34: - | M34: 3261.11 | N34: 0.05 | O34: 0.05 | P34: 1
A35: 825 | B35: 825 | C35: 1800060159192 | D35: 625 | E35: 625 | F35: 1800060159208 | G35: Aikengall | H35: - | I35: 937.97 | J35: - | K35: - | L35: - | M35: 8617.48 | N35: 0.05 | O35: 0.05 | P35: 1
A36: 826 | B36: 826 | C36: 1800053646251 | D36: 626 | E36: 626 | F36: 1800053646260 | G36: Hagshaw Hill | H36: - | I36: 55.88 | J36: 0.9 | K36: 0.9 | L36: - | M36: 1112.01 | N36: 0.05 | O36: 0.05 | P36: 1
A37: 827 | B37: 827 | C37: 1800053646190 | D37: 627 | E37: 627 | F37: 1800053646206 | G37: Gallow Rig | H37: - | I37: 194.88 | J37: 0.86 | K37: 0.86 | L37: - | M37: 4209.3 | N37: 0.05 | O37: 0.05 | P37: 1
A38: 828 | B38: 828 | C38: 1800053646172 | D38: 628 | E38: 628 | F38: 1800053646181 | G38: Polwhat Rig | H38: - | I38: 231.8 | J38: 0.84 | K38: 0.84 | L38: - | M38: 4172.38 | N38: 0.05 | O38: 0.05 | P38: 1
A39: 829 | B39: 829 | C39: 1800054738267 | D39: 624 | E39: 624 | F39: 1800054738276 | G39: Greendykeside | H39: - | I39: 53.18 | J39: 0.93 | K39: 0.93 | L39: - | M39: 3731.55 | N39: 0.05 | O39: 0.05 | P39: 1
A40: 830 | B40: 830 | C40: 1800053647237 | D40: 630 | E40: 630 | F40: 1800053647246 | G40: Dun Law | H40: - | I40: 33.51 | J40: 0.87 | K40: 0.87 | L40: - | M40: - | N40: - | O40: - | P40: 2
...

Sheet Annex 2a Import
A1: Note: The list of MPANs / MSIDs provided may be incomplete; the DNO reserves the right to apply the listed charges to any other MPANs / MSIDs associated with the site. Note: This table is automatically populated based on the content of the tab entitled 'Annex 2 EHV Charges'. The timebands are as shown in Annex 2.
A2: =Overview!B4& " - Effective from "&Overview!D4&" - "&Overview!E4&" EDCM import charges" -> SP Distribution - Effective from 1 April 2022 - Final EDCM import charges
A4: Import Unique Identifier | B4: LLFC | C4: Import MPANs/MSIDs | D4: Name | E4: ='Annex 2 EHV charges'!H10 -> Import Super Red unit charge (p/kWh) | F4: ='Annex 2 EHV charges'!I10 -> Import fixed charge (p/day) | G4: ='Annex 2 EHV charges'!J10 -> Import capacity charge (p/kVA/day) | H4: ='Annex 2 EHV charges'!K10 -> Import exceeded capacity charge (p/kVA/day)
A5: {=IFERROR(INDEX('Annex 2 EHV charges'!$A$11:$A$260, MATCH(0, IF(ISBLANK('Annex 2 EHV charges'!$A$11:$A$260),1, COUNTIF(A$4:$A4, 'Annex 2 EHV charges'!$A$11:$A$260)), 0)),"")} -> 800 | B5: =IF($A5="","",VLOOKUP($A5,'Annex 2 EHV charges'!$A:$O,2,0)) -> 800 | C5: =IF($A5="","",VLOOKUP($A5,'Annex 2 EHV charges'!$A:$O,3,0)) -> 1800060775972 | D5: =IF($A5="","",VLOOKUP($A5,'Annex 2 EHV charges'!$A:$O,7,0)) -> Rhodders | E5: =IFERROR(IF(VLOOKUP($A5,'Annex 2 EHV charges'!$A:$O,8,FALSE)=0,"",VLOOKUP($A5,'Annex 2 EHV charges'!$A:$O,8,FALSE)),"") -> - | F5: =IFERROR(IF(VLOOKUP($A5,'Annex 2 EHV charges'!$A:$O,9,FALSE)=0,"",VLOOKUP($A5,'Annex 2 EHV charges'!$A:$O,9,FALSE)),"") -> 253.25 | G5: =IFERROR(IF(VLOOKUP($A5,'Annex 2 EHV charges'!$A:$O,10,FALSE)=0,"",VLOOKUP($A5,'Annex 2 EHV charges'!$A:$O,10,FALSE)),"") -> 0.66 | H5: =IFERROR(IF(VLOOKUP($A5,'Annex 2 EHV charges'!$A:$O,11,FALSE)=0,"",VLOOKUP($A5,'Annex 2 EHV charges'!$A:$O,11,FALSE)),"") -> 0.66 | I5: =IF(VLOOKUP(C5,'Annex 2 EHV charges'!$C$11:$P$154,14,FALSE)<=5,"",VLOOKUP(C5,'Annex 2 EHV charges'!$C$11:$P$154,14,FALSE))
A6: {=IFERROR(INDEX('Annex 2 EHV charges'!$A$11:$A$260, MATCH(0, IF(ISBLANK('Annex 2 EHV charges'!$A$11:$A$260),1, COUNTIF(A$4:$A5, 'Annex 2 EHV charges'!$A$11:$A$260)), 0)),"")} -> 801 | B6: =IF($A6="","",VLOOKUP($A6,'Annex 2 EHV charges'!$A:$O,2,0)) -> 801 | C6: =IF($A6="","",VLOOKUP($A6,'Annex 2 EHV charges'!$A:$O,3,0)) -> 1800060004220 | D6: =IF($A6="","",VLOOKUP($A6,'Annex 2 EHV charges'!$A:$O,7,0)) -> Minsca | E6: =IFERROR(IF(VLOOKUP($A6,'Annex 2 EHV charges'!$A:$O,8,FALSE)=0,"",VLOOKUP($A6,'Annex 2 EHV charges'!$A:$O,8,FALSE)),"") -> - | F6: =IFERROR(IF(VLOOKUP($A6,'Annex 2 EHV charges'!$A:$O,9,FALSE)=0,"",VLOOKUP($A6,'Annex 2 EHV charges'!$A:$O,9,FALSE)),"") -> 419.5 | G6: =IFERROR(IF(VLOOKUP($A6,'Annex 2 EHV charges'!$A:$O,10,FALSE)=0,"",VLOOKUP($A6,'Annex 2 EHV charges'!$A:$O,10,FALSE)),"") -> - | H6: =IFERROR(IF(VLOOKUP($A6,'Annex 2 EHV charges'!$A:$O,11,FALSE)=0,"",VLOOKUP($A6,'Annex 2 EHV charges'!$A:$O,11,FALSE)),"") -> - | I6: =IF(VLOOKUP(C6,'Annex 2 EHV charges'!$C$11:$P$154,14,FALSE)<=5,"",VLOOKUP(C6,'Annex 2 EHV charges'!$C$11:$P$154,14,FALSE))
A7: {=IFERROR(INDEX('Annex 2 EHV charges'!$A$11:$A$260, MATCH(0, IF(ISBLANK('Annex 2 EHV charges'!$A$11:$A$260),1, COUNTIF(A$4:$A6, 'Annex 2 EHV charges'!$A$11:$A$260)), 0)),"")} -> 802 | B7: =IF($A7="","",VLOOKUP($A7,'Annex 2 EHV charges'!$A:$O,2,0)) -> 802 | C7: =IF($A7="","",VLOOKUP($A7,'Annex 2 EHV charges'!$A:$O,3,0)) -> 1800060539962 | D7: =IF($A7="","",VLOOKUP($A7,'Annex 2 EHV charges'!$A:$O,7,0)) -> Bankend Rig | E7: =IFERROR(IF(VLOOKUP($A7,'Annex 2 EHV charges'!$A:$O,8,FALSE)=0,"",VLOOKUP($A7,'Annex 2 EHV charges'!$A:$O,8,FALSE)),"") -> - | F7: =IFERROR(IF(VLOOKUP($A7,'Annex 2 EHV charges'!$A:$O,9,FALSE)=0,"",VLOOKUP($A7,'Annex 2 EHV charges'!$A:$O,9,FALSE)),"") -> 131.36 | G7: =IFERROR(IF(VLOOKUP($A7,'Annex 2 EHV charges'!$A:$O,10,FALSE)=0,"",VLOOKUP($A7,'Annex 2 EHV charges'!$A:$O,10,FALSE)),"") -> 2.69 | H7: =IFERROR(IF(VLOOKUP($A7,'Annex 2 EHV charges'!$A:$O,11,FALSE)=0,"",VLOOKUP($A7,'Annex 2 EHV charges'!$A:$O,11,FALSE)),"") -> 2.69 | I7: =IF(VLOOKUP(C7,'Annex 2 EHV charges'!$C$11:$P$154,14,FALSE)<=5,"",VLOOKUP(C7,'Annex 2 EHV charges'!$C$11:$P$154,14,FALSE))
A8: {=IFERROR(INDEX('Annex 2 EHV charges'!$A$11:$A$260, MATCH(0, IF(ISBLANK('Annex 2 EHV charges'!$A$11:$A$260),1, COUNTIF(A$4:$A7, 'Annex 2 EHV charges'!$A$11:$A$260)), 0)),"")} -> 803 | B8: =IF($A8="","",VLOOKUP($A8,'Annex 2 EHV charges'!$A:$O,2,0)) -> 803 | C8: =IF($A8="","",VLOOKUP($A8,'Annex 2 EHV charges'!$A:$O,3,0)) -> 1800060532708 | D8: =IF($A8="","",VLOOKUP($A8,'Annex 2 EHV charges'!$A:$O,7,0)) -> Barlockhart Moor | E8: =IFERROR(IF(VLOOKUP($A8,'Annex 2 EHV charges'!$A:$O,8,FALSE)=0,"",VLOOKUP($A8,'Annex 2 EHV charges'!$A:$O,8,FALSE)),"") -> - | F8: =IFERROR(IF(VLOOKUP($A8,'Annex 2 EHV charges'!$A:$O,9,FALSE)=0,"",VLOOKUP($A8,'Annex 2 EHV charges'!$A:$O,9,FALSE)),"") -> 160.43 | G8: =IFERROR(IF(VLOOKUP($A8,'Annex 2 EHV charges'!$A:$O,10,FALSE)=0,"",VLOOKUP($A8,'Annex 2 EHV charges'!$A:$O,10,FALSE)),"") -> 0.84 | H8: =IFERROR(IF(VLOOKUP($A8,'Annex 2 EHV charges'!$A:$O,11,FALSE)=0,"",VLOOKUP($A8,'Annex 2 EHV charges'!$A:$O,11,FALSE)),"") -> 0.84 | I8: =IF(VLOOKUP(C8,'Annex 2 EHV charges'!$C$11:$P$154,14,FALSE)<=5,"",VLOOKUP(C8,'Annex 2 EHV charges'!$C$11:$P$154,14,FALSE))
A9: {=IFERROR(INDEX('Annex 2 EHV charges'!$A$11:$A$260, MATCH(0, IF(ISBLANK('Annex 2 EHV charges'!$A$11:$A$260),1, COUNTIF(A$4:$A8, 'Annex 2 EHV charges'!$A$11:$A$260)), 0)),"")} -> 804 | B9: =IF($A9="","",VLOOKUP($A9,'Annex 2 EHV charges'!$A:$O,2,0)) -> 804 | C9: =IF($A9="","",VLOOKUP($A9,'Annex 2 EHV charges'!$A:$O,3,0)) -> 1800060532726 | D9: =IF($A9="","",VLOOKUP($A9,'Annex 2 EHV charges'!$A:$O,7,0)) -> Blantyre Muir | E9: =IFERROR(IF(VLOOKUP($A9,'Annex 2 EHV charges'!$A:$O,8,FALSE)=0,"",VLOOKUP($A9,'Annex 2 EHV charges'!$A:$O,8,FALSE)),"") -> - | F9: =IFERROR(IF(VLOOKUP($A9,'Annex 2 EHV charges'!$A:$O,9,FALSE)=0,"",VLOOKUP($A9,'Annex 2 EHV charges'!$A:$O,9,FALSE)),"") -> 370.62 | G9: =IFERROR(IF(VLOOKUP($A9,'Annex 2 EHV charges'!$A:$O,10,FALSE)=0,"",VLOOKUP($A9,'Annex 2 EHV charges'!$A:$O,10,FALSE)),"") -> 0.66 | H9: =IFERROR(IF(VLOOKUP($A9,'Annex 2 EHV charges'!$A:$O,11,FALSE)=0,"",VLOOKUP($A9,'Annex 2 EHV charges'!$A:$O,11,FALSE)),"") -> 0.66 | I9: =IF(VLOOKUP(C9,'Annex 2 EHV charges'!$C$11:$P$154,14,FALSE)<=5,"",VLOOKUP(C9,'Annex 2 EHV charges'!$C$11:$P$154,14,FALSE))
A10: {=IFERROR(INDEX('Annex 2 EHV charges'!$A$11:$A$260, MATCH(0, IF(ISBLANK('Annex 2 EHV charges'!$A$11:$A$260),1, COUNTIF(A$4:$A9, 'Annex 2 EHV charges'!$A$11:$A$260)), 0)),"")} -> 805 | B10: =IF($A10="","",VLOOKUP($A10,'Annex 2 EHV charges'!$A:$O,2,0)) -> 805 | C10: =IF($A10="","",VLOOKUP($A10,'Annex 2 EHV charges'!$A:$O,3,0)) -> 1800060587850 | D10: =IF($A10="","",VLOOKUP($A10,'Annex 2 EHV charges'!$A:$O,7,0)) -> Hunterston WF | E10: =IFERROR(IF(VLOOKUP($A10,'Annex 2 EHV charges'!$A:$O,8,FALSE)=0,"",VLOOKUP($A10,'Annex 2 EHV charges'!$A:$O,8,FALSE)),"") -> - | F10: =IFERROR(IF(VLOOKUP($A10,'Annex 2 EHV charges'!$A:$O,9,FALSE)=0,"",VLOOKUP($A10,'Annex 2 EHV charges'!$A:$O,9,FALSE)),"") -> 10916.73 | G10: =IFERROR(IF(VLOOKUP($A10,'Annex 2 EHV charges'!$A:$O,10,FALSE)=0,"",VLOOKUP($A10,'Annex 2 EHV charges'!$A:$O,10,FALSE)),"") -> 0.63 | H10: =IFERROR(IF(VLOOKUP($A10,'Annex 2 EHV charges'!$A:$O,11,FALSE)=0,"",VLOOKUP($A10,'Annex 2 EHV charges'!$A:$O,11,FALSE)),"") -> 0.63 | I10: =IF(VLOOKUP(C10,'Annex 2 EHV charges'!$C$11:$P$154,14,FALSE)<=5,"",VLOOKUP(C10,'Annex 2 EHV charges'!$C$11:$P$154,14,FALSE))
A11: {=IFERROR(INDEX('Annex 2 EHV charges'!$A$11:$A$260, MATCH(0, IF(ISBLANK('Annex 2 EHV charges'!$A$11:$A$260),1, COUNTIF(A$4:$A10, 'Annex 2 EHV charges'!$A$11:$A$260)), 0)),"")} -> 806 | B11: =IF($A11="","",VLOOKUP($A11,'Annex 2 EHV charges'!$A:$O,2,0)) -> 806 | C11: =IF($A11="","",VLOOKUP($A11,'Annex 2 EHV charges'!$A:$O,3,0)) -> 1800060532647 | D11: =IF($A11="","",VLOOKUP($A11,'Annex 2 EHV charges'!$A:$O,7,0)) -> Middleton Farm | E11: =IFERROR(IF(VLOOKUP($A11,'Annex 2 EHV charges'!$A:$O,8,FALSE)=0,"",VLOOKUP($A11,'Annex 2 EHV charges'!$A:$O,8,FALSE)),"") -> - | F11: =IFERROR(IF(VLOOKUP($A11,'Annex 2 EHV charges'!$A:$O,9,FALSE)=0,"",VLOOKUP($A11,'Annex 2 EHV charges'!$A:$O,9,FALSE)),"") -> 229.85 | G11: =IFERROR(IF(VLOOKUP($A11,'Annex 2 EHV charges'!$A:$O,10,FALSE)=0,"",VLOOKUP($A11,'Annex 2 EHV charges'!$A:$O,10,FALSE)),"") -> 0.85 | H11: =IFERROR(IF(VLOOKUP($A11,'Annex 2 EHV charges'!$A:$O,11,FALSE)=0,"",VLOOKUP($A11,'Annex 2 EHV charges'!$A:$O,11,FALSE)),"") -> 0.85 | I11: =IF(VLOOKUP(C11,'Annex 2 EHV charges'!$C$11:$P$154,14,FALSE)<=5,"",VLOOKUP(C11,'Annex 2 EHV charges'!$C$11:$P$154,14,FALSE))
A12: {=IFERROR(INDEX('Annex 2 EHV charges'!$A$11:$A$260, MATCH(0, IF(ISBLANK('Annex 2 EHV charges'!$A$11:$A$260),1, COUNTIF(A$4:$A11, 'Annex 2 EHV charges'!$A$11:$A$260)), 0)),"")} -> 807 | B12: =IF($A12="","",VLOOKUP($A12,'Annex 2 EHV charges'!$A:$O,2,0)) -> 807 | C12: =IF($A12="","",VLOOKUP($A12,'Annex 2 EHV charges'!$A:$O,3,0)) -> 1800060532665 | D12: =IF($A12="","",VLOOKUP($A12,'Annex 2 EHV charges'!$A:$O,7,0)) -> Neilston Community | E12: =IFERROR(IF(VLOOKUP($A12,'Annex 2 EHV charges'!$A:$O,8,FALSE)=0,"",VLOOKUP($A12,'Annex 2 EHV charges'!$A:$O,8,FALSE)),"") -> - | F12: =IFERROR(IF(VLOOKUP($A12,'Annex 2 EHV charges'!$A:$O,9,FALSE)=0,"",VLOOKUP($A12,'Annex 2 EHV charges'!$A:$O,9,FALSE)),"") -> 135.72 | G12: =IFERROR(IF(VLOOKUP($A12,'Annex 2 EHV charges'!$A:$O,10,FALSE)=0,"",VLOOKUP($A12,'Annex 2 EHV charges'!$A:$O,10,FALSE)),"") -> 0.94 | H12: =IFERROR(IF(VLOOKUP($A12,'Annex 2 EHV charges'!$A:$O,11,FALSE)=0,"",VLOOKUP($A12,'Annex 2 EHV charges'!$A:$O,11,FALSE)),"") -> 0.94 | I12: =IF(VLOOKUP(C12,'Annex 2 EHV charges'!$C$11:$P$154,14,FALSE)<=5,"",VLOOKUP(C12,'Annex 2 EHV charges'!$C$11:$P$154,14,FALSE))
A13: {=IFERROR(INDEX('Annex 2 EHV charges'!$A$11:$A$260, MATCH(0, IF(ISBLANK('Annex 2 EHV charges'!$A$11:$A$260),1, COUNTIF(A$4:$A12, 'Annex 2 EHV charges'!$A$11:$A$260)), 0)),"")} -> 808 | B13: =IF($A13="","",VLOOKUP($A13,'Annex 2 EHV charges'!$A:$O,2,0)) -> 808 | C13: =IF($A13="","",VLOOKUP($A13,'Annex 2 EHV charges'!$A:$O,3,0)) -> 1800053653870 | D13: =IF($A13="","",VLOOKUP($A13,'Annex 2 EHV charges'!$A:$O,7,0)) -> Garlaff Landfill | E13: =IFERROR(IF(VLOOKUP($A13,'Annex 2 EHV charges'!$A:$O,8,FALSE)=0,"",VLOOKUP($A13,'Annex 2 EHV charges'!$A:$O,8,FALSE)),"") -> - | F13: =IFERROR(IF(VLOOKUP($A13,'Annex 2 EHV charges'!$A:$O,9,FALSE)=0,"",VLOOKUP($A13,'Annex 2 EHV charges'!$A:$O,9,FALSE)),"") -> 104.76 | G13: =IFERROR(IF(VLOOKUP($A13,'Annex 2 EHV charges'!$A:$O,10,FALSE)=0,"",VLOOKUP($A13,'Annex 2 EHV charges'!$A:$O,10,FALSE)),"") -> 0.63 | H13: =IFERROR(IF(VLOOKUP($A13,'Annex 2 EHV charges'!$A:$O,11,FALSE)=0,"",VLOOKUP($A13,'Annex 2 EHV charges'!$A:$O,11,FALSE)),"") -> 0.63 | I13: =IF(VLOOKUP(C13,'Annex 2 EHV charges'!$C$11:$P$154,14,FALSE)<=5,"",VLOOKUP(C13,'Annex 2 EHV charges'!$C$11:$P$154,14,FALSE))
A14: {=IFERROR(INDEX('Annex 2 EHV charges'!$A$11:$A$260, MATCH(0, IF(ISBLANK('Annex 2 EHV charges'!$A$11:$A$260),1, COUNTIF(A$4:$A13, 'Annex 2 EHV charges'!$A$11:$A$260)), 0)),"")} -> 809 | B14: =IF($A14="","",VLOOKUP($A14,'Annex 2 EHV charges'!$A:$O,2,0)) -> 809 | C14: =IF($A14="","",VLOOKUP($A14,'Annex 2 EHV charges'!$A:$O,3,0)) -> 1800054992968 | D14: =IF($A14="","",VLOOKUP($A14,'Annex 2 EHV charges'!$A:$O,7,0)) -> Hagshaw Hill Extension | E14: =IFERROR(IF(VLOOKUP($A14,'Annex 2 EHV charges'!$A:$O,8,FALSE)=0,"",VLOOKUP($A14,'Annex 2 EHV charges'!$A:$O,8,FALSE)),"") -> - | F14: =IFERROR(IF(VLOOKUP($A14,'Annex 2 EHV charges'!$A:$O,9,FALSE)=0,"",VLOOKUP($A14,'Annex 2 EHV charges'!$A:$O,9,FALSE)),"") -> 718.91 | G14: =IFERROR(IF(VLOOKUP($A14,'Annex 2 EHV charges'!$A:$O,10,FALSE)=0,"",VLOOKUP($A14,'Annex 2 EHV charges'!$A:$O,10,FALSE)),"") -> 0.66 | H14: =IFERROR(IF(VLOOKUP($A14,'Annex 2 EHV charges'!$A:$O,11,FALSE)=0,"",VLOOKUP($A14,'Annex 2 EHV charges'!$A:$O,11,FALSE)),"") -> 0.66 | I14: =IF(VLOOKUP(C14,'Annex 2 EHV charges'!$C$11:$P$154,14,FALSE)<=5,"",VLOOKUP(C14,'Annex 2 EHV charges'!$C$11:$P$154,14,FALSE))
A15: {=IFERROR(INDEX('Annex 2 EHV charges'!$A$11:$A$260, MATCH(0, IF(ISBLANK('Annex 2 EHV charges'!$A$11:$A$260),1, COUNTIF(A$4:$A14, 'Annex 2 EHV charges'!$A$11:$A$260)), 0)),"")} -> 811 | B15: =IF($A15="","",VLOOKUP($A15,'Annex 2 EHV charges'!$A:$O,2,0)) -> 811 | C15: =IF($A15="","",VLOOKUP($A15,'Annex 2 EHV charges'!$A:$O,3,0)) -> 1800060328035 | D15: =IF($A15="","",VLOOKUP($A15,'Annex 2 EHV charges'!$A:$O,7,0)) -> Muirhall | E15: =IFERROR(IF(VLOOKUP($A15,'Annex 2 EHV charges'!$A:$O,8,FALSE)=0,"",VLOOKUP($A15,'Annex 2 EHV charges'!$A:$O,8,FALSE)),"") -> - | F15: =IFERROR(IF(VLOOKUP($A15,'Annex 2 EHV charges'!$A:$O,9,FALSE)=0,"",VLOOKUP($A15,'Annex 2 EHV charges'!$A:$O,9,FALSE)),"") -> 341.85 | G15: =IFERROR(IF(VLOOKUP($A15,'Annex 2 EHV charges'!$A:$O,10,FALSE)=0,"",VLOOKUP($A15,'Annex 2 EHV charges'!$A:$O,10,FALSE)),"") -> 0.83 | H15: =IFERROR(IF(VLOOKUP($A15,'Annex 2 EHV charges'!$A:$O,11,FALSE)=0,"",VLOOKUP($A15,'Annex 2 EHV charges'!$A:$O,11,FALSE)),"") -> 0.83 | I15: =IF(VLOOKUP(C15,'Annex 2 EHV charges'!$C$11:$P$154,14,FALSE)<=5,"",VLOOKUP(C15,'Annex 2 EHV charges'!$C$11:$P$154,14,FALSE))
A16: {=IFERROR(INDEX('Annex 2 EHV charges'!$A$11:$A$260, MATCH(0, IF(ISBLANK('Annex 2 EHV charges'!$A$11:$A$260),1, COUNTIF(A$4:$A15, 'Annex 2 EHV charges'!$A$11:$A$260)), 0)),"")} -> 812 | B16: =IF($A16="","",VLOOKUP($A16,'Annex 2 EHV charges'!$A:$O,2,0)) -> 812 | C16: =IF($A16="","",VLOOKUP($A16,'Annex 2 EHV charges'!$A:$O,3,0)) -> 1800060372113 | D16: =IF($A16="","",VLOOKUP($A16,'Annex 2 EHV charges'!$A:$O,7,0)) -> Burnfoot | E16: =IFERROR(IF(VLOOKUP($A16,'Annex 2 EHV charges'!$A:$O,8,FALSE)=0,"",VLOOKUP($A16,'Annex 2 EHV charges'!$A:$O,8,FALSE)),"") -> - | F16: =IFERROR(IF(VLOOKUP($A16,'Annex 2 EHV charges'!$A:$O,9,FALSE)=0,"",VLOOKUP($A16,'Annex 2 EHV charges'!$A:$O,9,FALSE)),"") -> 114.9 | G16: =IFERROR(IF(VLOOKUP($A16,'Annex 2 EHV charges'!$A:$O,10,FALSE)=0,"",VLOOKUP($A16,'Annex 2 EHV charges'!$A:$O,10,FALSE)),"") -> 0.7 | H16: =IFERROR(IF(VLOOKUP($A16,'Annex 2 EHV charges'!$A:$O,11,FALSE)=0,"",VLOOKUP($A16,'Annex 2 EHV charges'!$A:$O,11,FALSE)),"") -> 0.7 | I16: =IF(VLOOKUP(C16,'Annex 2 EHV charges'!$C$11:$P$154,14,FALSE)<=5,"",VLOOKUP(C16,'Annex 2 EHV charges'!$C$11:$P$154,14,FALSE))
... A142: {=IFERROR(INDEX('Annex 2 EHV charges'!$A$11:$A$260, MATCH(0, IF(ISBLANK('Annex 2 EHV charges'!$A$11:$A$260),1, COUNTIF(A$4:$A141, 'Annex 2 EHV charges'!$A$11:$A$260)), 0)),"")} | B142: =IF($A142="","",VLOOKUP($A142,'Annex 2 EHV charges'!$A:$O,2,0)) | C142: =IF($A142="","",VLOOKUP($A142,'Annex 2 EHV charges'!$A:$O,3,0)) | D142: =IF($A142="","",VLOOKUP($A142,'Annex 2 EHV charges'!$A:$O,7,0)) | E142: =IFERROR(IF(VLOOKUP($A142,'Annex 2 EHV charges'!$A:$O,8,FALSE)=0,"",VLOOKUP($A142,'Annex 2 EHV charges'!$A:$O,8,FALSE)),"") | F142: =IFERROR(IF(VLOOKUP($A142,'Annex 2 EHV charges'!$A:$O,9,FALSE)=0,"",VLOOKUP($A142,'Annex 2 EHV charges'!$A:$O,9,FALSE)),"") | G142: =IFERROR(IF(VLOOKUP($A142,'Annex 2 EHV charges'!$A:$O,10,FALSE)=0,"",VLOOKUP($A142,'Annex 2 EHV charges'!$A:$O,10,FALSE)),"") | H142: =IFERROR(IF(VLOOKUP($A142,'Annex 2 EHV charges'!$A:$O,11,FALSE)=0,"",VLOOKUP($A142,'Annex 2 EHV charges'!$A:$O,11,FALSE)),"") | I142: =IF(VLOOKUP(C142,'Annex 2 EHV charges'!$C$11:$P$154,14,FALSE)<=5,"",VLOOKUP(C142,'Annex 2 EHV charges'!$C$11:$P$154,14,FALSE))
A143: {=IFERROR(INDEX('Annex 2 EHV charges'!$A$11:$A$260, MATCH(0, IF(ISBLANK('Annex 2 EHV charges'!$A$11:$A$260),1, COUNTIF(A$4:$A142, 'Annex 2 EHV charges'!$A$11:$A$260)), 0)),"")} | B143: =IF($A143="","",VLOOKUP($A143,'Annex 2 EHV charges'!$A:$O,2,0)) | C143: =IF($A143="","",VLOOKUP($A143,'Annex 2 EHV charges'!$A:$O,3,0)) | D143: =IF($A143="","",VLOOKUP($A143,'Annex 2 EHV charges'!$A:$O,7,0)) | E143: =IFERROR(IF(VLOOKUP($A143,'Annex 2 EHV charges'!$A:$O,8,FALSE)=0,"",VLOOKUP($A143,'Annex 2 EHV charges'!$A:$O,8,FALSE)),"") | F143: =IFERROR(IF(VLOOKUP($A143,'Annex 2 EHV charges'!$A:$O,9,FALSE)=0,"",VLOOKUP($A143,'Annex 2 EHV charges'!$A:$O,9,FALSE)),"") | G143: =IFERROR(IF(VLOOKUP($A143,'Annex 2 EHV charges'!$A:$O,10,FALSE)=0,"",VLOOKUP($A143,'Annex 2 EHV charges'!$A:$O,10,FALSE)),"") | H143: =IFERROR(IF(VLOOKUP($A143,'Annex 2 EHV charges'!$A:$O,11,FALSE)=0,"",VLOOKUP($A143,'Annex 2 EHV charges'!$A:$O,11,FALSE)),"")
A144: {=IFERROR(INDEX('Annex 2 EHV charges'!$A$11:$A$260, MATCH(0, IF(ISBLANK('Annex 2 EHV charges'!$A$11:$A$260),1, COUNTIF(A$4:$A143, 'Annex 2 EHV charges'!$A$11:$A$260)), 0)),"")} | B144: =IF($A144="","",VLOOKUP($A144,'Annex 2 EHV charges'!$A:$O,2,0)) | C144: =IF($A144="","",VLOOKUP($A144,'Annex 2 EHV charges'!$A:$O,3,0)) | D144: =IF($A144="","",VLOOKUP($A144,'Annex 2 EHV charges'!$A:$O,7,0)) | E144: =IFERROR(IF(VLOOKUP($A144,'Annex 2 EHV charges'!$A:$O,8,FALSE)=0,"",VLOOKUP($A144,'Annex 2 EHV charges'!$A:$O,8,FALSE)),"") | F144: =IFERROR(IF(VLOOKUP($A144,'Annex 2 EHV charges'!$A:$O,9,FALSE)=0,"",VLOOKUP($A144,'Annex 2 EHV charges'!$A:$O,9,FALSE)),"") | G144: =IFERROR(IF(VLOOKUP($A144,'Annex 2 EHV charges'!$A:$O,10,FALSE)=0,"",VLOOKUP($A144,'Annex 2 EHV charges'!$A:$O,10,FALSE)),"") | H144: =IFERROR(IF(VLOOKUP($A144,'Annex 2 EHV charges'!$A:$O,11,FALSE)=0,"",VLOOKUP($A144,'Annex 2 EHV charges'!$A:$O,11,FALSE)),"")
A145: {=IFERROR(INDEX('Annex 2 EHV charges'!$A$11:$A$260, MATCH(0, IF(ISBLANK('Annex 2 EHV charges'!$A$11:$A$260),1, COUNTIF(A$4:$A144, 'Annex 2 EHV charges'!$A$11:$A$260)), 0)),"")} | B145: =IF($A145="","",VLOOKUP($A145,'Annex 2 EHV charges'!$A:$O,2,0)) | C145: =IF($A145="","",VLOOKUP($A145,'Annex 2 EHV charges'!$A:$O,3,0)) | D145: =IF($A145="","",VLOOKUP($A145,'Annex 2 EHV charges'!$A:$O,7,0)) | E145: =IFERROR(IF(VLOOKUP($A145,'Annex 2 EHV charges'!$A:$O,8,FALSE)=0,"",VLOOKUP($A145,'Annex 2 EHV charges'!$A:$O,8,FALSE)),"") | F145: =IFERROR(IF(VLOOKUP($A145,'Annex 2 EHV charges'!$A:$O,9,FALSE)=0,"",VLOOKUP($A145,'Annex 2 EHV charges'!$A:$O,9,FALSE)),"") | G145: =IFERROR(IF(VLOOKUP($A145,'Annex 2 EHV charges'!$A:$O,10,FALSE)=0,"",VLOOKUP($A145,'Annex 2 EHV charges'!$A:$O,10,FALSE)),"") | H145: =IFERROR(IF(VLOOKUP($A145,'Annex 2 EHV charges'!$A:$O,11,FALSE)=0,"",VLOOKUP($A145,'Annex 2 EHV charges'!$A:$O,11,FALSE)),"")
A146: {=IFERROR(INDEX('Annex 2 EHV charges'!$A$11:$A$260, MATCH(0, IF(ISBLANK('Annex 2 EHV charges'!$A$11:$A$260),1, COUNTIF(A$4:$A145, 'Annex 2 EHV charges'!$A$11:$A$260)), 0)),"")} | B146: =IF($A146="","",VLOOKUP($A146,'Annex 2 EHV charges'!$A:$O,2,0)) | C146: =IF($A146="","",VLOOKUP($A146,'Annex 2 EHV charges'!$A:$O,3,0)) | D146: =IF($A146="","",VLOOKUP($A146,'Annex 2 EHV charges'!$A:$O,7,0)) | E146: =IFERROR(IF(VLOOKUP($A146,'Annex 2 EHV charges'!$A:$O,8,FALSE)=0,"",VLOOKUP($A146,'Annex 2 EHV charges'!$A:$O,8,FALSE)),"") | F146: =IFERROR(IF(VLOOKUP($A146,'Annex 2 EHV charges'!$A:$O,9,FALSE)=0,"",VLOOKUP($A146,'Annex 2 EHV charges'!$A:$O,9,FALSE)),"") | G146: =IFERROR(IF(VLOOKUP($A146,'Annex 2 EHV charges'!$A:$O,10,FALSE)=0,"",VLOOKUP($A146,'Annex 2 EHV charges'!$A:$O,10,FALSE)),"") | H146: =IFERROR(IF(VLOOKUP($A146,'Annex 2 EHV charges'!$A:$O,11,FALSE)=0,"",VLOOKUP($A146,'Annex 2 EHV charges'!$A:$O,11,FALSE)),"")
A147: {=IFERROR(INDEX('Annex 2 EHV charges'!$A$11:$A$260, MATCH(0, IF(ISBLANK('Annex 2 EHV charges'!$A$11:$A$260),1, COUNTIF(A$4:$A146, 'Annex 2 EHV charges'!$A$11:$A$260)), 0)),"")} | B147: =IF($A147="","",VLOOKUP($A147,'Annex 2 EHV charges'!$A:$O,2,0)) | C147: =IF($A147="","",VLOOKUP($A147,'Annex 2 EHV charges'!$A:$O,3,0)) | D147: =IF($A147="","",VLOOKUP($A147,'Annex 2 EHV charges'!$A:$O,7,0)) | E147: =IFERROR(IF(VLOOKUP($A147,'Annex 2 EHV charges'!$A:$O,8,FALSE)=0,"",VLOOKUP($A147,'Annex 2 EHV charges'!$A:$O,8,FALSE)),"") | F147: =IFERROR(IF(VLOOKUP($A147,'Annex 2 EHV charges'!$A:$O,9,FALSE)=0,"",VLOOKUP($A147,'Annex 2 EHV charges'!$A:$O,9,FALSE)),"") | G147: =IFERROR(IF(VLOOKUP($A147,'Annex 2 EHV charges'!$A:$O,10,FALSE)=0,"",VLOOKUP($A147,'Annex 2 EHV charges'!$A:$O,10,FALSE)),"") | H147: =IFERROR(IF(VLOOKUP($A147,'Annex 2 EHV charges'!$A:$O,11,FALSE)=0,"",VLOOKUP($A147,'Annex 2 EHV charges'!$A:$O,11,FALSE)),"")
A148: {=IFERROR(INDEX('Annex 2 EHV charges'!$A$11:$A$260, MATCH(0, IF(ISBLANK('Annex 2 EHV charges'!$A$11:$A$260),1, COUNTIF(A$4:$A147, 'Annex 2 EHV charges'!$A$11:$A$260)), 0)),"")} | B148: =IF($A148="","",VLOOKUP($A148,'Annex 2 EHV charges'!$A:$O,2,0)) | C148: =IF($A148="","",VLOOKUP($A148,'Annex 2 EHV charges'!$A:$O,3,0)) | D148: =IF($A148="","",VLOOKUP($A148,'Annex 2 EHV charges'!$A:$O,7,0)) | E148: =IFERROR(IF(VLOOKUP($A148,'Annex 2 EHV charges'!$A:$O,8,FALSE)=0,"",VLOOKUP($A148,'Annex 2 EHV charges'!$A:$O,8,FALSE)),"") | F148: =IFERROR(IF(VLOOKUP($A148,'Annex 2 EHV charges'!$A:$O,9,FALSE)=0,"",VLOOKUP($A148,'Annex 2 EHV charges'!$A:$O,9,FALSE)),"") | G148: =IFERROR(IF(VLOOKUP($A148,'Annex 2 EHV charges'!$A:$O,10,FALSE)=0,"",VLOOKUP($A148,'Annex 2 EHV charges'!$A:$O,10,FALSE)),"") | H148: =IFERROR(IF(VLOOKUP($A148,'Annex 2 EHV charges'!$A:$O,11,FALSE)=0,"",VLOOKUP($A148,'Annex 2 EHV charges'!$A:$O,11,FALSE)),"")
A149: {=IFERROR(INDEX('Annex 2 EHV charges'!$A$11:$A$260, MATCH(0, IF(ISBLANK('Annex 2 EHV charges'!$A$11:$A$260),1, COUNTIF(A$4:$A148, 'Annex 2 EHV charges'!$A$11:$A$260)), 0)),"")} | B149: =IF($A149="","",VLOOKUP($A149,'Annex 2 EHV charges'!$A:$O,2,0)) | C149: =IF($A149="","",VLOOKUP($A149,'Annex 2 EHV charges'!$A:$O,3,0)) | D149: =IF($A149="","",VLOOKUP($A149,'Annex 2 EHV charges'!$A:$O,7,0)) | E149: =IFERROR(IF(VLOOKUP($A149,'Annex 2 EHV charges'!$A:$O,8,FALSE)=0,"",VLOOKUP($A149,'Annex 2 EHV charges'!$A:$O,8,FALSE)),"") | F149: =IFERROR(IF(VLOOKUP($A149,'Annex 2 EHV charges'!$A:$O,9,FALSE)=0,"",VLOOKUP($A149,'Annex 2 EHV charges'!$A:$O,9,FALSE)),"") | G149: =IFERROR(IF(VLOOKUP($A149,'Annex 2 EHV charges'!$A:$O,10,FALSE)=0,"",VLOOKUP($A149,'Annex 2 EHV charges'!$A:$O,10,FALSE)),"") | H149: =IFERROR(IF(VLOOKUP($A149,'Annex 2 EHV charges'!$A:$O,11,FALSE)=0,"",VLOOKUP($A149,'Annex 2 EHV charges'!$A:$O,11,FALSE)),"")
A150: {=IFERROR(INDEX('Annex 2 EHV charges'!$A$11:$A$260, MATCH(0, IF(ISBLANK('Annex 2 EHV charges'!$A$11:$A$260),1, COUNTIF(A$4:$A149, 'Annex 2 EHV charges'!$A$11:$A$260)), 0)),"")} | B150: =IF($A150="","",VLOOKUP($A150,'Annex 2 EHV charges'!$A:$O,2,0)) | C150: =IF($A150="","",VLOOKUP($A150,'Annex 2 EHV charges'!$A:$O,3,0)) | D150: =IF($A150="","",VLOOKUP($A150,'Annex 2 EHV charges'!$A:$O,7,0)) | E150: =IFERROR(IF(VLOOKUP($A150,'Annex 2 EHV charges'!$A:$O,8,FALSE)=0,"",VLOOKUP($A150,'Annex 2 EHV charges'!$A:$O,8,FALSE)),"") | F150: =IFERROR(IF(VLOOKUP($A150,'Annex 2 EHV charges'!$A:$O,9,FALSE)=0,"",VLOOKUP($A150,'Annex 2 EHV charges'!$A:$O,9,FALSE)),"") | G150: =IFERROR(IF(VLOOKUP($A150,'Annex 2 EHV charges'!$A:$O,10,FALSE)=0,"",VLOOKUP($A150,'Annex 2 EHV charges'!$A:$O,10,FALSE)),"") | H150: =IFERROR(IF(VLOOKUP($A150,'Annex 2 EHV charges'!$A:$O,11,FALSE)=0,"",VLOOKUP($A150,'Annex 2 EHV charges'!$A:$O,11,FALSE)),"")
A151: {=IFERROR(INDEX('Annex 2 EHV charges'!$A$11:$A$260, MATCH(0, IF(ISBLANK('Annex 2 EHV charges'!$A$11:$A$260),1, COUNTIF(A$4:$A150, 'Annex 2 EHV charges'!$A$11:$A$260)), 0)),"")} | B151: =IF($A151="","",VLOOKUP($A151,'Annex 2 EHV charges'!$A:$O,2,0)) | C151: =IF($A151="","",VLOOKUP($A151,'Annex 2 EHV charges'!$A:$O,3,0)) | D151: =IF($A151="","",VLOOKUP($A151,'Annex 2 EHV charges'!$A:$O,7,0)) | E151: =IFERROR(IF(VLOOKUP($A151,'Annex 2 EHV charges'!$A:$O,8,FALSE)=0,"",VLOOKUP($A151,'Annex 2 EHV charges'!$A:$O,8,FALSE)),"") | F151: =IFERROR(IF(VLOOKUP($A151,'Annex 2 EHV charges'!$A:$O,9,FALSE)=0,"",VLOOKUP($A151,'Annex 2 EHV charges'!$A:$O,9,FALSE)),"") | G151: =IFERROR(IF(VLOOKUP($A151,'Annex 2 EHV charges'!$A:$O,10,FALSE)=0,"",VLOOKUP($A151,'Annex 2 EHV charges'!$A:$O,10,FALSE)),"") | H151: =IFERROR(IF(VLOOKUP($A151,'Annex 2 EHV charges'!$A:$O,11,FALSE)=0,"",VLOOKUP($A151,'Annex 2 EHV charges'!$A:$O,11,FALSE)),"")
A152: {=IFERROR(INDEX('Annex 2 EHV charges'!$A$11:$A$260, MATCH(0, IF(ISBLANK('Annex 2 EHV charges'!$A$11:$A$260),1, COUNTIF(A$4:$A151, 'Annex 2 EHV charges'!$A$11:$A$260)), 0)),"")} | B152: =IF($A152="","",VLOOKUP($A152,'Annex 2 EHV charges'!$A:$O,2,0)) | C152: =IF($A152="","",VLOOKUP($A152,'Annex 2 EHV charges'!$A:$O,3,0)) | D152: =IF($A152="","",VLOOKUP($A152,'Annex 2 EHV charges'!$A:$O,7,0)) | E152: =IFERROR(IF(VLOOKUP($A152,'Annex 2 EHV charges'!$A:$O,8,FALSE)=0,"",VLOOKUP($A152,'Annex 2 EHV charges'!$A:$O,8,FALSE)),"") | F152: =IFERROR(IF(VLOOKUP($A152,'Annex 2 EHV charges'!$A:$O,9,FALSE)=0,"",VLOOKUP($A152,'Annex 2 EHV charges'!$A:$O,9,FALSE)),"") | G152: =IFERROR(IF(VLOOKUP($A152,'Annex 2 EHV charges'!$A:$O,10,FALSE)=0,"",VLOOKUP($A152,'Annex 2 EHV charges'!$A:$O,10,FALSE)),"") | H152: =IFERROR(IF(VLOOKUP($A152,'Annex 2 EHV charges'!$A:$O,11,FALSE)=0,"",VLOOKUP($A152,'Annex 2 EHV charges'!$A:$O,11,FALSE)),"")
A153: {=IFERROR(INDEX('Annex 2 EHV charges'!$A$11:$A$260, MATCH(0, IF(ISBLANK('Annex 2 EHV charges'!$A$11:$A$260),1, COUNTIF(A$4:$A152, 'Annex 2 EHV charges'!$A$11:$A$260)), 0)),"")} | B153: =IF($A153="","",VLOOKUP($A153,'Annex 2 EHV charges'!$A:$O,2,0)) | C153: =IF($A153="","",VLOOKUP($A153,'Annex 2 EHV charges'!$A:$O,3,0)) | D153: =IF($A153="","",VLOOKUP($A153,'Annex 2 EHV charges'!$A:$O,7,0)) | E153: =IFERROR(IF(VLOOKUP($A153,'Annex 2 EHV charges'!$A:$O,8,FALSE)=0,"",VLOOKUP($A153,'Annex 2 EHV charges'!$A:$O,8,FALSE)),"") | F153: =IFERROR(IF(VLOOKUP($A153,'Annex 2 EHV charges'!$A:$O,9,FALSE)=0,"",VLOOKUP($A153,'Annex 2 EHV charges'!$A:$O,9,FALSE)),"") | G153: =IFERROR(IF(VLOOKUP($A153,'Annex 2 EHV charges'!$A:$O,10,FALSE)=0,"",VLOOKUP($A153,'Annex 2 EHV charges'!$A:$O,10,FALSE)),"") | H153: =IFERROR(IF(VLOOKUP($A153,'Annex 2 EHV charges'!$A:$O,11,FALSE)=0,"",VLOOKUP($A153,'Annex 2 EHV charges'!$A:$O,11,FALSE)),"")
A154: {=IFERROR(INDEX('Annex 2 EHV charges'!$A$11:$A$260, MATCH(0, IF(ISBLANK('Annex 2 EHV charges'!$A$11:$A$260),1, COUNTIF(A$4:$A153, 'Annex 2 EHV charges'!$A$11:$A$260)), 0)),"")} | B154: =IF($A154="","",VLOOKUP($A154,'Annex 2 EHV charges'!$A:$O,2,0)) | C154: =IF($A154="","",VLOOKUP($A154,'Annex 2 EHV charges'!$A:$O,3,0)) | D154: =IF($A154="","",VLOOKUP($A154,'Annex 2 EHV charges'!$A:$O,7,0)) | E154: =IFERROR(IF(VLOOKUP($A154,'Annex 2 EHV charges'!$A:$O,8,FALSE)=0,"",VLOOKUP($A154,'Annex 2 EHV charges'!$A:$O,8,FALSE)),"") | F154: =IFERROR(IF(VLOOKUP($A154,'Annex 2 EHV charges'!$A:$O,9,FALSE)=0,"",VLOOKUP($A154,'Annex 2 EHV charges'!$A:$O,9,FALSE)),"") | G154: =IFERROR(IF(VLOOKUP($A154,'Annex 2 EHV charges'!$A:$O,10,FALSE)=0,"",VLOOKUP($A154,'Annex 2 EHV charges'!$A:$O,10,FALSE)),"") | H154: =IFERROR(IF(VLOOKUP($A154,'Annex 2 EHV charges'!$A:$O,11,FALSE)=0,"",VLOOKUP($A154,'Annex 2 EHV charges'!$A:$O,11,FALSE)),"")
... A254: {=IFERROR(INDEX('Annex 2 EHV charges'!$A$11:$A$260, MATCH(0, IF(ISBLANK('Annex 2 EHV charges'!$A$11:$A$260),1, COUNTIF(A$4:$A253, 'Annex 2 EHV charges'!$A$11:$A$260)), 0)),"")} | B254: =IF($A254="","",VLOOKUP($A254,'Annex 2 EHV charges'!$A:$O,2,0)) | C254: =IF($A254="","",VLOOKUP($A254,'Annex 2 EHV charges'!$A:$O,3,0)) | D254: =IF($A254="","",VLOOKUP($A254,'Annex 2 EHV charges'!$A:$O,7,0)) | E254: =IFERROR(IF(VLOOKUP($A254,'Annex 2 EHV charges'!$A:$O,8,FALSE)=0,"",VLOOKUP($A254,'Annex 2 EHV charges'!$A:$O,8,FALSE)),"") | F254: =IFERROR(IF(VLOOKUP($A254,'Annex 2 EHV charges'!$A:$O,9,FALSE)=0,"",VLOOKUP($A254,'Annex 2 EHV charges'!$A:$O,9,FALSE)),"") | G254: =IFERROR(IF(VLOOKUP($A254,'Annex 2 EHV charges'!$A:$O,10,FALSE)=0,"",VLOOKUP($A254,'Annex 2 EHV charges'!$A:$O,10,FALSE)),"") | H254: =IFERROR(IF(VLOOKUP($A254,'Annex 2 EHV charges'!$A:$O,11,FALSE)=0,"",VLOOKUP($A254,'Annex 2 EHV charges'!$A:$O,11,FALSE)),"")

Sheet Annex 2b Export
A1: Note: The list of MPANs / MSIDs provided may be incomplete; the DNO reserves the right to apply the listed charges to any other MPANs / MSIDs associated with the site. Note: This table is automatically populated based on the content of the tab entitled 'Annex 2 EHV Charges'. The timebands are as shown in Annex 2.
A2: =Overview!B4& " - Effective from "&Overview!D4&" - "&Overview!E4&" EDCM export charges" -> SP Distribution - Effective from 1 April 2022 - Final EDCM export charges
A4: Export Unique Identifier | B4: LLFC | C4: Export MPANs/MSIDs | D4: Name | E4: ='Annex 2 EHV charges'!L10 -> Export Super Red unit charge (p/kWh) | F4: ='Annex 2 EHV charges'!M10 -> Export fixed charge (p/day) | G4: ='Annex 2 EHV charges'!N10 -> Export capacity charge (p/kVA/day) | H4: ='Annex 2 EHV charges'!O10 -> Export exceeded capacity charge (p/kVA/day)
A5: {=IFERROR(INDEX('Annex 2 EHV charges'!$D$11:$D$260, MATCH(0, IF(ISBLANK('Annex 2 EHV charges'!$D$11:$D$260),1, COUNTIF(A$4:$A4, 'Annex 2 EHV charges'!$D$11:$D$260)), 0)),"")} -> 644 | B5: =IF($A5="","",VLOOKUP($A5,'Annex 2 EHV charges'!$D:$O,2,0)) -> 644 | C5: =IF($A5="","",VLOOKUP($A5,'Annex 2 EHV charges'!$D:$O,3,0)) -> 1800060775990 | D5: =IF($A5="","",VLOOKUP($A5,'Annex 2 EHV charges'!$D:$O,4,0)) -> Rhodders | E5: =IFERROR(IF(VLOOKUP($A5,'Annex 2 EHV charges'!$D:$O,9,FALSE)=0,"",VLOOKUP($A5,'Annex 2 EHV charges'!$D:$O,9,FALSE)),"") -> - | F5: =IFERROR(IF(VLOOKUP($A5,'Annex 2 EHV charges'!$D:$O,10,FALSE)=0,"",VLOOKUP($A5,'Annex 2 EHV charges'!$D:$O,10,FALSE)),"") -> 5687.62 | G5: =IFERROR(IF(VLOOKUP($A5,'Annex 2 EHV charges'!$D:$O,11,FALSE)=0,"",VLOOKUP($A5,'Annex 2 EHV charges'!$D:$O,11,FALSE)),"") -> 0.05 | H5: =IFERROR(IF(VLOOKUP($A5,'Annex 2 EHV charges'!$D:$O,12,FALSE)=0,"",VLOOKUP($A5,'Annex 2 EHV charges'!$D:$O,12,FALSE)),"") -> 0.05 | I5: =IF(VLOOKUP(C5,'Annex 2 EHV charges'!$F$11:$P$157,11,FALSE)<=5,"",VLOOKUP(C5,'Annex 2 EHV charges'!$F$11:$P$157,11,FALSE))
A6: {=IFERROR(INDEX('Annex 2 EHV charges'!$D$11:$D$260, MATCH(0, IF(ISBLANK('Annex 2 EHV charges'!$D$11:$D$260),1, COUNTIF(A$4:$A5, 'Annex 2 EHV charges'!$D$11:$D$260)), 0)),"")} -> MSID 8182 | B6: =IF($A6="","",VLOOKUP($A6,'Annex 2 EHV charges'!$D:$O,2,0)) -> MSID 8182 | C6: =IF($A6="","",VLOOKUP($A6,'Annex 2 EHV charges'!$D:$O,3,0)) -> MSID 8182 | D6: =IF($A6="","",VLOOKUP($A6,'Annex 2 EHV charges'!$D:$O,4,0)) -> Minsca | E6: =IFERROR(IF(VLOOKUP($A6,'Annex 2 EHV charges'!$D:$O,9,FALSE)=0,"",VLOOKUP($A6,'Annex 2 EHV charges'!$D:$O,9,FALSE)),"") -> - | F6: =IFERROR(IF(VLOOKUP($A6,'Annex 2 EHV charges'!$D:$O,10,FALSE)=0,"",VLOOKUP($A6,'Annex 2 EHV charges'!$D:$O,10,FALSE)),"") -> - | G6: =IFERROR(IF(VLOOKUP($A6,'Annex 2 EHV charges'!$D:$O,11,FALSE)=0,"",VLOOKUP($A6,'Annex 2 EHV charges'!$D:$O,11,FALSE)),"") -> - | H6: =IFERROR(IF(VLOOKUP($A6,'Annex 2 EHV charges'!$D:$O,12,FALSE)=0,"",VLOOKUP($A6,'Annex 2 EHV charges'!$D:$O,12,FALSE)),"") -> - | I6: =IF(VLOOKUP(C6,'Annex 2 EHV charges'!$F$11:$P$157,11,FALSE)<=5,"",VLOOKUP(C6,'Annex 2 EHV charges'!$F$11:$P$157,11,FALSE))
A7: {=IFERROR(INDEX('Annex 2 EHV charges'!$D$11:$D$260, MATCH(0, IF(ISBLANK('Annex 2 EHV charges'!$D$11:$D$260),1, COUNTIF(A$4:$A6, 'Annex 2 EHV charges'!$D$11:$D$260)), 0)),"")} -> 683 | B7: =IF($A7="","",VLOOKUP($A7,'Annex 2 EHV charges'!$D:$O,2,0)) -> 683 | C7: =IF($A7="","",VLOOKUP($A7,'Annex 2 EHV charges'!$D:$O,3,0)) -> 1800060539971 | D7: =IF($A7="","",VLOOKUP($A7,'Annex 2 EHV charges'!$D:$O,4,0)) -> Bankend Rig | E7: =IFERROR(IF(VLOOKUP($A7,'Annex 2 EHV charges'!$D:$O,9,FALSE)=0,"",VLOOKUP($A7,'Annex 2 EHV charges'!$D:$O,9,FALSE)),"") -> - | F7: =IFERROR(IF(VLOOKUP($A7,'Annex 2 EHV charges'!$D:$O,10,FALSE)=0,"",VLOOKUP($A7,'Annex 2 EHV charges'!$D:$O,10,FALSE)),"") -> 4944.09 | G7: =IFERROR(IF(VLOOKUP($A7,'Annex 2 EHV charges'!$D:$O,11,FALSE)=0,"",VLOOKUP($A7,'Annex 2 EHV charges'!$D:$O,11,FALSE)),"") -> 0.05 | H7: =IFERROR(IF(VLOOKUP($A7,'Annex 2 EHV charges'!$D:$O,12,FALSE)=0,"",VLOOKUP($A7,'Annex 2 EHV charges'!$D:$O,12,FALSE)),"") -> 0.05 | I7: =IF(VLOOKUP(C7,'Annex 2 EHV charges'!$F$11:$P$157,11,FALSE)<=5,"",VLOOKUP(C7,'Annex 2 EHV charges'!$F$11:$P$157,11,FALSE))
A8: {=IFERROR(INDEX('Annex 2 EHV charges'!$D$11:$D$260, MATCH(0, IF(ISBLANK('Annex 2 EHV charges'!$D$11:$D$260),1, COUNTIF(A$4:$A7, 'Annex 2 EHV charges'!$D$11:$D$260)), 0)),"")} -> 684 | B8: =IF($A8="","",VLOOKUP($A8,'Annex 2 EHV charges'!$D:$O,2,0)) -> 684 | C8: =IF($A8="","",VLOOKUP($A8,'Annex 2 EHV charges'!$D:$O,3,0)) -> 1800060532717 | D8: =IF($A8="","",VLOOKUP($A8,'Annex 2 EHV charges'!$D:$O,4,0)) -> Barlockhart Moor | E8: =IFERROR(IF(VLOOKUP($A8,'Annex 2 EHV charges'!$D:$O,9,FALSE)=0,"",VLOOKUP($A8,'Annex 2 EHV charges'!$D:$O,9,FALSE)),"") -> - | F8: =IFERROR(IF(VLOOKUP($A8,'Annex 2 EHV charges'!$D:$O,10,FALSE)=0,"",VLOOKUP($A8,'Annex 2 EHV charges'!$D:$O,10,FALSE)),"") -> 8983 | G8: =IFERROR(IF(VLOOKUP($A8,'Annex 2 EHV charges'!$D:$O,11,FALSE)=0,"",VLOOKUP($A8,'Annex 2 EHV charges'!$D:$O,11,FALSE)),"") -> 0.05 | H8: =IFERROR(IF(VLOOKUP($A8,'Annex 2 EHV charges'!$D:$O,12,FALSE)=0,"",VLOOKUP($A8,'Annex 2 EHV charges'!$D:$O,12,FALSE)),"") -> 0.05 | I8: =IF(VLOOKUP(C8,'Annex 2 EHV charges'!$F$11:$P$157,11,FALSE)<=5,"",VLOOKUP(C8,'Annex 2 EHV charges'!$F$11:$P$157,11,FALSE))
A9: {=IFERROR(INDEX('Annex 2 EHV charges'!$D$11:$D$260, MATCH(0, IF(ISBLANK('Annex 2 EHV charges'!$D$11:$D$260),1, COUNTIF(A$4:$A8, 'Annex 2 EHV charges'!$D$11:$D$260)), 0)),"")} -> 685 | B9: =IF($A9="","",VLOOKUP($A9,'Annex 2 EHV charges'!$D:$O,2,0)) -> 685 | C9: =IF($A9="","",VLOOKUP($A9,'Annex 2 EHV charges'!$D:$O,3,0)) -> 1800060532735 | D9: =IF($A9="","",VLOOKUP($A9,'Annex 2 EHV charges'!$D:$O,4,0)) -> Blantyre Muir | E9: =IFERROR(IF(VLOOKUP($A9,'Annex 2 EHV charges'!$D:$O,9,FALSE)=0,"",VLOOKUP($A9,'Annex 2 EHV charges'!$D:$O,9,FALSE)),"") -> - | F9: =IFERROR(IF(VLOOKUP($A9,'Annex 2 EHV charges'!$D:$O,10,FALSE)=0,"",VLOOKUP($A9,'Annex 2 EHV charges'!$D:$O,10,FALSE)),"") -> 5840.28 | G9: =IFERROR(IF(VLOOKUP($A9,'Annex 2 EHV charges'!$D:$O,11,FALSE)=0,"",VLOOKUP($A9,'Annex 2 EHV charges'!$D:$O,11,FALSE)),"") -> 0.05 | H9: =IFERROR(IF(VLOOKUP($A9,'Annex 2 EHV charges'!$D:$O,12,FALSE)=0,"",VLOOKUP($A9,'Annex 2 EHV charges'!$D:$O,12,FALSE)),"") -> 0.05 | I9: =IF(VLOOKUP(C9,'Annex 2 EHV charges'!$F$11:$P$157,11,FALSE)<=5,"",VLOOKUP(C9,'Annex 2 EHV charges'!$F$11:$P$157,11,FALSE))
A10: {=IFERROR(INDEX('Annex 2 EHV charges'!$D$11:$D$260, MATCH(0, IF(ISBLANK('Annex 2 EHV charges'!$D$11:$D$260),1, COUNTIF(A$4:$A9, 'Annex 2 EHV charges'!$D$11:$D$260)), 0)),"")} -> 693 | B10: =IF($A10="","",VLOOKUP($A10,'Annex 2 EHV charges'!$D:$O,2,0)) -> 693 | C10: =IF($A10="","",VLOOKUP($A10,'Annex 2 EHV charges'!$D:$O,3,0)) -> 1800060587869 | D10: =IF($A10="","",VLOOKUP($A10,'Annex 2 EHV charges'!$D:$O,4,0)) -> Hunterston WF | E10: =IFERROR(IF(VLOOKUP($A10,'Annex 2 EHV charges'!$D:$O,9,FALSE)=0,"",VLOOKUP($A10,'Annex 2 EHV charges'!$D:$O,9,FALSE)),"") -> - | F10: =IFERROR(IF(VLOOKUP($A10,'Annex 2 EHV charges'!$D:$O,10,FALSE)=0,"",VLOOKUP($A10,'Annex 2 EHV charges'!$D:$O,10,FALSE)),"") -> - | G10: =IFERROR(IF(VLOOKUP($A10,'Annex 2 EHV charges'!$D:$O,11,FALSE)=0,"",VLOOKUP($A10,'Annex 2 EHV charges'!$D:$O,11,FALSE)),"") -> - | H10: =IFERROR(IF(VLOOKUP($A10,'Annex 2 EHV charges'!$D:$O,12,FALSE)=0,"",VLOOKUP($A10,'Annex 2 EHV charges'!$D:$O,12,FALSE)),"") -> - | I10: =IF(VLOOKUP(C10,'Annex 2 EHV charges'!$F$11:$P$157,11,FALSE)<=5,"",VLOOKUP(C10,'Annex 2 EHV charges'!$F$11:$P$157,11,FALSE))
A11: {=IFERROR(INDEX('Annex 2 EHV charges'!$D$11:$D$260, MATCH(0, IF(ISBLANK('Annex 2 EHV charges'!$D$11:$D$260),1, COUNTIF(A$4:$A10, 'Annex 2 EHV charges'!$D$11:$D$260)), 0)),"")} -> 688 | B11: =IF($A11="","",VLOOKUP($A11,'Annex 2 EHV charges'!$D:$O,2,0)) -> 688 | C11: =IF($A11="","",VLOOKUP($A11,'Annex 2 EHV charges'!$D:$O,3,0)) -> 1800060532656 | D11: =IF($A11="","",VLOOKUP($A11,'Annex 2 EHV charges'!$D:$O,4,0)) -> Middleton Farm | E11: =IFERROR(IF(VLOOKUP($A11,'Annex 2 EHV charges'!$D:$O,9,FALSE)=0,"",VLOOKUP($A11,'Annex 2 EHV charges'!$D:$O,9,FALSE)),"") -> - | F11: =IFERROR(IF(VLOOKUP($A11,'Annex 2 EHV charges'!$D:$O,10,FALSE)=0,"",VLOOKUP($A11,'Annex 2 EHV charges'!$D:$O,10,FALSE)),"") -> 5222.16 | G11: =IFERROR(IF(VLOOKUP($A11,'Annex 2 EHV charges'!$D:$O,11,FALSE)=0,"",VLOOKUP($A11,'Annex 2 EHV charges'!$D:$O,11,FALSE)),"") -> 0.05 | H11: =IFERROR(IF(VLOOKUP($A11,'Annex 2 EHV charges'!$D:$O,12,FALSE)=0,"",VLOOKUP($A11,'Annex 2 EHV charges'!$D:$O,12,FALSE)),"") -> 0.05 | I11: =IF(VLOOKUP(C11,'Annex 2 EHV charges'!$F$11:$P$157,11,FALSE)<=5,"",VLOOKUP(C11,'Annex 2 EHV charges'!$F$11:$P$157,11,FALSE))
A12: {=IFERROR(INDEX('Annex 2 EHV charges'!$D$11:$D$260, MATCH(0, IF(ISBLANK('Annex 2 EHV charges'!$D$11:$D$260),1, COUNTIF(A$4:$A11, 'Annex 2 EHV charges'!$D$11:$D$260)), 0)),"")} -> 689 | B12: =IF($A12="","",VLOOKUP($A12,'Annex 2 EHV charges'!$D:$O,2,0)) -> 689 | C12: =IF($A12="","",VLOOKUP($A12,'Annex 2 EHV charges'!$D:$O,3,0)) -> 1800060532674 | D12: =IF($A12="","",VLOOKUP($A12,'Annex 2 EHV charges'!$D:$O,4,0)) -> Neilston Community | E12: =IFERROR(IF(VLOOKUP($A12,'Annex 2 EHV charges'!$D:$O,9,FALSE)=0,"",VLOOKUP($A12,'Annex 2 EHV charges'!$D:$O,9,FALSE)),"") -> - | F12: =IFERROR(IF(VLOOKUP($A12,'Annex 2 EHV charges'!$D:$O,10,FALSE)=0,"",VLOOKUP($A12,'Annex 2 EHV charges'!$D:$O,10,FALSE)),"") -> 6406.7 | G12: =IFERROR(IF(VLOOKUP($A12,'Annex 2 EHV charges'!$D:$O,11,FALSE)=0,"",VLOOKUP($A12,'Annex 2 EHV charges'!$D:$O,11,FALSE)),"") -> 0.05 | H12: =IFERROR(IF(VLOOKUP($A12,'Annex 2 EHV charges'!$D:$O,12,FALSE)=0,"",VLOOKUP($A12,'Annex 2 EHV charges'!$D:$O,12,FALSE)),"") -> 0.05 | I12: =IF(VLOOKUP(C12,'Annex 2 EHV charges'!$F$11:$P$157,11,FALSE)<=5,"",VLOOKUP(C12,'Annex 2 EHV charges'!$F$11:$P$157,11,FALSE))
A13: {=IFERROR(INDEX('Annex 2 EHV charges'!$D$11:$D$260, MATCH(0, IF(ISBLANK('Annex 2 EHV charges'!$D$11:$D$260),1, COUNTIF(A$4:$A12, 'Annex 2 EHV charges'!$D$11:$D$260)), 0)),"")} -> 681 | B13: =IF($A13="","",VLOOKUP($A13,'Annex 2 EHV charges'!$D:$O,2,0)) -> 681 | C13: =IF($A13="","",VLOOKUP($A13,'Annex 2 EHV charges'!$D:$O,3,0)) -> 1800053653880 | D13: =IF($A13="","",VLOOKUP($A13,'Annex 2 EHV charges'!$D:$O,4,0)) -> Garlaff Landfill | E13: =IFERROR(IF(VLOOKUP($A13,'Annex 2 EHV charges'!$D:$O,9,FALSE)=0,"",VLOOKUP($A13,'Annex 2 EHV charges'!$D:$O,9,FALSE)),"") -> - | F13: =IFERROR(IF(VLOOKUP($A13,'Annex 2 EHV charges'!$D:$O,10,FALSE)=0,"",VLOOKUP($A13,'Annex 2 EHV charges'!$D:$O,10,FALSE)),"") -> - | G13: =IFERROR(IF(VLOOKUP($A13,'Annex 2 EHV charges'!$D:$O,11,FALSE)=0,"",VLOOKUP($A13,'Annex 2 EHV charges'!$D:$O,11,FALSE)),"") -> - | H13: =IFERROR(IF(VLOOKUP($A13,'Annex 2 EHV charges'!$D:$O,12,FALSE)=0,"",VLOOKUP($A13,'Annex 2 EHV charges'!$D:$O,12,FALSE)),"") -> - | I13: =IF(VLOOKUP(C13,'Annex 2 EHV charges'!$F$11:$P$157,11,FALSE)<=5,"",VLOOKUP(C13,'Annex 2 EHV charges'!$F$11:$P$157,11,FALSE))
A14: {=IFERROR(INDEX('Annex 2 EHV charges'!$D$11:$D$260, MATCH(0, IF(ISBLANK('Annex 2 EHV charges'!$D$11:$D$260),1, COUNTIF(A$4:$A13, 'Annex 2 EHV charges'!$D$11:$D$260)), 0)),"")} -> 629 | B14: =IF($A14="","",VLOOKUP($A14,'Annex 2 EHV charges'!$D:$O,2,0)) -> 629 | C14: =IF($A14="","",VLOOKUP($A14,'Annex 2 EHV charges'!$D:$O,3,0)) -> 1800054992977 | D14: =IF($A14="","",VLOOKUP($A14,'Annex 2 EHV charges'!$D:$O,4,0)) -> Hagshaw Hill Extension | E14: =IFERROR(IF(VLOOKUP($A14,'Annex 2 EHV charges'!$D:$O,9,FALSE)=0,"",VLOOKUP($A14,'Annex 2 EHV charges'!$D:$O,9,FALSE)),"") -> - | F14: =IFERROR(IF(VLOOKUP($A14,'Annex 2 EHV charges'!$D:$O,10,FALSE)=0,"",VLOOKUP($A14,'Annex 2 EHV charges'!$D:$O,10,FALSE)),"") -> 18154.96 | G14: =IFERROR(IF(VLOOKUP($A14,'Annex 2 EHV charges'!$D:$O,11,FALSE)=0,"",VLOOKUP($A14,'Annex 2 EHV charges'!$D:$O,11,FALSE)),"") -> 0.05 | H14: =IFERROR(IF(VLOOKUP($A14,'Annex 2 EHV charges'!$D:$O,12,FALSE)=0,"",VLOOKUP($A14,'Annex 2 EHV charges'!$D:$O,12,FALSE)),"") -> 0.05 | I14: =IF(VLOOKUP(C14,'Annex 2 EHV charges'!$F$11:$P$157,11,FALSE)<=5,"",VLOOKUP(C14,'Annex 2 EHV charges'!$F$11:$P$157,11,FALSE))
A15: {=IFERROR(INDEX('Annex 2 EHV charges'!$D$11:$D$260, MATCH(0, IF(ISBLANK('Annex 2 EHV charges'!$D$11:$D$260),1, COUNTIF(A$4:$A14, 'Annex 2 EHV charges'!$D$11:$D$260)), 0)),"")} -> 671 | B15: =IF($A15="","",VLOOKUP($A15,'Annex 2 EHV charges'!$D:$O,2,0)) -> 671 | C15: =IF($A15="","",VLOOKUP($A15,'Annex 2 EHV charges'!$D:$O,3,0)) -> 1800060328044 | D15: =IF($A15="","",VLOOKUP($A15,'Annex 2 EHV charges'!$D:$O,4,0)) -> Muirhall | E15: =IFERROR(IF(VLOOKUP($A15,'Annex 2 EHV charges'!$D:$O,9,FALSE)=0,"",VLOOKUP($A15,'Annex 2 EHV charges'!$D:$O,9,FALSE)),"") -> - | F15: =IFERROR(IF(VLOOKUP($A15,'Annex 2 EHV charges'!$D:$O,10,FALSE)=0,"",VLOOKUP($A15,'Annex 2 EHV charges'!$D:$O,10,FALSE)),"") -> 8204.45 | G15: =IFERROR(IF(VLOOKUP($A15,'Annex 2 EHV charges'!$D:$O,11,FALSE)=0,"",VLOOKUP($A15,'Annex 2 EHV charges'!$D:$O,11,FALSE)),"") -> 0.05 | H15: =IFERROR(IF(VLOOKUP($A15,'Annex 2 EHV charges'!$D:$O,12,FALSE)=0,"",VLOOKUP($A15,'Annex 2 EHV charges'!$D:$O,12,FALSE)),"") -> 0.05 | I15: =IF(VLOOKUP(C15,'Annex 2 EHV charges'!$F$11:$P$157,11,FALSE)<=5,"",VLOOKUP(C15,'Annex 2 EHV charges'!$F$11:$P$157,11,FALSE))
A16: {=IFERROR(INDEX('Annex 2 EHV charges'!$D$11:$D$260, MATCH(0, IF(ISBLANK('Annex 2 EHV charges'!$D$11:$D$260),1, COUNTIF(A$4:$A15, 'Annex 2 EHV charges'!$D$11:$D$260)), 0)),"")} -> 672 | B16: =IF($A16="","",VLOOKUP($A16,'Annex 2 EHV charges'!$D:$O,2,0)) -> 672 | C16: =IF($A16="","",VLOOKUP($A16,'Annex 2 EHV charges'!$D:$O,3,0)) -> 1800060372122 | D16: =IF($A16="","",VLOOKUP($A16,'Annex 2 EHV charges'!$D:$O,4,0)) -> Burnfoot | E16: =IFERROR(IF(VLOOKUP($A16,'Annex 2 EHV charges'!$D:$O,9,FALSE)=0,"",VLOOKUP($A16,'Annex 2 EHV charges'!$D:$O,9,FALSE)),"") -> - | F16: =IFERROR(IF(VLOOKUP($A16,'Annex 2 EHV charges'!$D:$O,10,FALSE)=0,"",VLOOKUP($A16,'Annex 2 EHV charges'!$D:$O,10,FALSE)),"") -> 8017.86 | G16: =IFERROR(IF(VLOOKUP($A16,'Annex 2 EHV charges'!$D:$O,11,FALSE)=0,"",VLOOKUP($A16,'Annex 2 EHV charges'!$D:$O,11,FALSE)),"") -> 0.05 | H16: =IFERROR(IF(VLOOKUP($A16,'Annex 2 EHV charges'!$D:$O,12,FALSE)=0,"",VLOOKUP($A16,'Annex 2 EHV charges'!$D:$O,12,FALSE)),"") -> 0.05 | I16: =IF(VLOOKUP(C16,'Annex 2 EHV charges'!$F$11:$P$157,11,FALSE)<=5,"",VLOOKUP(C16,'Annex 2 EHV charges'!$F$11:$P$157,11,FALSE))
