Workbook
Name OLE_LINK1: 'Annex 3 Preserved charges'!#REF!

Sheet Overview
A2: Company and Licence name, charging year, effective from, status
B3: Company and Licence name | C3: Year | D3: Effective From | E3: Status
A4: Company and Licence name, charging year, effective from, status | B4: SP Manweb | C4: 2019/20 | D4: 1 April 2019 | E4: Final
A6: List of data tables in this workbook
A7: Worksheet | B7: Information
A8: Annex 1 LV and HV charges | B8: Annex 1 contains the charges to LV and HV Designated Properties.
A9: Annex 2 EHV charges | B9: ="Annex 2 contains the charges to Designated EHV Properties and charges applied to LDNOs with Designated EHV Properties/end-users embedded in networks within the " &B4 &" Licence area." -> Annex 2 contains the charges to Designated EHV Properties and charges applied to LDNOs with Designated EHV Properties/end-users embedded in networks within the SP Manweb Licence area.
A10: Annex 3 Preserved charges | B10: Annex 3 contains details of any preserved and additional charges that are valid at this time.
A11: Annex 4 LDNO charges | B11: ="Annex 4 contains charges that are levied on the owner of an embedded network within the "&B4&" Licence area. "&"Electricity suppliers and consumers who have properties connected to an embedded network should contact the embedded network owner to determine their distribution charges."&" The charges listed in this table are not payable by domestic consumers, business consumers or electricity suppliers." -> Annex 4 contains charges that are levied on the owner of an embedded network within the SP Manweb Licence area. Electricity suppliers and consumers who have properties connected to an embedded network should contact the embedded network owner to determine their distribution charges. The charges listed in this table are not payable by domestic consumers, business consumers or electricity suppliers.
A12: Annex 5 LLFs | B12: Annex 5 has been intentionally left blank as this charging statement is published a complete year before the LLFs have been audited. The line loss factors that are approved by the BSC Panel for the applicable year and consequently published on the Elexon website will take precedence and be used in Settlement. This annex will be re-published with these values once they are available.
A13: Annex 6 Charges for New or Amended Designated EHV Properties | B13: ="Annex 6 contains the charges for new or amended Designated EHV Properties and charges applied to LDNOs with new or amended Designated EHV Properties/end-users embedded in networks within the " &B4 &" Licence area." -> Annex 6 contains the charges for new or amended Designated EHV Properties and charges applied to LDNOs with new or amended Designated EHV Properties/end-users embedded in networks within the SP Manweb Licence area.
A14: Nodal prices | B14: Contains the underlying [nodal/network group] costs used to calculate the current EDCM charges.
A15: SSC TPR to unit rate lookup table | B15: The time periods for the non half hourly metered charge rates in Annex 1 are as specified by the SSC. To determine the appropriate charge rate for each SSC/TPR a lookup table is provided.
A16: Charge calculator | B16: Charge calculator is a tool to help you estimate your distribution charges using current consumption data and forecast consumption data.
A18: Notes to users of this spreadsheet
A20: Please use this spreadsheet with reference to the LC14 use of system charging statement.
A22: Notes to DNOs populating this spreadsheet
A24: DNOs must endeavour to maintain consistency in the structure of this spreadsheet. Any changes to the structure must be noted in the 'Notes to users of this spreadsheet'
A25: The drop down list on the charge calculator can be expanded by unprotecting the charge calculator sheet and selecting 'data', 'data validation...' and then expanding the 'source' data range. The sheet can then be protected.

Sheet Annex 1 LV and HV charges
A1: Back to Overview | B1: 'DNOs paste value cells A15:J47 from CDCM 3701 into cells A14:J46 | E1: Note: Where a tariff only has a p/kWh unit rate in Unit Charge 1 then this unit rate applies at all times.
A2: SP Manweb - Effective from 1 April 2019 - Final LV and HV charges
A4: Time Bands for Half Hourly Metered Properties | G4: Time Bands for Half Hourly Unmetered Properties
A5: Time periods | B5: Red Time Band | C5: Amber Time Band | E5: Green Time Band | I5: Black Time Band | J5: Yellow Time Band | K5: Green Time Band
A6: Monday to Friday (Including Bank Holidays) All Year | B6: 16.30 - 19.30 | C6: 08.00 - 16.30 19.30 - 22.30 | E6: 00.00 - 08.00 22.30 - 00.00 | G6: Monday to Friday (Including Bank Holidays) June to August Inclusive | J6: 08.00 - 22.30 | K6: 00.00 - 08.00 22.30 - 00.00
A7: Saturday and Sunday All Year | C7: 16.00 - 20.00 | E7: 00.00 - 16.00 20.00 - 00.00 | G7: Monday to Friday (Including Bank Holidays) November to February Inclusive | I7: 16.30 - 19.30 | J7: 08.00 - 16.30 19.30 - 22.30 | K7: 00.00 - 08.00 22.30 - 00.00
A8: Notes | B8: All the above times are in UK Clock time | G8: Monday to Friday (Including Bank Holidays) March, April, May and September, October | J8: 08.00 - 22.30 | K8: 00.00 - 08.00 22.30 - 00.00
G9: Saturday and Sunday All year | J9: 16.00 - 20.00 | K9: 00:00-16:00 20:00-00:00
G10: Notes | I10: All the above times are in UK Clock time
A13: Tariff name | B13: Open LLFCs | C13: PCs | D13: Unit charge 1 (NHH) or red/black charge (HH) p/kWh | E13: Unit charge 2 (NHH) or amber/yellow charge (HH) p/kWh | F13: Green charge(HH) p/kWh | G13: Fixed charge p/MPAN/day | H13: Capacity charge p/kVA/day | I13: Exceeded capacity charge p/kVA/day | J13: Reactive power charge p/kVArh | K13: Closed LLFCs
A14: Domestic Unrestricted* | B14: 101, 102 | C14: 1 | D14: 3.356 | G14: 3.68
A15: Domestic Two Rate* | B15: 103, 105, 111, 112, 113, 114, 115, 116, 117, 118, 119, 120, 131, 132, 133, 134, 147, 148, 149, 150 | C15: 2 | D15: 3.686 | E15: 1.545 | G15: 3.68 | K15: 145, 146
A16: Domestic Off Peak (related MPAN) | B16: 104, 106, 130, 153, 155 | C16: 2 | D16: 1.556 | K16: 135, 136, 137, 138, 140, 141, 142, 143
A17: Small Non Domestic Unrestricted | B17: 201, 202, 203, 209 | C17: 3 | D17: 3.367 | G17: 4.63 | K17: 207
A18: Small Non Domestic Two Rate | B18: 205, 211, 231, 232 | C18: 4 | D18: 3.515 | E18: 1.466 | G18: 4.63 | K18: 208, 210
A19: Small Non Domestic Off Peak (related MPAN) | B19: 212 | C19: 4 | D19: 1.498 | K19: 233, 234, 235, 236, 237
A20: LV Network Domestic* | B20: 180 | C20: 0 | D20: 12.266 | E20: 2.621 | F20: 1.453 | G20: 3.68
A21: LV Network Non-Domestic Non-CT | B21: 280 | C21: 0 | D21: 12.568 | E21: 2.659 | F21: 1.458 | G21: 4.63
A22: LV HH Metered | B22: 511, 591 | C22: 0 | D22: 10.481 | E22: 2.305 | F22: 1.423 | G22: 18.71 | H22: 2.51 | I22: 4.46 | J22: 0.367 | K22: 501
A23: LV Sub HH Metered | B23: 513, 592 | C23: 0 | D23: 8.066 | E23: 1.869 | F23: 1.383 | G23: 6.6 | H23: 5.15 | I23: 7.12 | J23: 0.232 | K23: 503
A24: HV HH Metered | B24: 515, 593 | C24: 0 | D24: 6.54 | E24: 1.653 | F24: 1.352 | G24: 99.97 | H24: 4.05 | I24: 6.63 | J24: 0.161 | K24: 505
A25: NHH UMS category A | B25: 900 | C25: 8 | D25: 2.707 | K25: 904, 912, 913
A26: NHH UMS category B | B26: 901 | C26: 1 | D26: 2.974 | K26: 905
A27: NHH UMS category C | B27: 902 | C27: 1 | D27: 4.108 | K27: 906
A28: NHH UMS category D | B28: 903 | C28: 1 | D28: 2.521 | K28: 907
A29: LV UMS (Pseudo HH Metered) | B29: 910 | C29: 0 | D29: 20.912 | E29: 2.645 | F29: 1.731
A30: LV Generation NHH or Aggregate HH | B30: 781, 782, 783, 784, 785 | C30: 8&0 | D30: -1.228 | G30: 0
A31: LV Sub Generation NHH | B31: 780 | C31: 8 | D31: -1.098 | G31: 0
A32: LV Generation Intermittent | B32: 786, 787 | C32: 0 | D32: -1.228 | G32: 0 | J32: 0.302
A33: LV Generation Intermittent no RP charge | B33: 764 | C33: 0 | D33: -1.228 | G33: 0
A34: LV Generation Non-Intermittent | B34: 791, 795 | C34: 0 | D34: -8.287 | E34: -1.036 | F34: -0.158 | G34: 0 | J34: 0.302
A35: LV Generation Non-Intermittent no RP charge | B35: 765 | C35: 0 | D35: -8.287 | E35: -1.036 | F35: -0.158 | G35: 0
A36: LV Sub Generation Intermittent | B36: 788, 789 | C36: 0 | D36: -1.098 | G36: 0 | J36: 0.28
A37: LV Sub Generation Intermittent no RP charge | B37: 766 | C37: 0 | D37: -1.098 | G37: 0
A38: LV Sub Generation Non-Intermittent | B38: 792, 796 | C38: 0 | D38: -7.514 | E38: -0.898 | F38: -0.145 | G38: 0 | J38: 0.28
A39: LV Sub Generation Non-Intermittent no RP charge | B39: 767 | C39: 0 | D39: -7.514 | E39: -0.898 | F39: -0.145 | G39: 0
A40: HV Generation Intermittent | B40: 770, 771 | C40: 0 | D40: -0.723 | G40: 73 | J40: 0.214
A41: HV Generation Intermittent no RP charge | B41: 768 | C41: 0 | D41: -0.723 | G41: 73
A42: HV Generation Non-Intermittent | B42: 793, 797 | C42: 0 | D42: -5.385 | E42: -0.471 | F42: -0.11 | G42: 73 | J42: 0.214
A43: HV Generation Non-Intermittent no RP charge | B43: 769 | C43: 0 | D43: -5.385 | E43: -0.471 | F43: -0.11 | G43: 73
...

Sheet Annex 2 EHV charges
A1: Back to Overview | C1: Copy EDCM table 5001 range starting B101 and paste into G11. Extend or reduce print area as required. | F1: Note: The list of MPANs / MSIDs provided may be incomplete; the DNO reserves the right to apply the listed charges to any other MPANs / MSIDs associated with the site.
A2: SP Manweb - Effective from 1 April 2019 - Final EDCM charges
A4: Time Periods for Designated EHV Properties
A5: Time periods | D5: Super Red Time Band
A6: Monday to Friday (Including Bank Holidays) June to August Inclusive
A7: Monday to Friday (Including Bank Holidays) November to February Inclusive | D7: 16:30 - 19:30
A8: Notes | D8: All the above times are in UK Clock time
A10: Import Unique Identifier | B10: LLFC | C10: Import MPANs/MSIDs | D10: Export Unique Identifier | E10: LLFC | F10: Export MPANs/MSIDs | G10: Name | H10: Import Super Red unit charge (p/kWh) | I10: Import fixed charge (p/day) | J10: Import capacity charge (p/kVA/day) | K10: Import exceeded capacity charge (p/kVA/day) | L10: Export Super Red unit charge (p/kWh) | M10: Export fixed charge (p/day) | N10: Export capacity charge (p/kVA/day) | O10: Export exceeded capacity charge (p/kVA/day)
A11: 803 | B11: 803 | C11: 1300035361194 | D11: 603 | E11: 603 | F11: 1300050649372 | G11: Shell Stanlow | I11: 19306.088 | J11: 6.6 | K11: 6.6 | L11: -0.262 | M11: 2382.34 | N11: 0.05 | O11: 0.05
A12: 804 | B12: 804 | C12: 1300035352942 | G12: Jaguar & Land Rover | H12: 0.302 | I12: 8711.76 | J12: 8.49 | K12: 8.49
A13: 805 | B13: 805 | C13: 1300035359423 | G13: Innospec | H13: 0.263 | I13: 844.42 | J13: 4.65 | K13: 4.65
A14: 806 | B14: 806 | C14: 1300051060972 | D14: 606 | E14: 606 | F14: 1300051060981 | G14: Bridgewater Paper | I14: 98.14 | J14: 3.14 | K14: 3.14
A15: 807 | B15: 807 | C15: 1300035359752 | G15: General Motors | H15: 0.266 | I15: 14550.17 | J15: 4.52 | K15: 4.52
A16: 808 | B16: 808 | C16: 1300035360066 | G16: TATA Steel | I16: 38475.65 | J16: 5.07 | K16: 5.07
A17: 809 | B17: 809 | C17: 1300035362480 | G17: Urenco | J17: 4.09 | K17: 4.09
A18: 810 | B18: 810 | C18: 1300051694818 | D18: 618 | E18: 618 | F18: 1300060704603 | G18: Ineos Chlor Ltd (Lostock) | I18: 13181.11 | J18: 1.56 | K18: 1.56 | M18: 2015.58 | N18: 0.05 | O18: 0.05
A19: 811 | B19: 811 | C19: 1300060704073 | D19: 655 | E19: 655 | F19: 1300060704082 | G19: SafeGuard Bradwell | H19: 1.713 | I19: 45.24 | J19: 4.42 | K19: 4.42 | M19: 3528.34 | N19: 0.05 | O19: 0.05
A20: 812 | B20: 812 | C20: 1300035356130 | G20: Knauf Insulation | H20: 0.305 | I20: 1697.93 | J20: 7.75 | K20: 7.75
A21: 813 | B21: 813 | C21: 1300035359585 | G21: Air Products | H21: 0.34 | I21: 384.2 | J21: 4.42 | K21: 4.42
A22: 814 | B22: 814 | C22: 1300035359619 | G22: Shell Chemicals | H22: 0.275 | I22: 1697.93 | J22: 8.79 | K22: 8.79
A23: 815 | B23: 815 | C23: 1300035359780 | G23: GrowHow | H23: 0.27 | I23: 8712.75 | J23: 9.18 | K23: 9.18
A24: 816 | B24: 816 | C24: 1300053536398 | G24: Castle Cement | I24: 954.31 | J24: 3.98 | K24: 3.98
A25: 817 | B25: 817 | C25: 1300035361992 | D25: 648 | E25: 648 | F25: 1300060640474 | G25: Kronospan | I25: 3839.5651 | J25: 14.85 | K25: 14.88 | M25: 388.97 | N25: 0.05 | O25: 0.05
A26: 819 | B26: 819 | C26: 1300035365082 | D26: 619 | E26: 619 | F26: 1300051136210 | G26: Albion Inorganic | H26: 1.956 | I26: 203.72 | J26: 1.91 | K26: 1.91
A27: 820 | B27: 820 | C27: 1300060563740 | D27: 658 | E27: 658 | F27: 1300060563759 | G27: Tyn dryfol PV | I27: 8.05 | J27: 3.68 | K27: 3.68 | M27: 2414.17 | N27: 0.05 | O27: 0.05
A28: 821 | B28: 821 | C28: 1300035367967 | D28: 621 | E28: 621 | F28: 1300050649336 | G28: BHP | I28: 8456.6218 | J28: 2.89 | K28: 2.89
A29: 822 | B29: 822 | C29: 1300060251601 | G29: Hole House Farm | I29: 9536.12 | J29: 6.33 | K29: 6.33
A30: 823 | B30: 823 | C30: 1300060652610 | D30: 659 | E30: 659 | F30: 1300060652629 | G30: Williams Farm Solar Park | I30: 6.76 | J30: 3.78 | K30: 3.78 | M30: 743.42 | N30: 0.05 | O30: 0.05
A31: 824 | B31: 824 | C31: 1300054940674 | D31: 604 | E31: 604 | F31: 1300054940683 | G31: Port of Liverpool | I31: 27.66 | J31: 2.62 | K31: 2.62 | M31: 1659.61 | N31: 0.05 | O31: 0.05
A32: 826 | B32: 826 | C32: 1300060579173 | D32: 661 | E32: 661 | F32: 1300060579182 | G32: Combermere Abbey PV | I32: 14.3 | J32: 5.02 | K32: 5.02 | M32: 2496.2 | N32: 0.05 | O32: 0.05
A33: 827 | B33: 827 | C33: 1300052785147 | G33: Kimberley Clark | I33: 677.72 | J33: 14.05 | K33: 14.05
A34: 828 | B34: 828 | C34: 1300060075390 | D34: 628 | E34: 628 | F34: 1300060075405 | G34: Amegni | I34: 7.96 | J34: 2.28 | K34: 2.28 | M34: 620.7 | N34: 0.05 | O34: 0.05
A35: 829 | B35: 829 | C35: 1300035400611 | D35: 629 | E35: 629 | F35: 1300038004507 | G35: Salt Union | I35: 348.62 | J35: 2.75 | K35: 2.75
A36: 830 | B36: 830 | C36: 1300060584270 | D36: 681 | E36: 681 | F36: 1300060584280 | G36: Parciau Solar Park | I36: 6.35 | J36: 4.18 | K36: 4.18 | M36: 756.47 | N36: 0.05 | O36: 0.05
A37: 831 | B37: 831 | C37: 1300035437700 | G37: Ineos Chlor Ltd (Percival Lane) | I37: 416.27 | J37: 5.85 | K37: 5.85
A38: 833 | B38: 833 | C38: 1300035361803 | G38: Toyota | I38: 2830.69 | J38: 5.57 | K38: 5.57
A39: 834 | B39: 834 | C39: 1300051028551 | G39: Warmingham Gas Storage | I39: 3884.8343 | J39: 6.71 | K39: 6.71
A40: 835 | B40: 835 | C40: 1300050648875 | D40: 635 | E40: 635 | F40: 1300050931602 | G40: Arpley Landfill | H40: 1.713 | I40: 11.68 | J40: 3.29 | K40: 3.29
A41: 836 | B41: 836 | C41: 1300035360800 | G41: Amcor | I41: 2010.87 | J41: 10.64 | K41: 10.64
A42: 838 | B42: 838 | C42: 1300052122840 | D42: 638 | E42: 638 | F42: 1300052122859 | G42: Cemmaes C | I42: 8.94 | J42: 2.78 | K42: 2.78
...

Sheet Annex 2a Import
A1: Note: The list of MPANs / MSIDs provided may be incomplete; the DNO reserves the right to apply the listed charges to any other MPANs / MSIDs associated with the site. Note: This table is automatically populated based on the content of the tab entitled 'Annex 2 EHV Charges'. The timebands are as shown in Annex 2.
A2: =Overview!B4& " - Effective from "&Overview!D4&" - "&Overview!E4&" EDCM import charges" -> SP Manweb - Effective from 1 April 2019 - Final EDCM import charges
A4: Import Unique Identifier | B4: LLFC | C4: Import MPANs/MSIDs | D4: Name | E4: ='Annex 2 EHV charges'!H10 -> Import Super Red unit charge (p/kWh) | F4: ='Annex 2 EHV charges'!I10 -> Import fixed charge (p/day) | G4: ='Annex 2 EHV charges'!J10 -> Import capacity charge (p/kVA/day) | H4: ='Annex 2 EHV charges'!K10 -> Import exceeded capacity charge (p/kVA/day)
A5: {=IFERROR(INDEX('Annex 2 EHV charges'!$A$11:$A$259, MATCH(0, IF(ISBLANK('Annex 2 EHV charges'!$A$11:$A$259),1, COUNTIF(A$4:$A4, 'Annex 2 EHV charges'!$A$11:$A$259)), 0)),"")} -> 803 | B5: =IF($A5="","",VLOOKUP($A5,'Annex 2 EHV charges'!$A:$O,2,0)) -> 803 | C5: =IF($A5="","",VLOOKUP($A5,'Annex 2 EHV charges'!$A:$O,3,0)) -> 1300035361194 | D5: =IF($A5="","",VLOOKUP($A5,'Annex 2 EHV charges'!$A:$O,7,0)) -> Shell Stanlow | E5: =IFERROR(IF(VLOOKUP($A5,'Annex 2 EHV charges'!$A:$O,8,FALSE)=0,"",VLOOKUP($A5,'Annex 2 EHV charges'!$A:$O,8,FALSE)),"") | F5: =IFERROR(IF(VLOOKUP($A5,'Annex 2 EHV charges'!$A:$O,9,FALSE)=0,"",VLOOKUP($A5,'Annex 2 EHV charges'!$A:$O,9,FALSE)),"") -> 19306.088 | G5: =IFERROR(IF(VLOOKUP($A5,'Annex 2 EHV charges'!$A:$O,10,FALSE)=0,"",VLOOKUP($A5,'Annex 2 EHV charges'!$A:$O,10,FALSE)),"") -> 6.6 | H5: =IFERROR(IF(VLOOKUP($A5,'Annex 2 EHV charges'!$A:$O,11,FALSE)=0,"",VLOOKUP($A5,'Annex 2 EHV charges'!$A:$O,11,FALSE)),"") -> 6.6
A6: {=IFERROR(INDEX('Annex 2 EHV charges'!$A$11:$A$259, MATCH(0, IF(ISBLANK('Annex 2 EHV charges'!$A$11:$A$259),1, COUNTIF(A$4:$A5, 'Annex 2 EHV charges'!$A$11:$A$259)), 0)),"")} -> 804 | B6: =IF($A6="","",VLOOKUP($A6,'Annex 2 EHV charges'!$A:$O,2,0)) -> 804 | C6: =IF($A6="","",VLOOKUP($A6,'Annex 2 EHV charges'!$A:$O,3,0)) -> 1300035352942 | D6: =IF($A6="","",VLOOKUP($A6,'Annex 2 EHV charges'!$A:$O,7,0)) -> Jaguar & Land Rover | E6: =IFERROR(IF(VLOOKUP($A6,'Annex 2 EHV charges'!$A:$O,8,FALSE)=0,"",VLOOKUP($A6,'Annex 2 EHV charges'!$A:$O,8,FALSE)),"") -> 0.302 | F6: =IFERROR(IF(VLOOKUP($A6,'Annex 2 EHV charges'!$A:$O,9,FALSE)=0,"",VLOOKUP($A6,'Annex 2 EHV charges'!$A:$O,9,FALSE)),"") -> 8711.76 | G6: =IFERROR(IF(VLOOKUP($A6,'Annex 2 EHV charges'!$A:$O,10,FALSE)=0,"",VLOOKUP($A6,'Annex 2 EHV charges'!$A:$O,10,FALSE)),"") -> 8.49 | H6: =IFERROR(IF(VLOOKUP($A6,'Annex 2 EHV charges'!$A:$O,11,FALSE)=0,"",VLOOKUP($A6,'Annex 2 EHV charges'!$A:$O,11,FALSE)),"") -> 8.49
A7: {=IFERROR(INDEX('Annex 2 EHV charges'!$A$11:$A$259, MATCH(0, IF(ISBLANK('Annex 2 EHV charges'!$A$11:$A$259),1, COUNTIF(A$4:$A6, 'Annex 2 EHV charges'!$A$11:$A$259)), 0)),"")} -> 805 | B7: =IF($A7="","",VLOOKUP($A7,'Annex 2 EHV charges'!$A:$O,2,0)) -> 805 | C7: =IF($A7="","",VLOOKUP($A7,'Annex 2 EHV charges'!$A:$O,3,0)) -> 1300035359423 | D7: =IF($A7="","",VLOOKUP($A7,'Annex 2 EHV charges'!$A:$O,7,0)) -> Innospec | E7: =IFERROR(IF(VLOOKUP($A7,'Annex 2 EHV charges'!$A:$O,8,FALSE)=0,"",VLOOKUP($A7,'Annex 2 EHV charges'!$A:$O,8,FALSE)),"") -> 0.263 | F7: =IFERROR(IF(VLOOKUP($A7,'Annex 2 EHV charges'!$A:$O,9,FALSE)=0,"",VLOOKUP($A7,'Annex 2 EHV charges'!$A:$O,9,FALSE)),"") -> 844.42 | G7: =IFERROR(IF(VLOOKUP($A7,'Annex 2 EHV charges'!$A:$O,10,FALSE)=0,"",VLOOKUP($A7,'Annex 2 EHV charges'!$A:$O,10,FALSE)),"") -> 4.65 | H7: =IFERROR(IF(VLOOKUP($A7,'Annex 2 EHV charges'!$A:$O,11,FALSE)=0,"",VLOOKUP($A7,'Annex 2 EHV charges'!$A:$O,11,FALSE)),"") -> 4.65
A8: {=IFERROR(INDEX('Annex 2 EHV charges'!$A$11:$A$259, MATCH(0, IF(ISBLANK('Annex 2 EHV charges'!$A$11:$A$259),1, COUNTIF(A$4:$A7, 'Annex 2 EHV charges'!$A$11:$A$259)), 0)),"")} -> 806 | B8: =IF($A8="","",VLOOKUP($A8,'Annex 2 EHV charges'!$A:$O,2,0)) -> 806 | C8: =IF($A8="","",VLOOKUP($A8,'Annex 2 EHV charges'!$A:$O,3,0)) -> 1300051060972 | D8: =IF($A8="","",VLOOKUP($A8,'Annex 2 EHV charges'!$A:$O,7,0)) -> Bridgewater Paper | E8: =IFERROR(IF(VLOOKUP($A8,'Annex 2 EHV charges'!$A:$O,8,FALSE)=0,"",VLOOKUP($A8,'Annex 2 EHV charges'!$A:$O,8,FALSE)),"") | F8: =IFERROR(IF(VLOOKUP($A8,'Annex 2 EHV charges'!$A:$O,9,FALSE)=0,"",VLOOKUP($A8,'Annex 2 EHV charges'!$A:$O,9,FALSE)),"") -> 98.14 | G8: =IFERROR(IF(VLOOKUP($A8,'Annex 2 EHV charges'!$A:$O,10,FALSE)=0,"",VLOOKUP($A8,'Annex 2 EHV charges'!$A:$O,10,FALSE)),"") -> 3.14 | H8: =IFERROR(IF(VLOOKUP($A8,'Annex 2 EHV charges'!$A:$O,11,FALSE)=0,"",VLOOKUP($A8,'Annex 2 EHV charges'!$A:$O,11,FALSE)),"") -> 3.14
A9: {=IFERROR(INDEX('Annex 2 EHV charges'!$A$11:$A$259, MATCH(0, IF(ISBLANK('Annex 2 EHV charges'!$A$11:$A$259),1, COUNTIF(A$4:$A8, 'Annex 2 EHV charges'!$A$11:$A$259)), 0)),"")} -> 807 | B9: =IF($A9="","",VLOOKUP($A9,'Annex 2 EHV charges'!$A:$O,2,0)) -> 807 | C9: =IF($A9="","",VLOOKUP($A9,'Annex 2 EHV charges'!$A:$O,3,0)) -> 1300035359752 | D9: =IF($A9="","",VLOOKUP($A9,'Annex 2 EHV charges'!$A:$O,7,0)) -> General Motors | E9: =IFERROR(IF(VLOOKUP($A9,'Annex 2 EHV charges'!$A:$O,8,FALSE)=0,"",VLOOKUP($A9,'Annex 2 EHV charges'!$A:$O,8,FALSE)),"") -> 0.266 | F9: =IFERROR(IF(VLOOKUP($A9,'Annex 2 EHV charges'!$A:$O,9,FALSE)=0,"",VLOOKUP($A9,'Annex 2 EHV charges'!$A:$O,9,FALSE)),"") -> 14550.17 | G9: =IFERROR(IF(VLOOKUP($A9,'Annex 2 EHV charges'!$A:$O,10,FALSE)=0,"",VLOOKUP($A9,'Annex 2 EHV charges'!$A:$O,10,FALSE)),"") -> 4.52 | H9: =IFERROR(IF(VLOOKUP($A9,'Annex 2 EHV charges'!$A:$O,11,FALSE)=0,"",VLOOKUP($A9,'Annex 2 EHV charges'!$A:$O,11,FALSE)),"") -> 4.52
A10: {=IFERROR(INDEX('Annex 2 EHV charges'!$A$11:$A$259, MATCH(0, IF(ISBLANK('Annex 2 EHV charges'!$A$11:$A$259),1, COUNTIF(A$4:$A9, 'Annex 2 EHV charges'!$A$11:$A$259)), 0)),"")} -> 808 | B10: =IF($A10="","",VLOOKUP($A10,'Annex 2 EHV charges'!$A:$O,2,0)) -> 808 | C10: =IF($A10="","",VLOOKUP($A10,'Annex 2 EHV charges'!$A:$O,3,0)) -> 1300035360066 | D10: =IF($A10="","",VLOOKUP($A10,'Annex 2 EHV charges'!$A:$O,7,0)) -> TATA Steel | E10: =IFERROR(IF(VLOOKUP($A10,'Annex 2 EHV charges'!$A:$O,8,FALSE)=0,"",VLOOKUP($A10,'Annex 2 EHV charges'!$A:$O,8,FALSE)),"") | F10: =IFERROR(IF(VLOOKUP($A10,'Annex 2 EHV charges'!$A:$O,9,FALSE)=0,"",VLOOKUP($A10,'Annex 2 EHV charges'!$A:$O,9,FALSE)),"") -> 38475.65 | G10: =IFERROR(IF(VLOOKUP($A10,'Annex 2 EHV charges'!$A:$O,10,FALSE)=0,"",VLOOKUP($A10,'Annex 2 EHV charges'!$A:$O,10,FALSE)),"") -> 5.07 | H10: =IFERROR(IF(VLOOKUP($A10,'Annex 2 EHV charges'!$A:$O,11,FALSE)=0,"",VLOOKUP($A10,'Annex 2 EHV charges'!$A:$O,11,FALSE)),"") -> 5.07
A11: {=IFERROR(INDEX('Annex 2 EHV charges'!$A$11:$A$259, MATCH(0, IF(ISBLANK('Annex 2 EHV charges'!$A$11:$A$259),1, COUNTIF(A$4:$A10, 'Annex 2 EHV charges'!$A$11:$A$259)), 0)),"")} -> 809 | B11: =IF($A11="","",VLOOKUP($A11,'Annex 2 EHV charges'!$A:$O,2,0)) -> 809 | C11: =IF($A11="","",VLOOKUP($A11,'Annex 2 EHV charges'!$A:$O,3,0)) -> 1300035362480 | D11: =IF($A11="","",VLOOKUP($A11,'Annex 2 EHV charges'!$A:$O,7,0)) -> Urenco | E11: =IFERROR(IF(VLOOKUP($A11,'Annex 2 EHV charges'!$A:$O,8,FALSE)=0,"",VLOOKUP($A11,'Annex 2 EHV charges'!$A:$O,8,FALSE)),"") | F11: =IFERROR(IF(VLOOKUP($A11,'Annex 2 EHV charges'!$A:$O,9,FALSE)=0,"",VLOOKUP($A11,'Annex 2 EHV charges'!$A:$O,9,FALSE)),"") | G11: =IFERROR(IF(VLOOKUP($A11,'Annex 2 EHV charges'!$A:$O,10,FALSE)=0,"",VLOOKUP($A11,'Annex 2 EHV charges'!$A:$O,10,FALSE)),"") -> 4.09 | H11: =IFERROR(IF(VLOOKUP($A11,'Annex 2 EHV charges'!$A:$O,11,FALSE)=0,"",VLOOKUP($A11,'Annex 2 EHV charges'!$A:$O,11,FALSE)),"") -> 4.09
A12: {=IFERROR(INDEX('Annex 2 EHV charges'!$A$11:$A$259, MATCH(0, IF(ISBLANK('Annex 2 EHV charges'!$A$11:$A$259),1, COUNTIF(A$4:$A11, 'Annex 2 EHV charges'!$A$11:$A$259)), 0)),"")} -> 810 | B12: =IF($A12="","",VLOOKUP($A12,'Annex 2 EHV charges'!$A:$O,2,0)) -> 810 | C12: =IF($A12="","",VLOOKUP($A12,'Annex 2 EHV charges'!$A:$O,3,0)) -> 1300051694818 | D12: =IF($A12="","",VLOOKUP($A12,'Annex 2 EHV charges'!$A:$O,7,0)) -> Ineos Chlor Ltd (Lostock) | E12: =IFERROR(IF(VLOOKUP($A12,'Annex 2 EHV charges'!$A:$O,8,FALSE)=0,"",VLOOKUP($A12,'Annex 2 EHV charges'!$A:$O,8,FALSE)),"") | F12: =IFERROR(IF(VLOOKUP($A12,'Annex 2 EHV charges'!$A:$O,9,FALSE)=0,"",VLOOKUP($A12,'Annex 2 EHV charges'!$A:$O,9,FALSE)),"") -> 13181.11 | G12: =IFERROR(IF(VLOOKUP($A12,'Annex 2 EHV charges'!$A:$O,10,FALSE)=0,"",VLOOKUP($A12,'Annex 2 EHV charges'!$A:$O,10,FALSE)),"") -> 1.56 | H12: =IFERROR(IF(VLOOKUP($A12,'Annex 2 EHV charges'!$A:$O,11,FALSE)=0,"",VLOOKUP($A12,'Annex 2 EHV charges'!$A:$O,11,FALSE)),"") -> 1.56
A13: {=IFERROR(INDEX('Annex 2 EHV charges'!$A$11:$A$259, MATCH(0, IF(ISBLANK('Annex 2 EHV charges'!$A$11:$A$259),1, COUNTIF(A$4:$A12, 'Annex 2 EHV charges'!$A$11:$A$259)), 0)),"")} -> 811 | B13: =IF($A13="","",VLOOKUP($A13,'Annex 2 EHV charges'!$A:$O,2,0)) -> 811 | C13: =IF($A13="","",VLOOKUP($A13,'Annex 2 EHV charges'!$A:$O,3,0)) -> 1300060704073 | D13: =IF($A13="","",VLOOKUP($A13,'Annex 2 EHV charges'!$A:$O,7,0)) -> SafeGuard Bradwell | E13: =IFERROR(IF(VLOOKUP($A13,'Annex 2 EHV charges'!$A:$O,8,FALSE)=0,"",VLOOKUP($A13,'Annex 2 EHV charges'!$A:$O,8,FALSE)),"") -> 1.713 | F13: =IFERROR(IF(VLOOKUP($A13,'Annex 2 EHV charges'!$A:$O,9,FALSE)=0,"",VLOOKUP($A13,'Annex 2 EHV charges'!$A:$O,9,FALSE)),"") -> 45.24 | G13: =IFERROR(IF(VLOOKUP($A13,'Annex 2 EHV charges'!$A:$O,10,FALSE)=0,"",VLOOKUP($A13,'Annex 2 EHV charges'!$A:$O,10,FALSE)),"") -> 4.42 | H13: =IFERROR(IF(VLOOKUP($A13,'Annex 2 EHV charges'!$A:$O,11,FALSE)=0,"",VLOOKUP($A13,'Annex 2 EHV charges'!$A:$O,11,FALSE)),"") -> 4.42
A14: {=IFERROR(INDEX('Annex 2 EHV charges'!$A$11:$A$259, MATCH(0, IF(ISBLANK('Annex 2 EHV charges'!$A$11:$A$259),1, COUNTIF(A$4:$A13, 'Annex 2 EHV charges'!$A$11:$A$259)), 0)),"")} -> 812 | B14: =IF($A14="","",VLOOKUP($A14,'Annex 2 EHV charges'!$A:$O,2,0)) -> 812 | C14: =IF($A14="","",VLOOKUP($A14,'Annex 2 EHV charges'!$A:$O,3,0)) -> 1300035356130 | D14: =IF($A14="","",VLOOKUP($A14,'Annex 2 EHV charges'!$A:$O,7,0)) -> Knauf Insulation | E14: =IFERROR(IF(VLOOKUP($A14,'Annex 2 EHV charges'!$A:$O,8,FALSE)=0,"",VLOOKUP($A14,'Annex 2 EHV charges'!$A:$O,8,FALSE)),"") -> 0.305 | F14: =IFERROR(IF(VLOOKUP($A14,'Annex 2 EHV charges'!$A:$O,9,FALSE)=0,"",VLOOKUP($A14,'Annex 2 EHV charges'!$A:$O,9,FALSE)),"") -> 1697.93 | G14: =IFERROR(IF(VLOOKUP($A14,'Annex 2 EHV charges'!$A:$O,10,FALSE)=0,"",VLOOKUP($A14,'Annex 2 EHV charges'!$A:$O,10,FALSE)),"") -> 7.75 | H14: =IFERROR(IF(VLOOKUP($A14,'Annex 2 EHV charges'!$A:$O,11,FALSE)=0,"",VLOOKUP($A14,'Annex 2 EHV charges'!$A:$O,11,FALSE)),"") -> 7.75
A15: {=IFERROR(INDEX('Annex 2 EHV charges'!$A$11:$A$259, MATCH(0, IF(ISBLANK('Annex 2 EHV charges'!$A$11:$A$259),1, COUNTIF(A$4:$A14, 'Annex 2 EHV charges'!$A$11:$A$259)), 0)),"")} -> 813 | B15: =IF($A15="","",VLOOKUP($A15,'Annex 2 EHV charges'!$A:$O,2,0)) -> 813 | C15: =IF($A15="","",VLOOKUP($A15,'Annex 2 EHV charges'!$A:$O,3,0)) -> 1300035359585 | D15: =IF($A15="","",VLOOKUP($A15,'Annex 2 EHV charges'!$A:$O,7,0)) -> Air Products | E15: =IFERROR(IF(VLOOKUP($A15,'Annex 2 EHV charges'!$A:$O,8,FALSE)=0,"",VLOOKUP($A15,'Annex 2 EHV charges'!$A:$O,8,FALSE)),"") -> 0.34 | F15: =IFERROR(IF(VLOOKUP($A15,'Annex 2 EHV charges'!$A:$O,9,FALSE)=0,"",VLOOKUP($A15,'Annex 2 EHV charges'!$A:$O,9,FALSE)),"") -> 384.2 | G15: =IFERROR(IF(VLOOKUP($A15,'Annex 2 EHV charges'!$A:$O,10,FALSE)=0,"",VLOOKUP($A15,'Annex 2 EHV charges'!$A:$O,10,FALSE)),"") -> 4.42 | H15: =IFERROR(IF(VLOOKUP($A15,'Annex 2 EHV charges'!$A:$O,11,FALSE)=0,"",VLOOKUP($A15,'Annex 2 EHV charges'!$A:$O,11,FALSE)),"") -> 4.42
A16: {=IFERROR(INDEX('Annex 2 EHV charges'!$A$11:$A$259, MATCH(0, IF(ISBLANK('Annex 2 EHV charges'!$A$11:$A$259),1, COUNTIF(A$4:$A15, 'Annex 2 EHV charges'!$A$11:$A$259)), 0)),"")} -> 814 | B16: =IF($A16="","",VLOOKUP($A16,'Annex 2 EHV charges'!$A:$O,2,0)) -> 814 | C16: =IF($A16="","",VLOOKUP($A16,'Annex 2 EHV charges'!$A:$O,3,0)) -> 1300035359619 | D16: =IF($A16="","",VLOOKUP($A16,'Annex 2 EHV charges'!$A:$O,7,0)) -> Shell Chemicals | E16: =IFERROR(IF(VLOOKUP($A16,'Annex 2 EHV charges'!$A:$O,8,FALSE)=0,"",VLOOKUP($A16,'Annex 2 EHV charges'!$A:$O,8,FALSE)),"") -> 0.275 | F16: =IFERROR(IF(VLOOKUP($A16,'Annex 2 EHV charges'!$A:$O,9,FALSE)=0,"",VLOOKUP($A16,'Annex 2 EHV charges'!$A:$O,9,FALSE)),"") -> 1697.93 | G16: =IFERROR(IF(VLOOKUP($A16,'Annex 2 EHV charges'!$A:$O,10,FALSE)=0,"",VLOOKUP($A16,'Annex 2 EHV charges'!$A:$O,10,FALSE)),"") -> 8.79 | H16: =IFERROR(IF(VLOOKUP($A16,'Annex 2 EHV charges'!$A:$O,11,FALSE)=0,"",VLOOKUP($A16,'Annex 2 EHV charges'!$A:$O,11,FALSE)),"") -> 8.79
... A254: {=IFERROR(INDEX('Annex 2 EHV charges'!$A$11:$A$259, MATCH(0, IF(ISBLANK('Annex 2 EHV charges'!$A$11:$A$259),1, COUNTIF(A$4:$A253, 'Annex 2 EHV charges'!$A$11:$A$259)), 0)),"")} | B254: =IF($A254="","",VLOOKUP($A254,'Annex 2 EHV charges'!$A:$O,2,0)) | C254: =IF($A254="","",VLOOKUP($A254,'Annex 2 EHV charges'!$A:$O,3,0)) | D254: =IF($A254="","",VLOOKUP($A254,'Annex 2 EHV charges'!$A:$O,7,0)) | E254: =IFERROR(IF(VLOOKUP($A254,'Annex 2 EHV charges'!$A:$O,8,FALSE)=0,"",VLOOKUP($A254,'Annex 2 EHV charges'!$A:$O,8,FALSE)),"") | F254: =IFERROR(IF(VLOOKUP($A254,'Annex 2 EHV charges'!$A:$O,9,FALSE)=0,"",VLOOKUP($A254,'Annex 2 EHV charges'!$A:$O,9,FALSE)),"") | G254: =IFERROR(IF(VLOOKUP($A254,'Annex 2 EHV charges'!$A:$O,10,FALSE)=0,"",VLOOKUP($A254,'Annex 2 EHV charges'!$A:$O,10,FALSE)),"") | H254: =IFERROR(IF(VLOOKUP($A254,'Annex 2 EHV charges'!$A:$O,11,FALSE)=0,"",VLOOKUP($A254,'Annex 2 EHV charges'!$A:$O,11,FALSE)),"")

Sheet Annex 2b Export
A1: Note: The list of MPANs / MSIDs provided may be incomplete; the DNO reserves the right to apply the listed charges to any other MPANs / MSIDs associated with the site. Note: This table is automatically populated based on the content of the tab entitled 'Annex 2 EHV Charges'. The timebands are as shown in Annex 2.
A2: =Overview!B4& " - Effective from "&Overview!D4&" - "&Overview!E4&" EDCM export charges" -> SP Manweb - Effective from 1 April 2019 - Final EDCM export charges
A4: Export Unique Identifier | B4: LLFC | C4: Export MPANs/MSIDs | D4: Name | E4: ='Annex 2 EHV charges'!L10 -> Export Super Red unit charge (p/kWh) | F4: ='Annex 2 EHV charges'!M10 -> Export fixed charge (p/day) | G4: ='Annex 2 EHV charges'!N10 -> Export capacity charge (p/kVA/day) | H4: ='Annex 2 EHV charges'!O10 -> Export exceeded capacity charge (p/kVA/day)
A5: {=IFERROR(INDEX('Annex 2 EHV charges'!$D$11:$D$259, MATCH(0, IF(ISBLANK('Annex 2 EHV charges'!$D$11:$D$259),1, COUNTIF(A$4:$A4, 'Annex 2 EHV charges'!$D$11:$D$259)), 0)),"")} -> 603 | B5: =IF($A5="","",VLOOKUP($A5,'Annex 2 EHV charges'!$D:$O,2,0)) -> 603 | C5: =IF($A5="","",VLOOKUP($A5,'Annex 2 EHV charges'!$D:$O,3,0)) -> 1300050649372 | D5: =IF($A5="","",VLOOKUP($A5,'Annex 2 EHV charges'!$D:$O,4,0)) -> Shell Stanlow | E5: =IFERROR(IF(VLOOKUP($A5,'Annex 2 EHV charges'!$D:$O,9,FALSE)=0,"",VLOOKUP($A5,'Annex 2 EHV charges'!$D:$O,9,FALSE)),"") -> -0.262 | F5: =IFERROR(IF(VLOOKUP($A5,'Annex 2 EHV charges'!$D:$O,10,FALSE)=0,"",VLOOKUP($A5,'Annex 2 EHV charges'!$D:$O,10,FALSE)),"") -> 2382.34 | G5: =IFERROR(IF(VLOOKUP($A5,'Annex 2 EHV charges'!$D:$O,11,FALSE)=0,"",VLOOKUP($A5,'Annex 2 EHV charges'!$D:$O,11,FALSE)),"") -> 0.05 | H5: =IFERROR(IF(VLOOKUP($A5,'Annex 2 EHV charges'!$D:$O,12,FALSE)=0,"",VLOOKUP($A5,'Annex 2 EHV charges'!$D:$O,12,FALSE)),"") -> 0.05
A6: {=IFERROR(INDEX('Annex 2 EHV charges'!$D$11:$D$259, MATCH(0, IF(ISBLANK('Annex 2 EHV charges'!$D$11:$D$259),1, COUNTIF(A$4:$A5, 'Annex 2 EHV charges'!$D$11:$D$259)), 0)),"")} -> 606 | B6: =IF($A6="","",VLOOKUP($A6,'Annex 2 EHV charges'!$D:$O,2,0)) -> 606 | C6: =IF($A6="","",VLOOKUP($A6,'Annex 2 EHV charges'!$D:$O,3,0)) -> 1300051060981 | D6: =IF($A6="","",VLOOKUP($A6,'Annex 2 EHV charges'!$D:$O,4,0)) -> Bridgewater Paper | E6: =IFERROR(IF(VLOOKUP($A6,'Annex 2 EHV charges'!$D:$O,9,FALSE)=0,"",VLOOKUP($A6,'Annex 2 EHV charges'!$D:$O,9,FALSE)),"") | F6: =IFERROR(IF(VLOOKUP($A6,'Annex 2 EHV charges'!$D:$O,10,FALSE)=0,"",VLOOKUP($A6,'Annex 2 EHV charges'!$D:$O,10,FALSE)),"") | G6: =IFERROR(IF(VLOOKUP($A6,'Annex 2 EHV charges'!$D:$O,11,FALSE)=0,"",VLOOKUP($A6,'Annex 2 EHV charges'!$D:$O,11,FALSE)),"") | H6: =IFERROR(IF(VLOOKUP($A6,'Annex 2 EHV charges'!$D:$O,12,FALSE)=0,"",VLOOKUP($A6,'Annex 2 EHV charges'!$D:$O,12,FALSE)),"")
A7: {=IFERROR(INDEX('Annex 2 EHV charges'!$D$11:$D$259, MATCH(0, IF(ISBLANK('Annex 2 EHV charges'!$D$11:$D$259),1, COUNTIF(A$4:$A6, 'Annex 2 EHV charges'!$D$11:$D$259)), 0)),"")} -> 618 | B7: =IF($A7="","",VLOOKUP($A7,'Annex 2 EHV charges'!$D:$O,2,0)) -> 618 | C7: =IF($A7="","",VLOOKUP($A7,'Annex 2 EHV charges'!$D:$O,3,0)) -> 1300060704603 | D7: =IF($A7="","",VLOOKUP($A7,'Annex 2 EHV charges'!$D:$O,4,0)) -> Ineos Chlor Ltd (Lostock) | E7: =IFERROR(IF(VLOOKUP($A7,'Annex 2 EHV charges'!$D:$O,9,FALSE)=0,"",VLOOKUP($A7,'Annex 2 EHV charges'!$D:$O,9,FALSE)),"") | F7: =IFERROR(IF(VLOOKUP($A7,'Annex 2 EHV charges'!$D:$O,10,FALSE)=0,"",VLOOKUP($A7,'Annex 2 EHV charges'!$D:$O,10,FALSE)),"") -> 2015.58 | G7: =IFERROR(IF(VLOOKUP($A7,'Annex 2 EHV charges'!$D:$O,11,FALSE)=0,"",VLOOKUP($A7,'Annex 2 EHV charges'!$D:$O,11,FALSE)),"") -> 0.05 | H7: =IFERROR(IF(VLOOKUP($A7,'Annex 2 EHV charges'!$D:$O,12,FALSE)=0,"",VLOOKUP($A7,'Annex 2 EHV charges'!$D:$O,12,FALSE)),"") -> 0.05
A8: {=IFERROR(INDEX('Annex 2 EHV charges'!$D$11:$D$259, MATCH(0, IF(ISBLANK('Annex 2 EHV charges'!$D$11:$D$259),1, COUNTIF(A$4:$A7, 'Annex 2 EHV charges'!$D$11:$D$259)), 0)),"")} -> 655 | B8: =IF($A8="","",VLOOKUP($A8,'Annex 2 EHV charges'!$D:$O,2,0)) -> 655 | C8: =IF($A8="","",VLOOKUP($A8,'Annex 2 EHV charges'!$D:$O,3,0)) -> 1300060704082 | D8: =IF($A8="","",VLOOKUP($A8,'Annex 2 EHV charges'!$D:$O,4,0)) -> SafeGuard Bradwell | E8: =IFERROR(IF(VLOOKUP($A8,'Annex 2 EHV charges'!$D:$O,9,FALSE)=0,"",VLOOKUP($A8,'Annex 2 EHV charges'!$D:$O,9,FALSE)),"") | F8: =IFERROR(IF(VLOOKUP($A8,'Annex 2 EHV charges'!$D:$O,10,FALSE)=0,"",VLOOKUP($A8,'Annex 2 EHV charges'!$D:$O,10,FALSE)),"") -> 3528.34 | G8: =IFERROR(IF(VLOOKUP($A8,'Annex 2 EHV charges'!$D:$O,11,FALSE)=0,"",VLOOKUP($A8,'Annex 2 EHV charges'!$D:$O,11,FALSE)),"") -> 0.05 | H8: =IFERROR(IF(VLOOKUP($A8,'Annex 2 EHV charges'!$D:$O,12,FALSE)=0,"",VLOOKUP($A8,'Annex 2 EHV charges'!$D:$O,12,FALSE)),"") -> 0.05
A9: {=IFERROR(INDEX('Annex 2 EHV charges'!$D$11:$D$259, MATCH(0, IF(ISBLANK('Annex 2 EHV charges'!$D$11:$D$259),1, COUNTIF(A$4:$A8, 'Annex 2 EHV charges'!$D$11:$D$259)), 0)),"")} -> 648 | B9: =IF($A9="","",VLOOKUP($A9,'Annex 2 EHV charges'!$D:$O,2,0)) -> 648 | C9: =IF($A9="","",VLOOKUP($A9,'Annex 2 EHV charges'!$D:$O,3,0)) -> 1300060640474 | D9: =IF($A9="","",VLOOKUP($A9,'Annex 2 EHV charges'!$D:$O,4,0)) -> Kronospan | E9: =IFERROR(IF(VLOOKUP($A9,'Annex 2 EHV charges'!$D:$O,9,FALSE)=0,"",VLOOKUP($A9,'Annex 2 EHV charges'!$D:$O,9,FALSE)),"") | F9: =IFERROR(IF(VLOOKUP($A9,'Annex 2 EHV charges'!$D:$O,10,FALSE)=0,"",VLOOKUP($A9,'Annex 2 EHV charges'!$D:$O,10,FALSE)),"") -> 388.97 | G9: =IFERROR(IF(VLOOKUP($A9,'Annex 2 EHV charges'!$D:$O,11,FALSE)=0,"",VLOOKUP($A9,'Annex 2 EHV charges'!$D:$O,11,FALSE)),"") -> 0.05 | H9: =IFERROR(IF(VLOOKUP($A9,'Annex 2 EHV charges'!$D:$O,12,FALSE)=0,"",VLOOKUP($A9,'Annex 2 EHV charges'!$D:$O,12,FALSE)),"") -> 0.05
A10: {=IFERROR(INDEX('Annex 2 EHV charges'!$D$11:$D$259, MATCH(0, IF(ISBLANK('Annex 2 EHV charges'!$D$11:$D$259),1, COUNTIF(A$4:$A9, 'Annex 2 EHV charges'!$D$11:$D$259)), 0)),"")} -> 619 | B10: =IF($A10="","",VLOOKUP($A10,'Annex 2 EHV charges'!$D:$O,2,0)) -> 619 | C10: =IF($A10="","",VLOOKUP($A10,'Annex 2 EHV charges'!$D:$O,3,0)) -> 1300051136210 | D10: =IF($A10="","",VLOOKUP($A10,'Annex 2 EHV charges'!$D:$O,4,0)) -> Albion Inorganic | E10: =IFERROR(IF(VLOOKUP($A10,'Annex 2 EHV charges'!$D:$O,9,FALSE)=0,"",VLOOKUP($A10,'Annex 2 EHV charges'!$D:$O,9,FALSE)),"") | F10: =IFERROR(IF(VLOOKUP($A10,'Annex 2 EHV charges'!$D:$O,10,FALSE)=0,"",VLOOKUP($A10,'Annex 2 EHV charges'!$D:$O,10,FALSE)),"") | G10: =IFERROR(IF(VLOOKUP($A10,'Annex 2 EHV charges'!$D:$O,11,FALSE)=0,"",VLOOKUP($A10,'Annex 2 EHV charges'!$D:$O,11,FALSE)),"") | H10: =IFERROR(IF(VLOOKUP($A10,'Annex 2 EHV charges'!$D:$O,12,FALSE)=0,"",VLOOKUP($A10,'Annex 2 EHV charges'!$D:$O,12,FALSE)),"")
A11: {=IFERROR(INDEX('Annex 2 EHV charges'!$D$11:$D$259, MATCH(0, IF(ISBLANK('Annex 2 EHV charges'!$D$11:$D$259),1, COUNTIF(A$4:$A10, 'Annex 2 EHV charges'!$D$11:$D$259)), 0)),"")} -> 658 | B11: =IF($A11="","",VLOOKUP($A11,'Annex 2 EHV charges'!$D:$O,2,0)) -> 658 | C11: =IF($A11="","",VLOOKUP($A11,'Annex 2 EHV charges'!$D:$O,3,0)) -> 1300060563759 | D11: =IF($A11="","",VLOOKUP($A11,'Annex 2 EHV charges'!$D:$O,4,0)) -> Tyn dryfol PV | E11: =IFERROR(IF(VLOOKUP($A11,'Annex 2 EHV charges'!$D:$O,9,FALSE)=0,"",VLOOKUP($A11,'Annex 2 EHV charges'!$D:$O,9,FALSE)),"") | F11: =IFERROR(IF(VLOOKUP($A11,'Annex 2 EHV charges'!$D:$O,10,FALSE)=0,"",VLOOKUP($A11,'Annex 2 EHV charges'!$D:$O,10,FALSE)),"") -> 2414.17 | G11: =IFERROR(IF(VLOOKUP($A11,'Annex 2 EHV charges'!$D:$O,11,FALSE)=0,"",VLOOKUP($A11,'Annex 2 EHV charges'!$D:$O,11,FALSE)),"") -> 0.05 | H11: =IFERROR(IF(VLOOKUP($A11,'Annex 2 EHV charges'!$D:$O,12,FALSE)=0,"",VLOOKUP($A11,'Annex 2 EHV charges'!$D:$O,12,FALSE)),"") -> 0.05
A12: {=IFERROR(INDEX('Annex 2 EHV charges'!$D$11:$D$259, MATCH(0, IF(ISBLANK('Annex 2 EHV charges'!$D$11:$D$259),1, COUNTIF(A$4:$A11, 'Annex 2 EHV charges'!$D$11:$D$259)), 0)),"")} -> 621 | B12: =IF($A12="","",VLOOKUP($A12,'Annex 2 EHV charges'!$D:$O,2,0)) -> 621 | C12: =IF($A12="","",VLOOKUP($A12,'Annex 2 EHV charges'!$D:$O,3,0)) -> 1300050649336 | D12: =IF($A12="","",VLOOKUP($A12,'Annex 2 EHV charges'!$D:$O,4,0)) -> BHP | E12: =IFERROR(IF(VLOOKUP($A12,'Annex 2 EHV charges'!$D:$O,9,FALSE)=0,"",VLOOKUP($A12,'Annex 2 EHV charges'!$D:$O,9,FALSE)),"") | F12: =IFERROR(IF(VLOOKUP($A12,'Annex 2 EHV charges'!$D:$O,10,FALSE)=0,"",VLOOKUP($A12,'Annex 2 EHV charges'!$D:$O,10,FALSE)),"") | G12: =IFERROR(IF(VLOOKUP($A12,'Annex 2 EHV charges'!$D:$O,11,FALSE)=0,"",VLOOKUP($A12,'Annex 2 EHV charges'!$D:$O,11,FALSE)),"") | H12: =IFERROR(IF(VLOOKUP($A12,'Annex 2 EHV charges'!$D:$O,12,FALSE)=0,"",VLOOKUP($A12,'Annex 2 EHV charges'!$D:$O,12,FALSE)),"")
A13: {=IFERROR(INDEX('Annex 2 EHV charges'!$D$11:$D$259, MATCH(0, IF(ISBLANK('Annex 2 EHV charges'!$D$11:$D$259),1, COUNTIF(A$4:$A12, 'Annex 2 EHV charges'!$D$11:$D$259)), 0)),"")} -> 659 | B13: =IF($A13="","",VLOOKUP($A13,'Annex 2 EHV charges'!$D:$O,2,0)) -> 659 | C13: =IF($A13="","",VLOOKUP($A13,'Annex 2 EHV charges'!$D:$O,3,0)) -> 1300060652629 | D13: =IF($A13="","",VLOOKUP($A13,'Annex 2 EHV charges'!$D:$O,4,0)) -> Williams Farm Solar Park | E13: =IFERROR(IF(VLOOKUP($A13,'Annex 2 EHV charges'!$D:$O,9,FALSE)=0,"",VLOOKUP($A13,'Annex 2 EHV charges'!$D:$O,9,FALSE)),"") | F13: =IFERROR(IF(VLOOKUP($A13,'Annex 2 EHV charges'!$D:$O,10,FALSE)=0,"",VLOOKUP($A13,'Annex 2 EHV charges'!$D:$O,10,FALSE)),"") -> 743.42 | G13: =IFERROR(IF(VLOOKUP($A13,'Annex 2 EHV charges'!$D:$O,11,FALSE)=0,"",VLOOKUP($A13,'Annex 2 EHV charges'!$D:$O,11,FALSE)),"") -> 0.05 | H13: =IFERROR(IF(VLOOKUP($A13,'Annex 2 EHV charges'!$D:$O,12,FALSE)=0,"",VLOOKUP($A13,'Annex 2 EHV charges'!$D:$O,12,FALSE)),"") -> 0.05
A14: {=IFERROR(INDEX('Annex 2 EHV charges'!$D$11:$D$259, MATCH(0, IF(ISBLANK('Annex 2 EHV charges'!$D$11:$D$259),1, COUNTIF(A$4:$A13, 'Annex 2 EHV charges'!$D$11:$D$259)), 0)),"")} -> 604 | B14: =IF($A14="","",VLOOKUP($A14,'Annex 2 EHV charges'!$D:$O,2,0)) -> 604 | C14: =IF($A14="","",VLOOKUP($A14,'Annex 2 EHV charges'!$D:$O,3,0)) -> 1300054940683 | D14: =IF($A14="","",VLOOKUP($A14,'Annex 2 EHV charges'!$D:$O,4,0)) -> Port of Liverpool | E14: =IFERROR(IF(VLOOKUP($A14,'Annex 2 EHV charges'!$D:$O,9,FALSE)=0,"",VLOOKUP($A14,'Annex 2 EHV charges'!$D:$O,9,FALSE)),"") | F14: =IFERROR(IF(VLOOKUP($A14,'Annex 2 EHV charges'!$D:$O,10,FALSE)=0,"",VLOOKUP($A14,'Annex 2 EHV charges'!$D:$O,10,FALSE)),"") -> 1659.61 | G14: =IFERROR(IF(VLOOKUP($A14,'Annex 2 EHV charges'!$D:$O,11,FALSE)=0,"",VLOOKUP($A14,'Annex 2 EHV charges'!$D:$O,11,FALSE)),"") -> 0.05 | H14: =IFERROR(IF(VLOOKUP($A14,'Annex 2 EHV charges'!$D:$O,12,FALSE)=0,"",VLOOKUP($A14,'Annex 2 EHV charges'!$D:$O,12,FALSE)),"") -> 0.05
A15: {=IFERROR(INDEX('Annex 2 EHV charges'!$D$11:$D$259, MATCH(0, IF(ISBLANK('Annex 2 EHV charges'!$D$11:$D$259),1, COUNTIF(A$4:$A14, 'Annex 2 EHV charges'!$D$11:$D$259)), 0)),"")} -> 661 | B15: =IF($A15="","",VLOOKUP($A15,'Annex 2 EHV charges'!$D:$O,2,0)) -> 661 | C15: =IF($A15="","",VLOOKUP($A15,'Annex 2 EHV charges'!$D:$O,3,0)) -> 1300060579182 | D15: =IF($A15="","",VLOOKUP($A15,'Annex 2 EHV charges'!$D:$O,4,0)) -> Combermere Abbey PV | E15: =IFERROR(IF(VLOOKUP($A15,'Annex 2 EHV charges'!$D:$O,9,FALSE)=0,"",VLOOKUP($A15,'Annex 2 EHV charges'!$D:$O,9,FALSE)),"") | F15: =IFERROR(IF(VLOOKUP($A15,'Annex 2 EHV charges'!$D:$O,10,FALSE)=0,"",VLOOKUP($A15,'Annex 2 EHV charges'!$D:$O,10,FALSE)),"") -> 2496.2 | G15: =IFERROR(IF(VLOOKUP($A15,'Annex 2 EHV charges'!$D:$O,11,FALSE)=0,"",VLOOKUP($A15,'Annex 2 EHV charges'!$D:$O,11,FALSE)),"") -> 0.05 | H15: =IFERROR(IF(VLOOKUP($A15,'Annex 2 EHV charges'!$D:$O,12,FALSE)=0,"",VLOOKUP($A15,'Annex 2 EHV charges'!$D:$O,12,FALSE)),"") -> 0.05
A16: {=IFERROR(INDEX('Annex 2 EHV charges'!$D$11:$D$259, MATCH(0, IF(ISBLANK('Annex 2 EHV charges'!$D$11:$D$259),1, COUNTIF(A$4:$A15, 'Annex 2 EHV charges'!$D$11:$D$259)), 0)),"")} -> 628 | B16: =IF($A16="","",VLOOKUP($A16,'Annex 2 EHV charges'!$D:$O,2,0)) -> 628 | C16: =IF($A16="","",VLOOKUP($A16,'Annex 2 EHV charges'!$D:$O,3,0)) -> 1300060075405 | D16: =IF($A16="","",VLOOKUP($A16,'Annex 2 EHV charges'!$D:$O,4,0)) -> Amegni | E16: =IFERROR(IF(VLOOKUP($A16,'Annex 2 EHV charges'!$D:$O,9,FALSE)=0,"",VLOOKUP($A16,'Annex 2 EHV charges'!$D:$O,9,FALSE)),"") | F16: =IFERROR(IF(VLOOKUP($A16,'Annex 2 EHV charges'!$D:$O,10,FALSE)=0,"",VLOOKUP($A16,'Annex 2 EHV charges'!$D:$O,10,FALSE)),"") -> 620.7 | G16: =IFERROR(IF(VLOOKUP($A16,'Annex 2 EHV charges'!$D:$O,11,FALSE)=0,"",VLOOKUP($A16,'Annex 2 EHV charges'!$D:$O,11,FALSE)),"") -> 0.05 | H16: =IFERROR(IF(VLOOKUP($A16,'Annex 2 EHV charges'!$D:$O,12,FALSE)=0,"",VLOOKUP($A16,'Annex 2 EHV charges'!$D:$O,12,FALSE)),"") -> 0.05
... A254: {=IFERROR(INDEX('Annex 2 EHV charges'!$D$11:$D$259, MATCH(0, IF(ISBLANK('Annex 2 EHV charges'!$D$11:$D$259),1, COUNTIF(A$4:$A253, 'Annex 2 EHV charges'!$D$11:$D$259)), 0)),"")} | B254: =IF($A254="","",VLOOKUP($A254,'Annex 2 EHV charges'!$D:$O,2,0)) | C254: =IF($A254="","",VLOOKUP($A254,'Annex 2 EHV charges'!$D:$O,3,0)) | D254: =IF($A254="","",VLOOKUP($A254,'Annex 2 EHV charges'!$D:$O,4,0)) | E254: =IFERROR(IF(VLOOKUP($A254,'Annex 2 EHV charges'!$D:$O,9,FALSE)=0,"",VLOOKUP($A254,'Annex 2 EHV charges'!$D:$O,9,FALSE)),"") | F254: =IFERROR(IF(VLOOKUP($A254,'Annex 2 EHV charges'!$D:$O,10,FALSE)=0,"",VLOOKUP($A254,'Annex 2 EHV charges'!$D:$O,10,FALSE)),"") | G254: =IFERROR(IF(VLOOKUP($A254,'Annex 2 EHV charges'!$D:$O,11,FALSE)=0,"",VLOOKUP($A254,'Annex 2 EHV charges'!$D:$O,11,FALSE)),"") | H254: =IFERROR(IF(VLOOKUP($A254,'Annex 2 EHV charges'!$D:$O,12,FALSE)=0,"",VLOOKUP($A254,'Annex 2 EHV charges'!$D:$O,12,FALSE)),"")

Sheet Annex 3 Preserved charges
A1: Back to Overview
A2: SP Manweb - Effective from 1 April 2019 - Final LV and HV tariffs
A3: NHH preserved charges/additional LLFCs
B4: Closed LLFCs | C4: PCs | D4: Unit charge 1 (NHH) or red/black charge (HH) p/kWh | E4: Unit charge 2 (NHH) or amber/yellow charge (HH) p/kWh | F4: Green charge(HH) p/kWh | G4: Fixed charge p/MPAN/day | H4: Capacity charge p/kVA/day | I4: Exceeded capacity charge p/kVA/day | J4: Reactive power charge p/kVArh
A5: Domestic Two Rate* | B5: 145, 146 | C5: 2 | D5: 3.686 | E5: 1.545 | G5: 3.68
A6: Domestic Off Peak (related MPAN) | B6: 135, 136, 137, 138, 140, 141, 142, 143 | C6: 2 | D6: 1.556
A7: Small Non Domestic Unrestricted | B7: 207 | C7: 3 | D7: 3.367 | G7: 4.63
A8: Small Non Domestic Two Rate | B8: 208, 210 | C8: 4 | D8: 3.515 | E8: 1.466 | G8: 4.63
A9: Small Non Domestic Off Peak (related MPAN) | B9: 233, 234, 235, 236, 237 | C9: 4 | D9: 1.498
A10: LV Medium Non-Domestic | B10: 401, 402 | C10: 5-8 | D10: 3.452 | E10: 1.434 | G10: 20.58
A11: LV Sub Medium Non-Domestic | B11: 403, 404 | C11: 5-8 | D11: 3.44 | E11: 1.434 | G11: 24.87
A12: HV Medium Non-Domestic | B12: 405 | C12: 5-8 | D12: 2.533 | E12: 1.378 | G12: 190.08
A14: Notes: | B14: Unit time periods are as specified in the SSC.
B15: SP Manweb uses a default tariff for invalid settlement combinations these will be charged at the Domestic Unrestricted Rates. The Domestic and Non-Domestic Off Peak (related MPAN) tariffs are supplementary to a standard published tariff and therefore only available under these conditions. Preserved tariffs are only available to existing supplies, subject to certain conditions: a) Suppliers may not normally transfer a meter point from one preserved tariff to another preserved tariff; b) If a supply under a preserved tariff should cease, other than on change of tenancy, the preserved tariff may not normally be restored; c) Any additional load requried to be supplied on the preserved tariff must be within the existing supply capacity.
B16: *Supplier of Last Resort increases to the Fixed Charges for the Domestic Unrestricted, Domestic Two Rate and LV Domestic Network tariffs. The increase for each of these tariffs is 0.08p/MPAN/day. No other tariffs affected by this change.
A19: HH preserved charges/additional LLFCs
B20: Closed LLFCs | C20: PCs | D20: Red/black charge (HH) p/kWh | E20: Amber/yellow charge (HH) p/kWh | F20: Green charge (HH) p/kWh | G20: Fixed charge p/MPAN/day | H20: Capacity charge p/kVA/day | I20: Exceeded capacity charge p/kVA/day | J20: Reactive power charge p/kVArh
A21: LV HH Metered | B21: 501 | C21: 0 | D21: 10.481 | E21: 2.305 | F21: 1.423 | G21: 18.71 | H21: 2.51 | I21: 4.46 | J21: 0.367
A22: LV Sub HH Metered | B22: 503 | C22: 0 | D22: 8.066 | E22: 1.869 | F22: 1.383 | G22: 6.6 | H22: 5.15 | I22: 7.12 | J22: 0.232
A23: HV HH Metered | B23: 505 | C23: 0 | D23: 6.54 | E23: 1.653 | F23: 1.352 | G23: 99.97 | H23: 4.05 | I23: 6.63 | J23: 0.161
A24: Notes: | B24: Time periods
B26: As detailed in Annex 1
B28: All times are UK clock-time.
B30: Preserved tariffs are only available to existing supplies, subject to certain conditions: a) Suppliers may not normally transfer a meter point from one preserved tariff to another preserved tariff; b) If a supply under a preserved tariff should cease, other than on change of tenancy, the preserved tariff may not normally be restored; c) Any additional load requried to be supplied on the preserved tariff must be within the existing supply capacity.

Sheet Annex 4 LDNO charges
A1: Back to Overview | B1: Copy from CDCM table 3701 "Tariffs!A42:I84" and paste values into A14 | F1: Copy from EDCM table 6005 "LDNORev!B549:G683" and paste values into D57
A2: SP Manweb - Effective from 1 April 2019 - Final LDNO tariffs
A4: Time Bands for Half Hourly Metered Properties | F4: Time Bands for Half Hourly Unmetered Properties
A5: Time periods | B5: Red Time Band | C5: Amber Time Band | D5: Green Time Band | H5: Black Time Band | I5: Yellow Time Band | J5: Green Time Band
A6: Monday to Friday (Including Bank Holidays) All Year | B6: 16.30 - 19.30 | C6: 08.00 - 16.30 19.30 - 22.30 | D6: 00.00 - 08.00 22.30 - 00.00 | F6: Monday to Friday (Including Bank Holidays) June to August Inclusive | I6: 08.00 - 22.30 | J6: 00.00 - 08.00 22.30 - 00.00
A7: Saturday and Sunday All Year | C7: 16.00 - 20.00 | D7: 00.00 - 16.00 20.00 - 00.00 | F7: Monday to Friday (Including Bank Holidays) November to February Inclusive | H7: 16.30 - 19.30 | I7: 08.00 - 16.30 19.30 - 22.30 | J7: 00.00 - 08.00 22.30 - 00.00
A8: Notes | B8: All the above times are in UK Clock time | F8: Monday to Friday (Including Bank Holidays) March to May, & September to October, Inclusive | I8: 08.00 - 22.30 | J8: 00.00 - 08.00 22.30 - 00.00
F9: Saturday and Sunday All year | I9: 16.00 - 20.00 | J9: 00:00-16:00 20:00-00:00
A12: Tariff name | B12: Unique billing identifier | C12: PCs | D12: Unit charge 1 (NHH) or red/black charge (HH) p/kWh | E12: Unit charge 2 (NHH) or amber/yellow charge (HH) p/kWh | F12: Green charge(HH) p/kWh | G12: Fixed charge p/MPAN/day | H12: Capacity charge p/kVA/day | I12: Exceeded capacity charge p/kVA/day | J12: Reactive power charge p/kVArh
A13: LDNO LV: Domestic Unrestricted | D13: 2.09 | G13: 2.24
A14: LDNO LV: Domestic Two Rate | D14: 2.296 | E14: 0.962 | G14: 2.24
A15: LDNO LV: Domestic Off Peak (related MPAN) | D15: 0.969
A16: LDNO LV: Small Non Domestic Unrestricted | D16: 2.097 | G16: 2.88
A17: LDNO LV: Small Non Domestic Two Rate | D17: 2.19 | E17: 0.913 | G17: 2.88
A18: LDNO LV: Small Non Domestic Off Peak (related MPAN) | D18: 0.933
A19: LDNO LV: LV Medium Non-Domestic | D19: 2.15 | E19: 0.893 | G19: 12.82
A20: LDNO LV: LV Network Domestic | D20: 7.641 | E20: 1.633 | F20: 0.905 | G20: 2.24
A21: LDNO LV: LV Network Non-Domestic Non-CT | D21: 7.829 | E21: 1.656 | F21: 0.908 | G21: 2.88
A22: LDNO LV: LV HH Metered | D22: 6.529 | E22: 1.436 | F22: 0.886 | G22: 11.65 | H22: 1.56 | I22: 2.78 | J22: 0.229
A23: LDNO LV: NHH UMS category A | D23: 1.686
A24: LDNO LV: NHH UMS category B | D24: 1.853
A25: LDNO LV: NHH UMS category C | D25: 2.559
A26: LDNO LV: NHH UMS category D | D26: 1.57
A27: LDNO LV: LV UMS (Pseudo HH Metered) | D27: 13.026 | E27: 1.648 | F27: 1.078
A28: LDNO LV: LV Generation NHH or Aggregate HH | D28: -1.228 | G28: 0
A29: LDNO LV: LV Generation Intermittent | D29: -1.228 | G29: 0 | J29: 0.302
A30: LDNO LV: LV Generation Non-Intermittent | D30: -8.287 | E30: -1.036 | F30: -0.158 | G30: 0 | J30: 0.302
A31: LDNO HV: Domestic Unrestricted | D31: 1.353 | G31: 1.45
A32: LDNO HV: Domestic Two Rate | D32: 1.486 | E32: 0.623 | G32: 1.45
A33: LDNO HV: Domestic Off Peak (related MPAN) | D33: 0.627
A34: LDNO HV: Small Non Domestic Unrestricted | D34: 1.358 | G34: 1.87
A35: LDNO HV: Small Non Domestic Two Rate | D35: 1.417 | E35: 0.591 | G35: 1.87
A36: LDNO HV: Small Non Domestic Off Peak (related MPAN) | D36: 0.604
A37: LDNO HV: LV Medium Non-Domestic | D37: 1.392 | E37: 0.578 | G37: 8.3
A38: LDNO HV: LV Network Domestic | D38: 4.946 | E38: 1.057 | F38: 0.586 | G38: 1.45
A39: LDNO HV: LV Network Non-Domestic Non-CT | D39: 5.068 | E39: 1.072 | F39: 0.588 | G39: 1.87
A40: LDNO HV: LV HH Metered | D40: 4.226 | E40: 0.929 | F40: 0.574 | G40: 7.54 | H40: 1.01 | I40: 1.8 | J40: 0.148
A41: LDNO HV: LV Sub HH Metered | D41: 5.232 | E41: 1.212 | F41: 0.897 | G41: 4.28 | H41: 3.34 | I41: 4.62 | J41: 0.15
A42: LDNO HV: HV HH Metered | D42: 4.796 | E42: 1.212 | F42: 0.992 | G42: 73.32 | H42: 2.97 | I42: 4.86 | J42: 0.118
A43: LDNO HV: NHH UMS category A | D43: 1.092
...

Sheet Annex 5 LLFs
A1: Back to Overview
A2: This table has intentionally been left blank. The line loss factors that are approved by the BSC Panel for the applicable year and consequently published on the Elexon website will take precedence and be used in Settlement. This annex will be re-published once these values are available.
A3: SP Manweb - Illustrative LLFs for year beginning 1 April 2019
A4: Time periods | B4: Period 1 | C4: Period 2 | D4: Period 3 | E4: Period 4
B5: (Name 1) | C5: (Name 2) | D5: (Name 3) | E5: (Name 4)
A6: Monday to Friday March to October | B6: 23:30 – 07:30 | C6: 07:30 – 23:30
A7: Monday to Friday November to February | B7: 23:30 – 07:30 | C7: 20:00 – 23:30 | D7: 07:30 – 16:00 19:00 – 20:00 | E7: 16:00 – 19:00
A8: Saturday and Sunday All Year | B8: 23:30 – 07:30 | C8: 07:30 – 23:30
A9: Notes | B9: All the above times are in UK Clock time
A12: Generic demand and generation LLFs
A13: Metered voltage, respective periods and associated LLFCs
A14: Metered voltage | B14: Period 1 | C14: Period 2 | D14: Period 3 | E14: Period 4 | F14: Associated LLFC
A15: Low-voltage network | B15: 1.087 | C15: 1.105 | D15: 1.118 | E15: 1.138 | F15: 101,102,103,104,105,106,111,112,113,114,115,116,117,118,119,120,130,131,132,133,134,135,136,137,138,140,141,142,143,145,146,147,148,149,150,153,155,180,201,202,203,205,211,212,231,232,233,234,235,236,237,280,401,402,501,511,591,764,765,781,782,783,784,785,786,787,791,795,900,901,902,903,910
A16: Low-voltage substation | B16: 1.057 | C16: 1.06 | D16: 1.065 | E16: 1.069 | F16: 207,208,209,210,403,404,503,513,592,780,788,789,792,796
A17: High-voltage network | B17: 1.032 | C17: 1.038 | D17: 1.043 | E17: 1.047 | F17: 405,505,515,593,768,769,770,771,774,775,776,777,778,779,793,797
A18: High-voltage substation | B18: 1.024 | C18: 1.026 | D18: 1.029 | E18: 1.031 | F18: 300 to 399 Inclusive 445 to 499 Inclusive 700 to 725 Inclusive
A19: 33kV generic Import | B19: 1.016 | C19: 1.018 | D19: 1.02 | E19: 1.022
A20: 33kV generic Export | B20: 1.012 | C20: 1.012 | D20: 1.013 | E20: 1.014
A21: 132kV generic Import | B21: 1.004 | C21: 1.005 | D21: 1.006 | E21: 1.006
A22: 132kV generic Export | B22: 1 | C22: 1 | D22: 1 | E22: 1
A24: EHV site specific LLFs
A25: Demand
A26: Site | B26: Period 1 | C26: Period 2 | D26: Period 3 | E26: Period 4 | F26: Associated LLFC
A27: Shell Stanlow | B27: 1.043 | C27: 1.047 | D27: 1.044 | E27: 1.048 | F27: 803
A28: Jaguar & Land Rover | B28: 1.073 | C28: 1.08 | D28: 1.078 | E28: 1.087 | F28: 804
A29: Innospec | B29: 1.035 | C29: 1.046 | D29: 1.043 | E29: 1.052 | F29: 805
A30: Bridgewater Paper | B30: 1.03 | C30: 1.034 | D30: 1.034 | E30: 1.038 | F30: 806
A31: General Motors | B31: 1.028 | C31: 1.032 | D31: 1.031 | E31: 1.034 | F31: 807
A32: TATA Steel | B32: 1.019 | C32: 1.022 | D32: 1.02 | E32: 1.026 | F32: 808
A33: Urenco | B33: 1.029 | C33: 1.03 | D33: 1.03 | E33: 1.032 | F33: 809
A34: Ineos Chlor Ltd (Lostock) | B34: 1.04 | C34: 1.058 | D34: 1.046 | E34: 1.066 | F34: 810
A35: SafeGuard Bradwell | B35: 1.016 | C35: 1.018 | D35: 1.02 | E35: 1.022 | F35: 811
A36: Knauf Insulation | B36: 1.078 | C36: 1.088 | D36: 1.084 | E36: 1.096 | F36: 812
A37: Air Products | B37: 1.052 | C37: 1.057 | D37: 1.055 | E37: 1.06 | F37: 813
A38: Shell Chemicals | B38: 1.043 | C38: 1.047 | D38: 1.045 | E38: 1.05 | F38: 814
... A123: CEW | B123: 1.016 | C123: 1.018 | D123: 1.02 | E123: 1.022 | F123: 853
A124: Risley DSCP | B124: 1.019 | C124: 1.023 | D124: 1.023 | E124: 1.027 | F124: MSID 0030
A125: Bold DSCP | B125: 1.039 | C125: 1.05 | D125: 1.06 | E125: 1.069 | F125: MSID 0031/32
A126: Dolgarrog PS | B126: 0.986 | C126: 0.991 | D126: 0.985 | E126: 0.991 | F126: MSID 4532/33
A127: Shotton Paper | B127: 1.004 | C127: 1.005 | D127: 1.006 | E127: 1.006 | F127: 802
...

Sheet Annex 6 new or amended EHV
A1: Back to Overview | H1: Note: The list of MPANs/MSIDs provided may be incomplete; the DNO reserves the right to apply the listed charges to any other MPANs/MSIDs associated with the site. If sites appear in both Annex 2 and Annex 6, the charges in Annex 6 take precedence. Where an existing Designated EHV Property is modified and energised in the charging year, we may revise the EDCM charges for the modified Designated EHV Property.
A2: Annex 6 - Charges for New or Amended Designated EHV Properties
A4: =Overview!B4& " - Effective from "&Overview!D4&" - "&Overview!E4&" new designated EHV charges" -> SP Manweb - Effective from 1 April 2019 - Final new designated EHV charges
A5: Effective from date | B5: Import Unique Identifier | C5: LLFC | D5: Import MPANs/MSIDs | E5: Export Unique Identifier | F5: LLFC | G5: Export MPANs/MSIDs | H5: Name | I5: ='Annex 2 EHV charges'!H10 -> Import Super Red unit charge (p/kWh) | J5: ='Annex 2 EHV charges'!I10 -> Import fixed charge (p/day) | K5: ='Annex 2 EHV charges'!J10 -> Import capacity charge (p/kVA/day) | L5: ='Annex 2 EHV charges'!K10 -> Import exceeded capacity charge (p/kVA/day) | M5: ='Annex 2 EHV charges'!L10 -> Export Super Red unit charge (p/kWh) | N5: ='Annex 2 EHV charges'!M10 -> Export fixed charge (p/day) | O5: ='Annex 2 EHV charges'!N10 -> Export capacity charge (p/kVA/day) | P5: ='Annex 2 EHV charges'!O10 -> Export exceeded capacity charge (p/kVA/day)
A6: 01/04/2019 | B6: 895 | C6: 895 | D6: 1300060785462 | E6: 696 | F6: 696 | G6: 1300060785453 | H6: Brenig Wind Farm | I6: 0 | J6: 296.11 | K6: 3.22 | L6: 3.22 | M6: 0 | N6: 23451.82 | O6: 0.05 | P6: 0.05
A7: 01/04/2019 | B7: 911 | C7: 911 | D7: 1300060805612 | E7: 623 | F7: 623 | G7: 1300060805621 | H7: Griffiths Road STOR | I7: 1.713 | J7: 212.44 | K7: 3.19 | L7: 3.19 | M7: -2.32 | N7: 5664.15 | O7: 0.05 | P7: 0.05
A8: 01/04/2019 | B8: 912 | C8: 912 | D8: 1300060805560 | E8: 624 | F8: 624 | G8: 1300060805570 | H8: Warrington Pwr Slutcher | I8: 1.713 | J8: 153.71 | K8: 4.77 | L8: 4.77 | M8: -2.811 | N8: 4100.51 | O8: 0.05 | P8: 0.05
A9: 01/04/2019 | B9: 914 | C9: 914 | D9: 1300060818597 | E9: 626 | F9: 626 | G9: 1300060818602 | H9: Latchford Lane STOR | I9: 1.713 | J9: 16.67 | K9: 4.77 | L9: 4.77 | M9: -2.811 | N9: 1267.98 | O9: 0.05 | P9: 0.05
A10: 01/04/2019 | B10: 853 | C10: 853 | E10: 653 | F10: 653 | H10: CEW | I10: 0.281 | J10: 278.44 | K10: 4.46 | L10: 4.46 | M10: -0.913 | N10: 5822.98 | O10: 0.05 | P10: 0.05
A11: 01/04/2019 | B11: 833 | C11: 833 | D11: 1300035361803 | E11: 663 | F11: 663 | G11: 1300060327224 | H11: Toyota | J11: 1880.85 | K11: 5.56 | L11: 5.56 | M11: 0 | N11: 949.83 | O11: 0.05 | P11: 0.05
A12: 01/04/2019 | B12: 898 | C12: 898 | D12: 1300051694552 | E12: 698 | F12: 698 | G12: 1300051694827 | H12: PG Winnington | I12: 0 | J12: 594.99 | K12: 2.17 | L12: 3.4 | M12: -1.745 | N12: 3545.62 | O12: 0.05 | P12: 0.05
A13: 01/04/2019 | B13: 806 | C13: 806 | D13: 1300051060972 | E13: 606 | F13: 606 | G13: 1300051060981 | H13: Bridgewater Paper | I13: 0 | J13: 54.88 | K13: 3.14 | L13: 3.14 | M13: -0.117 | N13: 4134.92 | O13: 0.05 | P13: 0.05
A14: 01/04/2019 | B14: 312 | C14: 312 | D14: 1300060736891 | H14: Alpoco Orthios Eco Park | I14: 0.232 | J14: 210.49 | K14: 3.58 | L14: 3.58
A15: 01/04/2019 | B15: 336 | C15: 336 | D15: 1300060254338 | H15: Altcar Rifle Range Estate | I15: 0 | J15: 1001.98 | K15: 3.58 | L15: 3.58
A20: =[1]Overview!B4& " - Effective from "&[1]Overview!D4&" - "&[1]Overview!E4&" new designated EHV line loss factors" -> SP Manweb - Effective from 1 April 2019 - Final new designated EHV line loss factors
A21: Effective from date | B21: Import Unique Identifier | C21: LLFC | D21: Import MPANs/MSIDs | E21: Export Unique Identifier | F21: LLFC | G21: Export MPANs/MSIDs | H21: Name | I21: Import LLF period 1 | J21: Import LLF period 2 | K21: Import LLF period 3 | L21: Import LLF period 4 | M21: Import LLF period 5 | N21: Export LLF period 1 | O21: Export LLF period 2 | P21: Export LLF period 3 | Q21: Export LLF period 4 | R21: Export LLF period 5
A22: 01/04/2019 | B22: 895 | C22: 895 | D22: 1300060785462 | E22: 696 | F22: 696 | G22: 1300060785453 | H22: Brenig Wind Farm | I22: 1.016 | J22: 1.018 | K22: 1.02 | L22: 1.022 | N22: 1.012 | O22: 1.012 | P22: 1.013 | Q22: 1.014
A23: 01/04/2019 | B23: 911 | C23: 911 | D23: 1300060805612 | E23: 623 | F23: 623 | G23: 1300060805621 | H23: Griffiths Road STOR | I23: 1.016 | J23: 1.018 | K23: 1.02 | L23: 1.022 | N23: 1.012 | O23: 1.012 | P23: 1.013 | Q23: 1.014
A24: 01/04/2019 | B24: 912 | C24: 912 | D24: 1300060805560 | E24: 624 | F24: 624 | G24: 1300060805570 | H24: Warrington Pwr Slutcher | I24: 1.016 | J24: 1.018 | K24: 1.02 | L24: 1.022 | N24: 1.012 | O24: 1.012 | P24: 1.013 | Q24: 1.014
A25: 01/04/2019 | B25: 914 | C25: 914 | D25: 1300060818597 | E25: 626 | F25: 626 | G25: 1300060818602 | H25: Latchford Lane STOR | I25: 1.016 | J25: 1.018 | K25: 1.02 | L25: 1.022 | N25: 1.012 | O25: 1.012 | P25: 1.013 | Q25: 1.014
A26: 01/04/2019 | B26: 853 | C26: 853 | E26: 653 | F26: 653 | H26: CEW | I26: 1.016 | J26: 1.018 | K26: 1.02 | L26: 1.022 | N26: 1.012 | O26: 1.012 | P26: 1.013 | Q26: 1.014
A27: 01/04/2019 | B27: 833 | C27: 833 | D27: 1300035361803 | E27: 663 | F27: 663 | G27: 1300060327224 | H27: Toyota | I27: 1.022 | J27: 1.028 | K27: 1.023 | L27: 1.031 | N27: 1.012 | O27: 1.012 | P27: 1.013 | Q27: 1.014
A28: 01/04/2019 | B28: 898 | C28: 898 | D28: 1300051694552 | E28: 698 | F28: 698 | G28: 1300051694827 | H28: PG Winnington | I28: 1.038 | J28: 1.047 | K28: 1.043 | L28: 1.052 | N28: 1.015 | O28: 1.021 | P28: 1.017 | Q28: 1.022
A29: 01/04/2019 | B29: 806 | C29: 806 | D29: 1300051060972 | E29: 606 | F29: 606 | G29: 1300051060981 | H29: Bridgewater Paper | I29: 1.03 | J29: 1.034 | K29: 1.034 | L29: 1.038 | N29: 1.001 | O29: 1.003 | P29: 1.002 | Q29: 1.003
A30: 01/04/2019 | B30: 312 | C30: 312 | D30: 1300060736891 | H30: Alpoco Orthios Eco Park | I30: 1.024 | J30: 1.026 | K30: 1.029 | L30: 1.031
A31: 01/04/2019 | B31: 336 | C31: 336 | D31: 1300060254338 | H31: Altcar Rifle Range Estate | I31: 1.024 | J31: 1.026 | K31: 1.029 | L31: 1.031

Sheet Nodal prices
A1: Back to Overview
A2: =Overview!B4& " - Effective from "&Overview!D4&" - "&Overview!E4&" Nodal/Zonal charges" -> SP Manweb - Effective from 1 April 2019 - Final Nodal/Zonal charges
A3: Node/Zone ID | B3: Geographical name | C3: Local charge 1 £/kVA | D3: Remote charge 1 £/kVA
A4: ABER RHYD 132KV | B4: 1
A5: BIRKENHEAD 132KV | B5: 1
A6: CARRINGTON 132KV | B6: 1 | D6: 4.5022747
A7: CONNAHS QUAY PENTIR 132KV | B7: 1 | D7: 0
A8: CREWE 132KV | B8: 1 | D8: 0
A9: FRODSHAM 132KV | B9: 1 | D9: 0
A10: KIRKBY 132KV | B10: 1 | D10: 0
A11: LEGACY 132KV | B11: 1 | D11: 0
A12: LISTER DRIVE 132KV | B12: 1 | D12: 0
A13: RAINHILL 132KV | B13: 1 | D13: 0.73877517
A14: TRAWSFYNYDD 132KV | B14: 1 | D14: 0
A15: WYLFA 132KV | B15: 1 | D15: 0
A16: CONNAHS QUAY (SHOTTON) 132KV | B16: 1 | D16: 0
A17: CAPENHURST and INCE 132KV | B17: 1 | D17: 0.6770084
