Workbook
Name OLE_LINK1: 'Annex 3 Preserved charges'!#REF!

Sheet Overview
A2: Company and Licence name, charging year, effective from, status
B3: Company and Licence name | C3: Year | D3: Effective From | E3: Status
A4: Company and Licence name, charging year, effective from, status | B4: Northern Powergrid (Northeast) Ltd | C4: 2019/20 | D4: 1 April 2019 | E4: Final
A6: List of data tables in this workbook
A7: Worksheet | B7: Information
A8: Annex 1 LV and HV charges | B8: Annex 1 contains the charges to LV and HV Designated Properties.
A9: Annex 2 EHV charges | B9: ="Annex 2 contains the charges to Designated EHV Properties and charges applied to LDNOs with Designated EHV Properties/end-users embedded in networks within the " &B4 &" Licence area." -> Annex 2 contains the charges to Designated EHV Properties and charges applied to LDNOs with Designated EHV Properties/end-users embedded in networks within the Northern Powergrid (Northeast) Ltd Licence area.
A10: Annex 3 Preserved charges | B10: Annex 3 contains details of any preserved and additional charges that are valid at this time.
A11: Annex 4 LDNO charges | B11: ="Annex 4 contains charges that are levied on the owner of an embedded network within the "&B4&" Licence area. "&"Electricity suppliers and consumers who have properties connected to an embedded network should contact the embedded network owner to determine their distribution charges."&" The charges listed in this table are not payable by domestic consumers, business consumers or electricity suppliers." -> Annex 4 contains charges that are levied on the owner of an embedded network within the Northern Powergrid (Northeast) Ltd Licence area. Electricity suppliers and consumers who have properties connected to an embedded network should contact the embedded network owner to determine their distribution charges. The charges listed in this table are not payable by domestic consumers, business consumers or electricity suppliers.
A12: Annex 5 LLFs | B12: Annex 5 has been intentionally left blank as this charging statement is published a complete year before the LLFs have been audited. The line loss factors that are approved by the BSC Panel for the applicable year and consequently published on the Elexon website will take precedence and be used in Settlement. This annex will be re-published with these values once they are available.
A13: Annex 6 Charges for New or Amended Designated EHV Properties | B13: ="Annex 6 contains the charges for new or amended Designated EHV Properties and charges applied to LDNOs with new or amended Designated EHV Properties/end-users embedded in networks within the " &B4 &" Licence area." -> Annex 6 contains the charges for new or amended Designated EHV Properties and charges applied to LDNOs with new or amended Designated EHV Properties/end-users embedded in networks within the Northern Powergrid (Northeast) Ltd Licence area.
A14: Nodal prices | B14: Contains the underlying nodal costs used to calculate the current EDCM charges.
A15: SSC TPR to unit rate lookup table | B15: The time periods for the non half hourly metered charge rates in Annex 1 are as specified by the SSC. To determine the appropriate charge rate for each SSC/TPR a lookup table is provided.
A16: Charge calculator | B16: Charge calculator is a tool to help you estimate your distribution charges using current consumption data and forecast consumption data.
A18: Notes to users of this spreadsheet
A20: Please use this spreadsheet with reference to the LC14 use of system charging statement.
A22: Notes to DNOs populating this spreadsheet
A24: DNOs must endeavour to maintain consistency in the structure of this spreadsheet. Any changes to the structure must be noted in the 'Notes to users of this spreadsheet'
A25: The drop down list on the charge calculator can be expanded by unprotecting the charge calculator sheet and selecting 'data', 'data validation...' and then expanding the 'source' data range. The sheet can then be protected.

Sheet Annex 1 LV and HV charges
A1: Back to Overview | E1: Note: Where a tariff only has a p/kWh unit rate in Unit Charge 1 then this unit rate applies at all times.
A2: =Overview!B4& " - Effective from "&Overview!D4&" - "&Overview!E4&" LV and HV charges" -> Northern Powergrid (Northeast) Ltd - Effective from 1 April 2019 - Final LV and HV charges
A4: Time Bands for Half Hourly Metered Properties | G4: Time Bands for Half Hourly Unmetered Properties
A5: Time periods | B5: Red Time Band | C5: Amber Time Band | E5: Green Time Band | I5: Black Time Band | J5: Yellow Time Band | K5: Green Time Band
A6: Monday to Friday (Including Bank Holidays) All Year | B6: 16:00 to 19:30 | C6: 08:00 to 16:00 19:30 to 22:00 | E6: 00:00 to 08:00 22:00 to 24:00 | G6: Monday to Friday (Including Bank Holidays) November to February Inclusive | I6: 16:00 to 19:30 | J6: 08:00 to 16:00 19:30 to 22:00 | K6: 00:00 to 08:00 22:00 to 24:00
A7: Saturday and Sunday All Year | E7: 00:00 to 24:00 | G7: Monday to Friday (Including Bank Holidays) April to October Inclusive and March | J7: 08:00 to 22:00 | K7: 00:00 to 08:00 22:00 to 24:00
A8: Notes | B8: All the above times are in UK Clock time | G8: Saturday and Sunday All year | K8: 00:00 to 24:00
G9: Notes | I9: All the above times are in UK Clock time
A11: Tariff name | B11: Open LLFCs | C11: PCs | D11: Unit charge 1 (NHH) or red/black charge (HH) p/kWh | E11: Unit charge 2 (NHH) or amber/yellow charge (HH) p/kWh | F11: Green charge(HH) p/kWh | G11: Fixed charge p/MPAN/day | H11: Capacity charge p/kVA/day | I11: Exceeded capacity charge p/kVA/day | J11: Reactive power charge p/kVArh | K11: Closed LLFCs
A12: Domestic Unrestricted * | B12: 1 | C12: 1 | D12: 2.355 | E12: 0 | F12: 0 | G12: 5.57 | H12: 0 | I12: 0 | J12: 0 | K12: 998, 999
A13: Domestic Two Rate * | B13: 2 | C13: 2 | D13: 2.674 | E13: 1.131 | F13: 0 | G13: 5.57 | H13: 0 | I13: 0 | J13: 0 | K13: 0
A14: Domestic Off Peak (related MPAN) | B14: 12 | C14: 2 | D14: 1.25 | E14: 0 | F14: 0 | G14: 0 | H14: 0 | I14: 0 | J14: 0 | K14: 0
A15: Small Non Domestic Unrestricted | B15: 203 | C15: 3 | D15: 2.379 | E15: 0 | F15: 0 | G15: 5.84 | H15: 0 | I15: 0 | J15: 0 | K15: 0
A16: Small Non Domestic Two Rate | B16: 204 | C16: 4 | D16: 2.6 | E16: 1.166 | F16: 0 | G16: 5.84 | H16: 0 | I16: 0 | J16: 0 | K16: 0
A17: Small Non Domestic Off Peak (related MPAN) | B17: 205 | C17: 4 | D17: 1.311 | E17: 0 | F17: 0 | G17: 0 | H17: 0 | I17: 0 | J17: 0 | K17: 0
A18: LV Medium Non-Domestic | B18: 257 | C18: 5-8 | D18: 2.29 | E18: 1.12 | F18: 0 | G18: 30.49 | H18: 0 | I18: 0 | J18: 0 | K18: 0
A19: LV Sub Medium Non-Domestic | B19: 265 | C19: 5-8 | D19: 2.343 | E19: 1.152 | F19: 0 | G19: 30.5 | H19: 0 | I19: 0 | J19: 0 | K19: 0
A20: HV Medium Non-Domestic | B20: 304 | C20: 5-8 | D20: 1.653 | E20: 1.103 | F20: 0 | G20: 284.23 | H20: 0 | I20: 0 | J20: 0 | K20: 0
A21: LV Network Domestic * | B21: 249 | C21: 0 | D21: 7.567 | E21: 1.91 | F21: 1.117 | G21: 5.57 | H21: 0 | I21: 0 | J21: 0 | K21: 0
A22: LV Network Non-Domestic Non-CT | B22: 278 | C22: 0 | D22: 7.934 | E22: 1.958 | F22: 1.12 | G22: 5.84 | H22: 0 | I22: 0 | J22: 0 | K22: 0
A23: LV HH Metered | B23: 251 | C23: 0 | D23: 5.589 | E23: 1.641 | F23: 1.099 | G23: 15.9 | H23: 1.77 | I23: 4.14 | J23: 0.166 | K23: 0
A24: LV Sub HH Metered | B24: 293 | C24: 0 | D24: 4.01 | E24: 1.419 | F24: 1.086 | G24: 15.9 | H24: 2.49 | I24: 4.11 | J24: 0.097 | K24: 0
A25: HV HH Metered | B25: 301 | C25: 0 | D25: 3.266 | E25: 1.314 | F25: 1.08 | G25: 151.06 | H25: 2.39 | I25: 4.32 | J25: 0.067 | K25: 0
A26: NHH UMS category A | B26: 506 | C26: 8 | D26: 1.972 | E26: 0 | F26: 0 | G26: 0 | H26: 0 | I26: 0 | J26: 0 | K26: 0
A27: NHH UMS category B | B27: 507 | C27: 1 | D27: 2.283 | E27: 0 | F27: 0 | G27: 0 | H27: 0 | I27: 0 | J27: 0 | K27: 0
A28: NHH UMS category C | B28: 508 | C28: 1 | D28: 3.317 | E28: 0 | F28: 0 | G28: 0 | H28: 0 | I28: 0 | J28: 0 | K28: 0
A29: NHH UMS category D | B29: 509 | C29: 1 | D29: 1.762 | E29: 0 | F29: 0 | G29: 0 | H29: 0 | I29: 0 | J29: 0 | K29: 0
A30: LV UMS (Pseudo HH Metered) | B30: 554 & 555 | C30: 0 | D30: 18.384 | E30: 1.815 | F30: 1.112 | G30: 0 | H30: 0 | I30: 0 | J30: 0 | K30: 0
A31: LV Generation NHH or Aggregate HH | B31: 774 | C31: 8&0 | D31: -0.671 | E31: 0 | F31: 0 | G31: 0 | H31: 0 | I31: 0 | J31: 0 | K31: 0
A32: LV Sub Generation NHH | B32: 776 | C32: 8 | D32: -0.595 | E32: 0 | F32: 0 | G32: 0 | H32: 0 | I32: 0 | J32: 0 | K32: 0
A33: LV Generation Intermittent | B33: 792 | C33: 0 | D33: -0.671 | E33: 0 | F33: 0 | G33: 0 | H33: 0 | I33: 0 | J33: 0.141 | K33: 0
A34: LV Generation Intermittent no RP charge | B34: 392 | C34: 0 | D34: -0.671 | E34: 0 | F34: 0 | G34: 0 | H34: 0 | I34: 0 | J34: 0 | K34: 0
A35: LV Generation Non-Intermittent | B35: 794 | C35: 0 | D35: -4.445 | E35: -0.583 | F35: -0.042 | G35: 0 | H35: 0 | I35: 0 | J35: 0.141 | K35: 0
A36: LV Generation Non-Intermittent no RP charge | B36: 394 | C36: 0 | D36: -4.445 | E36: -0.583 | F36: -0.042 | G36: 0 | H36: 0 | I36: 0 | J36: 0 | K36: 0
A37: LV Sub Generation Intermittent | B37: 793 | C37: 0 | D37: -0.595 | E37: 0 | F37: 0 | G37: 0 | H37: 0 | I37: 0 | J37: 0.134 | K37: 0
A38: LV Sub Generation Intermittent no RP charge | B38: 393 | C38: 0 | D38: -0.595 | E38: 0 | F38: 0 | G38: 0 | H38: 0 | I38: 0 | J38: 0 | K38: 0
A39: LV Sub Generation Non-Intermittent | B39: 795 | C39: 0 | D39: -3.947 | E39: -0.514 | F39: -0.038 | G39: 0 | H39: 0 | I39: 0 | J39: 0.134 | K39: 0
A40: LV Sub Generation Non-Intermittent no RP charge | B40: 395 | C40: 0 | D40: -3.947 | E40: -0.514 | F40: -0.038 | G40: 0 | H40: 0 | I40: 0 | J40: 0 | K40: 0
A41: HV Generation Intermittent | B41: 796 | C41: 0 | D41: -0.379 | E41: 0 | F41: 0 | G41: 84.92 | H41: 0 | I41: 0 | J41: 0.104 | K41: 0
A42: HV Generation Intermittent no RP charge | B42: 396 | C42: 0 | D42: -0.379 | E42: 0 | F42: 0 | G42: 84.92 | H42: 0 | I42: 0 | J42: 0 | K42: 0
...

Sheet Annex 2 EHV charges
A1: Back to Overview | F1: Note: The list of MPANs / MSIDs provided may be incomplete; the DNO reserves the right to apply the listed charges to any other MPANs / MSIDs associated with the site.
A2: =Overview!B4& " - Effective from "&Overview!D4&" - "&Overview!E4&" EDCM charges" -> Northern Powergrid (Northeast) Ltd - Effective from 1 April 2019 - Final EDCM charges
A4: Time Periods for Designated EHV Properties
A5: Time periods | D5: Super Red Time Band
A6: Monday to Friday (Including Bank Holidays) November to February Inclusive | D6: 1600 - 1930
A7: Notes | D7: All the above times are in UK Clock time
A9: Import Unique Identifier | B9: LLFC | C9: Import MPANs/MSIDs | D9: Export Unique Identifier | E9: LLFC | F9: Export MPANs/MSIDs | G9: Name | H9: Import Super Red unit charge (p/kWh) | I9: Import fixed charge (p/day) | J9: Import capacity charge (p/kVA/day) | K9: Import exceeded capacity charge (p/kVA/day) | L9: Export Super Red unit charge (p/kWh) | M9: Export fixed charge (p/day) | N9: Export capacity charge (p/kVA/day) | O9: Export exceeded capacity charge (p/kVA/day)
A10: 601 | B10: 601 | C10: 1592001005770 1592101005776 | D10: 701 | E10: 701 | F10: 1574000216135 1594001005774 | G10: EHV Site Specific - Generation Exempt (LLFC 601 & 701) | H10: 0 | I10: 715.82 | J10: 0.72 | K10: 0.72 | L10: 0 | M10: 0 | N10: 0 | O10: 0
A11: 603 | B11: 603 | C11: 1592001051182 | E11: 0 | F11: 0 | G11: EHV Site Specific (LLFC 603) | H11: 0 | I11: 8053.96 | J11: 1.92 | K11: 1.92 | L11: 0 | M11: 0 | N11: 0 | O11: 0
A12: 604 | B12: 604 | C12: MSID_7299 | D12: 727 | E12: 727 | F12: MSID_7300 | G12: EHV Site Specific (LLFC 604 & 727) | H12: 0 | I12: 52.97 | J12: 0.77 | K12: 0.77 | L12: 0 | M12: 1059.37 | N12: 0.05 | O12: 0.05
A13: 605 | B13: 605 | C13: 1592001092676 | E13: 0 | F13: 0 | G13: EHV Site Specific (LLFC 605) | H13: 0.372 | I13: 1997.93 | J13: 1.75 | K13: 1.75 | L13: 0 | M13: 0 | N13: 0 | O13: 0
A14: 606 | B14: 606 | C14: 1592001092719 | E14: 0 | F14: 0 | G14: EHV Site Specific (LLFC 606) | H14: 0.408 | I14: 3995.86 | J14: 2 | K14: 2 | L14: 0 | M14: 0 | N14: 0 | O14: 0
A15: 607 | B15: 607 | C15: 1592001092728 | E15: 0 | F15: 0 | G15: EHV Site Specific (LLFC 607) | H15: 1.182 | I15: 3995.86 | J15: 2.91 | K15: 2.91 | L15: 0 | M15: 0 | N15: 0 | O15: 0
A16: 608 | B16: 608 | C16: 1592001092737 | E16: 0 | F16: 0 | G16: EHV Site Specific (LLFC 608) | H16: 0.037 | I16: 3995.86 | J16: 2.7 | K16: 2.7 | L16: 0 | M16: 0 | N16: 0 | O16: 0
A17: 609 | B17: 609 | C17: 1592001046085 | E17: 0 | F17: 0 | G17: EHV Site Specific (LLFC 609) | H17: 0 | I17: 703.73 | J17: 3.05 | K17: 3.05 | L17: 0 | M17: 0 | N17: 0 | O17: 0
A18: 611 | B18: 611 | C18: 1592001111628 | E18: 0 | F18: 0 | G18: EHV Site Specific (LLFC 611) | H18: 0 | I18: 3493.87 | J18: 4.97 | K18: 4.97 | L18: 0 | M18: 0 | N18: 0 | O18: 0
A19: 612 | B19: 612 | C19: 1592001073112 | D19: 704 | E19: 704 | F19: 1594001073116 | G19: EHV Site Specific (LLFC 612 & 704) | H19: 0.448 | I19: 184.47 | J19: 1.18 | K19: 1.18 | L19: -0.565 | M19: 1844.66 | N19: 0.05 | O19: 0.05
A20: 613 | B20: 613 | C20: TBC | E20: 0 | F20: 0 | G20: EHV Site Specific (LLFC 613) | H20: 0.982 | I20: 65.85 | J20: 1.16 | K20: 1.16 | L20: 0 | M20: 0 | N20: 0 | O20: 0
A21: 614 | B21: 614 | C21: 1592001055257 | D21: 709 | E21: 709 | F21: 1594001055250 | G21: EHV Site Specific (LLFC 614 & 709) | H21: 0 | I21: 6364.26 | J21: 0.53 | K21: 0.53 | L21: 0 | M21: 1272.85 | N21: 0.05 | O21: 0.05
A22: 615 & 616 | B22: 615 & 616 | C22: 1592001055239 1592001055248 | E22: 0 | F22: 0 | G22: EHV Site Specific (LLFC 615 & 616) | H22: 0.309 | I22: 3313.77 | J22: 2.63 | K22: 2.63 | L22: 0 | M22: 0 | N22: 0 | O22: 0
A23: 617 | B23: 617 | C23: 1592001110572 | E23: 0 | F23: 0 | G23: EHV Site Specific (LLFC 617) | H23: 0 | I23: 9368.64 | J23: 1.8 | K23: 1.8 | L23: 0 | M23: 0 | N23: 0 | O23: 0
A24: 618 | B24: 618 | C24: 1592001094308 | E24: 0 | F24: 0 | G24: EHV Site Specific (LLFC 618) | H24: 0.239 | I24: 3342.48 | J24: 5.17 | K24: 5.17 | L24: 0 | M24: 0 | N24: 0 | O24: 0
A25: 619 | B25: 619 | C25: 1570000150382 | D25: 710 | E25: 710 | F25: 1594000000038 | G25: EHV Site Specific - Generation Exempt (LLFC 619 & 710) | H25: 0.027 | I25: 24 | J25: 1.33 | K25: 1.33 | L25: 0 | M25: 0 | N25: 0 | O25: 0
A26: 620 | B26: 620 | C26: 1592001007476 | E26: 0 | F26: 0 | G26: EHV Site Specific (LLFC 620) | H26: 0 | I26: 1407.46 | J26: 5.02 | K26: 5.02 | L26: 0 | M26: 0 | N26: 0 | O26: 0
A27: 621 | B27: 621 | C27: 1592001007494 | E27: 0 | F27: 0 | G27: EHV Site Specific (LLFC 621) | H27: 0.091 | I27: 65.85 | J27: 2.21 | K27: 2.21 | L27: 0 | M27: 0 | N27: 0 | O27: 0
A28: 622 | B28: 622 | C28: 1592001036574 | D28: 711 | E28: 711 | F28: 1594001036578 | G28: EHV Site Specific - Generation Exempt (LLFC 622 & 711) | H28: 0.163 | I28: 465.53 | J28: 1.5 | K28: 1.5 | L28: 0 | M28: 0 | N28: 0 | O28: 0
A29: 624 | B29: 624 | C29: 1592001063540 | D29: 804 | E29: 804 | F29: 1574000324772 | G29: EHV Site Specific (LLFC 624 & 804) | H29: 0.009 | I29: 3063.56 | J29: 2.46 | K29: 2.46 | L29: 0 | M29: 958.73 | N29: 0.05 | O29: 0.05
A30: 625 | B30: 625 | C30: 1592001006890 | D30: 748 | E30: 748 | F30: 1594001006893 | G30: EHV Site Specific - Generation Exempt (LLFC 625 & 748) | H30: 1.158 | I30: 25.46 | J30: 2.32 | K30: 2.32 | L30: 0 | M30: 0 | N30: 0 | O30: 0
A31: 627 | B31: 627 | C31: 1570000199077 | D31: 729 | E31: 729 | F31: 1574000199083 | G31: EHV Site Specific - Generation Exempt (LLFC 627 & 729) | H31: 0 | I31: 1104.16 | J31: 1.49 | K31: 1.49 | L31: 0 | M31: 0 | N31: 0 | O31: 0
A32: 626 | B32: 626 | C32: 1592001005637 | E32: 0 | F32: 0 | G32: EHV Site Specific (LLFC 626) | H32: 0.237 | I32: 3132.37 | J32: 3.99 | K32: 3.99 | L32: 0 | M32: 0 | N32: 0 | O32: 0
A33: 628 | B33: 628 | C33: 1592001111405 | E33: 0 | F33: 0 | G33: EHV Site Specific (LLFC 628) | H33: 1.081 | I33: 601.63 | J33: 4.06 | K33: 4.06 | L33: 0 | M33: 0 | N33: 0 | O33: 0
A34: 631 | B34: 631 | C34: 1592001110216 | E34: 0 | F34: 0 | G34: EHV Site Specific (LLFC 631) | H34: 0 | I34: 65.85 | J34: 3.38 | K34: 3.38 | L34: 0 | M34: 0 | N34: 0 | O34: 0
A35: 632 | B35: 632 | C35: 1592001007467 | E35: 0 | F35: 0 | G35: EHV Site Specific (LLFC 632) | H35: 0.286 | I35: 256.45 | J35: 4.18 | K35: 4.18 | L35: 0 | M35: 0 | N35: 0 | O35: 0
A36: 633 | B36: 633 | C36: 1580001273940 1580001273950 | E36: 0 | F36: 0 | G36: EHV Site Specific (LLFC 633) | H36: 0.18 | I36: 3439.26 | J36: 2.71 | K36: 2.71 | L36: 0 | M36: 0 | N36: 0 | O36: 0
A37: 637 | B37: 637 | C37: 1592001141543 | D37: 728 | E37: 728 | F37: 1594001141547 | G37: EHV Site Specific - Generation Exempt (LLFC 637 & 728) | H37: 0.053 | I37: 1299.31 | J37: 1.52 | K37: 1.52 | L37: 0 | M37: 0 | N37: 0 | O37: 0
A38: 680 | B38: 680 | C38: 1580000675845 | D38: 759 | E38: 759 | F38: 1574000275033 | G38: EHV Site Specific (LLFC 680 & 759) | H38: 0.25 | I38: 2.96 | J38: 1.17 | K38: 1.17 | L38: 0 | M38: 125.26 | N38: 0.05 | O38: 0.05
A39: 681 | B39: 681 | C39: 1580000872387 | D39: 760 | E39: 760 | F39: 1574000283735 | G39: EHV Site Specific (LLFC 681 & 760) | H39: 0.285 | I39: 106.93 | J39: 1.27 | K39: 1.27 | L39: 0 | M39: 4277.3 | N39: 0.05 | O39: 0.05
A40: 544 | B40: 544 | C40: 1570000124531 | D40: 761 | E40: 761 | F40: 1594000000047 | G40: EHV Site Specific - Generation Exempt (LLFC 544 & 761) | H40: 0 | I40: 11.25 | J40: 0.81 | K40: 0.81 | L40: 0 | M40: 0 | N40: 0 | O40: 0
A41: 682 | B41: 682 | C41: 1580000909309 | D41: 762 | E41: 762 | F41: 1574000285644 | G41: EHV Site Specific (LLFC 682 & 762) | H41: 0.448 | I41: 805.14 | J41: 0.84 | K41: 0.84 | L41: -0.565 | M41: 4391.65 | N41: 0.05 | O41: 0.05
A42: 691 | B42: 691 | C42: 1592101007746 | E42: 0 | F42: 0 | G42: EHV Site Specific (LLFC 691) | H42: 0.062 | I42: 32.92 | J42: 4.59 | K42: 4.59 | L42: 0 | M42: 0 | N42: 0 | O42: 0
...

Sheet Annex 2a Import
A1: Note: The list of MPANs / MSIDs provided may be incomplete; the DNO reserves the right to apply the listed charges to any other MPANs / MSIDs associated with the site. Note: This table is automatically populated based on the content of the tab entitled 'Annex 2 EHV Charges'. The timebands are as shown in Annex 2.
A2: =Overview!B4& " - Effective from "&Overview!D4&" - "&Overview!E4&" EDCM import charges" -> Northern Powergrid (Northeast) Ltd - Effective from 1 April 2019 - Final EDCM import charges
A4: Import Unique Identifier | B4: LLFC | C4: Import MPANs/MSIDs | D4: Name | E4: ='Annex 2 EHV charges'!H9 -> Import Super Red unit charge (p/kWh) | F4: ='Annex 2 EHV charges'!I9 -> Import fixed charge (p/day) | G4: ='Annex 2 EHV charges'!J9 -> Import capacity charge (p/kVA/day) | H4: ='Annex 2 EHV charges'!K9 -> Import exceeded capacity charge (p/kVA/day)
A5: {=IFERROR(INDEX('Annex 2 EHV charges'!$A$10:$A$150, MATCH(0, IF(('Annex 2 EHV charges'!$A$10:$A$150=""),1, COUNTIF(A$4:$A4, 'Annex 2 EHV charges'!$A$10:$A$150)), 0)),"")} -> 601 | B5: =IF($A5="","",VLOOKUP($A5,'Annex 2 EHV charges'!$A:$O,2,0)) -> 601 | C5: =IF($A5="","",VLOOKUP($A5,'Annex 2 EHV charges'!$A:$O,3,0)) -> 1592001005770 1592101005776 | D5: =IF($A5="","",VLOOKUP($A5,'Annex 2 EHV charges'!$A:$O,7,0)) -> EHV Site Specific - Generation Exempt (LLFC 601 & 701) | E5: =IFERROR(IF(VLOOKUP($A5,'Annex 2 EHV charges'!$A:$O,8,FALSE)=0,"",VLOOKUP($A5,'Annex 2 EHV charges'!$A:$O,8,FALSE)),"") | F5: =IFERROR(IF(VLOOKUP($A5,'Annex 2 EHV charges'!$A:$O,9,FALSE)=0,"",VLOOKUP($A5,'Annex 2 EHV charges'!$A:$O,9,FALSE)),"") -> 715.82 | G5: =IFERROR(IF(VLOOKUP($A5,'Annex 2 EHV charges'!$A:$O,10,FALSE)=0,"",VLOOKUP($A5,'Annex 2 EHV charges'!$A:$O,10,FALSE)),"") -> 0.72 | H5: =IFERROR(IF(VLOOKUP($A5,'Annex 2 EHV charges'!$A:$O,11,FALSE)=0,"",VLOOKUP($A5,'Annex 2 EHV charges'!$A:$O,11,FALSE)),"") -> 0.72
A6: {=IFERROR(INDEX('Annex 2 EHV charges'!$A$10:$A$150, MATCH(0, IF(('Annex 2 EHV charges'!$A$10:$A$150=""),1, COUNTIF(A$4:$A5, 'Annex 2 EHV charges'!$A$10:$A$150)), 0)),"")} -> 603 | B6: =IF($A6="","",VLOOKUP($A6,'Annex 2 EHV charges'!$A:$O,2,0)) -> 603 | C6: =IF($A6="","",VLOOKUP($A6,'Annex 2 EHV charges'!$A:$O,3,0)) -> 1592001051182 | D6: =IF($A6="","",VLOOKUP($A6,'Annex 2 EHV charges'!$A:$O,7,0)) -> EHV Site Specific (LLFC 603) | E6: =IFERROR(IF(VLOOKUP($A6,'Annex 2 EHV charges'!$A:$O,8,FALSE)=0,"",VLOOKUP($A6,'Annex 2 EHV charges'!$A:$O,8,FALSE)),"") | F6: =IFERROR(IF(VLOOKUP($A6,'Annex 2 EHV charges'!$A:$O,9,FALSE)=0,"",VLOOKUP($A6,'Annex 2 EHV charges'!$A:$O,9,FALSE)),"") -> 8053.96 | G6: =IFERROR(IF(VLOOKUP($A6,'Annex 2 EHV charges'!$A:$O,10,FALSE)=0,"",VLOOKUP($A6,'Annex 2 EHV charges'!$A:$O,10,FALSE)),"") -> 1.92 | H6: =IFERROR(IF(VLOOKUP($A6,'Annex 2 EHV charges'!$A:$O,11,FALSE)=0,"",VLOOKUP($A6,'Annex 2 EHV charges'!$A:$O,11,FALSE)),"") -> 1.92
A7: {=IFERROR(INDEX('Annex 2 EHV charges'!$A$10:$A$150, MATCH(0, IF(('Annex 2 EHV charges'!$A$10:$A$150=""),1, COUNTIF(A$4:$A6, 'Annex 2 EHV charges'!$A$10:$A$150)), 0)),"")} -> 604 | B7: =IF($A7="","",VLOOKUP($A7,'Annex 2 EHV charges'!$A:$O,2,0)) -> 604 | C7: =IF($A7="","",VLOOKUP($A7,'Annex 2 EHV charges'!$A:$O,3,0)) -> MSID_7299 | D7: =IF($A7="","",VLOOKUP($A7,'Annex 2 EHV charges'!$A:$O,7,0)) -> EHV Site Specific (LLFC 604 & 727) | E7: =IFERROR(IF(VLOOKUP($A7,'Annex 2 EHV charges'!$A:$O,8,FALSE)=0,"",VLOOKUP($A7,'Annex 2 EHV charges'!$A:$O,8,FALSE)),"") | F7: =IFERROR(IF(VLOOKUP($A7,'Annex 2 EHV charges'!$A:$O,9,FALSE)=0,"",VLOOKUP($A7,'Annex 2 EHV charges'!$A:$O,9,FALSE)),"") -> 52.97 | G7: =IFERROR(IF(VLOOKUP($A7,'Annex 2 EHV charges'!$A:$O,10,FALSE)=0,"",VLOOKUP($A7,'Annex 2 EHV charges'!$A:$O,10,FALSE)),"") -> 0.77 | H7: =IFERROR(IF(VLOOKUP($A7,'Annex 2 EHV charges'!$A:$O,11,FALSE)=0,"",VLOOKUP($A7,'Annex 2 EHV charges'!$A:$O,11,FALSE)),"") -> 0.77
A8: {=IFERROR(INDEX('Annex 2 EHV charges'!$A$10:$A$150, MATCH(0, IF(('Annex 2 EHV charges'!$A$10:$A$150=""),1, COUNTIF(A$4:$A7, 'Annex 2 EHV charges'!$A$10:$A$150)), 0)),"")} -> 605 | B8: =IF($A8="","",VLOOKUP($A8,'Annex 2 EHV charges'!$A:$O,2,0)) -> 605 | C8: =IF($A8="","",VLOOKUP($A8,'Annex 2 EHV charges'!$A:$O,3,0)) -> 1592001092676 | D8: =IF($A8="","",VLOOKUP($A8,'Annex 2 EHV charges'!$A:$O,7,0)) -> EHV Site Specific (LLFC 605) | E8: =IFERROR(IF(VLOOKUP($A8,'Annex 2 EHV charges'!$A:$O,8,FALSE)=0,"",VLOOKUP($A8,'Annex 2 EHV charges'!$A:$O,8,FALSE)),"") -> 0.372 | F8: =IFERROR(IF(VLOOKUP($A8,'Annex 2 EHV charges'!$A:$O,9,FALSE)=0,"",VLOOKUP($A8,'Annex 2 EHV charges'!$A:$O,9,FALSE)),"") -> 1997.93 | G8: =IFERROR(IF(VLOOKUP($A8,'Annex 2 EHV charges'!$A:$O,10,FALSE)=0,"",VLOOKUP($A8,'Annex 2 EHV charges'!$A:$O,10,FALSE)),"") -> 1.75 | H8: =IFERROR(IF(VLOOKUP($A8,'Annex 2 EHV charges'!$A:$O,11,FALSE)=0,"",VLOOKUP($A8,'Annex 2 EHV charges'!$A:$O,11,FALSE)),"") -> 1.75
A9: {=IFERROR(INDEX('Annex 2 EHV charges'!$A$10:$A$150, MATCH(0, IF(('Annex 2 EHV charges'!$A$10:$A$150=""),1, COUNTIF(A$4:$A8, 'Annex 2 EHV charges'!$A$10:$A$150)), 0)),"")} -> 606 | B9: =IF($A9="","",VLOOKUP($A9,'Annex 2 EHV charges'!$A:$O,2,0)) -> 606 | C9: =IF($A9="","",VLOOKUP($A9,'Annex 2 EHV charges'!$A:$O,3,0)) -> 1592001092719 | D9: =IF($A9="","",VLOOKUP($A9,'Annex 2 EHV charges'!$A:$O,7,0)) -> EHV Site Specific (LLFC 606) | E9: =IFERROR(IF(VLOOKUP($A9,'Annex 2 EHV charges'!$A:$O,8,FALSE)=0,"",VLOOKUP($A9,'Annex 2 EHV charges'!$A:$O,8,FALSE)),"") -> 0.408 | F9: =IFERROR(IF(VLOOKUP($A9,'Annex 2 EHV charges'!$A:$O,9,FALSE)=0,"",VLOOKUP($A9,'Annex 2 EHV charges'!$A:$O,9,FALSE)),"") -> 3995.86 | G9: =IFERROR(IF(VLOOKUP($A9,'Annex 2 EHV charges'!$A:$O,10,FALSE)=0,"",VLOOKUP($A9,'Annex 2 EHV charges'!$A:$O,10,FALSE)),"") -> 2 | H9: =IFERROR(IF(VLOOKUP($A9,'Annex 2 EHV charges'!$A:$O,11,FALSE)=0,"",VLOOKUP($A9,'Annex 2 EHV charges'!$A:$O,11,FALSE)),"") -> 2
A10: {=IFERROR(INDEX('Annex 2 EHV charges'!$A$10:$A$150, MATCH(0, IF(('Annex 2 EHV charges'!$A$10:$A$150=""),1, COUNTIF(A$4:$A9, 'Annex 2 EHV charges'!$A$10:$A$150)), 0)),"")} -> 607 | B10: =IF($A10="","",VLOOKUP($A10,'Annex 2 EHV charges'!$A:$O,2,0)) -> 607 | C10: =IF($A10="","",VLOOKUP($A10,'Annex 2 EHV charges'!$A:$O,3,0)) -> 1592001092728 | D10: =IF($A10="","",VLOOKUP($A10,'Annex 2 EHV charges'!$A:$O,7,0)) -> EHV Site Specific (LLFC 607) | E10: =IFERROR(IF(VLOOKUP($A10,'Annex 2 EHV charges'!$A:$O,8,FALSE)=0,"",VLOOKUP($A10,'Annex 2 EHV charges'!$A:$O,8,FALSE)),"") -> 1.182 | F10: =IFERROR(IF(VLOOKUP($A10,'Annex 2 EHV charges'!$A:$O,9,FALSE)=0,"",VLOOKUP($A10,'Annex 2 EHV charges'!$A:$O,9,FALSE)),"") -> 3995.86 | G10: =IFERROR(IF(VLOOKUP($A10,'Annex 2 EHV charges'!$A:$O,10,FALSE)=0,"",VLOOKUP($A10,'Annex 2 EHV charges'!$A:$O,10,FALSE)),"") -> 2.91 | H10: =IFERROR(IF(VLOOKUP($A10,'Annex 2 EHV charges'!$A:$O,11,FALSE)=0,"",VLOOKUP($A10,'Annex 2 EHV charges'!$A:$O,11,FALSE)),"") -> 2.91
A11: {=IFERROR(INDEX('Annex 2 EHV charges'!$A$10:$A$150, MATCH(0, IF(('Annex 2 EHV charges'!$A$10:$A$150=""),1, COUNTIF(A$4:$A10, 'Annex 2 EHV charges'!$A$10:$A$150)), 0)),"")} -> 608 | B11: =IF($A11="","",VLOOKUP($A11,'Annex 2 EHV charges'!$A:$O,2,0)) -> 608 | C11: =IF($A11="","",VLOOKUP($A11,'Annex 2 EHV charges'!$A:$O,3,0)) -> 1592001092737 | D11: =IF($A11="","",VLOOKUP($A11,'Annex 2 EHV charges'!$A:$O,7,0)) -> EHV Site Specific (LLFC 608) | E11: =IFERROR(IF(VLOOKUP($A11,'Annex 2 EHV charges'!$A:$O,8,FALSE)=0,"",VLOOKUP($A11,'Annex 2 EHV charges'!$A:$O,8,FALSE)),"") -> 0.037 | F11: =IFERROR(IF(VLOOKUP($A11,'Annex 2 EHV charges'!$A:$O,9,FALSE)=0,"",VLOOKUP($A11,'Annex 2 EHV charges'!$A:$O,9,FALSE)),"") -> 3995.86 | G11: =IFERROR(IF(VLOOKUP($A11,'Annex 2 EHV charges'!$A:$O,10,FALSE)=0,"",VLOOKUP($A11,'Annex 2 EHV charges'!$A:$O,10,FALSE)),"") -> 2.7 | H11: =IFERROR(IF(VLOOKUP($A11,'Annex 2 EHV charges'!$A:$O,11,FALSE)=0,"",VLOOKUP($A11,'Annex 2 EHV charges'!$A:$O,11,FALSE)),"") -> 2.7
A12: {=IFERROR(INDEX('Annex 2 EHV charges'!$A$10:$A$150, MATCH(0, IF(('Annex 2 EHV charges'!$A$10:$A$150=""),1, COUNTIF(A$4:$A11, 'Annex 2 EHV charges'!$A$10:$A$150)), 0)),"")} -> 609 | B12: =IF($A12="","",VLOOKUP($A12,'Annex 2 EHV charges'!$A:$O,2,0)) -> 609 | C12: =IF($A12="","",VLOOKUP($A12,'Annex 2 EHV charges'!$A:$O,3,0)) -> 1592001046085 | D12: =IF($A12="","",VLOOKUP($A12,'Annex 2 EHV charges'!$A:$O,7,0)) -> EHV Site Specific (LLFC 609) | E12: =IFERROR(IF(VLOOKUP($A12,'Annex 2 EHV charges'!$A:$O,8,FALSE)=0,"",VLOOKUP($A12,'Annex 2 EHV charges'!$A:$O,8,FALSE)),"") | F12: =IFERROR(IF(VLOOKUP($A12,'Annex 2 EHV charges'!$A:$O,9,FALSE)=0,"",VLOOKUP($A12,'Annex 2 EHV charges'!$A:$O,9,FALSE)),"") -> 703.73 | G12: =IFERROR(IF(VLOOKUP($A12,'Annex 2 EHV charges'!$A:$O,10,FALSE)=0,"",VLOOKUP($A12,'Annex 2 EHV charges'!$A:$O,10,FALSE)),"") -> 3.05 | H12: =IFERROR(IF(VLOOKUP($A12,'Annex 2 EHV charges'!$A:$O,11,FALSE)=0,"",VLOOKUP($A12,'Annex 2 EHV charges'!$A:$O,11,FALSE)),"") -> 3.05
A13: {=IFERROR(INDEX('Annex 2 EHV charges'!$A$10:$A$150, MATCH(0, IF(('Annex 2 EHV charges'!$A$10:$A$150=""),1, COUNTIF(A$4:$A12, 'Annex 2 EHV charges'!$A$10:$A$150)), 0)),"")} -> 611 | B13: =IF($A13="","",VLOOKUP($A13,'Annex 2 EHV charges'!$A:$O,2,0)) -> 611 | C13: =IF($A13="","",VLOOKUP($A13,'Annex 2 EHV charges'!$A:$O,3,0)) -> 1592001111628 | D13: =IF($A13="","",VLOOKUP($A13,'Annex 2 EHV charges'!$A:$O,7,0)) -> EHV Site Specific (LLFC 611) | E13: =IFERROR(IF(VLOOKUP($A13,'Annex 2 EHV charges'!$A:$O,8,FALSE)=0,"",VLOOKUP($A13,'Annex 2 EHV charges'!$A:$O,8,FALSE)),"") | F13: =IFERROR(IF(VLOOKUP($A13,'Annex 2 EHV charges'!$A:$O,9,FALSE)=0,"",VLOOKUP($A13,'Annex 2 EHV charges'!$A:$O,9,FALSE)),"") -> 3493.87 | G13: =IFERROR(IF(VLOOKUP($A13,'Annex 2 EHV charges'!$A:$O,10,FALSE)=0,"",VLOOKUP($A13,'Annex 2 EHV charges'!$A:$O,10,FALSE)),"") -> 4.97 | H13: =IFERROR(IF(VLOOKUP($A13,'Annex 2 EHV charges'!$A:$O,11,FALSE)=0,"",VLOOKUP($A13,'Annex 2 EHV charges'!$A:$O,11,FALSE)),"") -> 4.97
A14: {=IFERROR(INDEX('Annex 2 EHV charges'!$A$10:$A$150, MATCH(0, IF(('Annex 2 EHV charges'!$A$10:$A$150=""),1, COUNTIF(A$4:$A13, 'Annex 2 EHV charges'!$A$10:$A$150)), 0)),"")} -> 612 | B14: =IF($A14="","",VLOOKUP($A14,'Annex 2 EHV charges'!$A:$O,2,0)) -> 612 | C14: =IF($A14="","",VLOOKUP($A14,'Annex 2 EHV charges'!$A:$O,3,0)) -> 1592001073112 | D14: =IF($A14="","",VLOOKUP($A14,'Annex 2 EHV charges'!$A:$O,7,0)) -> EHV Site Specific (LLFC 612 & 704) | E14: =IFERROR(IF(VLOOKUP($A14,'Annex 2 EHV charges'!$A:$O,8,FALSE)=0,"",VLOOKUP($A14,'Annex 2 EHV charges'!$A:$O,8,FALSE)),"") -> 0.448 | F14: =IFERROR(IF(VLOOKUP($A14,'Annex 2 EHV charges'!$A:$O,9,FALSE)=0,"",VLOOKUP($A14,'Annex 2 EHV charges'!$A:$O,9,FALSE)),"") -> 184.47 | G14: =IFERROR(IF(VLOOKUP($A14,'Annex 2 EHV charges'!$A:$O,10,FALSE)=0,"",VLOOKUP($A14,'Annex 2 EHV charges'!$A:$O,10,FALSE)),"") -> 1.18 | H14: =IFERROR(IF(VLOOKUP($A14,'Annex 2 EHV charges'!$A:$O,11,FALSE)=0,"",VLOOKUP($A14,'Annex 2 EHV charges'!$A:$O,11,FALSE)),"") -> 1.18
A15: {=IFERROR(INDEX('Annex 2 EHV charges'!$A$10:$A$150, MATCH(0, IF(('Annex 2 EHV charges'!$A$10:$A$150=""),1, COUNTIF(A$4:$A14, 'Annex 2 EHV charges'!$A$10:$A$150)), 0)),"")} -> 613 | B15: =IF($A15="","",VLOOKUP($A15,'Annex 2 EHV charges'!$A:$O,2,0)) -> 613 | C15: =IF($A15="","",VLOOKUP($A15,'Annex 2 EHV charges'!$A:$O,3,0)) -> TBC | D15: =IF($A15="","",VLOOKUP($A15,'Annex 2 EHV charges'!$A:$O,7,0)) -> EHV Site Specific (LLFC 613) | E15: =IFERROR(IF(VLOOKUP($A15,'Annex 2 EHV charges'!$A:$O,8,FALSE)=0,"",VLOOKUP($A15,'Annex 2 EHV charges'!$A:$O,8,FALSE)),"") -> 0.982 | F15: =IFERROR(IF(VLOOKUP($A15,'Annex 2 EHV charges'!$A:$O,9,FALSE)=0,"",VLOOKUP($A15,'Annex 2 EHV charges'!$A:$O,9,FALSE)),"") -> 65.85 | G15: =IFERROR(IF(VLOOKUP($A15,'Annex 2 EHV charges'!$A:$O,10,FALSE)=0,"",VLOOKUP($A15,'Annex 2 EHV charges'!$A:$O,10,FALSE)),"") -> 1.16 | H15: =IFERROR(IF(VLOOKUP($A15,'Annex 2 EHV charges'!$A:$O,11,FALSE)=0,"",VLOOKUP($A15,'Annex 2 EHV charges'!$A:$O,11,FALSE)),"") -> 1.16
A16: {=IFERROR(INDEX('Annex 2 EHV charges'!$A$10:$A$150, MATCH(0, IF(('Annex 2 EHV charges'!$A$10:$A$150=""),1, COUNTIF(A$4:$A15, 'Annex 2 EHV charges'!$A$10:$A$150)), 0)),"")} -> 614 | B16: =IF($A16="","",VLOOKUP($A16,'Annex 2 EHV charges'!$A:$O,2,0)) -> 614 | C16: =IF($A16="","",VLOOKUP($A16,'Annex 2 EHV charges'!$A:$O,3,0)) -> 1592001055257 | D16: =IF($A16="","",VLOOKUP($A16,'Annex 2 EHV charges'!$A:$O,7,0)) -> EHV Site Specific (LLFC 614 & 709) | E16: =IFERROR(IF(VLOOKUP($A16,'Annex 2 EHV charges'!$A:$O,8,FALSE)=0,"",VLOOKUP($A16,'Annex 2 EHV charges'!$A:$O,8,FALSE)),"") | F16: =IFERROR(IF(VLOOKUP($A16,'Annex 2 EHV charges'!$A:$O,9,FALSE)=0,"",VLOOKUP($A16,'Annex 2 EHV charges'!$A:$O,9,FALSE)),"") -> 6364.26 | G16: =IFERROR(IF(VLOOKUP($A16,'Annex 2 EHV charges'!$A:$O,10,FALSE)=0,"",VLOOKUP($A16,'Annex 2 EHV charges'!$A:$O,10,FALSE)),"") -> 0.53 | H16: =IFERROR(IF(VLOOKUP($A16,'Annex 2 EHV charges'!$A:$O,11,FALSE)=0,"",VLOOKUP($A16,'Annex 2 EHV charges'!$A:$O,11,FALSE)),"") -> 0.53
... A65: {=IFERROR(INDEX('Annex 2 EHV charges'!$A$10:$A$150, MATCH(0, IF(('Annex 2 EHV charges'!$A$10:$A$150=""),1, COUNTIF(A$4:$A64, 'Annex 2 EHV charges'!$A$10:$A$150)), 0)),"")} -> 566 | B65: =IF($A65="","",VLOOKUP($A65,'Annex 2 EHV charges'!$A:$O,2,0)) -> 566 | C65: =IF($A65="","",VLOOKUP($A65,'Annex 2 EHV charges'!$A:$O,3,0)) -> 1580001511800 | D65: =IF($A65="","",VLOOKUP($A65,'Annex 2 EHV charges'!$A:$O,7,0)) -> EHV Site Specific (LLFC 566 & 808) | E65: =IFERROR(IF(VLOOKUP($A65,'Annex 2 EHV charges'!$A:$O,8,FALSE)=0,"",VLOOKUP($A65,'Annex 2 EHV charges'!$A:$O,8,FALSE)),"") -> 0.001 | F65: =IFERROR(IF(VLOOKUP($A65,'Annex 2 EHV charges'!$A:$O,9,FALSE)=0,"",VLOOKUP($A65,'Annex 2 EHV charges'!$A:$O,9,FALSE)),"") -> 495.72 | G65: =IFERROR(IF(VLOOKUP($A65,'Annex 2 EHV charges'!$A:$O,10,FALSE)=0,"",VLOOKUP($A65,'Annex 2 EHV charges'!$A:$O,10,FALSE)),"") -> 2.45 | H65: =IFERROR(IF(VLOOKUP($A65,'Annex 2 EHV charges'!$A:$O,11,FALSE)=0,"",VLOOKUP($A65,'Annex 2 EHV charges'!$A:$O,11,FALSE)),"") -> 2.45

Sheet Annex 2b Export
A1: Note: The list of MPANs / MSIDs provided may be incomplete; the DNO reserves the right to apply the listed charges to any other MPANs / MSIDs associated with the site. Note: This table is automatically populated based on the content of the tab entitled 'Annex 2 EHV Charges'. The timebands are as shown in Annex 2.
A2: =Overview!B4& " - Effective from "&Overview!D4&" - "&Overview!E4&" EDCM export charges" -> Northern Powergrid (Northeast) Ltd - Effective from 1 April 2019 - Final EDCM export charges
A4: Export Unique Identifier | B4: LLFC | C4: Export MPANs/MSIDs | D4: Name | E4: ='Annex 2 EHV charges'!L9 -> Export Super Red unit charge (p/kWh) | F4: ='Annex 2 EHV charges'!M9 -> Export fixed charge (p/day) | G4: ='Annex 2 EHV charges'!N9 -> Export capacity charge (p/kVA/day) | H4: ='Annex 2 EHV charges'!O9 -> Export exceeded capacity charge (p/kVA/day)
A5: {=IFERROR(INDEX('Annex 2 EHV charges'!$D$10:$D$150, MATCH(0, IF(('Annex 2 EHV charges'!$D$10:$D$150=""),1, COUNTIF(A$4:$A4, 'Annex 2 EHV charges'!$D$10:$D$150)), 0)),"")} -> 701 | B5: =IF($A5="","",VLOOKUP($A5,'Annex 2 EHV charges'!$D:$O,2,0)) -> 701 | C5: =IF($A5="","",VLOOKUP($A5,'Annex 2 EHV charges'!$D:$O,3,0)) -> 1574000216135 1594001005774 | D5: =IF($A5="","",VLOOKUP($A5,'Annex 2 EHV charges'!$D:$O,4,0)) -> EHV Site Specific - Generation Exempt (LLFC 601 & 701) | E5: =IFERROR(IF(VLOOKUP($A5,'Annex 2 EHV charges'!$D:$O,9,FALSE)=0,"",VLOOKUP($A5,'Annex 2 EHV charges'!$D:$O,9,FALSE)),"") | F5: =IFERROR(IF(VLOOKUP($A5,'Annex 2 EHV charges'!$D:$O,10,FALSE)=0,"",VLOOKUP($A5,'Annex 2 EHV charges'!$D:$O,10,FALSE)),"") | G5: =IFERROR(IF(VLOOKUP($A5,'Annex 2 EHV charges'!$D:$O,11,FALSE)=0,"",VLOOKUP($A5,'Annex 2 EHV charges'!$D:$O,11,FALSE)),"") | H5: =IFERROR(IF(VLOOKUP($A5,'Annex 2 EHV charges'!$D:$O,12,FALSE)=0,"",VLOOKUP($A5,'Annex 2 EHV charges'!$D:$O,12,FALSE)),"")
A6: {=IFERROR(INDEX('Annex 2 EHV charges'!$D$10:$D$150, MATCH(0, IF(('Annex 2 EHV charges'!$D$10:$D$150=""),1, COUNTIF(A$4:$A5, 'Annex 2 EHV charges'!$D$10:$D$150)), 0)),"")} -> 727 | B6: =IF($A6="","",VLOOKUP($A6,'Annex 2 EHV charges'!$D:$O,2,0)) -> 727 | C6: =IF($A6="","",VLOOKUP($A6,'Annex 2 EHV charges'!$D:$O,3,0)) -> MSID_7300 | D6: =IF($A6="","",VLOOKUP($A6,'Annex 2 EHV charges'!$D:$O,4,0)) -> EHV Site Specific (LLFC 604 & 727) | E6: =IFERROR(IF(VLOOKUP($A6,'Annex 2 EHV charges'!$D:$O,9,FALSE)=0,"",VLOOKUP($A6,'Annex 2 EHV charges'!$D:$O,9,FALSE)),"") | F6: =IFERROR(IF(VLOOKUP($A6,'Annex 2 EHV charges'!$D:$O,10,FALSE)=0,"",VLOOKUP($A6,'Annex 2 EHV charges'!$D:$O,10,FALSE)),"") -> 1059.37 | G6: =IFERROR(IF(VLOOKUP($A6,'Annex 2 EHV charges'!$D:$O,11,FALSE)=0,"",VLOOKUP($A6,'Annex 2 EHV charges'!$D:$O,11,FALSE)),"") -> 0.05 | H6: =IFERROR(IF(VLOOKUP($A6,'Annex 2 EHV charges'!$D:$O,12,FALSE)=0,"",VLOOKUP($A6,'Annex 2 EHV charges'!$D:$O,12,FALSE)),"") -> 0.05
A7: {=IFERROR(INDEX('Annex 2 EHV charges'!$D$10:$D$150, MATCH(0, IF(('Annex 2 EHV charges'!$D$10:$D$150=""),1, COUNTIF(A$4:$A6, 'Annex 2 EHV charges'!$D$10:$D$150)), 0)),"")} -> 704 | B7: =IF($A7="","",VLOOKUP($A7,'Annex 2 EHV charges'!$D:$O,2,0)) -> 704 | C7: =IF($A7="","",VLOOKUP($A7,'Annex 2 EHV charges'!$D:$O,3,0)) -> 1594001073116 | D7: =IF($A7="","",VLOOKUP($A7,'Annex 2 EHV charges'!$D:$O,4,0)) -> EHV Site Specific (LLFC 612 & 704) | E7: =IFERROR(IF(VLOOKUP($A7,'Annex 2 EHV charges'!$D:$O,9,FALSE)=0,"",VLOOKUP($A7,'Annex 2 EHV charges'!$D:$O,9,FALSE)),"") -> -0.565 | F7: =IFERROR(IF(VLOOKUP($A7,'Annex 2 EHV charges'!$D:$O,10,FALSE)=0,"",VLOOKUP($A7,'Annex 2 EHV charges'!$D:$O,10,FALSE)),"") -> 1844.66 | G7: =IFERROR(IF(VLOOKUP($A7,'Annex 2 EHV charges'!$D:$O,11,FALSE)=0,"",VLOOKUP($A7,'Annex 2 EHV charges'!$D:$O,11,FALSE)),"") -> 0.05 | H7: =IFERROR(IF(VLOOKUP($A7,'Annex 2 EHV charges'!$D:$O,12,FALSE)=0,"",VLOOKUP($A7,'Annex 2 EHV charges'!$D:$O,12,FALSE)),"") -> 0.05
A8: {=IFERROR(INDEX('Annex 2 EHV charges'!$D$10:$D$150, MATCH(0, IF(('Annex 2 EHV charges'!$D$10:$D$150=""),1, COUNTIF(A$4:$A7, 'Annex 2 EHV charges'!$D$10:$D$150)), 0)),"")} -> 709 | B8: =IF($A8="","",VLOOKUP($A8,'Annex 2 EHV charges'!$D:$O,2,0)) -> 709 | C8: =IF($A8="","",VLOOKUP($A8,'Annex 2 EHV charges'!$D:$O,3,0)) -> 1594001055250 | D8: =IF($A8="","",VLOOKUP($A8,'Annex 2 EHV charges'!$D:$O,4,0)) -> EHV Site Specific (LLFC 614 & 709) | E8: =IFERROR(IF(VLOOKUP($A8,'Annex 2 EHV charges'!$D:$O,9,FALSE)=0,"",VLOOKUP($A8,'Annex 2 EHV charges'!$D:$O,9,FALSE)),"") | F8: =IFERROR(IF(VLOOKUP($A8,'Annex 2 EHV charges'!$D:$O,10,FALSE)=0,"",VLOOKUP($A8,'Annex 2 EHV charges'!$D:$O,10,FALSE)),"") -> 1272.85 | G8: =IFERROR(IF(VLOOKUP($A8,'Annex 2 EHV charges'!$D:$O,11,FALSE)=0,"",VLOOKUP($A8,'Annex 2 EHV charges'!$D:$O,11,FALSE)),"") -> 0.05 | H8: =IFERROR(IF(VLOOKUP($A8,'Annex 2 EHV charges'!$D:$O,12,FALSE)=0,"",VLOOKUP($A8,'Annex 2 EHV charges'!$D:$O,12,FALSE)),"") -> 0.05
A9: {=IFERROR(INDEX('Annex 2 EHV charges'!$D$10:$D$150, MATCH(0, IF(('Annex 2 EHV charges'!$D$10:$D$150=""),1, COUNTIF(A$4:$A8, 'Annex 2 EHV charges'!$D$10:$D$150)), 0)),"")} -> 710 | B9: =IF($A9="","",VLOOKUP($A9,'Annex 2 EHV charges'!$D:$O,2,0)) -> 710 | C9: =IF($A9="","",VLOOKUP($A9,'Annex 2 EHV charges'!$D:$O,3,0)) -> 1594000000038 | D9: =IF($A9="","",VLOOKUP($A9,'Annex 2 EHV charges'!$D:$O,4,0)) -> EHV Site Specific - Generation Exempt (LLFC 619 & 710) | E9: =IFERROR(IF(VLOOKUP($A9,'Annex 2 EHV charges'!$D:$O,9,FALSE)=0,"",VLOOKUP($A9,'Annex 2 EHV charges'!$D:$O,9,FALSE)),"") | F9: =IFERROR(IF(VLOOKUP($A9,'Annex 2 EHV charges'!$D:$O,10,FALSE)=0,"",VLOOKUP($A9,'Annex 2 EHV charges'!$D:$O,10,FALSE)),"") | G9: =IFERROR(IF(VLOOKUP($A9,'Annex 2 EHV charges'!$D:$O,11,FALSE)=0,"",VLOOKUP($A9,'Annex 2 EHV charges'!$D:$O,11,FALSE)),"") | H9: =IFERROR(IF(VLOOKUP($A9,'Annex 2 EHV charges'!$D:$O,12,FALSE)=0,"",VLOOKUP($A9,'Annex 2 EHV charges'!$D:$O,12,FALSE)),"")
A10: {=IFERROR(INDEX('Annex 2 EHV charges'!$D$10:$D$150, MATCH(0, IF(('Annex 2 EHV charges'!$D$10:$D$150=""),1, COUNTIF(A$4:$A9, 'Annex 2 EHV charges'!$D$10:$D$150)), 0)),"")} -> 711 | B10: =IF($A10="","",VLOOKUP($A10,'Annex 2 EHV charges'!$D:$O,2,0)) -> 711 | C10: =IF($A10="","",VLOOKUP($A10,'Annex 2 EHV charges'!$D:$O,3,0)) -> 1594001036578 | D10: =IF($A10="","",VLOOKUP($A10,'Annex 2 EHV charges'!$D:$O,4,0)) -> EHV Site Specific - Generation Exempt (LLFC 622 & 711) | E10: =IFERROR(IF(VLOOKUP($A10,'Annex 2 EHV charges'!$D:$O,9,FALSE)=0,"",VLOOKUP($A10,'Annex 2 EHV charges'!$D:$O,9,FALSE)),"") | F10: =IFERROR(IF(VLOOKUP($A10,'Annex 2 EHV charges'!$D:$O,10,FALSE)=0,"",VLOOKUP($A10,'Annex 2 EHV charges'!$D:$O,10,FALSE)),"") | G10: =IFERROR(IF(VLOOKUP($A10,'Annex 2 EHV charges'!$D:$O,11,FALSE)=0,"",VLOOKUP($A10,'Annex 2 EHV charges'!$D:$O,11,FALSE)),"") | H10: =IFERROR(IF(VLOOKUP($A10,'Annex 2 EHV charges'!$D:$O,12,FALSE)=0,"",VLOOKUP($A10,'Annex 2 EHV charges'!$D:$O,12,FALSE)),"")
A11: {=IFERROR(INDEX('Annex 2 EHV charges'!$D$10:$D$150, MATCH(0, IF(('Annex 2 EHV charges'!$D$10:$D$150=""),1, COUNTIF(A$4:$A10, 'Annex 2 EHV charges'!$D$10:$D$150)), 0)),"")} -> 804 | B11: =IF($A11="","",VLOOKUP($A11,'Annex 2 EHV charges'!$D:$O,2,0)) -> 804 | C11: =IF($A11="","",VLOOKUP($A11,'Annex 2 EHV charges'!$D:$O,3,0)) -> 1574000324772 | D11: =IF($A11="","",VLOOKUP($A11,'Annex 2 EHV charges'!$D:$O,4,0)) -> EHV Site Specific (LLFC 624 & 804) | E11: =IFERROR(IF(VLOOKUP($A11,'Annex 2 EHV charges'!$D:$O,9,FALSE)=0,"",VLOOKUP($A11,'Annex 2 EHV charges'!$D:$O,9,FALSE)),"") | F11: =IFERROR(IF(VLOOKUP($A11,'Annex 2 EHV charges'!$D:$O,10,FALSE)=0,"",VLOOKUP($A11,'Annex 2 EHV charges'!$D:$O,10,FALSE)),"") -> 958.73 | G11: =IFERROR(IF(VLOOKUP($A11,'Annex 2 EHV charges'!$D:$O,11,FALSE)=0,"",VLOOKUP($A11,'Annex 2 EHV charges'!$D:$O,11,FALSE)),"") -> 0.05 | H11: =IFERROR(IF(VLOOKUP($A11,'Annex 2 EHV charges'!$D:$O,12,FALSE)=0,"",VLOOKUP($A11,'Annex 2 EHV charges'!$D:$O,12,FALSE)),"") -> 0.05
A12: {=IFERROR(INDEX('Annex 2 EHV charges'!$D$10:$D$150, MATCH(0, IF(('Annex 2 EHV charges'!$D$10:$D$150=""),1, COUNTIF(A$4:$A11, 'Annex 2 EHV charges'!$D$10:$D$150)), 0)),"")} -> 748 | B12: =IF($A12="","",VLOOKUP($A12,'Annex 2 EHV charges'!$D:$O,2,0)) -> 748 | C12: =IF($A12="","",VLOOKUP($A12,'Annex 2 EHV charges'!$D:$O,3,0)) -> 1594001006893 | D12: =IF($A12="","",VLOOKUP($A12,'Annex 2 EHV charges'!$D:$O,4,0)) -> EHV Site Specific - Generation Exempt (LLFC 625 & 748) | E12: =IFERROR(IF(VLOOKUP($A12,'Annex 2 EHV charges'!$D:$O,9,FALSE)=0,"",VLOOKUP($A12,'Annex 2 EHV charges'!$D:$O,9,FALSE)),"") | F12: =IFERROR(IF(VLOOKUP($A12,'Annex 2 EHV charges'!$D:$O,10,FALSE)=0,"",VLOOKUP($A12,'Annex 2 EHV charges'!$D:$O,10,FALSE)),"") | G12: =IFERROR(IF(VLOOKUP($A12,'Annex 2 EHV charges'!$D:$O,11,FALSE)=0,"",VLOOKUP($A12,'Annex 2 EHV charges'!$D:$O,11,FALSE)),"") | H12: =IFERROR(IF(VLOOKUP($A12,'Annex 2 EHV charges'!$D:$O,12,FALSE)=0,"",VLOOKUP($A12,'Annex 2 EHV charges'!$D:$O,12,FALSE)),"")
A13: {=IFERROR(INDEX('Annex 2 EHV charges'!$D$10:$D$150, MATCH(0, IF(('Annex 2 EHV charges'!$D$10:$D$150=""),1, COUNTIF(A$4:$A12, 'Annex 2 EHV charges'!$D$10:$D$150)), 0)),"")} -> 729 | B13: =IF($A13="","",VLOOKUP($A13,'Annex 2 EHV charges'!$D:$O,2,0)) -> 729 | C13: =IF($A13="","",VLOOKUP($A13,'Annex 2 EHV charges'!$D:$O,3,0)) -> 1574000199083 | D13: =IF($A13="","",VLOOKUP($A13,'Annex 2 EHV charges'!$D:$O,4,0)) -> EHV Site Specific - Generation Exempt (LLFC 627 & 729) | E13: =IFERROR(IF(VLOOKUP($A13,'Annex 2 EHV charges'!$D:$O,9,FALSE)=0,"",VLOOKUP($A13,'Annex 2 EHV charges'!$D:$O,9,FALSE)),"") | F13: =IFERROR(IF(VLOOKUP($A13,'Annex 2 EHV charges'!$D:$O,10,FALSE)=0,"",VLOOKUP($A13,'Annex 2 EHV charges'!$D:$O,10,FALSE)),"") | G13: =IFERROR(IF(VLOOKUP($A13,'Annex 2 EHV charges'!$D:$O,11,FALSE)=0,"",VLOOKUP($A13,'Annex 2 EHV charges'!$D:$O,11,FALSE)),"") | H13: =IFERROR(IF(VLOOKUP($A13,'Annex 2 EHV charges'!$D:$O,12,FALSE)=0,"",VLOOKUP($A13,'Annex 2 EHV charges'!$D:$O,12,FALSE)),"")
A14: {=IFERROR(INDEX('Annex 2 EHV charges'!$D$10:$D$150, MATCH(0, IF(('Annex 2 EHV charges'!$D$10:$D$150=""),1, COUNTIF(A$4:$A13, 'Annex 2 EHV charges'!$D$10:$D$150)), 0)),"")} -> 728 | B14: =IF($A14="","",VLOOKUP($A14,'Annex 2 EHV charges'!$D:$O,2,0)) -> 728 | C14: =IF($A14="","",VLOOKUP($A14,'Annex 2 EHV charges'!$D:$O,3,0)) -> 1594001141547 | D14: =IF($A14="","",VLOOKUP($A14,'Annex 2 EHV charges'!$D:$O,4,0)) -> EHV Site Specific - Generation Exempt (LLFC 637 & 728) | E14: =IFERROR(IF(VLOOKUP($A14,'Annex 2 EHV charges'!$D:$O,9,FALSE)=0,"",VLOOKUP($A14,'Annex 2 EHV charges'!$D:$O,9,FALSE)),"") | F14: =IFERROR(IF(VLOOKUP($A14,'Annex 2 EHV charges'!$D:$O,10,FALSE)=0,"",VLOOKUP($A14,'Annex 2 EHV charges'!$D:$O,10,FALSE)),"") | G14: =IFERROR(IF(VLOOKUP($A14,'Annex 2 EHV charges'!$D:$O,11,FALSE)=0,"",VLOOKUP($A14,'Annex 2 EHV charges'!$D:$O,11,FALSE)),"") | H14: =IFERROR(IF(VLOOKUP($A14,'Annex 2 EHV charges'!$D:$O,12,FALSE)=0,"",VLOOKUP($A14,'Annex 2 EHV charges'!$D:$O,12,FALSE)),"")
A15: {=IFERROR(INDEX('Annex 2 EHV charges'!$D$10:$D$150, MATCH(0, IF(('Annex 2 EHV charges'!$D$10:$D$150=""),1, COUNTIF(A$4:$A14, 'Annex 2 EHV charges'!$D$10:$D$150)), 0)),"")} -> 759 | B15: =IF($A15="","",VLOOKUP($A15,'Annex 2 EHV charges'!$D:$O,2,0)) -> 759 | C15: =IF($A15="","",VLOOKUP($A15,'Annex 2 EHV charges'!$D:$O,3,0)) -> 1574000275033 | D15: =IF($A15="","",VLOOKUP($A15,'Annex 2 EHV charges'!$D:$O,4,0)) -> EHV Site Specific (LLFC 680 & 759) | E15: =IFERROR(IF(VLOOKUP($A15,'Annex 2 EHV charges'!$D:$O,9,FALSE)=0,"",VLOOKUP($A15,'Annex 2 EHV charges'!$D:$O,9,FALSE)),"") | F15: =IFERROR(IF(VLOOKUP($A15,'Annex 2 EHV charges'!$D:$O,10,FALSE)=0,"",VLOOKUP($A15,'Annex 2 EHV charges'!$D:$O,10,FALSE)),"") -> 125.26 | G15: =IFERROR(IF(VLOOKUP($A15,'Annex 2 EHV charges'!$D:$O,11,FALSE)=0,"",VLOOKUP($A15,'Annex 2 EHV charges'!$D:$O,11,FALSE)),"") -> 0.05 | H15: =IFERROR(IF(VLOOKUP($A15,'Annex 2 EHV charges'!$D:$O,12,FALSE)=0,"",VLOOKUP($A15,'Annex 2 EHV charges'!$D:$O,12,FALSE)),"") -> 0.05
A16: {=IFERROR(INDEX('Annex 2 EHV charges'!$D$10:$D$150, MATCH(0, IF(('Annex 2 EHV charges'!$D$10:$D$150=""),1, COUNTIF(A$4:$A15, 'Annex 2 EHV charges'!$D$10:$D$150)), 0)),"")} -> 760 | B16: =IF($A16="","",VLOOKUP($A16,'Annex 2 EHV charges'!$D:$O,2,0)) -> 760 | C16: =IF($A16="","",VLOOKUP($A16,'Annex 2 EHV charges'!$D:$O,3,0)) -> 1574000283735 | D16: =IF($A16="","",VLOOKUP($A16,'Annex 2 EHV charges'!$D:$O,4,0)) -> EHV Site Specific (LLFC 681 & 760) | E16: =IFERROR(IF(VLOOKUP($A16,'Annex 2 EHV charges'!$D:$O,9,FALSE)=0,"",VLOOKUP($A16,'Annex 2 EHV charges'!$D:$O,9,FALSE)),"") | F16: =IFERROR(IF(VLOOKUP($A16,'Annex 2 EHV charges'!$D:$O,10,FALSE)=0,"",VLOOKUP($A16,'Annex 2 EHV charges'!$D:$O,10,FALSE)),"") -> 4277.3 | G16: =IFERROR(IF(VLOOKUP($A16,'Annex 2 EHV charges'!$D:$O,11,FALSE)=0,"",VLOOKUP($A16,'Annex 2 EHV charges'!$D:$O,11,FALSE)),"") -> 0.05 | H16: =IFERROR(IF(VLOOKUP($A16,'Annex 2 EHV charges'!$D:$O,12,FALSE)=0,"",VLOOKUP($A16,'Annex 2 EHV charges'!$D:$O,12,FALSE)),"") -> 0.05
... A39: {=IFERROR(INDEX('Annex 2 EHV charges'!$D$10:$D$150, MATCH(0, IF(('Annex 2 EHV charges'!$D$10:$D$150=""),1, COUNTIF(A$4:$A38, 'Annex 2 EHV charges'!$D$10:$D$150)), 0)),"")} -> 808 | B39: =IF($A39="","",VLOOKUP($A39,'Annex 2 EHV charges'!$D:$O,2,0)) -> 808 | C39: =IF($A39="","",VLOOKUP($A39,'Annex 2 EHV charges'!$D:$O,3,0)) -> 1574000328094 | D39: =IF($A39="","",VLOOKUP($A39,'Annex 2 EHV charges'!$D:$O,4,0)) -> EHV Site Specific (LLFC 566 & 808) | E39: =IFERROR(IF(VLOOKUP($A39,'Annex 2 EHV charges'!$D:$O,9,FALSE)=0,"",VLOOKUP($A39,'Annex 2 EHV charges'!$D:$O,9,FALSE)),"") -> -0.014 | F39: =IFERROR(IF(VLOOKUP($A39,'Annex 2 EHV charges'!$D:$O,10,FALSE)=0,"",VLOOKUP($A39,'Annex 2 EHV charges'!$D:$O,10,FALSE)),"") -> 1990.84 | G39: =IFERROR(IF(VLOOKUP($A39,'Annex 2 EHV charges'!$D:$O,11,FALSE)=0,"",VLOOKUP($A39,'Annex 2 EHV charges'!$D:$O,11,FALSE)),"") -> 0.05 | H39: =IFERROR(IF(VLOOKUP($A39,'Annex 2 EHV charges'!$D:$O,12,FALSE)=0,"",VLOOKUP($A39,'Annex 2 EHV charges'!$D:$O,12,FALSE)),"") -> 0.05

Sheet Annex 3 Preserved charges
A1: Back to Overview
A2: =Overview!B4& " - Effective from "&Overview!D4&" - "&Overview!E4&" LV and HV tariffs" -> Northern Powergrid (Northeast) Ltd - Effective from 1 April 2019 - Final LV and HV tariffs
A3: NHH preserved charges/additional LLFCs
B4: Closed LLFCs | C4: PCs | D4: Unit charge 1 (NHH) p/kWh | E4: Unit charge 2 (NHH) p/kWh | F4: Fixed charge p/MPAN/day
A6: Notes: | B6: Unit time periods are as specified in the SSC.
A11: HH preserved charges/additional LLFCs
B12: Closed LLFCs | C12: PCs | D12: Red/black charge (HH) p/kWh | E12: Amber/yellow charge (HH) p/kWh | F12: Green charge (HH) p/kWh | G12: Fixed charge p/MPAN/day | H12: Capacity charge p/kVA/day | I12: Exceeded capacity charge p/kVA/day | J12: Reactive power charge p/kVArh
A14: Notes: | B14: Time periods
B15: Unit charges in the red time band apply – between 16:00 and 19:30, Monday to Friday including bank holidays.
B16: Unit charges in the amber time band apply – between 08:00 and 16:00; and between 19:30 and 22:00, Monday to Friday including bank holidays.
B17: Unit charges in the green time band apply – between 00:00 and 08:00; and between 22:00 and 24:00, Monday to Friday including bank holidays, and between 00:00 and 24:00 Saturday and Sunday.
B18: All times are UK clock-time.

Sheet Annex 4 LDNO charges
A1: Back to Overview
A2: =Overview!B4& " - Effective from "&Overview!D4&" - "&Overview!E4&" LDNO tariffs" -> Northern Powergrid (Northeast) Ltd - Effective from 1 April 2019 - Final LDNO tariffs
A4: Time Bands for Half Hourly Metered Properties | F4: Time Bands for Half Hourly Unmetered Properties
A5: Time periods | B5: Red Time Band | C5: Amber Time Band | D5: Green Time Band | H5: Black Time Band | I5: Yellow Time Band | J5: Green Time Band
A6: Monday to Friday (Including Bank Holidays) All Year | B6: 16:00 to 19:30 | C6: 08:00 to 16:00 19:30 to 22:00 | D6: 00:00 to 08:00 22:00 to 24:00 | F6: Monday to Friday (Including Bank Holidays) November to February Inclusive | H6: 16:00 to 19:30 | I6: 08:00 to 16:00 19:30 to 22:00 | J6: 00:00 to 08:00 22:00 to 24:00
A7: Saturday and Sunday All Year | D7: 00:00 to 24:00 | F7: Monday to Friday (Including Bank Holidays) April to October Inclusive and March | I7: 08:00 to 22:00 | J7: 00:00 to 08:00 22:00 to 24:00
A8: Notes | B8: All the above times are in UK Clock time | F8: Saturday and Sunday All year | J8: 00:00 to 24:00
F9: Notes | H9: All the above times are in UK Clock time
A11: Tariff name | B11: Unique billing identifier | C11: PCs | D11: ='Annex 1 LV and HV charges'!D11 -> Unit charge 1 (NHH) or red/black charge (HH) p/kWh | E11: ='Annex 1 LV and HV charges'!E11 -> Unit charge 2 (NHH) or amber/yellow charge (HH) p/kWh | F11: ='Annex 1 LV and HV charges'!F11 -> Green charge(HH) p/kWh | G11: ='Annex 1 LV and HV charges'!G11 -> Fixed charge p/MPAN/day | H11: ='Annex 1 LV and HV charges'!H11 -> Capacity charge p/kVA/day | I11: ='Annex 1 LV and HV charges'!I11 -> Exceeded capacity charge p/kVA/day | J11: ='Annex 1 LV and HV charges'!J11 -> Reactive power charge p/kVArh
A12: LDNO LV: Domestic Unrestricted | B12: 150 | C12: 1 | D12: 1.412 | E12: 0 | F12: 0 | G12: 3.29 | H12: 0 | I12: 0 | J12: 0
A13: LDNO LV: Domestic Two Rate | B13: 151 | C13: 2 | D13: 1.603 | E13: 0.678 | F13: 0 | G13: 3.29 | H13: 0 | I13: 0 | J13: 0
A14: LDNO LV: Domestic Off Peak (related MPAN) | B14: 152 | C14: 2 | D14: 0.749 | E14: 0 | F14: 0 | G14: 0 | H14: 0 | I14: 0 | J14: 0
A15: LDNO LV: Small Non Domestic Unrestricted | B15: 153 | C15: 3 | D15: 1.426 | E15: 0 | F15: 0 | G15: 3.5 | H15: 0 | I15: 0 | J15: 0
A16: LDNO LV: Small Non Domestic Two Rate | B16: 154 | C16: 4 | D16: 1.559 | E16: 0.699 | F16: 0 | G16: 3.5 | H16: 0 | I16: 0 | J16: 0
A17: LDNO LV: Small Non Domestic Off Peak (related MPAN) | B17: 155 | C17: 4 | D17: 0.786 | E17: 0 | F17: 0 | G17: 0 | H17: 0 | I17: 0 | J17: 0
A18: LDNO LV: LV Medium Non-Domestic | B18: 156 | C18: 5-8 | D18: 1.373 | E18: 0.671 | F18: 0 | G18: 18.28 | H18: 0 | I18: 0 | J18: 0
A19: LDNO LV: LV Network Domestic | B19: 199 | C19: 0 | D19: 4.536 | E19: 1.145 | F19: 0.67 | G19: 3.29 | H19: 0 | I19: 0 | J19: 0
A20: LDNO LV: LV Network Non-Domestic Non-CT | B20: 206 | C20: 0 | D20: 4.756 | E20: 1.174 | F20: 0.671 | G20: 3.5 | H20: 0 | I20: 0 | J20: 0
A21: LDNO LV: LV HH Metered | B21: 157 | C21: 0 | D21: 3.351 | E21: 0.984 | F21: 0.659 | G21: 9.53 | H21: 1.06 | I21: 2.48 | J21: 0.1
A22: LDNO LV: NHH UMS category A | B22: 37 | C22: 8 | D22: 1.182 | E22: 0 | F22: 0 | G22: 0 | H22: 0 | I22: 0 | J22: 0
A23: LDNO LV: NHH UMS category B | B23: 38 | C23: 1 | D23: 1.369 | E23: 0 | F23: 0 | G23: 0 | H23: 0 | I23: 0 | J23: 0
A24: LDNO LV: NHH UMS category C | B24: 39 | C24: 1 | D24: 1.989 | E24: 0 | F24: 0 | G24: 0 | H24: 0 | I24: 0 | J24: 0
A25: LDNO LV: NHH UMS category D | B25: 40 | C25: 1 | D25: 1.056 | E25: 0 | F25: 0 | G25: 0 | H25: 0 | I25: 0 | J25: 0
A26: LDNO LV: LV UMS (Pseudo HH Metered) | B26: 170 | C26: 0 | D26: 11.021 | E26: 1.088 | F26: 0.667 | G26: 0 | H26: 0 | I26: 0 | J26: 0
A27: LDNO LV: LV Generation NHH or Aggregate HH | B27: 172 | C27: 8&0 | D27: -0.671 | E27: 0 | F27: 0 | G27: 0 | H27: 0 | I27: 0 | J27: 0
A28: LDNO LV: LV Generation Intermittent | B28: 173 | C28: 0 | D28: -0.671 | E28: 0 | F28: 0 | G28: 0 | H28: 0 | I28: 0 | J28: 0.141
A29: LDNO LV: LV Generation Non-Intermittent | B29: 174 | C29: 0 | D29: -4.445 | E29: -0.583 | F29: -0.042 | G29: 0 | H29: 0 | I29: 0 | J29: 0.141
A30: LDNO HV: Domestic Unrestricted | B30: 158 | C30: 1 | D30: 0.858 | E30: 0 | F30: 0 | G30: 2 | H30: 0 | I30: 0 | J30: 0
A31: LDNO HV: Domestic Two Rate | B31: 159 | C31: 2 | D31: 0.975 | E31: 0.412 | F31: 0 | G31: 2 | H31: 0 | I31: 0 | J31: 0
A32: LDNO HV: Domestic Off Peak (related MPAN) | B32: 160 | C32: 2 | D32: 0.456 | E32: 0 | F32: 0 | G32: 0 | H32: 0 | I32: 0 | J32: 0
A33: LDNO HV: Small Non Domestic Unrestricted | B33: 161 | C33: 3 | D33: 0.867 | E33: 0 | F33: 0 | G33: 2.13 | H33: 0 | I33: 0 | J33: 0
A34: LDNO HV: Small Non Domestic Two Rate | B34: 162 | C34: 4 | D34: 0.948 | E34: 0.425 | F34: 0 | G34: 2.13 | H34: 0 | I34: 0 | J34: 0
A35: LDNO HV: Small Non Domestic Off Peak (related MPAN) | B35: 163 | C35: 4 | D35: 0.478 | E35: 0 | F35: 0 | G35: 0 | H35: 0 | I35: 0 | J35: 0
A36: LDNO HV: LV Medium Non-Domestic | B36: 164 | C36: 5-8 | D36: 0.835 | E36: 0.408 | F36: 0 | G36: 11.11 | H36: 0 | I36: 0 | J36: 0
A37: LDNO HV: LV Network Domestic | B37: 207 | C37: 0 | D37: 2.758 | E37: 0.696 | F37: 0.407 | G37: 2 | H37: 0 | I37: 0 | J37: 0
A38: LDNO HV: LV Network Non-Domestic Non-CT | B38: 208 | C38: 0 | D38: 2.892 | E38: 0.714 | F38: 0.408 | G38: 2.13 | H38: 0 | I38: 0 | J38: 0
A39: LDNO HV: LV HH Metered | B39: 165 | C39: 0 | D39: 2.037 | E39: 0.598 | F39: 0.401 | G39: 5.8 | H39: 0.65 | I39: 1.51 | J39: 0.061
A40: LDNO HV: LV Sub HH Metered | B40: 166 | C40: 0 | D40: 2.457 | E40: 0.869 | F40: 0.665 | G40: 9.74 | H40: 1.53 | I40: 2.52 | J40: 0.059
A41: LDNO HV: HV HH Metered | B41: 167 | C41: 0 | D41: 2.46 | E41: 0.99 | F41: 0.814 | G41: 113.79 | H41: 1.8 | I41: 3.25 | J41: 0.05
A42: LDNO HV: NHH UMS category A | B42: 41 | C42: 8 | D42: 0.719 | E42: 0 | F42: 0 | G42: 0 | H42: 0 | I42: 0 | J42: 0
...

Sheet Annex 5 LLFs
A1: Back to Overview
A2: This table has intentionally been left blank. The line loss factors that are approved by the BSC Panel for the applicable year and consequently published on the Elexon website will take precedence and be used in Settlement. This annex will be re-published once these values are available.
A3: =Overview!B4& " - Illustrative LLFs for year beginning "&Overview!D4 -> Northern Powergrid (Northeast) Ltd - Illustrative LLFs for year beginning 1 April 2019
A4: Time periods | B4: Period 1 | C4: Period 2 | D4: Period 3 | E4: Period 4
A5: Monday – Friday (Apr-Oct) | B5: 0 | C5: 0 | D5: 00:30 – 07:30 | E5: 00:00 – 00:30 07:30 – 24:00
A6: Monday – Friday (Nov) | B6: 0 | C6: 07:30 – 20:00 | D6: 00:30 – 07:30 | E6: 00:00 – 00:30 20:00 – 24:00
A7: Monday – Friday (Dec – Feb) | B7: 16:30 – 18:30 | C7: 07:30 – 16:30 18:30 – 20:00 | D7: 00:30 – 07:30 | E7: 00:00 – 00:30 20:00 – 24:00
A8: Monday – Friday (Mar) | B8: 0 | C8: 0 | D8: 00:30 – 07:30 | E8: 00:00 – 00:30 07:30 – 24:00
A9: Saturday and Sunday All Year | B9: 0 | C9: 0 | D9: 00:30 – 07:30 | E9: 00:00 – 00:30 07:30 – 24:00
A10: Notes | B10: All the above times are in UK Clock time
A13: Generic demand and generation LLFs
A14: Metered voltage, respective periods and associated LLFCs
A15: Metered voltage | B15: Period 1 | C15: Period 2 | D15: Period 3 | E15: Period 4 | F15: Associated LLFC
A16: Low Voltage Network | B16: 1.086 | C16: 1.079 | D16: 1.066 | E16: 1.07 | F16: 1, 12, 2, 203, 204, 205, 249, 251, 257, 278, 392, 394, 506, 507, 508, 509, 554, 555, 774, 792, 794, 998, 999
A17: Low Voltage Substation | B17: 1.04 | C17: 1.039 | D17: 1.042 | E17: 1.039 | F17: 265, 293, 393, 395, 776, 793, 795
A18: High Voltage Network | B18: 1.025 | C18: 1.023 | D18: 1.019 | E18: 1.021 | F18: 301, 304, 396, 398, 796, 798
A19: High Voltage Substation | B19: 1.015 | C19: 1.015 | D19: 1.014 | E19: 1.014 | F19: 691, 692, 693, 694, 695, 696, 697, 698, 699, 700, 777, 778, 779, 780, 781
A20: Greater than 22kV connected - generation | B20: 1.01 | C20: 1.01 | D20: 1.008 | E20: 1.009 | F20: 564, 568, 569, 570, 571, 572, 573, 574, 575, 576, 577, 578, 579, 613
A21: Greater than 22kV connected - demand | B21: 1.01 | C21: 1.01 | D21: 1.008 | E21: 1.009 | F21: 803, 810, 811, 812, 813, 814, 815, 816, 817, 818, 819, 820, 821, 822, 823, 824, 825
A23: EHV site specific LLFs
A24: Demand
A25: Site | B25: Period 1 | C25: Period 2 | D25: Period 3 | E25: Period 4 | F25: Associated LLFC
A26: Site 1 | B26: 1.013 | C26: 1.009 | D26: 1.006 | E26: 1.006 | F26: 601
A27: Site 2 | B27: 1.002 | C27: 1.002 | D27: 1.002 | E27: 1.002 | F27: 603
A28: Site 3 | B28: 1.003 | C28: 1.003 | D28: 1.003 | E28: 1.003 | F28: 604
A29: Site 4 | B29: 1.013 | C29: 1.013 | D29: 1.018 | E29: 1.013 | F29: 605
A30: Site 5 | B30: 1.021 | C30: 1.022 | D30: 1.055 | E30: 1.023 | F30: 606
A31: Site 6 | B31: 1.022 | C31: 1.022 | D31: 1.044 | E31: 1.022 | F31: 607
A32: Site 7 | B32: 1.037 | C32: 1.049 | D32: 1.157 | E32: 1.055 | F32: 608
A33: Site 8 | B33: 1.006 | C33: 1.005 | D33: 1.006 | E33: 1.006 | F33: 609
A34: Site 9 | B34: 1.014 | C34: 1.013 | D34: 1.013 | E34: 1.014 | F34: 611
A35: Site 10 | B35: 1.006 | C35: 1.006 | D35: 1.004 | E35: 1.005 | F35: 612
A36: Site 11 | B36: 1.007 | C36: 1.007 | D36: 1.008 | E36: 1.009 | F36: 614
A37: Site 12 | B37: 1.005 | C37: 1.005 | D37: 1.004 | E37: 1.005 | F37: 615
... A80: Site 55 | B80: 1.01 | C80: 1.01 | D80: 1.008 | E80: 1.009 | F80: 566
A82: EHV site specific LLFs
A83: Generation
A84: Site | B84: Period 1 | C84: Period 2 | D84: Period 3 | E84: Period 4 | F84: Associated LLFC
A85: Site 1 | B85: 1.013 | C85: 1.007 | D85: 1.004 | E85: 1.004 | F85: 701
A86: Site 2 | B86: 0.999 | C86: 0.998 | D86: 0.997 | E86: 0.998 | F86: 727
...

Sheet Annex 6 New or Amended EHV
A1: Back to Overview | H1: Note: The list of MPANs/MSIDs provided may be incomplete; the DNO reserves the right to apply the listed charges to any other MPANs/MSIDs associated with the site. If sites appear in both Annex 2 and Annex 6, the charges in Annex 6 take precedence. Where an existing Designated EHV Property is modified and energised in the charging year, we may revise the EDCM charges for the modified Designated EHV Property.
A2: Annex 6 - Charges for New or Amended Designated EHV Properties
A4: =Overview!B4& " - Effective from "&Overview!D4&" - "&Overview!E4&" new designated EHV charges" -> Northern Powergrid (Northeast) Ltd - Effective from 1 April 2019 - Final new designated EHV charges
A5: Effective from date | B5: Import Unique Identifier | C5: LLFC | D5: Import MPANs/MSIDs | E5: Export Unique Identifier | F5: LLFC | G5: Export MPANs/MSIDs | H5: Name | I5: ='Annex 2 EHV charges'!H9 -> Import Super Red unit charge (p/kWh) | J5: ='Annex 2 EHV charges'!I9 -> Import fixed charge (p/day) | K5: ='Annex 2 EHV charges'!J9 -> Import capacity charge (p/kVA/day) | L5: ='Annex 2 EHV charges'!K9 -> Import exceeded capacity charge (p/kVA/day) | M5: ='Annex 2 EHV charges'!L9 -> Export Super Red unit charge (p/kWh) | N5: ='Annex 2 EHV charges'!M9 -> Export fixed charge (p/day) | O5: ='Annex 2 EHV charges'!N9 -> Export capacity charge (p/kVA/day) | P5: ='Annex 2 EHV charges'!O9 -> Export exceeded capacity charge (p/kVA/day)
A17: =Overview!B4& " - Effective from "&Overview!D4&" - "&Overview!E4&" new designated EHV line loss factors" -> Northern Powergrid (Northeast) Ltd - Effective from 1 April 2019 - Final new designated EHV line loss factors
A18: Effective from date | B18: Import Unique Identifier | C18: LLFC | D18: Import MPANs/MSIDs | E18: Export Unique Identifier | F18: LLFC | G18: Export MPANs/MSIDs | H18: Name | I18: Import LLF period 1 | J18: Import LLF period 2 | K18: Import LLF period 3 | L18: Import LLF period 4 | M18: Import LLF period 5 | N18: Export LLF period 1 | O18: Export LLF period 2 | P18: Export LLF period 3 | Q18: Export LLF period 4 | R18: Export LLF period 5

Sheet Nodal prices
A1: Back to Overview
A2: =Overview!B4& " - Effective from "&Overview!D4&" - "&Overview!E4&" Nodal/Zonal charges" -> Northern Powergrid (Northeast) Ltd - Effective from 1 April 2019 - Final Nodal/Zonal charges
A3: Node/Zone ID | B3: Geographical name | C3: Local charge 1 £/kVA | D3: Remote charge 1 £/kVA
A4: Cramlington Biomass | B4: Blyth | C4: 0.039508918 | D4: 0.0034016663
A5: alcan | B5: Blyth | C5: 0 | D5: 0
A6: blyth offshore wf | B6: Blyth | C6: 0 | D6: 0
A7: lynemouth wf | B7: Blyth | C7: 0 | D7: 0
A8: middlemoor wf | B8: Blyth | C8: 2.3856557 | D8: -0.012133454
A9: north steads wf | B9: Blyth | C9: 2.3210547 | D9: -0.011859351
A10: sisters wf | B10: Blyth | C10: 2.3210547 | D10: -0.011859351
A11: wandylaw wf | B11: Blyth | C11: 2.3856706 | D11: -0.012133519
A12: alcan (1001) | B12: Blyth | C12: 0 | D12: 0.0014408679
A13: ashington (1002) | B13: Blyth | C13: 2.2323151 | D13: 1.7890227
A14: benton square (1008) | B14: Blyth | C14: 1.727197 | D14: 3.1196441
A15: cramlington t1 t3 (1015) | B15: Blyth | C15: 0.65691511 | D15: 0.046241662
... A246: west southwick (1062) | B246: West Boldon | C246: 0.08636522 | D246: 0.77185292

Sheet SSC TPR unit rate lookup
A1: Back to Overview
A28: Standard Settlement Configuration Id | B28: Time Pattern Regime Id | C28: Standard Settlement Configuration Desc | D28: Common Decode | G28: Change implemented | H28: Date | I28: Comments
A29: 3 | B29: 166 | C29: 10-hour OP | D29: O | H29: 40057 | I29: First published spreadsheet
