Workbook
Name OLE_LINK1: 'Annex 3 Preserved charges'!#REF!

Sheet Overview
A2: Company and Licence name, charging year, effective from, status.
B3: Company and Licence name | C3: Year | D3: Effective From | E3: Status
A4: Company and Licence name, charging year, effective from, status | B4: SP Distribution | C4: 2018/19 | D4: 1 April 2018 | E4: Final
A6: List of data tables in this workbook
A7: Worksheet | B7: Information
A8: Annex 1 LV and HV charges | B8: Annex 1 contains charges to LV and HV Designated Properties.
A9: Annex 2 EHV charges | B9: ="Annex 2 contains the charges to Designated EHV Properties and charges applied to LDNOs with Designated EHV Properties/end-users embedded in networks within the " &B4 &" Licence area." -> Annex 2 contains the charges to Designated EHV Properties and charges applied to LDNOs with Designated EHV Properties/end-users embedded in networks within the SP Distribution Licence area.
A10: Annex 3 Preserved charges | B10: Annex 3 contains details of any preserved and additional charges that are valid at this time.
A11: Annex 4 LDNO charges | B11: ="Annex 4 contains charges that are levied on the owner of an embedded network within the "&B4&" Licence area. "&"Electricity suppliers and consumers who have properties connected to an embedded network should contact the embedded network owner to determine their distribution charges."&" The charges listed in this table are not payable by domestic consumers, business consumers or electricity suppliers." -> Annex 4 contains charges that are levied on the owner of an embedded network within the SP Distribution Licence area. Electricity suppliers and consumers who have properties connected to an embedded network should contact the embedded network owner to determine their distribution charges. The charges listed in this table are not payable by domestic consumers, business consumers or electricity suppliers.
A12: Annex 5 LLFs | B12: Annex 5 contains illustrative LLFs. LLFs are used in Settlement to adjust the metering system volumes to take account of losses on the distribution network. Illustrative LLFs are provided with reference to the metered voltage or associated LLFC for generic LLFs and by reference to the LLFCs for site specific LLFs. Each LLF is applicable to a defined time period. The LLFs used in Settlement are published on the Elexon portal website, www.elexonportal.co.uk. The website contains the LLFs in standard industry data formats and in a summary form. A user guide with details on registering and using the portal is also available.
A13: Annex 6 new Designated EHV Properties | B13: ="Annex 6 contains the charges to new Designated EHV Properties and charges applied to LDNOs with new Designated EHV Properties/end-users embedded in networks within the " &B4 &" Licence area." -> Annex 6 contains the charges to new Designated EHV Properties and charges applied to LDNOs with new Designated EHV Properties/end-users embedded in networks within the SP Distribution Licence area.
A14: Nodal prices | B14: Contains the underlying [nodal/network group] costs used to calculate the current EDCM charges.
A15: SSC TPR to unit rate lookup table | B15: The time periods for the non half hourly metered charge rates in Annex 1 are as specified by the SSC. To determine the appropriate charge rate for each SSC/TPR a lookup table is provided.
A16: Charge calculator | B16: Charge calculator is a tool to help you estimate your distribution charges using current consumption data and forecast consumption data.
A18: Notes to users of this spreadsheet
A20: Please use this spreadsheet with reference to the LC14 use of system charging statement.
A22: Notes to DNOs populating this spreadsheet
A24: DNOs must endeavour to maintain consistency in the structure of this spreadsheet. Any changes to the structure must be noted in the 'Notes to users of this spreadsheet'
A25: The drop down list on the charge calculator can be expanded by unprotecting the charge calculator sheet and selecting 'data', 'data validation...' and then expanding the 'source' data range. The sheet can then be protected.

Sheet Annex 1 LV and HV charges
A1: Back to Overview | B1: 'DNOs paste value cells A15:J47 from CDCM 3701 into cells A14:J46 | E1: Note: Where a tariff only has a p/kWh unit rate in Unit Charge 1 then this unit rate applies at all times.
A2: =Overview!B4& " - Effective from "&Overview!D4&" - "&Overview!E4&" LV and HV charges" -> SP Distribution - Effective from 1 April 2018 - Final LV and HV charges
A4: Time Bands for Half Hourly Metered Properties | G4: Time Bands for Half Hourly Unmetered Properties
A5: Time periods | B5: Red Time Band | C5: Amber Time Band | E5: Green Time Band | I5: Black Time Band | J5: Yellow Time Band | K5: Green Time Band
A6: Monday to Friday (Including Bank Holidays) All Year | B6: 16.30 - 19.30 | C6: 08.00 - 16.30 19.30 - 22.30 | E6: 00.00 - 08.00 22.30 - 00.00 | G6: Monday to Friday (Including Bank Holidays) June to August Inclusive | J6: 08.00 - 22.30 | K6: 00.00 - 08.00 22.30 - 00.00
A7: Saturday and Sunday All Year | C7: 16.00 - 20.00 | E7: 00.00 - 16.00 20.00 - 00.00 | G7: Monday to Friday (Including Bank Holidays) November to February Inclusive | I7: 16.30 - 19.30 | J7: 08.00 - 16.30 19.30 - 22.30 | K7: 00.00 - 08.00 22.30 - 00.00
A8: Notes | B8: All the above times are in UK Clock time | G8: Monday to Friday (Including Bank Holidays) March, April, May and September, October | J8: 08.00 - 22.30 | K8: 00.00 - 08.00 22.30 - 00.00
G9: Saturday and Sunday All year | J9: 16.00 - 20.00 | K9: 00:00-16:00 20:00-00:00
G10: Notes | I10: All the above times are in UK Clock time
A13: Tariff name | B13: Open LLFCs | C13: PCs | D13: Unit charge 1 (NHH) or red/black charge (HH) p/kWh | E13: Unit charge 2 (NHH) or amber/yellow charge (HH) p/kWh | F13: Green charge(HH) p/kWh | G13: Fixed charge p/MPAN/day | H13: Capacity charge p/kVA/day | I13: Exceeded capacity charge p/kVA/day | J13: Reactive power charge p/kVArh | K13: Closed LLFCs
A14: Domestic Unrestricted | B14: 100, 101, 110, 111, 160, 161 | C14: 1 | D14: 2.416 | G14: 5.02
A15: Domestic Two Rate | B15: 114, 115, 118, 119, 120, 121, 162, 163 | C15: 2 | D15: 2.854 | E15: 1.117 | G15: 5.02
A16: Domestic Off Peak (related MPAN) | B16: 112, 113, 116, 117, 132, 133, 136, 137, 164, 165, 166 | C16: 2 | D16: 1.097 | K16: 130, 134, 135
A17: Small Non Domestic Unrestricted | B17: 201, 204 | C17: 3 | D17: 2.446 | G17: 6.43 | K17: 200, 202, 203, 205
A18: Small Non Domestic Two Rate | B18: 221, 224, 260 | C18: 3&4 | D18: 2.951 | E18: 1.184 | G18: 6.43 | K18: 220, 222
A19: Small Non Domestic Off Peak (related MPAN) | B19: 225, 240, 241, 301, 302 | C19: 3&4 | D19: 1.472 | K19: 223, 242, 243, 244, 245, 246
A20: LV Medium Non-Domestic | B20: 400, 402 | C20: 5-8 | D20: 2.216 | E20: 1.105 | G20: 30.02
A21: LV Sub Medium Non-Domestic | B21: 404 | C21: 5-8 | D21: 1.829 | E21: 1.066 | G21: 0
A22: HV Medium Non-Domestic | C22: 5-8 | D22: 1.465 | E22: 1.016 | G22: 318.78 | K22: 401
A23: LV Network Domestic | B23: 180 | C23: 0 | D23: 8.906 | E23: 1.856 | F23: 1.056 | G23: 5.02
A24: LV Network Non-Domestic Non-CT | B24: 280 | C24: 0 | D24: 9.336 | E24: 1.903 | F24: 1.06 | G24: 6.43
A25: LV HH Metered | B25: 500, 504 | C25: 0 | D25: 7.046 | E25: 1.608 | F25: 1.035 | G25: 25.48 | H25: 2.45 | I25: 3.59 | J25: 0.186
A26: LV Sub HH Metered | B26: 506, 507 | C26: 0 | D26: 5.118 | E26: 1.325 | F26: 1.009 | G26: 8.99 | H26: 4.46 | I26: 5.08 | J26: 0.098
A27: HV HH Metered | B27: 501, 505 | C27: 0 | D27: 3.835 | E27: 1.191 | F27: 0.999 | G27: 136.14 | H27: 4.92 | I27: 6.05 | J27: 0.057
A28: NHH UMS category A | B28: 900 | C28: 1&8 | D28: 2.147 | K28: 904, 908, 909
A29: NHH UMS category B | B29: 901 | C29: 1 | D29: 2.371 | K29: 905
A30: NHH UMS category C | B30: 902 | C30: 1 | D30: 3.159 | K30: 906
A31: NHH UMS category D | B31: 903 | C31: 1 | D31: 1.986 | K31: 907
A32: LV UMS (Pseudo HH Metered) | B32: 910 | C32: 0 | D32: 15.24 | E32: 2.032 | F32: 1.506
A33: LV Generation NHH or Aggregate HH | B33: 781, 782, 783, 784, 785 | C33: 0&8 | D33: -0.762 | G33: 0
A34: LV Sub Generation NHH | B34: 602 | C34: 8 | D34: -0.673 | G34: 0
A35: LV Generation Intermittent | B35: 603, 608 | C35: 0 | D35: -0.762 | G35: 0 | J35: 0.176
A36: LV Generation Intermittent no RP charge | B36: TBA | C36: 0 | D36: -0.762 | G36: 0
A37: LV Generation Non-Intermittent | B37: 604, 607 | C37: 0 | D37: -5.617 | E37: -0.613 | F37: -0.045 | G37: 0 | J37: 0.176
A38: LV Generation Non-Intermittent no RP charge | B38: TBA | C38: 0 | D38: -5.617 | E38: -0.613 | F38: -0.045 | G38: 0
A39: LV Sub Generation Intermittent | B39: 609 | C39: 0 | D39: -0.673 | G39: 0 | J39: 0.155
A40: LV Sub Generation Intermittent no RP charge | B40: TBA | C40: 0 | D40: -0.673 | G40: 0
A41: LV Sub Generation Non-Intermittent | B41: 610 | C41: 0 | D41: -5.025 | E41: -0.529 | F41: -0.038 | G41: 0 | J41: 0.155
A42: LV Sub Generation Non-Intermittent no RP charge | B42: TBA | C42: 0 | D42: -5.025 | E42: -0.529 | F42: -0.038 | G42: 0
A43: HV Generation Intermittent | B43: 611, 612 | C43: 0 | D43: -0.407 | G43: 99.41 | J43: 0.124
...

Sheet Annex 2 EHV charges
A1: Back to Overview | C1: Copy EDCM table 5001 range starting B101 and paste into G11. Extend or reduce print area as required. | F1: Note: The list of MPANs / MSIDs provided may be incomplete; the DNO reserves the right to apply the listed charges to any other MPANs / MSIDs associated with the site.
A2: =Overview!B4& " - Effective from "&Overview!D4&" - "&Overview!E4&" EDCM charges" -> SP Distribution - Effective from 1 April 2018 - Final EDCM charges
A4: Time Periods for Designated EHV Properties
A5: Time periods | D5: Super Red Time Band
A6: Monday to Friday (Including Bank Holidays) June to August Inclusive
A7: Monday to Friday (Including Bank Holidays) November to February Inclusive | D7: 16:30 - 19:30
A8: Notes | D8: All the above times are in UK Clock time
A10: Import Unique Identifier | B10: LLFC | C10: Import MPANs/MSIDs | D10: Export Unique Identifier | E10: LLFC | F10: Export MPANs/MSIDs | G10: Name | H10: Import Super Red unit charge (p/kWh) | I10: Import fixed charge (p/day) | J10: Import capacity charge (p/kVA/day) | K10: Import exceeded capacity charge (p/kVA/day) | L10: Export Super Red unit charge (p/kWh) | M10: Export fixed charge (p/day) | N10: Export capacity charge (p/kVA/day) | O10: Export exceeded capacity charge (p/kVA/day)
A11: 800 | B11: 800 | C11: 1800060775972 | D11: 644 | E11: 644 | F11: 1800060775990 | G11: Rhodders | I11: 352.11 | J11: 1.77 | K11: 1.77 | M11: 5861.03 | N11: 0.05 | O11: 0.05
A12: 801 | B12: 801 | C12: 1800060004220 | D12: MSID 8182 | E12: MSID 8182 | F12: MSID 8182 | G12: Minsca | I12: 504.96
A13: 802 | B13: 802 | C13: 1800060539962 | D13: 683 | E13: 683 | F13: 1800060539971 | G13: Bankend Rig | I13: 144.8 | J13: 4.31 | K13: 4.31 | M13: 5449.73 | N13: 0.05 | O13: 0.05
A14: 803 | B14: 803 | C14: 1800060532708 | D14: 684 | E14: 684 | F14: 1800060532717 | G14: Barlockhart Moor | I14: 176.83 | J14: 2.57 | K14: 2.57 | M14: 9901.7 | N14: 0.05 | O14: 0.05
A15: 804 | B15: 804 | C15: 1800060532726 | D15: 685 | E15: 685 | F15: 1800060532735 | G15: Blantyre Muir | I15: 408.53 | J15: 0.82 | K15: 0.82 | M15: 6437.57 | N15: 0.05 | O15: 0.05
A16: 805 | B16: 805 | C16: 1800060587850 | D16: 693 | E16: 693 | F16: 1800060587869 | G16: Hunterston WF | I16: 117.17 | J16: 0.95 | K16: 0.95 | M16: 8746.35 | N16: 0.05 | O16: 0.05
A17: 806 | B17: 806 | C17: 1800060532647 | D17: 688 | E17: 688 | F17: 1800060532656 | G17: Middleton Farm | I17: 253.36 | J17: 2.55 | K17: 2.55 | M17: 5756.23 | N17: 0.05 | O17: 0.05
A18: 807 | B18: 807 | C18: 1800060532665 | D18: 689 | E18: 689 | F18: 1800060532674 | G18: Neilston Community | I18: 149.6 | J18: 2.65 | K18: 2.65 | M18: 7061.91 | N18: 0.05 | O18: 0.05
A19: 808 | B19: 808 | C19: 1800053653870 | D19: 681 | E19: 681 | F19: 1800053653880 | G19: Garlaff Landfill | I19: 121.27 | J19: 0.8 | K19: 0.8
A20: 809 | B20: 809 | C20: 1800054992968 | D20: 629 | E20: 629 | F20: 1800054992977 | G20: Hagshaw Hill Extension | I20: 792.43 | J20: 0.83 | K20: 0.83 | M20: 20011.69 | N20: 0.05 | O20: 0.05
A21: 811 | B21: 811 | C21: 1800060328035 | D21: 671 | E21: 671 | F21: 1800060328044 | G21: Muirhall | I21: 376.81 | J21: 2.54 | K21: 2.54 | M21: 9043.53 | N21: 0.05 | O21: 0.05
A22: 812 | B22: 812 | C22: 1800060372113 | D22: 672 | E22: 672 | F22: 1800060372122 | G22: Burnfoot | I22: 126.65 | J22: 0.88 | K22: 0.88 | M22: 8837.86 | N22: 0.05 | O22: 0.05
A23: 813 | B23: 813 | C23: 1800060532498 | D23: 690 | E23: 690 | F23: 1800060532503 | G23: Westfield WF | I23: 66.98 | J23: 1.17 | K23: 1.17 | M23: 7868.41 | N23: 0.05 | O23: 0.05
A24: 814 | B24: 814 | C24: 1800060532683 | D24: 691 | E24: 691 | F24: 1800060532692 | G24: Barmoor WF | I24: 222.3 | J24: 2.78 | K24: 2.78 | M24: 21017.15 | N24: 0.05 | O24: 0.05
A25: 815 | B25: 815 | C25: 1800060566984 | D25: 692 | E25: 692 | F25: 1800060566993 | G25: Nutberry WF | I25: 894.83 | J25: 2.53 | K25: 2.53 | M25: 16940.53 | N25: 0.05 | O25: 0.05
A26: 816 | B26: 816 | C26: 1800060652454 | D26: 695 | E26: 695 | F26: 1800060652463 | G26: Carcreugh WF | I26: 346.87 | J26: 0.84 | K26: 0.84 | M26: 7080.28 | N26: 0.05 | O26: 0.05
A27: 817 | B27: 817 | C27: 1800060567668 | G27: Magnox | I27: 408.42 | J27: 1.22 | K27: 1.22
A28: 818 | B28: 818 | C28: 1800060642767 | D28: 700 | E28: 700 | F28: 1800060642776 | G28: West Browncastle WF | I28: 559.7 | J28: 0.86 | K28: 0.86 | M28: 31684.48 | N28: 0.05 | O28: 0.05
A29: 819 | B29: 819 | C29: 1800060632661 | D29: 699 | E29: 699 | F29: 1800060632670 | G29: Viridor (Waste energy) | I29: 1637.93 | J29: 2.63 | K29: 2.63 | M29: 9813.91 | N29: 0.05 | O29: 0.05
A30: 820 | B30: 820 | C30: 1800060289486 | D30: 620 | E30: 620 | F30: 1800060289510 | G30: Craigengelt | I30: 166.72 | J30: 0.94 | K30: 0.94 | M30: 22773.33 | N30: 0.05 | O30: 0.05
A31: 821 | B31: 821 | C31: 1800054865132 | D31: 621 | E31: 621 | F31: 1800054865141 | G31: Greenknowes | I31: 685.59 | J31: 0.91 | K31: 0.91 | M31: 41135.66 | N31: 0.05 | O31: 0.05
A32: 822 | B32: 822 | C32: 1800060683754 | D32: 703 | E32: 703 | F32: 1800060683763 | G32: Ewe Hill Dumfries WF | I32: 522.92 | J32: 2.57 | K32: 2.57 | M32: 23590.95 | N32: 0.05 | O32: 0.05
A33: 823 | B33: 823 | C33: 1800060697223 | D33: 704 | E33: 704 | F33: 1800060697232 | G33: Langhope Rig (D) WF | I33: 47.06 | J33: 1.65 | K33: 1.65 | M33: 1543.31 | N33: 0.05 | O33: 0.05
A34: 824 | B34: 824 | C34: 1800060674253 | D34: 705 | E34: 705 | F34: 1800060674262 | G34: Muirhall Extention WF | I34: 60.32 | J34: 2.62 | K34: 2.62 | M34: 3594.62 | N34: 0.05 | O34: 0.05
A35: 825 | B35: 825 | C35: 1800060159192 | D35: 625 | E35: 625 | F35: 1800060159208 | G35: Aikengall | I35: 1622.47 | M35: 40970.78 | N35: 0.05 | O35: 0.05
A36: 826 | B36: 826 | C36: 1800053646251 | D36: 626 | E36: 626 | F36: 1800053646260 | G36: Hagshaw Hill | I36: 44.62 | J36: 2.62 | K36: 2.62
A37: 827 | B37: 827 | C37: 1800053646190 | D37: 627 | E37: 627 | F37: 1800053646206 | G37: Gallow Rig | I37: 155.6 | J37: 2.54 | K37: 2.54
A38: 828 | B38: 828 | C38: 1800053646172 | D38: 628 | E38: 628 | F38: 1800053646181 | G38: Polwhat Rig | I38: 185.09 | J38: 2.53 | K38: 2.53
A39: 829 | B39: 829 | C39: 1800054738267 | D39: 624 | E39: 624 | F39: 1800054738276 | G39: Greendykeside | I39: 58.62 | J39: 2.65 | K39: 2.65 | M39: 4113.18 | N39: 0.05 | O39: 0.05
A40: 830 | B40: 830 | C40: 1800053647237 | D40: 630 | E40: 630 | F40: 1800053647246 | G40: Dun Law | I40: 38.8 | J40: 2.61 | K40: 2.61
A41: 831 | B41: 831 | C41: 1800053647194 | D41: 631 | E41: 631 | F41: 1800053647200 | G41: EPR Scotland Ltd | I41: 310.1 | J41: 2.71 | K41: 2.71
A42: 832 | B42: 832 | C42: 1800053648027 | D42: 632 | E42: 632 | F42: 1800053648036 | G42: Bowbeat (Emly Bank) | I42: 200.95 | J42: 2.55 | K42: 2.55
...

Sheet Annex 2a Import
A1: Note: The list of MPANs / MSIDs provided may be incomplete; the DNO reserves the right to apply the listed charges to any other MPANs / MSIDs associated with the site. Note: This table is automatically populated based on the content of the tab entitled 'Annex 2 EHV Charges'. The timebands are as shown in Annex 2.
A2: =Overview!B4& " - Effective from "&Overview!D4&" - "&Overview!E4&" EDCM import charges" -> SP Distribution - Effective from 1 April 2018 - Final EDCM import charges
A4: Import Unique Identifier | B4: LLFC | C4: Import MPANs/MSIDs | D4: Name | E4: ='Annex 2 EHV charges'!H10 -> Import Super Red unit charge (p/kWh) | F4: ='Annex 2 EHV charges'!I10 -> Import fixed charge (p/day) | G4: ='Annex 2 EHV charges'!J10 -> Import capacity charge (p/kVA/day) | H4: ='Annex 2 EHV charges'!K10 -> Import exceeded capacity charge (p/kVA/day)
A5: {=IFERROR(INDEX('Annex 2 EHV charges'!$A$11:$A$260, MATCH(0, IF(ISBLANK('Annex 2 EHV charges'!$A$11:$A$260),1, COUNTIF(A$4:$A4, 'Annex 2 EHV charges'!$A$11:$A$260)), 0)),"")} -> 800 | B5: =IF($A5="","",VLOOKUP($A5,'Annex 2 EHV charges'!$A:$O,2,0)) -> 800 | C5: =IF($A5="","",VLOOKUP($A5,'Annex 2 EHV charges'!$A:$O,3,0)) -> 1800060775972 | D5: =IF($A5="","",VLOOKUP($A5,'Annex 2 EHV charges'!$A:$O,7,0)) -> Rhodders | E5: =IFERROR(IF(VLOOKUP($A5,'Annex 2 EHV charges'!$A:$O,8,FALSE)=0,"",VLOOKUP($A5,'Annex 2 EHV charges'!$A:$O,8,FALSE)),"") | F5: =IFERROR(IF(VLOOKUP($A5,'Annex 2 EHV charges'!$A:$O,9,FALSE)=0,"",VLOOKUP($A5,'Annex 2 EHV charges'!$A:$O,9,FALSE)),"") -> 352.11 | G5: =IFERROR(IF(VLOOKUP($A5,'Annex 2 EHV charges'!$A:$O,10,FALSE)=0,"",VLOOKUP($A5,'Annex 2 EHV charges'!$A:$O,10,FALSE)),"") -> 1.77 | H5: =IFERROR(IF(VLOOKUP($A5,'Annex 2 EHV charges'!$A:$O,11,FALSE)=0,"",VLOOKUP($A5,'Annex 2 EHV charges'!$A:$O,11,FALSE)),"") -> 1.77
A6: {=IFERROR(INDEX('Annex 2 EHV charges'!$A$11:$A$260, MATCH(0, IF(ISBLANK('Annex 2 EHV charges'!$A$11:$A$260),1, COUNTIF(A$4:$A5, 'Annex 2 EHV charges'!$A$11:$A$260)), 0)),"")} -> 801 | B6: =IF($A6="","",VLOOKUP($A6,'Annex 2 EHV charges'!$A:$O,2,0)) -> 801 | C6: =IF($A6="","",VLOOKUP($A6,'Annex 2 EHV charges'!$A:$O,3,0)) -> 1800060004220 | D6: =IF($A6="","",VLOOKUP($A6,'Annex 2 EHV charges'!$A:$O,7,0)) -> Minsca | E6: =IFERROR(IF(VLOOKUP($A6,'Annex 2 EHV charges'!$A:$O,8,FALSE)=0,"",VLOOKUP($A6,'Annex 2 EHV charges'!$A:$O,8,FALSE)),"") | F6: =IFERROR(IF(VLOOKUP($A6,'Annex 2 EHV charges'!$A:$O,9,FALSE)=0,"",VLOOKUP($A6,'Annex 2 EHV charges'!$A:$O,9,FALSE)),"") -> 504.96 | G6: =IFERROR(IF(VLOOKUP($A6,'Annex 2 EHV charges'!$A:$O,10,FALSE)=0,"",VLOOKUP($A6,'Annex 2 EHV charges'!$A:$O,10,FALSE)),"") | H6: =IFERROR(IF(VLOOKUP($A6,'Annex 2 EHV charges'!$A:$O,11,FALSE)=0,"",VLOOKUP($A6,'Annex 2 EHV charges'!$A:$O,11,FALSE)),"")
A7: {=IFERROR(INDEX('Annex 2 EHV charges'!$A$11:$A$260, MATCH(0, IF(ISBLANK('Annex 2 EHV charges'!$A$11:$A$260),1, COUNTIF(A$4:$A6, 'Annex 2 EHV charges'!$A$11:$A$260)), 0)),"")} -> 802 | B7: =IF($A7="","",VLOOKUP($A7,'Annex 2 EHV charges'!$A:$O,2,0)) -> 802 | C7: =IF($A7="","",VLOOKUP($A7,'Annex 2 EHV charges'!$A:$O,3,0)) -> 1800060539962 | D7: =IF($A7="","",VLOOKUP($A7,'Annex 2 EHV charges'!$A:$O,7,0)) -> Bankend Rig | E7: =IFERROR(IF(VLOOKUP($A7,'Annex 2 EHV charges'!$A:$O,8,FALSE)=0,"",VLOOKUP($A7,'Annex 2 EHV charges'!$A:$O,8,FALSE)),"") | F7: =IFERROR(IF(VLOOKUP($A7,'Annex 2 EHV charges'!$A:$O,9,FALSE)=0,"",VLOOKUP($A7,'Annex 2 EHV charges'!$A:$O,9,FALSE)),"") -> 144.8 | G7: =IFERROR(IF(VLOOKUP($A7,'Annex 2 EHV charges'!$A:$O,10,FALSE)=0,"",VLOOKUP($A7,'Annex 2 EHV charges'!$A:$O,10,FALSE)),"") -> 4.31 | H7: =IFERROR(IF(VLOOKUP($A7,'Annex 2 EHV charges'!$A:$O,11,FALSE)=0,"",VLOOKUP($A7,'Annex 2 EHV charges'!$A:$O,11,FALSE)),"") -> 4.31
A8: {=IFERROR(INDEX('Annex 2 EHV charges'!$A$11:$A$260, MATCH(0, IF(ISBLANK('Annex 2 EHV charges'!$A$11:$A$260),1, COUNTIF(A$4:$A7, 'Annex 2 EHV charges'!$A$11:$A$260)), 0)),"")} -> 803 | B8: =IF($A8="","",VLOOKUP($A8,'Annex 2 EHV charges'!$A:$O,2,0)) -> 803 | C8: =IF($A8="","",VLOOKUP($A8,'Annex 2 EHV charges'!$A:$O,3,0)) -> 1800060532708 | D8: =IF($A8="","",VLOOKUP($A8,'Annex 2 EHV charges'!$A:$O,7,0)) -> Barlockhart Moor | E8: =IFERROR(IF(VLOOKUP($A8,'Annex 2 EHV charges'!$A:$O,8,FALSE)=0,"",VLOOKUP($A8,'Annex 2 EHV charges'!$A:$O,8,FALSE)),"") | F8: =IFERROR(IF(VLOOKUP($A8,'Annex 2 EHV charges'!$A:$O,9,FALSE)=0,"",VLOOKUP($A8,'Annex 2 EHV charges'!$A:$O,9,FALSE)),"") -> 176.83 | G8: =IFERROR(IF(VLOOKUP($A8,'Annex 2 EHV charges'!$A:$O,10,FALSE)=0,"",VLOOKUP($A8,'Annex 2 EHV charges'!$A:$O,10,FALSE)),"") -> 2.57 | H8: =IFERROR(IF(VLOOKUP($A8,'Annex 2 EHV charges'!$A:$O,11,FALSE)=0,"",VLOOKUP($A8,'Annex 2 EHV charges'!$A:$O,11,FALSE)),"") -> 2.57
A9: {=IFERROR(INDEX('Annex 2 EHV charges'!$A$11:$A$260, MATCH(0, IF(ISBLANK('Annex 2 EHV charges'!$A$11:$A$260),1, COUNTIF(A$4:$A8, 'Annex 2 EHV charges'!$A$11:$A$260)), 0)),"")} -> 804 | B9: =IF($A9="","",VLOOKUP($A9,'Annex 2 EHV charges'!$A:$O,2,0)) -> 804 | C9: =IF($A9="","",VLOOKUP($A9,'Annex 2 EHV charges'!$A:$O,3,0)) -> 1800060532726 | D9: =IF($A9="","",VLOOKUP($A9,'Annex 2 EHV charges'!$A:$O,7,0)) -> Blantyre Muir | E9: =IFERROR(IF(VLOOKUP($A9,'Annex 2 EHV charges'!$A:$O,8,FALSE)=0,"",VLOOKUP($A9,'Annex 2 EHV charges'!$A:$O,8,FALSE)),"") | F9: =IFERROR(IF(VLOOKUP($A9,'Annex 2 EHV charges'!$A:$O,9,FALSE)=0,"",VLOOKUP($A9,'Annex 2 EHV charges'!$A:$O,9,FALSE)),"") -> 408.53 | G9: =IFERROR(IF(VLOOKUP($A9,'Annex 2 EHV charges'!$A:$O,10,FALSE)=0,"",VLOOKUP($A9,'Annex 2 EHV charges'!$A:$O,10,FALSE)),"") -> 0.82 | H9: =IFERROR(IF(VLOOKUP($A9,'Annex 2 EHV charges'!$A:$O,11,FALSE)=0,"",VLOOKUP($A9,'Annex 2 EHV charges'!$A:$O,11,FALSE)),"") -> 0.82
A10: {=IFERROR(INDEX('Annex 2 EHV charges'!$A$11:$A$260, MATCH(0, IF(ISBLANK('Annex 2 EHV charges'!$A$11:$A$260),1, COUNTIF(A$4:$A9, 'Annex 2 EHV charges'!$A$11:$A$260)), 0)),"")} -> 805 | B10: =IF($A10="","",VLOOKUP($A10,'Annex 2 EHV charges'!$A:$O,2,0)) -> 805 | C10: =IF($A10="","",VLOOKUP($A10,'Annex 2 EHV charges'!$A:$O,3,0)) -> 1800060587850 | D10: =IF($A10="","",VLOOKUP($A10,'Annex 2 EHV charges'!$A:$O,7,0)) -> Hunterston WF | E10: =IFERROR(IF(VLOOKUP($A10,'Annex 2 EHV charges'!$A:$O,8,FALSE)=0,"",VLOOKUP($A10,'Annex 2 EHV charges'!$A:$O,8,FALSE)),"") | F10: =IFERROR(IF(VLOOKUP($A10,'Annex 2 EHV charges'!$A:$O,9,FALSE)=0,"",VLOOKUP($A10,'Annex 2 EHV charges'!$A:$O,9,FALSE)),"") -> 117.17 | G10: =IFERROR(IF(VLOOKUP($A10,'Annex 2 EHV charges'!$A:$O,10,FALSE)=0,"",VLOOKUP($A10,'Annex 2 EHV charges'!$A:$O,10,FALSE)),"") -> 0.95 | H10: =IFERROR(IF(VLOOKUP($A10,'Annex 2 EHV charges'!$A:$O,11,FALSE)=0,"",VLOOKUP($A10,'Annex 2 EHV charges'!$A:$O,11,FALSE)),"") -> 0.95
A11: {=IFERROR(INDEX('Annex 2 EHV charges'!$A$11:$A$260, MATCH(0, IF(ISBLANK('Annex 2 EHV charges'!$A$11:$A$260),1, COUNTIF(A$4:$A10, 'Annex 2 EHV charges'!$A$11:$A$260)), 0)),"")} -> 806 | B11: =IF($A11="","",VLOOKUP($A11,'Annex 2 EHV charges'!$A:$O,2,0)) -> 806 | C11: =IF($A11="","",VLOOKUP($A11,'Annex 2 EHV charges'!$A:$O,3,0)) -> 1800060532647 | D11: =IF($A11="","",VLOOKUP($A11,'Annex 2 EHV charges'!$A:$O,7,0)) -> Middleton Farm | E11: =IFERROR(IF(VLOOKUP($A11,'Annex 2 EHV charges'!$A:$O,8,FALSE)=0,"",VLOOKUP($A11,'Annex 2 EHV charges'!$A:$O,8,FALSE)),"") | F11: =IFERROR(IF(VLOOKUP($A11,'Annex 2 EHV charges'!$A:$O,9,FALSE)=0,"",VLOOKUP($A11,'Annex 2 EHV charges'!$A:$O,9,FALSE)),"") -> 253.36 | G11: =IFERROR(IF(VLOOKUP($A11,'Annex 2 EHV charges'!$A:$O,10,FALSE)=0,"",VLOOKUP($A11,'Annex 2 EHV charges'!$A:$O,10,FALSE)),"") -> 2.55 | H11: =IFERROR(IF(VLOOKUP($A11,'Annex 2 EHV charges'!$A:$O,11,FALSE)=0,"",VLOOKUP($A11,'Annex 2 EHV charges'!$A:$O,11,FALSE)),"") -> 2.55
A12: {=IFERROR(INDEX('Annex 2 EHV charges'!$A$11:$A$260, MATCH(0, IF(ISBLANK('Annex 2 EHV charges'!$A$11:$A$260),1, COUNTIF(A$4:$A11, 'Annex 2 EHV charges'!$A$11:$A$260)), 0)),"")} -> 807 | B12: =IF($A12="","",VLOOKUP($A12,'Annex 2 EHV charges'!$A:$O,2,0)) -> 807 | C12: =IF($A12="","",VLOOKUP($A12,'Annex 2 EHV charges'!$A:$O,3,0)) -> 1800060532665 | D12: =IF($A12="","",VLOOKUP($A12,'Annex 2 EHV charges'!$A:$O,7,0)) -> Neilston Community | E12: =IFERROR(IF(VLOOKUP($A12,'Annex 2 EHV charges'!$A:$O,8,FALSE)=0,"",VLOOKUP($A12,'Annex 2 EHV charges'!$A:$O,8,FALSE)),"") | F12: =IFERROR(IF(VLOOKUP($A12,'Annex 2 EHV charges'!$A:$O,9,FALSE)=0,"",VLOOKUP($A12,'Annex 2 EHV charges'!$A:$O,9,FALSE)),"") -> 149.6 | G12: =IFERROR(IF(VLOOKUP($A12,'Annex 2 EHV charges'!$A:$O,10,FALSE)=0,"",VLOOKUP($A12,'Annex 2 EHV charges'!$A:$O,10,FALSE)),"") -> 2.65 | H12: =IFERROR(IF(VLOOKUP($A12,'Annex 2 EHV charges'!$A:$O,11,FALSE)=0,"",VLOOKUP($A12,'Annex 2 EHV charges'!$A:$O,11,FALSE)),"") -> 2.65
A13: {=IFERROR(INDEX('Annex 2 EHV charges'!$A$11:$A$260, MATCH(0, IF(ISBLANK('Annex 2 EHV charges'!$A$11:$A$260),1, COUNTIF(A$4:$A12, 'Annex 2 EHV charges'!$A$11:$A$260)), 0)),"")} -> 808 | B13: =IF($A13="","",VLOOKUP($A13,'Annex 2 EHV charges'!$A:$O,2,0)) -> 808 | C13: =IF($A13="","",VLOOKUP($A13,'Annex 2 EHV charges'!$A:$O,3,0)) -> 1800053653870 | D13: =IF($A13="","",VLOOKUP($A13,'Annex 2 EHV charges'!$A:$O,7,0)) -> Garlaff Landfill | E13: =IFERROR(IF(VLOOKUP($A13,'Annex 2 EHV charges'!$A:$O,8,FALSE)=0,"",VLOOKUP($A13,'Annex 2 EHV charges'!$A:$O,8,FALSE)),"") | F13: =IFERROR(IF(VLOOKUP($A13,'Annex 2 EHV charges'!$A:$O,9,FALSE)=0,"",VLOOKUP($A13,'Annex 2 EHV charges'!$A:$O,9,FALSE)),"") -> 121.27 | G13: =IFERROR(IF(VLOOKUP($A13,'Annex 2 EHV charges'!$A:$O,10,FALSE)=0,"",VLOOKUP($A13,'Annex 2 EHV charges'!$A:$O,10,FALSE)),"") -> 0.8 | H13: =IFERROR(IF(VLOOKUP($A13,'Annex 2 EHV charges'!$A:$O,11,FALSE)=0,"",VLOOKUP($A13,'Annex 2 EHV charges'!$A:$O,11,FALSE)),"") -> 0.8
A14: {=IFERROR(INDEX('Annex 2 EHV charges'!$A$11:$A$260, MATCH(0, IF(ISBLANK('Annex 2 EHV charges'!$A$11:$A$260),1, COUNTIF(A$4:$A13, 'Annex 2 EHV charges'!$A$11:$A$260)), 0)),"")} -> 809 | B14: =IF($A14="","",VLOOKUP($A14,'Annex 2 EHV charges'!$A:$O,2,0)) -> 809 | C14: =IF($A14="","",VLOOKUP($A14,'Annex 2 EHV charges'!$A:$O,3,0)) -> 1800054992968 | D14: =IF($A14="","",VLOOKUP($A14,'Annex 2 EHV charges'!$A:$O,7,0)) -> Hagshaw Hill Extension | E14: =IFERROR(IF(VLOOKUP($A14,'Annex 2 EHV charges'!$A:$O,8,FALSE)=0,"",VLOOKUP($A14,'Annex 2 EHV charges'!$A:$O,8,FALSE)),"") | F14: =IFERROR(IF(VLOOKUP($A14,'Annex 2 EHV charges'!$A:$O,9,FALSE)=0,"",VLOOKUP($A14,'Annex 2 EHV charges'!$A:$O,9,FALSE)),"") -> 792.43 | G14: =IFERROR(IF(VLOOKUP($A14,'Annex 2 EHV charges'!$A:$O,10,FALSE)=0,"",VLOOKUP($A14,'Annex 2 EHV charges'!$A:$O,10,FALSE)),"") -> 0.83 | H14: =IFERROR(IF(VLOOKUP($A14,'Annex 2 EHV charges'!$A:$O,11,FALSE)=0,"",VLOOKUP($A14,'Annex 2 EHV charges'!$A:$O,11,FALSE)),"") -> 0.83
A15: {=IFERROR(INDEX('Annex 2 EHV charges'!$A$11:$A$260, MATCH(0, IF(ISBLANK('Annex 2 EHV charges'!$A$11:$A$260),1, COUNTIF(A$4:$A14, 'Annex 2 EHV charges'!$A$11:$A$260)), 0)),"")} -> 811 | B15: =IF($A15="","",VLOOKUP($A15,'Annex 2 EHV charges'!$A:$O,2,0)) -> 811 | C15: =IF($A15="","",VLOOKUP($A15,'Annex 2 EHV charges'!$A:$O,3,0)) -> 1800060328035 | D15: =IF($A15="","",VLOOKUP($A15,'Annex 2 EHV charges'!$A:$O,7,0)) -> Muirhall | E15: =IFERROR(IF(VLOOKUP($A15,'Annex 2 EHV charges'!$A:$O,8,FALSE)=0,"",VLOOKUP($A15,'Annex 2 EHV charges'!$A:$O,8,FALSE)),"") | F15: =IFERROR(IF(VLOOKUP($A15,'Annex 2 EHV charges'!$A:$O,9,FALSE)=0,"",VLOOKUP($A15,'Annex 2 EHV charges'!$A:$O,9,FALSE)),"") -> 376.81 | G15: =IFERROR(IF(VLOOKUP($A15,'Annex 2 EHV charges'!$A:$O,10,FALSE)=0,"",VLOOKUP($A15,'Annex 2 EHV charges'!$A:$O,10,FALSE)),"") -> 2.54 | H15: =IFERROR(IF(VLOOKUP($A15,'Annex 2 EHV charges'!$A:$O,11,FALSE)=0,"",VLOOKUP($A15,'Annex 2 EHV charges'!$A:$O,11,FALSE)),"") -> 2.54
A16: {=IFERROR(INDEX('Annex 2 EHV charges'!$A$11:$A$260, MATCH(0, IF(ISBLANK('Annex 2 EHV charges'!$A$11:$A$260),1, COUNTIF(A$4:$A15, 'Annex 2 EHV charges'!$A$11:$A$260)), 0)),"")} -> 812 | B16: =IF($A16="","",VLOOKUP($A16,'Annex 2 EHV charges'!$A:$O,2,0)) -> 812 | C16: =IF($A16="","",VLOOKUP($A16,'Annex 2 EHV charges'!$A:$O,3,0)) -> 1800060372113 | D16: =IF($A16="","",VLOOKUP($A16,'Annex 2 EHV charges'!$A:$O,7,0)) -> Burnfoot | E16: =IFERROR(IF(VLOOKUP($A16,'Annex 2 EHV charges'!$A:$O,8,FALSE)=0,"",VLOOKUP($A16,'Annex 2 EHV charges'!$A:$O,8,FALSE)),"") | F16: =IFERROR(IF(VLOOKUP($A16,'Annex 2 EHV charges'!$A:$O,9,FALSE)=0,"",VLOOKUP($A16,'Annex 2 EHV charges'!$A:$O,9,FALSE)),"") -> 126.65 | G16: =IFERROR(IF(VLOOKUP($A16,'Annex 2 EHV charges'!$A:$O,10,FALSE)=0,"",VLOOKUP($A16,'Annex 2 EHV charges'!$A:$O,10,FALSE)),"") -> 0.88 | H16: =IFERROR(IF(VLOOKUP($A16,'Annex 2 EHV charges'!$A:$O,11,FALSE)=0,"",VLOOKUP($A16,'Annex 2 EHV charges'!$A:$O,11,FALSE)),"") -> 0.88
... A254: {=IFERROR(INDEX('Annex 2 EHV charges'!$A$11:$A$260, MATCH(0, IF(ISBLANK('Annex 2 EHV charges'!$A$11:$A$260),1, COUNTIF(A$4:$A253, 'Annex 2 EHV charges'!$A$11:$A$260)), 0)),"")} | B254: =IF($A254="","",VLOOKUP($A254,'Annex 2 EHV charges'!$A:$O,2,0)) | C254: =IF($A254="","",VLOOKUP($A254,'Annex 2 EHV charges'!$A:$O,3,0)) | D254: =IF($A254="","",VLOOKUP($A254,'Annex 2 EHV charges'!$A:$O,7,0)) | E254: =IFERROR(IF(VLOOKUP($A254,'Annex 2 EHV charges'!$A:$O,8,FALSE)=0,"",VLOOKUP($A254,'Annex 2 EHV charges'!$A:$O,8,FALSE)),"") | F254: =IFERROR(IF(VLOOKUP($A254,'Annex 2 EHV charges'!$A:$O,9,FALSE)=0,"",VLOOKUP($A254,'Annex 2 EHV charges'!$A:$O,9,FALSE)),"") | G254: =IFERROR(IF(VLOOKUP($A254,'Annex 2 EHV charges'!$A:$O,10,FALSE)=0,"",VLOOKUP($A254,'Annex 2 EHV charges'!$A:$O,10,FALSE)),"") | H254: =IFERROR(IF(VLOOKUP($A254,'Annex 2 EHV charges'!$A:$O,11,FALSE)=0,"",VLOOKUP($A254,'Annex 2 EHV charges'!$A:$O,11,FALSE)),"")

Sheet Annex 2b Export
A1: Note: The list of MPANs / MSIDs provided may be incomplete; the DNO reserves the right to apply the listed charges to any other MPANs / MSIDs associated with the site. Note: This table is automatically populated based on the content of the tab entitled 'Annex 2 EHV Charges'. The timebands are as shown in Annex 2.
A2: =Overview!B4& " - Effective from "&Overview!D4&" - "&Overview!E4&" EDCM export charges" -> SP Distribution - Effective from 1 April 2018 - Final EDCM export charges
A4: Export Unique Identifier | B4: LLFC | C4: Export MPANs/MSIDs | D4: Name | E4: ='Annex 2 EHV charges'!L10 -> Export Super Red unit charge (p/kWh) | F4: ='Annex 2 EHV charges'!M10 -> Export fixed charge (p/day) | G4: ='Annex 2 EHV charges'!N10 -> Export capacity charge (p/kVA/day) | H4: ='Annex 2 EHV charges'!O10 -> Export exceeded capacity charge (p/kVA/day)
A5: {=IFERROR(INDEX('Annex 2 EHV charges'!$D$11:$D$260, MATCH(0, IF(ISBLANK('Annex 2 EHV charges'!$D$11:$D$260),1, COUNTIF(A$4:$A4, 'Annex 2 EHV charges'!$D$11:$D$260)), 0)),"")} -> 644 | B5: =IF($A5="","",VLOOKUP($A5,'Annex 2 EHV charges'!$D:$O,2,0)) -> 644 | C5: =IF($A5="","",VLOOKUP($A5,'Annex 2 EHV charges'!$D:$O,3,0)) -> 1800060775990 | D5: =IF($A5="","",VLOOKUP($A5,'Annex 2 EHV charges'!$D:$O,4,0)) -> Rhodders | E5: =IFERROR(IF(VLOOKUP($A5,'Annex 2 EHV charges'!$D:$O,9,FALSE)=0,"",VLOOKUP($A5,'Annex 2 EHV charges'!$D:$O,9,FALSE)),"") | F5: =IFERROR(IF(VLOOKUP($A5,'Annex 2 EHV charges'!$D:$O,10,FALSE)=0,"",VLOOKUP($A5,'Annex 2 EHV charges'!$D:$O,10,FALSE)),"") -> 5861.03 | G5: =IFERROR(IF(VLOOKUP($A5,'Annex 2 EHV charges'!$D:$O,11,FALSE)=0,"",VLOOKUP($A5,'Annex 2 EHV charges'!$D:$O,11,FALSE)),"") -> 0.05 | H5: =IFERROR(IF(VLOOKUP($A5,'Annex 2 EHV charges'!$D:$O,12,FALSE)=0,"",VLOOKUP($A5,'Annex 2 EHV charges'!$D:$O,12,FALSE)),"") -> 0.05
A6: {=IFERROR(INDEX('Annex 2 EHV charges'!$D$11:$D$260, MATCH(0, IF(ISBLANK('Annex 2 EHV charges'!$D$11:$D$260),1, COUNTIF(A$4:$A5, 'Annex 2 EHV charges'!$D$11:$D$260)), 0)),"")} -> MSID 8182 | B6: =IF($A6="","",VLOOKUP($A6,'Annex 2 EHV charges'!$D:$O,2,0)) -> MSID 8182 | C6: =IF($A6="","",VLOOKUP($A6,'Annex 2 EHV charges'!$D:$O,3,0)) -> MSID 8182 | D6: =IF($A6="","",VLOOKUP($A6,'Annex 2 EHV charges'!$D:$O,4,0)) -> Minsca | E6: =IFERROR(IF(VLOOKUP($A6,'Annex 2 EHV charges'!$D:$O,9,FALSE)=0,"",VLOOKUP($A6,'Annex 2 EHV charges'!$D:$O,9,FALSE)),"") | F6: =IFERROR(IF(VLOOKUP($A6,'Annex 2 EHV charges'!$D:$O,10,FALSE)=0,"",VLOOKUP($A6,'Annex 2 EHV charges'!$D:$O,10,FALSE)),"") | G6: =IFERROR(IF(VLOOKUP($A6,'Annex 2 EHV charges'!$D:$O,11,FALSE)=0,"",VLOOKUP($A6,'Annex 2 EHV charges'!$D:$O,11,FALSE)),"") | H6: =IFERROR(IF(VLOOKUP($A6,'Annex 2 EHV charges'!$D:$O,12,FALSE)=0,"",VLOOKUP($A6,'Annex 2 EHV charges'!$D:$O,12,FALSE)),"")
A7: {=IFERROR(INDEX('Annex 2 EHV charges'!$D$11:$D$260, MATCH(0, IF(ISBLANK('Annex 2 EHV charges'!$D$11:$D$260),1, COUNTIF(A$4:$A6, 'Annex 2 EHV charges'!$D$11:$D$260)), 0)),"")} -> 683 | B7: =IF($A7="","",VLOOKUP($A7,'Annex 2 EHV charges'!$D:$O,2,0)) -> 683 | C7: =IF($A7="","",VLOOKUP($A7,'Annex 2 EHV charges'!$D:$O,3,0)) -> 1800060539971 | D7: =IF($A7="","",VLOOKUP($A7,'Annex 2 EHV charges'!$D:$O,4,0)) -> Bankend Rig | E7: =IFERROR(IF(VLOOKUP($A7,'Annex 2 EHV charges'!$D:$O,9,FALSE)=0,"",VLOOKUP($A7,'Annex 2 EHV charges'!$D:$O,9,FALSE)),"") | F7: =IFERROR(IF(VLOOKUP($A7,'Annex 2 EHV charges'!$D:$O,10,FALSE)=0,"",VLOOKUP($A7,'Annex 2 EHV charges'!$D:$O,10,FALSE)),"") -> 5449.73 | G7: =IFERROR(IF(VLOOKUP($A7,'Annex 2 EHV charges'!$D:$O,11,FALSE)=0,"",VLOOKUP($A7,'Annex 2 EHV charges'!$D:$O,11,FALSE)),"") -> 0.05 | H7: =IFERROR(IF(VLOOKUP($A7,'Annex 2 EHV charges'!$D:$O,12,FALSE)=0,"",VLOOKUP($A7,'Annex 2 EHV charges'!$D:$O,12,FALSE)),"") -> 0.05
A8: {=IFERROR(INDEX('Annex 2 EHV charges'!$D$11:$D$260, MATCH(0, IF(ISBLANK('Annex 2 EHV charges'!$D$11:$D$260),1, COUNTIF(A$4:$A7, 'Annex 2 EHV charges'!$D$11:$D$260)), 0)),"")} -> 684 | B8: =IF($A8="","",VLOOKUP($A8,'Annex 2 EHV charges'!$D:$O,2,0)) -> 684 | C8: =IF($A8="","",VLOOKUP($A8,'Annex 2 EHV charges'!$D:$O,3,0)) -> 1800060532717 | D8: =IF($A8="","",VLOOKUP($A8,'Annex 2 EHV charges'!$D:$O,4,0)) -> Barlockhart Moor | E8: =IFERROR(IF(VLOOKUP($A8,'Annex 2 EHV charges'!$D:$O,9,FALSE)=0,"",VLOOKUP($A8,'Annex 2 EHV charges'!$D:$O,9,FALSE)),"") | F8: =IFERROR(IF(VLOOKUP($A8,'Annex 2 EHV charges'!$D:$O,10,FALSE)=0,"",VLOOKUP($A8,'Annex 2 EHV charges'!$D:$O,10,FALSE)),"") -> 9901.7 | G8: =IFERROR(IF(VLOOKUP($A8,'Annex 2 EHV charges'!$D:$O,11,FALSE)=0,"",VLOOKUP($A8,'Annex 2 EHV charges'!$D:$O,11,FALSE)),"") -> 0.05 | H8: =IFERROR(IF(VLOOKUP($A8,'Annex 2 EHV charges'!$D:$O,12,FALSE)=0,"",VLOOKUP($A8,'Annex 2 EHV charges'!$D:$O,12,FALSE)),"") -> 0.05
A9: {=IFERROR(INDEX('Annex 2 EHV charges'!$D$11:$D$260, MATCH(0, IF(ISBLANK('Annex 2 EHV charges'!$D$11:$D$260),1, COUNTIF(A$4:$A8, 'Annex 2 EHV charges'!$D$11:$D$260)), 0)),"")} -> 685 | B9: =IF($A9="","",VLOOKUP($A9,'Annex 2 EHV charges'!$D:$O,2,0)) -> 685 | C9: =IF($A9="","",VLOOKUP($A9,'Annex 2 EHV charges'!$D:$O,3,0)) -> 1800060532735 | D9: =IF($A9="","",VLOOKUP($A9,'Annex 2 EHV charges'!$D:$O,4,0)) -> Blantyre Muir | E9: =IFERROR(IF(VLOOKUP($A9,'Annex 2 EHV charges'!$D:$O,9,FALSE)=0,"",VLOOKUP($A9,'Annex 2 EHV charges'!$D:$O,9,FALSE)),"") | F9: =IFERROR(IF(VLOOKUP($A9,'Annex 2 EHV charges'!$D:$O,10,FALSE)=0,"",VLOOKUP($A9,'Annex 2 EHV charges'!$D:$O,10,FALSE)),"") -> 6437.57 | G9: =IFERROR(IF(VLOOKUP($A9,'Annex 2 EHV charges'!$D:$O,11,FALSE)=0,"",VLOOKUP($A9,'Annex 2 EHV charges'!$D:$O,11,FALSE)),"") -> 0.05 | H9: =IFERROR(IF(VLOOKUP($A9,'Annex 2 EHV charges'!$D:$O,12,FALSE)=0,"",VLOOKUP($A9,'Annex 2 EHV charges'!$D:$O,12,FALSE)),"") -> 0.05
A10: {=IFERROR(INDEX('Annex 2 EHV charges'!$D$11:$D$260, MATCH(0, IF(ISBLANK('Annex 2 EHV charges'!$D$11:$D$260),1, COUNTIF(A$4:$A9, 'Annex 2 EHV charges'!$D$11:$D$260)), 0)),"")} -> 693 | B10: =IF($A10="","",VLOOKUP($A10,'Annex 2 EHV charges'!$D:$O,2,0)) -> 693 | C10: =IF($A10="","",VLOOKUP($A10,'Annex 2 EHV charges'!$D:$O,3,0)) -> 1800060587869 | D10: =IF($A10="","",VLOOKUP($A10,'Annex 2 EHV charges'!$D:$O,4,0)) -> Hunterston WF | E10: =IFERROR(IF(VLOOKUP($A10,'Annex 2 EHV charges'!$D:$O,9,FALSE)=0,"",VLOOKUP($A10,'Annex 2 EHV charges'!$D:$O,9,FALSE)),"") | F10: =IFERROR(IF(VLOOKUP($A10,'Annex 2 EHV charges'!$D:$O,10,FALSE)=0,"",VLOOKUP($A10,'Annex 2 EHV charges'!$D:$O,10,FALSE)),"") -> 8746.35 | G10: =IFERROR(IF(VLOOKUP($A10,'Annex 2 EHV charges'!$D:$O,11,FALSE)=0,"",VLOOKUP($A10,'Annex 2 EHV charges'!$D:$O,11,FALSE)),"") -> 0.05 | H10: =IFERROR(IF(VLOOKUP($A10,'Annex 2 EHV charges'!$D:$O,12,FALSE)=0,"",VLOOKUP($A10,'Annex 2 EHV charges'!$D:$O,12,FALSE)),"") -> 0.05
A11: {=IFERROR(INDEX('Annex 2 EHV charges'!$D$11:$D$260, MATCH(0, IF(ISBLANK('Annex 2 EHV charges'!$D$11:$D$260),1, COUNTIF(A$4:$A10, 'Annex 2 EHV charges'!$D$11:$D$260)), 0)),"")} -> 688 | B11: =IF($A11="","",VLOOKUP($A11,'Annex 2 EHV charges'!$D:$O,2,0)) -> 688 | C11: =IF($A11="","",VLOOKUP($A11,'Annex 2 EHV charges'!$D:$O,3,0)) -> 1800060532656 | D11: =IF($A11="","",VLOOKUP($A11,'Annex 2 EHV charges'!$D:$O,4,0)) -> Middleton Farm | E11: =IFERROR(IF(VLOOKUP($A11,'Annex 2 EHV charges'!$D:$O,9,FALSE)=0,"",VLOOKUP($A11,'Annex 2 EHV charges'!$D:$O,9,FALSE)),"") | F11: =IFERROR(IF(VLOOKUP($A11,'Annex 2 EHV charges'!$D:$O,10,FALSE)=0,"",VLOOKUP($A11,'Annex 2 EHV charges'!$D:$O,10,FALSE)),"") -> 5756.23 | G11: =IFERROR(IF(VLOOKUP($A11,'Annex 2 EHV charges'!$D:$O,11,FALSE)=0,"",VLOOKUP($A11,'Annex 2 EHV charges'!$D:$O,11,FALSE)),"") -> 0.05 | H11: =IFERROR(IF(VLOOKUP($A11,'Annex 2 EHV charges'!$D:$O,12,FALSE)=0,"",VLOOKUP($A11,'Annex 2 EHV charges'!$D:$O,12,FALSE)),"") -> 0.05
A12: {=IFERROR(INDEX('Annex 2 EHV charges'!$D$11:$D$260, MATCH(0, IF(ISBLANK('Annex 2 EHV charges'!$D$11:$D$260),1, COUNTIF(A$4:$A11, 'Annex 2 EHV charges'!$D$11:$D$260)), 0)),"")} -> 689 | B12: =IF($A12="","",VLOOKUP($A12,'Annex 2 EHV charges'!$D:$O,2,0)) -> 689 | C12: =IF($A12="","",VLOOKUP($A12,'Annex 2 EHV charges'!$D:$O,3,0)) -> 1800060532674 | D12: =IF($A12="","",VLOOKUP($A12,'Annex 2 EHV charges'!$D:$O,4,0)) -> Neilston Community | E12: =IFERROR(IF(VLOOKUP($A12,'Annex 2 EHV charges'!$D:$O,9,FALSE)=0,"",VLOOKUP($A12,'Annex 2 EHV charges'!$D:$O,9,FALSE)),"") | F12: =IFERROR(IF(VLOOKUP($A12,'Annex 2 EHV charges'!$D:$O,10,FALSE)=0,"",VLOOKUP($A12,'Annex 2 EHV charges'!$D:$O,10,FALSE)),"") -> 7061.91 | G12: =IFERROR(IF(VLOOKUP($A12,'Annex 2 EHV charges'!$D:$O,11,FALSE)=0,"",VLOOKUP($A12,'Annex 2 EHV charges'!$D:$O,11,FALSE)),"") -> 0.05 | H12: =IFERROR(IF(VLOOKUP($A12,'Annex 2 EHV charges'!$D:$O,12,FALSE)=0,"",VLOOKUP($A12,'Annex 2 EHV charges'!$D:$O,12,FALSE)),"") -> 0.05
A13: {=IFERROR(INDEX('Annex 2 EHV charges'!$D$11:$D$260, MATCH(0, IF(ISBLANK('Annex 2 EHV charges'!$D$11:$D$260),1, COUNTIF(A$4:$A12, 'Annex 2 EHV charges'!$D$11:$D$260)), 0)),"")} -> 681 | B13: =IF($A13="","",VLOOKUP($A13,'Annex 2 EHV charges'!$D:$O,2,0)) -> 681 | C13: =IF($A13="","",VLOOKUP($A13,'Annex 2 EHV charges'!$D:$O,3,0)) -> 1800053653880 | D13: =IF($A13="","",VLOOKUP($A13,'Annex 2 EHV charges'!$D:$O,4,0)) -> Garlaff Landfill | E13: =IFERROR(IF(VLOOKUP($A13,'Annex 2 EHV charges'!$D:$O,9,FALSE)=0,"",VLOOKUP($A13,'Annex 2 EHV charges'!$D:$O,9,FALSE)),"") | F13: =IFERROR(IF(VLOOKUP($A13,'Annex 2 EHV charges'!$D:$O,10,FALSE)=0,"",VLOOKUP($A13,'Annex 2 EHV charges'!$D:$O,10,FALSE)),"") | G13: =IFERROR(IF(VLOOKUP($A13,'Annex 2 EHV charges'!$D:$O,11,FALSE)=0,"",VLOOKUP($A13,'Annex 2 EHV charges'!$D:$O,11,FALSE)),"") | H13: =IFERROR(IF(VLOOKUP($A13,'Annex 2 EHV charges'!$D:$O,12,FALSE)=0,"",VLOOKUP($A13,'Annex 2 EHV charges'!$D:$O,12,FALSE)),"")
A14: {=IFERROR(INDEX('Annex 2 EHV charges'!$D$11:$D$260, MATCH(0, IF(ISBLANK('Annex 2 EHV charges'!$D$11:$D$260),1, COUNTIF(A$4:$A13, 'Annex 2 EHV charges'!$D$11:$D$260)), 0)),"")} -> 629 | B14: =IF($A14="","",VLOOKUP($A14,'Annex 2 EHV charges'!$D:$O,2,0)) -> 629 | C14: =IF($A14="","",VLOOKUP($A14,'Annex 2 EHV charges'!$D:$O,3,0)) -> 1800054992977 | D14: =IF($A14="","",VLOOKUP($A14,'Annex 2 EHV charges'!$D:$O,4,0)) -> Hagshaw Hill Extension | E14: =IFERROR(IF(VLOOKUP($A14,'Annex 2 EHV charges'!$D:$O,9,FALSE)=0,"",VLOOKUP($A14,'Annex 2 EHV charges'!$D:$O,9,FALSE)),"") | F14: =IFERROR(IF(VLOOKUP($A14,'Annex 2 EHV charges'!$D:$O,10,FALSE)=0,"",VLOOKUP($A14,'Annex 2 EHV charges'!$D:$O,10,FALSE)),"") -> 20011.69 | G14: =IFERROR(IF(VLOOKUP($A14,'Annex 2 EHV charges'!$D:$O,11,FALSE)=0,"",VLOOKUP($A14,'Annex 2 EHV charges'!$D:$O,11,FALSE)),"") -> 0.05 | H14: =IFERROR(IF(VLOOKUP($A14,'Annex 2 EHV charges'!$D:$O,12,FALSE)=0,"",VLOOKUP($A14,'Annex 2 EHV charges'!$D:$O,12,FALSE)),"") -> 0.05
A15: {=IFERROR(INDEX('Annex 2 EHV charges'!$D$11:$D$260, MATCH(0, IF(ISBLANK('Annex 2 EHV charges'!$D$11:$D$260),1, COUNTIF(A$4:$A14, 'Annex 2 EHV charges'!$D$11:$D$260)), 0)),"")} -> 671 | B15: =IF($A15="","",VLOOKUP($A15,'Annex 2 EHV charges'!$D:$O,2,0)) -> 671 | C15: =IF($A15="","",VLOOKUP($A15,'Annex 2 EHV charges'!$D:$O,3,0)) -> 1800060328044 | D15: =IF($A15="","",VLOOKUP($A15,'Annex 2 EHV charges'!$D:$O,4,0)) -> Muirhall | E15: =IFERROR(IF(VLOOKUP($A15,'Annex 2 EHV charges'!$D:$O,9,FALSE)=0,"",VLOOKUP($A15,'Annex 2 EHV charges'!$D:$O,9,FALSE)),"") | F15: =IFERROR(IF(VLOOKUP($A15,'Annex 2 EHV charges'!$D:$O,10,FALSE)=0,"",VLOOKUP($A15,'Annex 2 EHV charges'!$D:$O,10,FALSE)),"") -> 9043.53 | G15: =IFERROR(IF(VLOOKUP($A15,'Annex 2 EHV charges'!$D:$O,11,FALSE)=0,"",VLOOKUP($A15,'Annex 2 EHV charges'!$D:$O,11,FALSE)),"") -> 0.05 | H15: =IFERROR(IF(VLOOKUP($A15,'Annex 2 EHV charges'!$D:$O,12,FALSE)=0,"",VLOOKUP($A15,'Annex 2 EHV charges'!$D:$O,12,FALSE)),"") -> 0.05
A16: {=IFERROR(INDEX('Annex 2 EHV charges'!$D$11:$D$260, MATCH(0, IF(ISBLANK('Annex 2 EHV charges'!$D$11:$D$260),1, COUNTIF(A$4:$A15, 'Annex 2 EHV charges'!$D$11:$D$260)), 0)),"")} -> 672 | B16: =IF($A16="","",VLOOKUP($A16,'Annex 2 EHV charges'!$D:$O,2,0)) -> 672 | C16: =IF($A16="","",VLOOKUP($A16,'Annex 2 EHV charges'!$D:$O,3,0)) -> 1800060372122 | D16: =IF($A16="","",VLOOKUP($A16,'Annex 2 EHV charges'!$D:$O,4,0)) -> Burnfoot | E16: =IFERROR(IF(VLOOKUP($A16,'Annex 2 EHV charges'!$D:$O,9,FALSE)=0,"",VLOOKUP($A16,'Annex 2 EHV charges'!$D:$O,9,FALSE)),"") | F16: =IFERROR(IF(VLOOKUP($A16,'Annex 2 EHV charges'!$D:$O,10,FALSE)=0,"",VLOOKUP($A16,'Annex 2 EHV charges'!$D:$O,10,FALSE)),"") -> 8837.86 | G16: =IFERROR(IF(VLOOKUP($A16,'Annex 2 EHV charges'!$D:$O,11,FALSE)=0,"",VLOOKUP($A16,'Annex 2 EHV charges'!$D:$O,11,FALSE)),"") -> 0.05 | H16: =IFERROR(IF(VLOOKUP($A16,'Annex 2 EHV charges'!$D:$O,12,FALSE)=0,"",VLOOKUP($A16,'Annex 2 EHV charges'!$D:$O,12,FALSE)),"") -> 0.05
... A254: {=IFERROR(INDEX('Annex 2 EHV charges'!$D$11:$D$260, MATCH(0, IF(ISBLANK('Annex 2 EHV charges'!$D$11:$D$260),1, COUNTIF(A$4:$A253, 'Annex 2 EHV charges'!$D$11:$D$260)), 0)),"")} | B254: =IF($A254="","",VLOOKUP($A254,'Annex 2 EHV charges'!$D:$O,2,0)) | C254: =IF($A254="","",VLOOKUP($A254,'Annex 2 EHV charges'!$D:$O,3,0)) | D254: =IF($A254="","",VLOOKUP($A254,'Annex 2 EHV charges'!$D:$O,4,0)) | E254: =IFERROR(IF(VLOOKUP($A254,'Annex 2 EHV charges'!$D:$O,9,FALSE)=0,"",VLOOKUP($A254,'Annex 2 EHV charges'!$D:$O,9,FALSE)),"") | F254: =IFERROR(IF(VLOOKUP($A254,'Annex 2 EHV charges'!$D:$O,10,FALSE)=0,"",VLOOKUP($A254,'Annex 2 EHV charges'!$D:$O,10,FALSE)),"") | G254: =IFERROR(IF(VLOOKUP($A254,'Annex 2 EHV charges'!$D:$O,11,FALSE)=0,"",VLOOKUP($A254,'Annex 2 EHV charges'!$D:$O,11,FALSE)),"") | H254: =IFERROR(IF(VLOOKUP($A254,'Annex 2 EHV charges'!$D:$O,12,FALSE)=0,"",VLOOKUP($A254,'Annex 2 EHV charges'!$D:$O,12,FALSE)),"")

Sheet Annex 3 Preserved charges
A1: Back to Overview
A2: =Overview!B4& " - Effective from "&Overview!D4&" - "&Overview!E4&" LV and HV tariffs" -> SP Distribution - Effective from 1 April 2018 - Final LV and HV tariffs
A3: NHH preserved charges/additional LLFCs
B4: Closed LLFCs | C4: PCs | D4: Unit charge 1 (NHH) p/kWh | E4: Unit charge 2 (NHH) p/kWh | F4: Unit charge 3 (NHH) p/kWh | G4: Fixed charge p/MPAN/day
A5: Domestic Off Peak (related MPAN) | B5: 130, 134,135 | C5: 2 | D5: 1.097 | F5: 0 | H5: 0 | I5: 0 | J5: 0
A6: Small Non Domestic Unrestricted | B6: 200, 202,203, 205 | C6: 3 | D6: 2.446 | E6: 0 | F6: 0 | G6: 6.43 | H6: 0 | I6: 0 | J6: 0
A7: Small Non Domestic Two Rate | B7: 220, 222 | C7: 4 | D7: 2.951 | E7: 1.184 | F7: 0 | G7: 6.43 | H7: 0 | I7: 0 | J7: 0
A8: Small Non Domestic Off Peak (related MPAN) | B8: 223, 242, 243, 244, 245, 246 | C8: 3&4 | D8: 1.472 | F8: 0 | H8: 0 | I8: 0 | J8: 0
A9: HV Medium Non-Domestic | B9: 401 | C9: 5-8 | D9: 1.465 | E9: 1.016 | F9: 0 | G9: 318.78 | H9: 0 | I9: 0 | J9: 0
A10: Notes: | B10: Unit time periods are as specified in the SSC.
B11: SP Distribution uses a default tariff for invalid settlement combinations these will be charged at the Domestic Unrestricted Rates. The Domestic and Non-Domestic Off Peak (related MPAN) tariffs are supplementary to a standard published tariff and therefore only available under these conditions. Preserved tariffs are only available to existing supplies, subject to certain conditions: a) Suppliers may not normally transfer a meter point from one preserved tariff to another preserved tariff; b) If a supply under a preserved tariff should cease, other than on change of tenancy, the preserved tariff may not normally be restored; c) Any additional load requried to be supplied on the preserved tariff must be within the existing supply capacity.

Sheet Annex 4 LDNO charges
A1: Back to Overview | B1: Copy from CDCM table 3701 "Tariffs!A42:I84" and paste values into A14 | F1: Copy from EDCM table 6005 "LDNORev!B549:G683" and paste values into D57
A2: =Overview!B4& " - Effective from "&Overview!D4&" - "&Overview!E4&" LDNO tariffs" -> SP Distribution - Effective from 1 April 2018 - Final LDNO tariffs
A4: Time Bands for Half Hourly Metered Properties | F4: Time Bands for Half Hourly Unmetered Properties
A5: Time periods | B5: Red Time Band | C5: Amber Time Band | D5: Green Time Band | H5: Black Time Band | I5: Yellow Time Band | J5: Green Time Band
A6: Monday to Friday (Including Bank Holidays) All Year | B6: 16.30 - 19.30 | C6: 08.00 - 16.30 19.30 - 22.30 | D6: 00.00 - 08.00 22.30 - 00.00 | F6: Monday to Friday (Including Bank Holidays) June to August Inclusive | I6: 08.00 - 22.30 | J6: 00.00 - 08.00 22.30 - 00.00
A7: Saturday and Sunday All Year | C7: 16.00 - 20.00 | D7: 00.00 - 16.00 20.00 - 00.00 | F7: Monday to Friday (Including Bank Holidays) November to February Inclusive | H7: 16.30 - 19.30 | I7: 08.00 - 16.30 19.30 - 22.30 | J7: 00.00 - 08.00 22.30 - 00.00
A8: Notes | B8: All the above times are in UK Clock time | F8: Monday to Friday (Including Bank Holidays) March to May, & September to October, Inclusive | I8: 08.00 - 22.30 | J8: 00.00 - 08.00 22.30 - 00.00
F9: Saturday and Sunday | I9: 16.00 - 20.00 | J9: 00:00-16:00 20:00-00:00
F10: Notes | H10: All the above times are in UK Clock time
A13: Tariff name | B13: Unique billing identifier | C13: PCs | D13: ='Annex 1 LV and HV charges'!D13 -> Unit charge 1 (NHH) or red/black charge (HH) p/kWh | E13: ='Annex 1 LV and HV charges'!E13 -> Unit charge 2 (NHH) or amber/yellow charge (HH) p/kWh | F13: ='Annex 1 LV and HV charges'!F13 -> Green charge(HH) p/kWh | G13: ='Annex 1 LV and HV charges'!G13 -> Fixed charge p/MPAN/day | H13: ='Annex 1 LV and HV charges'!H13 -> Capacity charge p/kVA/day | I13: ='Annex 1 LV and HV charges'!I13 -> Exceeded capacity charge p/kVA/day | J13: ='Annex 1 LV and HV charges'!J13 -> Reactive power charge p/kVArh
A14: LDNO LV: Domestic Unrestricted | C14: 1 | D14: 1.481 | G14: 3.08
A15: LDNO LV: Domestic Two Rate | C15: 2 | D15: 1.749 | E15: 0.685 | G15: 3.08
A16: LDNO LV: Domestic Off Peak (related MPAN) | C16: 2 | D16: 0.672
A17: LDNO LV: Small Non Domestic Unrestricted | C17: 3 | D17: 1.499 | G17: 3.94
A18: LDNO LV: Small Non Domestic Two Rate | C18: 4 | D18: 1.809 | E18: 0.726 | G18: 3.94
A19: LDNO LV: Small Non Domestic Off Peak (related MPAN) | C19: 4 | D19: 0.902
A20: LDNO LV: LV Medium Non-Domestic | C20: 5-8 | D20: 1.358 | E20: 0.677 | G20: 18.4
A21: LDNO LV: LV Network Domestic | C21: 0 | D21: 5.459 | E21: 1.138 | F21: 0.647 | G21: 3.08
A22: LDNO LV: LV Network Non-Domestic Non-CT | C22: 0 | D22: 5.723 | E22: 1.166 | F22: 0.65 | G22: 3.94
A23: LDNO LV: LV HH Metered | C23: 0 | D23: 4.319 | E23: 0.986 | F23: 0.634 | G23: 15.62 | H23: 1.5 | I23: 2.2 | J23: 0.114
A24: LDNO LV: NHH UMS category A | C24: 8 | D24: 1.316
A25: LDNO LV: NHH UMS category B | C25: 1 | D25: 1.453
A26: LDNO LV: NHH UMS category C | C26: 1 | D26: 1.936
A27: LDNO LV: NHH UMS category D | C27: 1 | D27: 1.217
A28: LDNO LV: LV UMS (Pseudo HH Metered) | C28: 0 | D28: 9.341 | E28: 1.246 | F28: 0.923
A29: LDNO LV: LV Generation NHH or Aggregate HH | C29: 8&0 | D29: -0.762 | G29: 0
A30: LDNO LV: LV Generation Intermittent | C30: 0 | D30: -0.762 | G30: 0 | J30: 0.176
A31: LDNO LV: LV Generation Non-Intermittent | C31: 0 | D31: -5.617 | E31: -0.613 | F31: -0.045 | G31: 0 | J31: 0.176
A32: LDNO HV: Domestic Unrestricted | C32: 1 | D32: 0.838 | G32: 1.74
A33: LDNO HV: Domestic Two Rate | C33: 2 | D33: 0.99 | E33: 0.387 | G33: 1.74
A34: LDNO HV: Domestic Off Peak (related MPAN) | C34: 2 | D34: 0.38
A35: LDNO HV: Small Non Domestic Unrestricted | C35: 3 | D35: 0.848 | G35: 2.23
A36: LDNO HV: Small Non Domestic Two Rate | C36: 4 | D36: 1.023 | E36: 0.411 | G36: 2.23
A37: LDNO HV: Small Non Domestic Off Peak (related MPAN) | C37: 4 | D37: 0.51
A38: LDNO HV: LV Medium Non-Domestic | C38: 5-8 | D38: 0.768 | E38: 0.383 | G38: 10.41
A39: LDNO HV: LV Network Domestic | C39: 0 | D39: 3.089 | E39: 0.644 | F39: 0.366 | G39: 1.74
A40: LDNO HV: LV Network Non-Domestic Non-CT | C40: 0 | D40: 3.238 | E40: 0.66 | F40: 0.368 | G40: 2.23
A41: LDNO HV: LV HH Metered | C41: 0 | D41: 2.443 | E41: 0.558 | F41: 0.359 | G41: 8.84 | H41: 0.85 | I41: 1.24 | J41: 0.065
A42: LDNO HV: LV Sub HH Metered | C42: 0 | D42: 2.903 | E42: 0.752 | F42: 0.572 | G42: 5.1 | H42: 2.53 | I42: 2.88 | J42: 0.056
A43: LDNO HV: HV HH Metered | C43: 0 | D43: 2.498 | E43: 0.776 | F43: 0.651 | G43: 88.68 | H43: 3.2 | I43: 3.94 | J43: 0.037
...

Sheet Annex 5 LLFs
A1: Back to Overview
A2: These line loss factors are illustrative based on the latest calculated values and are published in good faith. However, the line loss factors that are approved by the BSC Panel for the applicable year and consequently published on the Elexon website will take precedence and be used in Settlement if they differ from these values.
A3: =Overview!B4& " - Illustrative LLFs for year beginning "&Overview!D4 -> SP Distribution - Illustrative LLFs for year beginning 1 April 2018
A4: Time periods | B4: Period 1 | C4: Period 2 | D4: Period 3 | E4: Period 4
A6: Monday to Friday March to October | B6: 23:30 – 07:30 | C6: 07:30 – 23:30
A7: Monday to Friday November to February | B7: 23:30 – 07:30 | C7: 20:00 – 23:30 | D7: 07:30 – 16:00 19:00 – 20:00 | E7: 16:00 – 19:00
A8: Saturday and Sunday All Year | B8: 23:30 – 07:30 | C8: 07:30 – 23:30
A9: Notes | B9: All the above times are in UK Clock time
A12: Generic demand and generation LLFs
A13: Metered voltage, respective periods and associated LLFCs
A14: Metered voltage | B14: Period 1 | C14: Period 2 | D14: Period 3 | E14: Period 4 | F14: Associated LLFC
A15: Low-voltage network | B15: 1.082 | C15: 1.098 | D15: 1.112 | E15: 1.126 | F15: 100,101,110,111,112,113,114,115,116,117,118,119,120,121,130,132,133,134,135,136,137,160,161,162,163,164,165,166,180,200,201,202,203,204,205,220,221,222,223,224,225,240,241,242,243,244,245,246,260,280,400,402,500,504,603,604,607,608,781,782,783,784,785,900,901,902,903,910
A16: Low-voltage substation | B16: 1.045 | C16: 1.044 | D16: 1.046 | E16: 1.049 | F16: 404,506,507,602,609,610
A17: High-voltage network | B17: 1.023 | C17: 1.026 | D17: 1.029 | E17: 1.031 | F17: 301,302,401,501,505,599,600,601,605,606,611,612,615,616,617
A18: High-voltage substation | B18: 1.013 | C18: 1.012 | D18: 1.013 | E18: 1.013 | F18: 310,311,312,313,314,315,316,317,318,319,320,321,322,323,324,325,326,327,328,329,330,331,332,333,334,335,336,337,338,339,340,750,751,752,753,754,755,756,757,758,759,760,761,762,763,764,765,862,866,867
A19: 33kV generic (demand) | B19: 1.003 | C19: 1.004 | D19: 1.005 | E19: 1.005
A20: 33kV generic (generation) | B20: 1 | C20: 1 | D20: 1 | E20: 1
A21: 132kV generic
A22: 132kV generic
A24: EHV site specific LLFs
A25: Demand
A26: Site | B26: Period 1 | C26: Period 2 | D26: Period 3 | E26: Period 4 | F26: Associated LLFC
A27: Rhodders | B27: 1.003 | C27: 1.004 | D27: 1.005 | E27: 1.005 | F27: 800
A28: Minsca | B28: 1 | C28: 1.001 | D28: 1.001 | E28: 1.002 | F28: 801
A29: Bankend Rig | B29: 1.006 | C29: 1.01 | D29: 1.012 | E29: 1.014 | F29: 802
A30: Barlockhart Moor | B30: 1 | C30: 1 | D30: 1 | E30: 1.002 | F30: 803
A31: Blantyre Muir | B31: 1 | C31: 1 | D31: 1 | E31: 1.001 | F31: 804
A32: Hunteston WF | B32: 1 | C32: 1 | D32: 1 | E32: 1 | F32: 805
A33: Middleton Farm | B33: 1.001 | C33: 1.001 | D33: 1.002 | E33: 1.002 | F33: 806
A34: Neilston Community | B34: 1.001 | C34: 1.002 | D34: 1.002 | E34: 1.003 | F34: 807
A35: Garlaff Landfill | B35: 0.999 | C35: 1 | D35: 1.001 | E35: 1.019 | F35: 808
A36: Hagshaw Hill Extension | B36: 1 | C36: 1.001 | D36: 1.002 | E36: 1.002 | F36: 809
A37: Muirhall | B37: 1 | C37: 1 | D37: 1 | E37: 1 | F37: 811
A38: Burnfoot | B38: 1 | C38: 1 | D38: 1 | E38: 1 | F38: 812
... A111: Quixwood Windfarm | B111: 1.003 | C111: 1.004 | D111: 1.005 | E111: 1.005 | F111: 892
A112: Millerhill Windfarm | B112: 1.003 | C112: 1.004 | D112: 1.005 | E112: 1.005 | F112: TBC
A113: Drymen | B113: 0.998 | C113: 0.998 | D113: 0.998 | E113: 0.998 | F113: MSID 8083
A114: Killearn | B114: 1 | C114: 1 | D114: 1 | E114: 1 | F114: MSID 8085
A115: Markinch | B115: 0.999 | C115: 0.999 | D115: 0.998 | E115: 0.997 | F115: MSID 8334
A116: Auchrobert | B116: 1 | C116: 1 | D116: 1 | E116: 1 | F116: MSID 8348
...

Sheet Annex 6 New Designated EHV Prop
A1: Back to Overview | G1: Note: The list of MPANs/MSIDs provided may be incomplete; the DNO reserves the right to apply the listed charges to any other MPANs/MSIDs associated with the site.
A2: Annex 6 - Addendum to Annex 2 EHV charges
A4: =Overview!B4& " - Effective from "&Overview!D4&" - "&Overview!E4&" new designated EHV charges" -> SP Distribution - Effective from 1 April 2018 - Final new designated EHV charges
A5: Import Unique Identifier | B5: LLFC | C5: Import MPANs/MSIDs | D5: Export Unique Identifier | E5: LLFC | F5: Export MPANs/MSIDs | G5: Name | H5: ='Annex 2 EHV charges'!H10 -> Import Super Red unit charge (p/kWh) | I5: ='Annex 2 EHV charges'!I10 -> Import fixed charge (p/day) | J5: ='Annex 2 EHV charges'!J10 -> Import capacity charge (p/kVA/day) | K5: ='Annex 2 EHV charges'!K10 -> Import exceeded capacity charge (p/kVA/day) | L5: ='Annex 2 EHV charges'!L10 -> Export Super Red unit charge (p/kWh) | M5: ='Annex 2 EHV charges'!M10 -> Export fixed charge (p/day) | N5: ='Annex 2 EHV charges'!N10 -> Export capacity charge (p/kVA/day) | O5: ='Annex 2 EHV charges'!O10 -> Export exceeded capacity charge (p/kVA/day)
A6: EDCM import 1 | B6: 848 | C6: 1800060904910 | D6: EDCM export 1 | E6: 648 | F6: 1800060904929 | G6: Craigannet | H6: 0 | I6: 148.44 | J6: 4.49 | K6: 4.49 | L6: 0 | M6: 3180.83 | N6: 0.05 | O6: 0.05
A7: EDCM import 2 | B7: 810 | C7: 1800060954752 | D7: EDCM export 2 | E7: 619 | F7: 1800060954752 | G7: Broxburn ESS | H7: 0 | I7: 1786.25 | J7: 1.71 | K7: 1.71 | L7: 0 | M7: 1786.25 | N7: 0.05 | O7: 0.05
A8: EDCM import 3 | D8: EDCM export 3
A9: EDCM import 4 | D9: EDCM export 4
A10: EDCM import 5 | D10: EDCM export 5
A11: EDCM import 6 | D11: EDCM export 6
A12: EDCM import 7 | D12: EDCM export 7
A13: EDCM import 8 | D13: EDCM export 8
A14: EDCM import 9 | D14: EDCM export 9
A15: EDCM import 10 | D15: EDCM export 10
A17: =Overview!B4& " - Effective from "&Overview!D4&" - "&Overview!E4&" new designated EHV line loss factors" -> SP Distribution - Effective from 1 April 2018 - Final new designated EHV line loss factors
A18: Import Unique Identifier | B18: LLFC | C18: Import MPANs/MSIDs | D18: Export Unique Identifier | E18: LLFC | F18: Export MPANs/MSIDs | G18: Name | H18: Import LLF period 1 | I18: Import LLF period 2 | J18: Import LLF period 3 | K18: Import LLF period 4 | L18: Import LLF period 5 | M18: Export LLF period 1 | N18: Export LLF period 2 | O18: Export LLF period 3 | P18: Export LLF period 4 | Q18: Export LLF period 5
A19: EDCM Import 1 | B19: 848 | C19: 1800060904910 | D19: EDCM export 1 | E19: 648 | F19: 1800060904929 | G19: Craigannet | H19: 1.003 | I19: 1.004 | J19: 1.005 | K19: 1.005 | M19: 1 | N19: 1 | O19: 1 | P19: 1
A20: EDCM Import 2 | B20: 810 | C20: 1800060954752 | D20: EDCM export 2 | E20: 619 | F20: 1800060954752 | G20: Broxburn ESS | H20: 1 | I20: 1 | J20: 1 | K20: 1 | M20: 1.003 | N20: 1.004 | O20: 1.005 | P20: 1.005
A21: EDCM Import 3 | D21: EDCM Export 3
A22: EDCM Import 4 | D22: EDCM Export 4
A23: EDCM Import 5 | D23: EDCM Export 5
A24: EDCM Import 6 | D24: EDCM Export 6
A25: EDCM Import 7 | D25: EDCM Export 7
A26: EDCM Import 8 | D26: EDCM Export 8
A27: EDCM Import 9 | D27: EDCM Export 9
A28: EDCM Import 10 | D28: EDCM Export 10

Sheet Nodal prices
A1: Back to Overview
A2: =Overview!B4& " - Effective from "&Overview!D4&" - "&Overview!E4&" Nodal/Zonal charges" -> SP Distribution - Effective from 1 April 2018 - Final Nodal/Zonal charges
A3: Node/Zone ID | B3: Geographical name | C3: Local charge 1 £/kVA | D3: Remote charge 1 £/kVA
A4: KILBOWIE 33kV | B4: 2
A5: STRATHLEVEN | B5: 2
A6: CUMBERNAULD | B6: 2
A7: ST ANDREWS CROSS | B7: 2
A8: DUNBAR | B8: 2
A9: COATBRIDGE | B9: 2
A10: GLENLUCE | B10: 2
A11: NEWARTHILL | B11: 2
A12: DEVONSIDE | B12: 2
A13: LIVINGSTON EAST | B13: 2
A14: CHAPELCROSS | B14: 2
A15: LINMILL | B15: 2
A16: DEWAR PLACE & SHRUBHILL | B16: 2 | D16: 1.5745304
A17: LEVEN | B17: 2
A18: DRUMCHAPEL | B18: 2
A19: JOHNSTONE | B19: 2
A20: E KILBRIDE SOUTH | B20: 2
A21: BATHGATE | B21: 2
A22: DALMARNOCK | B22: 2
A23: MAYBOLE | B23: 2
A24: CUPAR | B24: 2 | D24: 12.94645
A25: CROOKSTON A | B25: 2
A26: GRANGEMOUTH A | B26: 2
A27: EASTERHOUSE | B27: 2
A28: AYR | B28: 2 | D28: 4.190074
A29: COYLTON | B29: 2
A30: BERWICK & ECCLES & GALASHIELDS | B30: 2
A31: SIGHTHILL | B31: 2
A32: WESTBURN ROAD | B32: 2
A33: BAINSFORD | B33: 2
A34: DEVOL MOOR | B34: 2
A35: KILLERMONT | B35: 2
A36: DUNFERMLINE | B36: 2
A37: KILMARNOCK SOUTH | B37: 2 | D37: 6.3394456
A38: PAISLEY | B38: 2
A39: KILMARNOCK TOWN | B39: 2
A40: WISHAW | B40: 2
...

Sheet SSC TPR unit rate lookup
A1: Back to Overview
A28: Standard Settlement Configuration Id | B28: Time Pattern Regime Id | C28: Standard Settlement Configuration Desc | D28: Common Decode | G28: Change implemented | H28: Date | I28: Comments
A29: 3 | B29: 166 | C29: 10-hour OP | D29: O | H29: 40057 | I29: First published spreadsheet
A30: 4 | B30: 168 | C30: 10-hour OP | D30: O | G30: SSC 0330 charge rates corrected | H30: 40275 | I30: Previous Off-peak rate corrected to charge 2
A31: 5 | B31: 100 | C31: 10-hour OP + w/e | D31: O | G31: SSC 0250 charge rate corrected | H31: 40347 | I31: Previous rate 1 corrected to Off Peak O
A32: 6 | B32: 257 | C32: 10.5-hour OP | D32: O | G32: SSC 0134 charge rate corrected | H32: 41166 | I32: TPR 00101 corrected from Off Peak O to Rate 1
A33: 7 | B33: 158 | C33: 10.5-hour OP | D33: O | G33: New SSCs added | H33: 41178 | I33: New SSCs from 0953 added.
A34: 8 | B34: 159 | C34: 10.5-hour OP | D34: O | G34: SSC 0394 charge rate corrected | H34: 41758 | I34: TPR 01177 corrected to rate 2
A35: 9 | B35: 1111 | C35: 10.5-hour OP | D35: O | G35: Table reviewed and updated | H35: 41758 | I35: New SSCs from 0949 to 0952, 0975 & 0976 and 0982 & 0983 added.
A36: 10 | B36: 1104 | C36: 10.5-hour OP | D36: O | G36: Table reviewed and updated | H36: 41944 | I36: New SSCs from 0984 and 0985 added.
A37: 11 | B37: 1112 | C37: 10.5-hour OP | D37: O | G37: SSC 0313 charge code corrected | H37: 42081 | I37: TPR 01006 corrected to code O
A38: 12 | B38: 1116 | C38: 10.5-hour OP | D38: O | G38: SSC 0320 charge code corrected | H38: 42081 | I38: TPR 00072 corrected to code 2
A39: 13 | B39: 139 | C39: 11 Hour OP | D39: EMEB or MIDE only | G39: SSC 0781 charge code corrected | H39: 42081 | I39: TPR 00327 corrected to code O
A40: 15 | B40: 152 | C40: 11 Hour OP | D40: EMEB or MIDE only | G40: SSC 0935 charge code corrected | H40: 42081 | I40: TPR 00375 corrected to code 1 or Unsupported (SWAE and SWEB)
A41: 16 | B41: 113 | C41: 11.5-hour OP | D41: Unsupported (SWEB) | G41: SSC 0953 charge code corrected | H41: 42081 | I41: TPR 00424 corrected to code 1 or Unsupported (SWAE and SWEB)
... A74: 50 | B74: 14 | C74: 12-hour OP + w/e & Summer | D74: O | G74: SSC 0942 charge code corrected | H74: 42166 | I74: TPR 00400 corrected to code 1
